Workbook
Name Slicer_Climate_Year: #N/A
Name Slicer_Generator_ID: #N/A
Name Slicer_Parameter: #N/A
Name Slicer_Sector: #N/A

Sheet variantdata
A1: variant | B1: option | C1: default | D1: check | E1: description
A2: dh-level | B2: national | D2: totals | E2: one heat node per country
A3: dh-level | B3: capitals | C3: yes | D3: totals | E3: capital region, rest of the country
A4: dh-level | B4: cities | D4: totals | E4: major cities separately

Sheet nodedata
A1: Country | B1: Grid | C1: Node_suffix | D1: Scenario | E1: Year | F1: variant | G1: upwardLimit | H1: reference | I1: balancePenalty | J1: selfDischargeLoss | K1: maxSpill | N1: ## | O1: ## capitals grouping | P1: ## | Q1: ## | R1: ## | S1: ## | T1: ## | U1: ##
A2: ## FI cities
A3: FI00 | B3: dheat | C3: ESP | D3: all | E3: 1 | F3: dh-level:cities | I3: 4000 | K3: =Q3 -> 52 | O3: =_xlfn.XLOOKUP(Table2[[#This Row],[Node_suffix]],$S$4:$S$11,$T$4:$T$11) -> HKI | Q3: =ROUND(SUMIFS(demanddata_dh!$G:$G,demanddata_dh!$A:$A,A3, demanddata_dh!$C:$C,$C3, demanddata_dh!$E:$E,2030, demanddata_dh!$F:$F,Table2[[#This Row],[variant]])*10^6/8760 * 0.2, 0) -> 52 | S3: cities | T3: capitals
A4: FI00 | B4: dheat | C4: ROF | D4: all | E4: 1 | F4: dh-level:cities | I4: 4000 | K4: =Q4 -> 466 | O4: =_xlfn.XLOOKUP(Table2[[#This Row],[Node_suffix]],$S$4:$S$11,$T$4:$T$11) -> ROF | Q4: =ROUND(SUMIFS(demanddata_dh!$G:$G,demanddata_dh!$A:$A,A4, demanddata_dh!$C:$C,$C4, demanddata_dh!$E:$E,2030, demanddata_dh!$F:$F,Table2[[#This Row],[variant]])*10^6/8760 * 0.2, 0) -> 466 | S4: HKI | T4: HKI
A5: FI00 | B5: dheat | C5: HKI | D5: all | E5: 1 | F5: dh-level:cities | I5: 4000 | K5: =Q5 -> 154 | O5: =_xlfn.XLOOKUP(Table2[[#This Row],[Node_suffix]],$S$4:$S$11,$T$4:$T$11) -> HKI | Q5: =ROUND(SUMIFS(demanddata_dh!$G:$G,demanddata_dh!$A:$A,A5, demanddata_dh!$C:$C,$C5, demanddata_dh!$E:$E,2030, demanddata_dh!$F:$F,Table2[[#This Row],[variant]])*10^6/8760 * 0.2, 0) -> 154 | S5: ESP | T5: HKI
A6: FI00 | B6: dheat | C6: JKL | D6: all | E6: 1 | F6: dh-level:cities | I6: 4000 | K6: =Q6 -> 28 | O6: =_xlfn.XLOOKUP(Table2[[#This Row],[Node_suffix]],$S$4:$S$11,$T$4:$T$11) -> ROF | Q6: =ROUND(SUMIFS(demanddata_dh!$G:$G,demanddata_dh!$A:$A,A6, demanddata_dh!$C:$C,$C6, demanddata_dh!$E:$E,2030, demanddata_dh!$F:$F,Table2[[#This Row],[variant]])*10^6/8760 * 0.2, 0) -> 28 | S6: VAN | T6: HKI
A7: FI00 | B7: dheat | C7: OUL | D7: all | E7: 1 | F7: dh-level:cities | I7: 4000 | K7: =Q7 -> 45 | O7: =_xlfn.XLOOKUP(Table2[[#This Row],[Node_suffix]],$S$4:$S$11,$T$4:$T$11) -> ROF | Q7: =ROUND(SUMIFS(demanddata_dh!$G:$G,demanddata_dh!$A:$A,A7, demanddata_dh!$C:$C,$C7, demanddata_dh!$E:$E,2030, demanddata_dh!$F:$F,Table2[[#This Row],[variant]])*10^6/8760 * 0.2, 0) -> 45 | S7: TKU | T7: ROF
A8: FI00 | B8: dheat | C8: TRE | D8: all | E8: 1 | F8: dh-level:cities | I8: 4000 | K8: =Q8 -> 51 | O8: =_xlfn.XLOOKUP(Table2[[#This Row],[Node_suffix]],$S$4:$S$11,$T$4:$T$11) -> ROF | Q8: =ROUND(SUMIFS(demanddata_dh!$G:$G,demanddata_dh!$A:$A,A8, demanddata_dh!$C:$C,$C8, demanddata_dh!$E:$E,2030, demanddata_dh!$F:$F,Table2[[#This Row],[variant]])*10^6/8760 * 0.2, 0) -> 51 | S8: TRE | T8: ROF
A9: FI00 | B9: dheat | C9: TKU | D9: all | E9: 1 | F9: dh-level:cities | I9: 4000 | K9: =Q9 -> 46 | O9: =_xlfn.XLOOKUP(Table2[[#This Row],[Node_suffix]],$S$4:$S$11,$T$4:$T$11) -> ROF | Q9: =ROUND(SUMIFS(demanddata_dh!$G:$G,demanddata_dh!$A:$A,A9, demanddata_dh!$C:$C,$C9, demanddata_dh!$E:$E,2030, demanddata_dh!$F:$F,Table2[[#This Row],[variant]])*10^6/8760 * 0.2, 0) -> 46 | S9: OUL | T9: ROF
A10: FI00 | B10: dheat | C10: VAN | D10: all | E10: 1 | F10: dh-level:cities | I10: 4000 | K10: =Q10 -> 44 | O10: =_xlfn.XLOOKUP(Table2[[#This Row],[Node_suffix]],$S$4:$S$11,$T$4:$T$11) -> HKI | Q10: =ROUND(SUMIFS(demanddata_dh!$G:$G,demanddata_dh!$A:$A,A10, demanddata_dh!$C:$C,$C10, demanddata_dh!$E:$E,2030, demanddata_dh!$F:$F,Table2[[#This Row],[variant]])*10^6/8760 * 0.2, 0) -> 44 | S10: JKL | T10: ROF
A11: ## FI capitals | S11: ROF | T11: ROF
A12: FI00 | B12: dheat | C12: HKI | D12: all | E12: 1 | F12: dh-level:capitals | I12: 4000 | K12: =SUMIFS($K$3:$K$10,$O$3:$O$10,Table2[[#This Row],[Node_suffix]]) -> 250
A13: FI00 | B13: dheat | C13: ROF | D13: all | E13: 1 | F13: dh-level:capitals | I13: 4000 | K13: =SUMIFS($K$3:$K$10,$O$3:$O$10,Table2[[#This Row],[Node_suffix]]) -> 636
A14: ## FI national
A15: FI00 | B15: dheat | D15: all | E15: 1 | F15: dh-level:national | I15: 4000 | K15: =K12+K13 -> 886
A16: ## Others national
A17: NOS0 | B17: dheat | D17: all | E17: 1 | I17: 4000 | K17: =Q17 -> 149 | Q17: =ROUND(SUMIFS(demanddata_dh!$G:$G,demanddata_dh!$A:$A,A17, demanddata_dh!$E:$E,2030)*10^6/8760 * 0.2, 0) -> 149
A18: NOM1 | B18: dheat | D18: all | E18: 1 | I18: 4000 | K18: =Q18 -> 21 | Q18: =ROUND(SUMIFS(demanddata_dh!$G:$G,demanddata_dh!$A:$A,A18, demanddata_dh!$E:$E,2030)*10^6/8760 * 0.2, 0) -> 21
A19: NON1 | B19: dheat | D19: all | E19: 1 | I19: 4000 | K19: =Q19 -> 23 | Q19: =ROUND(SUMIFS(demanddata_dh!$G:$G,demanddata_dh!$A:$A,A19, demanddata_dh!$E:$E,2030)*10^6/8760 * 0.2, 0) -> 23
A20: LT00 | B20: dheat | D20: all | E20: 1 | I20: 4000 | K20: =Q20 -> 182 | Q20: =ROUND(SUMIFS(demanddata_dh!$G:$G,demanddata_dh!$A:$A,A20, demanddata_dh!$E:$E,2030)*10^6/8760 * 0.2, 0) -> 182
A21: LV00 | B21: dheat | D21: all | E21: 1 | I21: 4000 | K21: =Q21 -> 229 | Q21: =ROUND(SUMIFS(demanddata_dh!$G:$G,demanddata_dh!$A:$A,A21, demanddata_dh!$E:$E,2030)*10^6/8760 * 0.2, 0) -> 229
A22: EE00 | B22: dheat | D22: all | E22: 1 | I22: 4000 | K22: =Q22 -> 111 | Q22: =ROUND(SUMIFS(demanddata_dh!$G:$G,demanddata_dh!$A:$A,A22, demanddata_dh!$E:$E,2030)*10^6/8760 * 0.2, 0) -> 111
A23: SE01 | B23: dheat | D23: all | E23: 1 | I23: 4000 | K23: =Q23 -> 30 | Q23: =ROUND(SUMIFS(demanddata_dh!$G:$G,demanddata_dh!$A:$A,A23, demanddata_dh!$E:$E,2030)*10^6/8760 * 0.2, 0) -> 30
A24: SE02 | B24: dheat | D24: all | E24: 1 | I24: 4000 | K24: =Q24 -> 117 | Q24: =ROUND(SUMIFS(demanddata_dh!$G:$G,demanddata_dh!$A:$A,A24, demanddata_dh!$E:$E,2030)*10^6/8760 * 0.2, 0) -> 117
A25: SE03 | B25: dheat | D25: all | E25: 1 | I25: 4000 | K25: =Q25 -> 937 | Q25: =ROUND(SUMIFS(demanddata_dh!$G:$G,demanddata_dh!$A:$A,A25, demanddata_dh!$E:$E,2030)*10^6/8760 * 0.2, 0) -> 937
A26: SE04 | B26: dheat | D26: all | E26: 1 | I26: 4000 | K26: =Q26 -> 275 | Q26: =ROUND(SUMIFS(demanddata_dh!$G:$G,demanddata_dh!$A:$A,A26, demanddata_dh!$E:$E,2030)*10^6/8760 * 0.2, 0) -> 275
A27: DKW1 | B27: dheat | D27: all | E27: 1 | I27: 4000 | K27: =Q27 -> 454 | Q27: =ROUND(SUMIFS(demanddata_dh!$G:$G,demanddata_dh!$A:$A,A27, demanddata_dh!$E:$E,2030)*10^6/8760 * 0.2, 0) -> 454
A28: DKE1 | B28: dheat | D28: all | E28: 1 | I28: 4000 | K28: =Q28 -> 398 | Q28: =ROUND(SUMIFS(demanddata_dh!$G:$G,demanddata_dh!$A:$A,A28, demanddata_dh!$E:$E,2030)*10^6/8760 * 0.2, 0) -> 398
... A31: AT00 | B31: dheat | D31: all | E31: 1 | I31: 4000 | K31: =Q31 -> 425 | Q31: =ROUND(SUMIFS(demanddata_dh!$G:$G,demanddata_dh!$A:$A,A31, demanddata_dh!$E:$E,2030)*10^6/8760 * 0.2, 0) -> 425

Sheet demanddata_dh
A1: Country | B1: Grid | C1: Node_suffix | D1: Scenario | E1: Year | F1: Variant | G1: TWh/year | H1: Constant_share
A2: =IF(Finland!B5="","",Finland!B5) -> FI00 | B2: =IF(Finland!C5="","",Finland!C5) -> dheat | C2: =IF(Finland!D5="","",Finland!D5) -> HKI | D2: =IF(Finland!E5="","",Finland!E5) -> all | E2: =IF(Finland!F5="","",Finland!F5) -> 2015 | F2: =IF(Finland!G5="","",Finland!G5) -> dh-level:cities | G2: =IF(Finland!H5="","",Finland!H5) -> 7.073604 | H2: =IF(Finland!I5="","",Finland!I5) -> 0.3
A3: =IF(Finland!B6="","",Finland!B6) -> FI00 | B3: =IF(Finland!C6="","",Finland!C6) -> dheat | C3: =IF(Finland!D6="","",Finland!D6) -> ESP | D3: =IF(Finland!E6="","",Finland!E6) -> all | E3: =IF(Finland!F6="","",Finland!F6) -> 2015 | F3: =IF(Finland!G6="","",Finland!G6) -> dh-level:cities | G3: =IF(Finland!H6="","",Finland!H6) -> 2.3605087 | H3: =IF(Finland!I6="","",Finland!I6) -> 0.3
A4: =IF(Finland!B7="","",Finland!B7) -> FI00 | B4: =IF(Finland!C7="","",Finland!C7) -> dheat | C4: =IF(Finland!D7="","",Finland!D7) -> VAN | D4: =IF(Finland!E7="","",Finland!E7) -> all | E4: =IF(Finland!F7="","",Finland!F7) -> 2015 | F4: =IF(Finland!G7="","",Finland!G7) -> dh-level:cities | G4: =IF(Finland!H7="","",Finland!H7) -> 1.8955076 | H4: =IF(Finland!I7="","",Finland!I7) -> 0.3
A5: =IF(Finland!B8="","",Finland!B8) -> FI00 | B5: =IF(Finland!C8="","",Finland!C8) -> dheat | C5: =IF(Finland!D8="","",Finland!D8) -> TKU | D5: =IF(Finland!E8="","",Finland!E8) -> all | E5: =IF(Finland!F8="","",Finland!F8) -> 2015 | F5: =IF(Finland!G8="","",Finland!G8) -> dh-level:cities | G5: =IF(Finland!H8="","",Finland!H8) -> 2.2187058 | H5: =IF(Finland!I8="","",Finland!I8) -> 0.3
A6: =IF(Finland!B9="","",Finland!B9) -> FI00 | B6: =IF(Finland!C9="","",Finland!C9) -> dheat | C6: =IF(Finland!D9="","",Finland!D9) -> TRE | D6: =IF(Finland!E9="","",Finland!E9) -> all | E6: =IF(Finland!F9="","",Finland!F9) -> 2015 | F6: =IF(Finland!G9="","",Finland!G9) -> dh-level:cities | G6: =IF(Finland!H9="","",Finland!H9) -> 2.2249794 | H6: =IF(Finland!I9="","",Finland!I9) -> 0.3
A7: =IF(Finland!B10="","",Finland!B10) -> FI00 | B7: =IF(Finland!C10="","",Finland!C10) -> dheat | C7: =IF(Finland!D10="","",Finland!D10) -> OUL | D7: =IF(Finland!E10="","",Finland!E10) -> all | E7: =IF(Finland!F10="","",Finland!F10) -> 2015 | F7: =IF(Finland!G10="","",Finland!G10) -> dh-level:cities | G7: =IF(Finland!H10="","",Finland!H10) -> 1.7214878 | H7: =IF(Finland!I10="","",Finland!I10) -> 0.3
A8: =IF(Finland!B11="","",Finland!B11) -> FI00 | B8: =IF(Finland!C11="","",Finland!C11) -> dheat | C8: =IF(Finland!D11="","",Finland!D11) -> JKL | D8: =IF(Finland!E11="","",Finland!E11) -> all | E8: =IF(Finland!F11="","",Finland!F11) -> 2015 | F8: =IF(Finland!G11="","",Finland!G11) -> dh-level:cities | G8: =IF(Finland!H11="","",Finland!H11) -> 1.1858506 | H8: =IF(Finland!I11="","",Finland!I11) -> 0.3
A9: =IF(Finland!B12="","",Finland!B12) -> FI00 | B9: =IF(Finland!C12="","",Finland!C12) -> dheat | C9: =IF(Finland!D12="","",Finland!D12) -> ROF | D9: =IF(Finland!E12="","",Finland!E12) -> all | E9: =IF(Finland!F12="","",Finland!F12) -> 2015 | F9: =IF(Finland!G12="","",Finland!G12) -> dh-level:cities | G9: =IF(Finland!H12="","",Finland!H12) -> 19.449074 | H9: =IF(Finland!I12="","",Finland!I12) -> 0.3
A10: =IF(Finland!B13="","",Finland!B13) -> FI00 | B10: =IF(Finland!C13="","",Finland!C13) -> dheat | C10: =IF(Finland!D13="","",Finland!D13) -> HKI | D10: =IF(Finland!E13="","",Finland!E13) -> all | E10: =IF(Finland!F13="","",Finland!F13) -> 2020 | F10: =IF(Finland!G13="","",Finland!G13) -> dh-level:cities | G10: =IF(Finland!H13="","",Finland!H13) -> 7.0888236 | H10: =IF(Finland!I13="","",Finland!I13) -> 0.3
A11: =IF(Finland!B14="","",Finland!B14) -> FI00 | B11: =IF(Finland!C14="","",Finland!C14) -> dheat | C11: =IF(Finland!D14="","",Finland!D14) -> ESP | D11: =IF(Finland!E14="","",Finland!E14) -> all | E11: =IF(Finland!F14="","",Finland!F14) -> 2020 | F11: =IF(Finland!G14="","",Finland!G14) -> dh-level:cities | G11: =IF(Finland!H14="","",Finland!H14) -> 2.3674261 | H11: =IF(Finland!I14="","",Finland!I14) -> 0.3
A12: =IF(Finland!B15="","",Finland!B15) -> FI00 | B12: =IF(Finland!C15="","",Finland!C15) -> dheat | C12: =IF(Finland!D15="","",Finland!D15) -> VAN | D12: =IF(Finland!E15="","",Finland!E15) -> all | E12: =IF(Finland!F15="","",Finland!F15) -> 2020 | F12: =IF(Finland!G15="","",Finland!G15) -> dh-level:cities | G12: =IF(Finland!H15="","",Finland!H15) -> 1.9443748 | H12: =IF(Finland!I15="","",Finland!I15) -> 0.3
A13: =IF(Finland!B16="","",Finland!B16) -> FI00 | B13: =IF(Finland!C16="","",Finland!C16) -> dheat | C13: =IF(Finland!D16="","",Finland!D16) -> TKU | D13: =IF(Finland!E16="","",Finland!E16) -> all | E13: =IF(Finland!F16="","",Finland!F16) -> 2020 | F13: =IF(Finland!G16="","",Finland!G16) -> dh-level:cities | G13: =IF(Finland!H16="","",Finland!H16) -> 2.0964712 | H13: =IF(Finland!I16="","",Finland!I16) -> 0.3
... A69: =IF(Finland!B72="","",Finland!B72) -> FI00 | B69: =IF(Finland!C72="","",Finland!C72) -> dheat | C69: =IF(Finland!D72="","",Finland!D72) | D69: =IF(Finland!E72="","",Finland!E72) -> all | E69: =IF(Finland!F72="","",Finland!F72) -> 2040 | F69: =IF(Finland!G72="","",Finland!G72) -> dh-level:national | G69: =IF(Finland!H72="","",Finland!H72) -> 37.895889 | H69: =IF(Finland!I72="","",Finland!I72) -> 0.3
A70: ## Norway
A71: =IF(Norway!B5="","",Norway!B5) -> NOS0 | B71: =IF(Norway!C5="","",Norway!C5) -> dheat | C71: =IF(Norway!D5="","",Norway!D5) | D71: =IF(Norway!E5="","",Norway!E5) -> all | E71: =IF(Norway!F5="","",Norway!F5) -> 2015 | G71: =IF(Norway!H5="","",Norway!H5) -> 4.2784352 | H71: =IF(Norway!I5="","",Norway!I5) -> 0.3
A72: =IF(Norway!B6="","",Norway!B6) -> NOM1 | B72: =IF(Norway!C6="","",Norway!C6) -> dheat | C72: =IF(Norway!D6="","",Norway!D6) | D72: =IF(Norway!E6="","",Norway!E6) -> all | E72: =IF(Norway!F6="","",Norway!F6) -> 2015 | G72: =IF(Norway!H6="","",Norway!H6) -> 0.61660863 | H72: =IF(Norway!I6="","",Norway!I6) -> 0.3
A73: =IF(Norway!B7="","",Norway!B7) -> NON1 | B73: =IF(Norway!C7="","",Norway!C7) -> dheat | C73: =IF(Norway!D7="","",Norway!D7) | D73: =IF(Norway!E7="","",Norway!E7) -> all | E73: =IF(Norway!F7="","",Norway!F7) -> 2015 | G73: =IF(Norway!H7="","",Norway!H7) -> 0.65078862 | H73: =IF(Norway!I7="","",Norway!I7) -> 0.3
A74: =IF(Norway!B8="","",Norway!B8) -> NOS0 | B74: =IF(Norway!C8="","",Norway!C8) -> dheat | C74: =IF(Norway!D8="","",Norway!D8) | D74: =IF(Norway!E8="","",Norway!E8) -> all | E74: =IF(Norway!F8="","",Norway!F8) -> 2020 | G74: =IF(Norway!H8="","",Norway!H8) -> 5.3214366 | H74: =IF(Norway!I8="","",Norway!I8) -> 0.3
A75: =IF(Norway!B9="","",Norway!B9) -> NOM1 | B75: =IF(Norway!C9="","",Norway!C9) -> dheat | C75: =IF(Norway!D9="","",Norway!D9) | D75: =IF(Norway!E9="","",Norway!E9) -> all | E75: =IF(Norway!F9="","",Norway!F9) -> 2020 | G75: =IF(Norway!H9="","",Norway!H9) -> 0.76692614 | H75: =IF(Norway!I9="","",Norway!I9) -> 0.3
A76: =IF(Norway!B10="","",Norway!B10) -> NON1 | B76: =IF(Norway!C10="","",Norway!C10) -> dheat | C76: =IF(Norway!D10="","",Norway!D10) | D76: =IF(Norway!E10="","",Norway!E10) -> all | E76: =IF(Norway!F10="","",Norway!F10) -> 2020 | G76: =IF(Norway!H10="","",Norway!H10) -> 0.80943856 | H76: =IF(Norway!I10="","",Norway!I10) -> 0.3
A77: =IF(Norway!B11="","",Norway!B11) -> NOS0 | B77: =IF(Norway!C11="","",Norway!C11) -> dheat | C77: =IF(Norway!D11="","",Norway!D11) | D77: =IF(Norway!E11="","",Norway!E11) -> all | E77: =IF(Norway!F11="","",Norway!F11) -> 2025 | G77: =IF(Norway!H11="","",Norway!H11) -> 6.1755444 | H77: =IF(Norway!I11="","",Norway!I11) -> 0.3
A78: =IF(Norway!B12="","",Norway!B12) -> NOM1 | B78: =IF(Norway!C12="","",Norway!C12) -> dheat | C78: =IF(Norway!D12="","",Norway!D12) | D78: =IF(Norway!E12="","",Norway!E12) -> all | E78: =IF(Norway!F12="","",Norway!F12) -> 2025 | G78: =IF(Norway!H12="","",Norway!H12) -> 0.89002027 | H78: =IF(Norway!I12="","",Norway!I12) -> 0.3
A79: =IF(Norway!B13="","",Norway!B13) -> NON1 | B79: =IF(Norway!C13="","",Norway!C13) -> dheat | C79: =IF(Norway!D13="","",Norway!D13) | D79: =IF(Norway!E13="","",Norway!E13) -> all | E79: =IF(Norway!F13="","",Norway!F13) -> 2025 | G79: =IF(Norway!H13="","",Norway!H13) -> 0.93935607 | H79: =IF(Norway!I13="","",Norway!I13) -> 0.3
A80: =IF(Norway!B14="","",Norway!B14) -> NOS0 | B80: =IF(Norway!C14="","",Norway!C14) -> dheat | C80: =IF(Norway!D14="","",Norway!D14) | D80: =IF(Norway!E14="","",Norway!E14) -> all | E80: =IF(Norway!F14="","",Norway!F14) -> 2030 | G80: =IF(Norway!H14="","",Norway!H14) -> 6.5152686 | H80: =IF(Norway!I14="","",Norway!I14) -> 0.3
A81: =IF(Norway!B15="","",Norway!B15) -> NOM1 | B81: =IF(Norway!C15="","",Norway!C15) -> dheat | C81: =IF(Norway!D15="","",Norway!D15) | D81: =IF(Norway!E15="","",Norway!E15) -> all | E81: =IF(Norway!F15="","",Norway!F15) -> 2030 | G81: =IF(Norway!H15="","",Norway!H15) -> 0.93898136 | H81: =IF(Norway!I15="","",Norway!I15) -> 0.3
A82: =IF(Norway!B16="","",Norway!B16) -> NON1 | B82: =IF(Norway!C16="","",Norway!C16) -> dheat | C82: =IF(Norway!D16="","",Norway!D16) | D82: =IF(Norway!E16="","",Norway!E16) -> all | E82: =IF(Norway!F16="","",Norway!F16) -> 2030 | G82: =IF(Norway!H16="","",Norway!H16) -> 0.99103118 | H82: =IF(Norway!I16="","",Norway!I16) -> 0.3
... A88: =IF(Norway!B22="","",Norway!B22) -> NON1 | B88: =IF(Norway!C22="","",Norway!C22) -> dheat | C88: =IF(Norway!D22="","",Norway!D22) | D88: =IF(Norway!E22="","",Norway!E22) -> all | E88: =IF(Norway!F22="","",Norway!F22) -> 2040 | G88: =IF(Norway!H22="","",Norway!H22) -> 1.0317742 | H88: =IF(Norway!I22="","",Norway!I22) -> 0.3
A89: ## Lithuania
A90: =IF(Lithuania!B5="","",Lithuania!B5) -> LT00 | B90: =IF(Lithuania!C5="","",Lithuania!C5) -> dheat | C90: =IF(Lithuania!D5="","",Lithuania!D5) | D90: =IF(Lithuania!E5="","",Lithuania!E5) -> all | E90: =IF(Lithuania!F5="","",Lithuania!F5) -> 2015 | G90: =IF(Lithuania!H5="","",Lithuania!H5) -> 7.5753418 | H90: =IF(Lithuania!I5="","",Lithuania!I5) -> 0.3
A91: =IF(Lithuania!B6="","",Lithuania!B6) -> LT00 | B91: =IF(Lithuania!C6="","",Lithuania!C6) -> dheat | C91: =IF(Lithuania!D6="","",Lithuania!D6) | D91: =IF(Lithuania!E6="","",Lithuania!E6) -> all | E91: =IF(Lithuania!F6="","",Lithuania!F6) -> 2020 | G91: =IF(Lithuania!H6="","",Lithuania!H6) -> 7.8357265 | H91: =IF(Lithuania!I6="","",Lithuania!I6) -> 0.3
A92: =IF(Lithuania!B7="","",Lithuania!B7) -> LT00 | B92: =IF(Lithuania!C7="","",Lithuania!C7) -> dheat | C92: =IF(Lithuania!D7="","",Lithuania!D7) | D92: =IF(Lithuania!E7="","",Lithuania!E7) -> all | E92: =IF(Lithuania!F7="","",Lithuania!F7) -> 2025 | G92: =IF(Lithuania!H7="","",Lithuania!H7) -> 7.994005 | H92: =IF(Lithuania!I7="","",Lithuania!I7) -> 0.3
A93: =IF(Lithuania!B8="","",Lithuania!B8) -> LT00 | B93: =IF(Lithuania!C8="","",Lithuania!C8) -> dheat | C93: =IF(Lithuania!D8="","",Lithuania!D8) | D93: =IF(Lithuania!E8="","",Lithuania!E8) -> all | E93: =IF(Lithuania!F8="","",Lithuania!F8) -> 2030 | G93: =IF(Lithuania!H8="","",Lithuania!H8) -> 7.9739675 | H93: =IF(Lithuania!I8="","",Lithuania!I8) -> 0.3
A94: =IF(Lithuania!B9="","",Lithuania!B9) -> LT00 | B94: =IF(Lithuania!C9="","",Lithuania!C9) -> dheat | C94: =IF(Lithuania!D9="","",Lithuania!D9) | D94: =IF(Lithuania!E9="","",Lithuania!E9) -> all | E94: =IF(Lithuania!F9="","",Lithuania!F9) -> 2035 | G94: =IF(Lithuania!H9="","",Lithuania!H9) -> 7.9907938 | H94: =IF(Lithuania!I9="","",Lithuania!I9) -> 0.3
A95: =IF(Lithuania!B10="","",Lithuania!B10) -> LT00 | B95: =IF(Lithuania!C10="","",Lithuania!C10) -> dheat | C95: =IF(Lithuania!D10="","",Lithuania!D10) | D95: =IF(Lithuania!E10="","",Lithuania!E10) -> all | E95: =IF(Lithuania!F10="","",Lithuania!F10) -> 2040 | G95: =IF(Lithuania!H10="","",Lithuania!H10) -> 7.9911811 | H95: =IF(Lithuania!I10="","",Lithuania!I10) -> 0.3
A96: ## Latvia
A97: =IF(Latvia!B5="","",Latvia!B5) -> LV00 | B97: =IF(Latvia!C5="","",Latvia!C5) -> dheat | C97: =IF(Latvia!D5="","",Latvia!D5) | D97: =IF(Latvia!E5="","",Latvia!E5) -> all | E97: =IF(Latvia!F5="","",Latvia!F5) -> 2015 | G97: =IF(Latvia!H5="","",Latvia!H5) -> 12.113744 | H97: =IF(Latvia!I5="","",Latvia!I5) -> 0.3
A98: =IF(Latvia!B6="","",Latvia!B6) -> LV00 | B98: =IF(Latvia!C6="","",Latvia!C6) -> dheat | C98: =IF(Latvia!D6="","",Latvia!D6) | D98: =IF(Latvia!E6="","",Latvia!E6) -> all | E98: =IF(Latvia!F6="","",Latvia!F6) -> 2020 | G98: =IF(Latvia!H6="","",Latvia!H6) -> 11.273483 | H98: =IF(Latvia!I6="","",Latvia!I6) -> 0.3
A99: =IF(Latvia!B7="","",Latvia!B7) -> LV00 | B99: =IF(Latvia!C7="","",Latvia!C7) -> dheat | C99: =IF(Latvia!D7="","",Latvia!D7) | D99: =IF(Latvia!E7="","",Latvia!E7) -> all | E99: =IF(Latvia!F7="","",Latvia!F7) -> 2025 | G99: =IF(Latvia!H7="","",Latvia!H7) -> 10.537036 | H99: =IF(Latvia!I7="","",Latvia!I7) -> 0.3
A100: =IF(Latvia!B8="","",Latvia!B8) -> LV00 | B100: =IF(Latvia!C8="","",Latvia!C8) -> dheat | C100: =IF(Latvia!D8="","",Latvia!D8) | D100: =IF(Latvia!E8="","",Latvia!E8) -> all | E100: =IF(Latvia!F8="","",Latvia!F8) -> 2030 | G100: =IF(Latvia!H8="","",Latvia!H8) -> 10.021074 | H100: =IF(Latvia!I8="","",Latvia!I8) -> 0.3
...

Sheet Finland
B2: Finland
B4: Country | C4: Grid | D4: Node_suffix | E4: Scenario | F4: Year | G4: Variant | H4: TWh/year | I4: Constant_share | L4: capitals
B5: FI00 | C5: dheat | D5: HKI | E5: all | F5: 2015 | G5: dh-level:cities | H5: {=SUM($P$6:$U$13*($P$5:$U$5=$F5)*($O$6:$O$13=$D5)) / 1000} -> 7.073604 | I5: 0.3 | L5: =_xlfn.XLOOKUP(D5,$O$18:$O$25,$P$18:$P$25) -> HKI | P5: 2015 | Q5: 2020 | R5: 2025 | S5: 2030 | T5: 2035 | U5: 2040
B6: FI00 | C6: dheat | D6: ESP | E6: all | F6: 2015 | G6: dh-level:cities | H6: {=SUM($P$6:$U$13*($P$5:$U$5=$F6)*($O$6:$O$13=$D6)) / 1000} -> 2.3605087 | I6: =I5 -> 0.3 | L6: =_xlfn.XLOOKUP(D6,$O$18:$O$25,$P$18:$P$25) -> HKI | O6: HKI | P6: =SUMIFS(AD$79:AD$136, $A$79:$A$136,$O6, $C$79:$C$136,"Produced DH") -> 7073.604 | Q6: =SUMIFS(AE$79:AE$136, $A$79:$A$136,$O6, $C$79:$C$136,"Produced DH") -> 7088.8236 | R6: =SUMIFS(AF$79:AF$136, $A$79:$A$136,$O6, $C$79:$C$136,"Produced DH") -> 6894.0564 | S6: =SUMIFS(AG$79:AG$136, $A$79:$A$136,$O6, $C$79:$C$136,"Produced DH") -> 6748.8075 | T6: =SUMIFS(AH$79:AH$136, $A$79:$A$136,$O6, $C$79:$C$136,"Produced DH") -> 6546.6202 | U6: =SUMIFS(AI$79:AI$136, $A$79:$A$136,$O6, $C$79:$C$136,"Produced DH") -> 6342.2362
B7: FI00 | C7: dheat | D7: VAN | E7: all | F7: 2015 | G7: dh-level:cities | H7: {=SUM($P$6:$U$13*($P$5:$U$5=$F7)*($O$6:$O$13=$D7)) / 1000} -> 1.8955076 | I7: =I6 -> 0.3 | L7: =_xlfn.XLOOKUP(D7,$O$18:$O$25,$P$18:$P$25) -> HKI | O7: ESP | P7: =SUMIFS(AD$79:AD$136, $A$79:$A$136,$O7, $C$79:$C$136,"Produced DH") -> 2360.5087 | Q7: =SUMIFS(AE$79:AE$136, $A$79:$A$136,$O7, $C$79:$C$136,"Produced DH") -> 2367.4261 | R7: =SUMIFS(AF$79:AF$136, $A$79:$A$136,$O7, $C$79:$C$136,"Produced DH") -> 2311.6653 | S7: =SUMIFS(AG$79:AG$136, $A$79:$A$136,$O7, $C$79:$C$136,"Produced DH") -> 2288.9009 | T7: =SUMIFS(AH$79:AH$136, $A$79:$A$136,$O7, $C$79:$C$136,"Produced DH") -> 2234.2093 | U7: =SUMIFS(AI$79:AI$136, $A$79:$A$136,$O7, $C$79:$C$136,"Produced DH") -> 2176.9856
B8: FI00 | C8: dheat | D8: TKU | E8: all | F8: 2015 | G8: dh-level:cities | H8: {=SUM($P$6:$U$13*($P$5:$U$5=$F8)*($O$6:$O$13=$D8)) / 1000} -> 2.2187058 | I8: =I7 -> 0.3 | L8: =_xlfn.XLOOKUP(D8,$O$18:$O$25,$P$18:$P$25) -> ROF | O8: VAN | P8: =SUMIFS(AD$79:AD$136, $A$79:$A$136,$O8, $C$79:$C$136,"Produced DH") -> 1895.5076 | Q8: =SUMIFS(AE$79:AE$136, $A$79:$A$136,$O8, $C$79:$C$136,"Produced DH") -> 1944.3748 | R8: =SUMIFS(AF$79:AF$136, $A$79:$A$136,$O8, $C$79:$C$136,"Produced DH") -> 1953.4343 | S8: =SUMIFS(AG$79:AG$136, $A$79:$A$136,$O8, $C$79:$C$136,"Produced DH") -> 1935.6428 | T8: =SUMIFS(AH$79:AH$136, $A$79:$A$136,$O8, $C$79:$C$136,"Produced DH") -> 1891.3769 | U8: =SUMIFS(AI$79:AI$136, $A$79:$A$136,$O8, $C$79:$C$136,"Produced DH") -> 1844.7875
B9: FI00 | C9: dheat | D9: TRE | E9: all | F9: 2015 | G9: dh-level:cities | H9: {=SUM($P$6:$U$13*($P$5:$U$5=$F9)*($O$6:$O$13=$D9)) / 1000} -> 2.2249794 | I9: =I8 -> 0.3 | L9: =_xlfn.XLOOKUP(D9,$O$18:$O$25,$P$18:$P$25) -> ROF | O9: TKU | P9: =SUMIFS(AD$79:AD$136, $A$79:$A$136,$O9, $C$79:$C$136,"Produced DH") -> 2218.7058 | Q9: =SUMIFS(AE$79:AE$136, $A$79:$A$136,$O9, $C$79:$C$136,"Produced DH") -> 2096.4712 | R9: =SUMIFS(AF$79:AF$136, $A$79:$A$136,$O9, $C$79:$C$136,"Produced DH") -> 2036.5953 | S9: =SUMIFS(AG$79:AG$136, $A$79:$A$136,$O9, $C$79:$C$136,"Produced DH") -> 2020.7279 | T9: =SUMIFS(AH$79:AH$136, $A$79:$A$136,$O9, $C$79:$C$136,"Produced DH") -> 1989.1836 | U9: =SUMIFS(AI$79:AI$136, $A$79:$A$136,$O9, $C$79:$C$136,"Produced DH") -> 1956.8544
B10: FI00 | C10: dheat | D10: OUL | E10: all | F10: 2015 | G10: dh-level:cities | H10: {=SUM($P$6:$U$13*($P$5:$U$5=$F10)*($O$6:$O$13=$D10)) / 1000} -> 1.7214878 | I10: =I9 -> 0.3 | L10: =_xlfn.XLOOKUP(D10,$O$18:$O$25,$P$18:$P$25) -> ROF | O10: TRE | P10: =SUMIFS(AD$79:AD$136, $A$79:$A$136,$O10, $C$79:$C$136,"Produced DH") -> 2224.9794 | Q10: =SUMIFS(AE$79:AE$136, $A$79:$A$136,$O10, $C$79:$C$136,"Produced DH") -> 2234.3768 | R10: =SUMIFS(AF$79:AF$136, $A$79:$A$136,$O10, $C$79:$C$136,"Produced DH") -> 2230.3642 | S10: =SUMIFS(AG$79:AG$136, $A$79:$A$136,$O10, $C$79:$C$136,"Produced DH") -> 2216.318 | T10: =SUMIFS(AH$79:AH$136, $A$79:$A$136,$O10, $C$79:$C$136,"Produced DH") -> 2178.5868 | U10: =SUMIFS(AI$79:AI$136, $A$79:$A$136,$O10, $C$79:$C$136,"Produced DH") -> 2139.2937
B11: FI00 | C11: dheat | D11: JKL | E11: all | F11: 2015 | G11: dh-level:cities | H11: {=SUM($P$6:$U$13*($P$5:$U$5=$F11)*($O$6:$O$13=$D11)) / 1000} -> 1.1858506 | I11: =I10 -> 0.3 | L11: =_xlfn.XLOOKUP(D11,$O$18:$O$25,$P$18:$P$25) -> ROF | O11: OUL | P11: =SUMIFS(AD$79:AD$136, $A$79:$A$136,$O11, $C$79:$C$136,"Produced DH") -> 1721.4878 | Q11: =SUMIFS(AE$79:AE$136, $A$79:$A$136,$O11, $C$79:$C$136,"Produced DH") -> 1821.834 | R11: =SUMIFS(AF$79:AF$136, $A$79:$A$136,$O11, $C$79:$C$136,"Produced DH") -> 1917.4791 | S11: =SUMIFS(AG$79:AG$136, $A$79:$A$136,$O11, $C$79:$C$136,"Produced DH") -> 1949.743 | T11: =SUMIFS(AH$79:AH$136, $A$79:$A$136,$O11, $C$79:$C$136,"Produced DH") -> 1965.1786 | U11: =SUMIFS(AI$79:AI$136, $A$79:$A$136,$O11, $C$79:$C$136,"Produced DH") -> 1979.8148
B12: FI00 | C12: dheat | D12: ROF | E12: all | F12: 2015 | G12: dh-level:cities | H12: {=SUM($P$6:$U$13*($P$5:$U$5=$F12)*($O$6:$O$13=$D12)) / 1000} -> 19.449074 | I12: =I11 -> 0.3 | L12: =_xlfn.XLOOKUP(D12,$O$18:$O$25,$P$18:$P$25) -> ROF | O12: JKL | P12: =SUMIFS(AD$79:AD$136, $A$79:$A$136,$O12, $C$79:$C$136,"Produced DH") -> 1185.8506 | Q12: =SUMIFS(AE$79:AE$136, $A$79:$A$136,$O12, $C$79:$C$136,"Produced DH") -> 1204.1925 | R12: =SUMIFS(AF$79:AF$136, $A$79:$A$136,$O12, $C$79:$C$136,"Produced DH") -> 1212.5036 | S12: =SUMIFS(AG$79:AG$136, $A$79:$A$136,$O12, $C$79:$C$136,"Produced DH") -> 1218.4677 | T12: =SUMIFS(AH$79:AH$136, $A$79:$A$136,$O12, $C$79:$C$136,"Produced DH") -> 1215.2906 | U12: =SUMIFS(AI$79:AI$136, $A$79:$A$136,$O12, $C$79:$C$136,"Produced DH") -> 1211.6177
B13: FI00 | C13: dheat | D13: HKI | E13: all | F13: =F5+5 -> 2020 | G13: dh-level:cities | H13: {=SUM($P$6:$U$13*($P$5:$U$5=$F13)*($O$6:$O$13=$D13)) / 1000} -> 7.0888236 | I13: =I12 -> 0.3 | L13: =_xlfn.XLOOKUP(D13,$O$18:$O$25,$P$18:$P$25) -> HKI | O13: ROF | P13: =SUMIFS(AD$79:AD$136, $A$79:$A$136,$O13, $C$79:$C$136,"Produced DH") -> 19449.074 | Q13: =SUMIFS(AE$79:AE$136, $A$79:$A$136,$O13, $C$79:$C$136,"Produced DH") -> 19732.75 | R13: =SUMIFS(AF$79:AF$136, $A$79:$A$136,$O13, $C$79:$C$136,"Produced DH") -> 20045.263 | S13: =SUMIFS(AG$79:AG$136, $A$79:$A$136,$O13, $C$79:$C$136,"Produced DH") -> 20388.968 | T13: =SUMIFS(AH$79:AH$136, $A$79:$A$136,$O13, $C$79:$C$136,"Produced DH") -> 20381.214 | U13: =SUMIFS(AI$79:AI$136, $A$79:$A$136,$O13, $C$79:$C$136,"Produced DH") -> 20244.299
B14: FI00 | C14: dheat | D14: ESP | E14: all | F14: =F6+5 -> 2020 | G14: dh-level:cities | H14: {=SUM($P$6:$U$13*($P$5:$U$5=$F14)*($O$6:$O$13=$D14)) / 1000} -> 2.3674261 | I14: =I13 -> 0.3 | L14: =_xlfn.XLOOKUP(D14,$O$18:$O$25,$P$18:$P$25) -> HKI
B15: FI00 | C15: dheat | D15: VAN | E15: all | F15: =F7+5 -> 2020 | G15: dh-level:cities | H15: {=SUM($P$6:$U$13*($P$5:$U$5=$F15)*($O$6:$O$13=$D15)) / 1000} -> 1.9443748 | I15: =I14 -> 0.3 | L15: =_xlfn.XLOOKUP(D15,$O$18:$O$25,$P$18:$P$25) -> HKI
B16: FI00 | C16: dheat | D16: TKU | E16: all | F16: =F8+5 -> 2020 | G16: dh-level:cities | H16: {=SUM($P$6:$U$13*($P$5:$U$5=$F16)*($O$6:$O$13=$D16)) / 1000} -> 2.0964712 | I16: =I15 -> 0.3 | L16: =_xlfn.XLOOKUP(D16,$O$18:$O$25,$P$18:$P$25) -> ROF
B17: FI00 | C17: dheat | D17: TRE | E17: all | F17: =F9+5 -> 2020 | G17: dh-level:cities | H17: {=SUM($P$6:$U$13*($P$5:$U$5=$F17)*($O$6:$O$13=$D17)) / 1000} -> 2.2343768 | I17: =I16 -> 0.3 | L17: =_xlfn.XLOOKUP(D17,$O$18:$O$25,$P$18:$P$25) -> ROF | O17: cities | P17: capitals
B18: FI00 | C18: dheat | D18: OUL | E18: all | F18: =F10+5 -> 2020 | G18: dh-level:cities | H18: {=SUM($P$6:$U$13*($P$5:$U$5=$F18)*($O$6:$O$13=$D18)) / 1000} -> 1.821834 | I18: =I17 -> 0.3 | L18: =_xlfn.XLOOKUP(D18,$O$18:$O$25,$P$18:$P$25) -> ROF | O18: HKI | P18: HKI
B19: FI00 | C19: dheat | D19: JKL | E19: all | F19: =F11+5 -> 2020 | G19: dh-level:cities | H19: {=SUM($P$6:$U$13*($P$5:$U$5=$F19)*($O$6:$O$13=$D19)) / 1000} -> 1.2041925 | I19: =I18 -> 0.3 | L19: =_xlfn.XLOOKUP(D19,$O$18:$O$25,$P$18:$P$25) -> ROF | O19: ESP | P19: HKI
B20: FI00 | C20: dheat | D20: ROF | E20: all | F20: =F12+5 -> 2020 | G20: dh-level:cities | H20: {=SUM($P$6:$U$13*($P$5:$U$5=$F20)*($O$6:$O$13=$D20)) / 1000} -> 19.73275 | I20: =I19 -> 0.3 | L20: =_xlfn.XLOOKUP(D20,$O$18:$O$25,$P$18:$P$25) -> ROF | O20: VAN | P20: HKI
B21: FI00 | C21: dheat | D21: HKI | E21: all | F21: =F13+5 -> 2025 | G21: dh-level:cities | H21: {=SUM($P$6:$U$13*($P$5:$U$5=$F21)*($O$6:$O$13=$D21)) / 1000} -> 6.8940564 | I21: 0.3 | L21: =_xlfn.XLOOKUP(D21,$O$18:$O$25,$P$18:$P$25) -> HKI | O21: TKU | P21: ROF
B22: FI00 | C22: dheat | D22: ESP | E22: all | F22: =F14+5 -> 2025 | G22: dh-level:cities | H22: {=SUM($P$6:$U$13*($P$5:$U$5=$F22)*($O$6:$O$13=$D22)) / 1000} -> 2.3116653 | I22: =I21 -> 0.3 | L22: =_xlfn.XLOOKUP(D22,$O$18:$O$25,$P$18:$P$25) -> HKI | O22: TRE | P22: ROF
B23: FI00 | C23: dheat | D23: VAN | E23: all | F23: =F15+5 -> 2025 | G23: dh-level:cities | H23: {=SUM($P$6:$U$13*($P$5:$U$5=$F23)*($O$6:$O$13=$D23)) / 1000} -> 1.9534343 | I23: =I22 -> 0.3 | L23: =_xlfn.XLOOKUP(D23,$O$18:$O$25,$P$18:$P$25) -> HKI | O23: OUL | P23: ROF
B24: FI00 | C24: dheat | D24: TKU | E24: all | F24: =F16+5 -> 2025 | G24: dh-level:cities | H24: {=SUM($P$6:$U$13*($P$5:$U$5=$F24)*($O$6:$O$13=$D24)) / 1000} -> 2.0365953 | I24: =I23 -> 0.3 | L24: =_xlfn.XLOOKUP(D24,$O$18:$O$25,$P$18:$P$25) -> ROF | O24: JKL | P24: ROF
B25: FI00 | C25: dheat | D25: TRE | E25: all | F25: =F17+5 -> 2025 | G25: dh-level:cities | H25: {=SUM($P$6:$U$13*($P$5:$U$5=$F25)*($O$6:$O$13=$D25)) / 1000} -> 2.2303642 | I25: =I24 -> 0.3 | L25: =_xlfn.XLOOKUP(D25,$O$18:$O$25,$P$18:$P$25) -> ROF | O25: ROF | P25: ROF
B26: FI00 | C26: dheat | D26: OUL | E26: all | F26: =F18+5 -> 2025 | G26: dh-level:cities | H26: {=SUM($P$6:$U$13*($P$5:$U$5=$F26)*($O$6:$O$13=$D26)) / 1000} -> 1.9174791 | I26: =I25 -> 0.3 | L26: =_xlfn.XLOOKUP(D26,$O$18:$O$25,$P$18:$P$25) -> ROF
B27: FI00 | C27: dheat | D27: JKL | E27: all | F27: =F19+5 -> 2025 | G27: dh-level:cities | H27: {=SUM($P$6:$U$13*($P$5:$U$5=$F27)*($O$6:$O$13=$D27)) / 1000} -> 1.2125036 | I27: =I26 -> 0.3 | L27: =_xlfn.XLOOKUP(D27,$O$18:$O$25,$P$18:$P$25) -> ROF
B28: FI00 | C28: dheat | D28: ROF | E28: all | F28: =F20+5 -> 2025 | G28: dh-level:cities | H28: {=SUM($P$6:$U$13*($P$5:$U$5=$F28)*($O$6:$O$13=$D28)) / 1000} -> 20.045263 | I28: =I27 -> 0.3 | L28: =_xlfn.XLOOKUP(D28,$O$18:$O$25,$P$18:$P$25) -> ROF
B29: FI00 | C29: dheat | D29: HKI | E29: all | F29: =F21+5 -> 2030 | G29: dh-level:cities | H29: {=SUM($P$6:$U$13*($P$5:$U$5=$F29)*($O$6:$O$13=$D29)) / 1000} -> 6.7488075 | I29: =I28 -> 0.3 | L29: =_xlfn.XLOOKUP(D29,$O$18:$O$25,$P$18:$P$25) -> HKI
B30: FI00 | C30: dheat | D30: ESP | E30: all | F30: =F22+5 -> 2030 | G30: dh-level:cities | H30: {=SUM($P$6:$U$13*($P$5:$U$5=$F30)*($O$6:$O$13=$D30)) / 1000} -> 2.2889009 | I30: =I29 -> 0.3 | L30: =_xlfn.XLOOKUP(D30,$O$18:$O$25,$P$18:$P$25) -> HKI
B31: FI00 | C31: dheat | D31: VAN | E31: all | F31: =F23+5 -> 2030 | G31: dh-level:cities | H31: {=SUM($P$6:$U$13*($P$5:$U$5=$F31)*($O$6:$O$13=$D31)) / 1000} -> 1.9356428 | I31: =I30 -> 0.3 | L31: =_xlfn.XLOOKUP(D31,$O$18:$O$25,$P$18:$P$25) -> HKI
B32: FI00 | C32: dheat | D32: TKU | E32: all | F32: =F24+5 -> 2030 | G32: dh-level:cities | H32: {=SUM($P$6:$U$13*($P$5:$U$5=$F32)*($O$6:$O$13=$D32)) / 1000} -> 2.0207279 | I32: =I31 -> 0.3 | L32: =_xlfn.XLOOKUP(D32,$O$18:$O$25,$P$18:$P$25) -> ROF
B33: FI00 | C33: dheat | D33: TRE | E33: all | F33: =F25+5 -> 2030 | G33: dh-level:cities | H33: {=SUM($P$6:$U$13*($P$5:$U$5=$F33)*($O$6:$O$13=$D33)) / 1000} -> 2.216318 | I33: =I32 -> 0.3 | L33: =_xlfn.XLOOKUP(D33,$O$18:$O$25,$P$18:$P$25) -> ROF
B34: FI00 | C34: dheat | D34: OUL | E34: all | F34: =F26+5 -> 2030 | G34: dh-level:cities | H34: {=SUM($P$6:$U$13*($P$5:$U$5=$F34)*($O$6:$O$13=$D34)) / 1000} -> 1.949743 | I34: =I33 -> 0.3 | L34: =_xlfn.XLOOKUP(D34,$O$18:$O$25,$P$18:$P$25) -> ROF
B35: FI00 | C35: dheat | D35: JKL | E35: all | F35: =F27+5 -> 2030 | G35: dh-level:cities | H35: {=SUM($P$6:$U$13*($P$5:$U$5=$F35)*($O$6:$O$13=$D35)) / 1000} -> 1.2184677 | I35: =I34 -> 0.3 | L35: =_xlfn.XLOOKUP(D35,$O$18:$O$25,$P$18:$P$25) -> ROF
B36: FI00 | C36: dheat | D36: ROF | E36: all | F36: =F28+5 -> 2030 | G36: dh-level:cities | H36: {=SUM($P$6:$U$13*($P$5:$U$5=$F36)*($O$6:$O$13=$D36)) / 1000} -> 20.388968 | I36: =I35 -> 0.3 | L36: =_xlfn.XLOOKUP(D36,$O$18:$O$25,$P$18:$P$25) -> ROF
B37: FI00 | C37: dheat | D37: HKI | E37: all | F37: =F29+5 -> 2035 | G37: dh-level:cities | H37: {=SUM($P$6:$U$13*($P$5:$U$5=$F37)*($O$6:$O$13=$D37)) / 1000} -> 6.5466202 | I37: =I36 -> 0.3 | L37: =_xlfn.XLOOKUP(D37,$O$18:$O$25,$P$18:$P$25) -> HKI
... B52: FI00 | C52: dheat | D52: ROF | E52: all | F52: =F44+5 -> 2040 | G52: dh-level:cities | H52: {=SUM($P$6:$U$13*($P$5:$U$5=$F52)*($O$6:$O$13=$D52)) / 1000} -> 20.244299 | I52: =I51 -> 0.3 | L52: =_xlfn.XLOOKUP(D52,$O$18:$O$25,$P$18:$P$25) -> ROF
B53: ## FI - capitals
B54: FI00 | C54: dheat | D54: HKI | E54: all | F54: 2015 | G54: dh-level:capitals | H54: =SUMIFS($H$5:$H$52, $F$5:$F$52,$F54, $L$5:$L$52,$D54) -> 11.32962 | I54: 0.3
B55: FI00 | C55: dheat | D55: HKI | E55: all | F55: 2020 | G55: dh-level:capitals | H55: =SUMIFS($H$5:$H$52, $F$5:$F$52,$F55, $L$5:$L$52,$D55) -> 11.400625 | I55: =I54 -> 0.3
B56: FI00 | C56: dheat | D56: HKI | E56: all | F56: 2025 | G56: dh-level:capitals | H56: =SUMIFS($H$5:$H$52, $F$5:$F$52,$F56, $L$5:$L$52,$D56) -> 11.159156 | I56: =I55 -> 0.3
...

Sheet Norway
B2: Norway
B4: Country | C4: Grid | D4: Node_suffix | E4: Scenario | F4: Year | G4: Variant | H4: TWh/year | I4: Constant_share
B5: NOS0 | C5: dheat | E5: all | F5: 2015 | H5: =SUMIFS($N$6:$N$8,$M$6:$M$8,$B5) * SUMIFS($N$11:$S$11,$N$10:$S$10,$F5) / 1000 -> 4.2784352 | I5: 0.3 | M5: region | N5: share (%)
B6: NOM1 | C6: dheat | E6: all | F6: 2015 | H6: =SUMIFS($N$6:$N$8,$M$6:$M$8,$B6) * SUMIFS($N$11:$S$11,$N$10:$S$10,$F6) / 1000 -> 0.61660863 | I6: =I5 -> 0.3 | M6: NOS0 | N6: =V44/$V$56 -> 0.77146853
B7: NON1 | C7: dheat | E7: all | F7: 2015 | H7: =SUMIFS($N$6:$N$8,$M$6:$M$8,$B7) * SUMIFS($N$11:$S$11,$N$10:$S$10,$F7) / 1000 -> 0.65078862 | I7: =I6 -> 0.3 | M7: NOM1 | N7: =V48/$V$56 -> 0.11118414
B8: NOS0 | C8: dheat | E8: all | F8: =F5+5 -> 2020 | H8: =SUMIFS($N$6:$N$8,$M$6:$M$8,$B8) * SUMIFS($N$11:$S$11,$N$10:$S$10,$F8) / 1000 -> 5.3214366 | I8: =I7 -> 0.3 | M8: NON1 | N8: =V54/$V$56 -> 0.11734733
B9: NOM1 | C9: dheat | E9: all | F9: =F6+5 -> 2020 | H9: =SUMIFS($N$6:$N$8,$M$6:$M$8,$B9) * SUMIFS($N$11:$S$11,$N$10:$S$10,$F9) / 1000 -> 0.76692614 | I9: =I8 -> 0.3
B10: NON1 | C10: dheat | E10: all | F10: =F7+5 -> 2020 | H10: =SUMIFS($N$6:$N$8,$M$6:$M$8,$B10) * SUMIFS($N$11:$S$11,$N$10:$S$10,$F10) / 1000 -> 0.80943856 | I10: =I9 -> 0.3 | N10: 2015 | O10: 2020 | P10: 2025 | Q10: 2030 | R10: 2035 | S10: 2040
B11: NOS0 | C11: dheat | E11: all | F11: =F8+5 -> 2025 | H11: =SUMIFS($N$6:$N$8,$M$6:$M$8,$B11) * SUMIFS($N$11:$S$11,$N$10:$S$10,$F11) / 1000 -> 6.1755444 | I11: 0.3 | M11: Normal year, DH net production (GWh) | N11: =AB71 -> 5545.8324 | O11: =AC71 -> 6897.8013 | P11: =AD71 -> 8004.9208 | Q11: =AE71 -> 8445.2811 | R11: =AF71 -> 8675.0858 | S11: =AG71 -> 8792.4811
B12: NOM1 | C12: dheat | E12: all | F12: =F9+5 -> 2025 | H12: =SUMIFS($N$6:$N$8,$M$6:$M$8,$B12) * SUMIFS($N$11:$S$11,$N$10:$S$10,$F12) / 1000 -> 0.89002027 | I12: =I11 -> 0.3
B13: NON1 | C13: dheat | E13: all | F13: =F10+5 -> 2025 | H13: =SUMIFS($N$6:$N$8,$M$6:$M$8,$B13) * SUMIFS($N$11:$S$11,$N$10:$S$10,$F13) / 1000 -> 0.93935607 | I13: =I12 -> 0.3
B14: NOS0 | C14: dheat | E14: all | F14: =F11+5 -> 2030 | H14: =SUMIFS($N$6:$N$8,$M$6:$M$8,$B14) * SUMIFS($N$11:$S$11,$N$10:$S$10,$F14) / 1000 -> 6.5152686 | I14: =I13 -> 0.3
B15: NOM1 | C15: dheat | E15: all | F15: =F12+5 -> 2030 | H15: =SUMIFS($N$6:$N$8,$M$6:$M$8,$B15) * SUMIFS($N$11:$S$11,$N$10:$S$10,$F15) / 1000 -> 0.93898136 | I15: =I14 -> 0.3 | N15: City level statistics would be at
B16: NON1 | C16: dheat | E16: all | F16: =F13+5 -> 2030 | H16: =SUMIFS($N$6:$N$8,$M$6:$M$8,$B16) * SUMIFS($N$11:$S$11,$N$10:$S$10,$F16) / 1000 -> 0.99103118 | I16: =I15 -> 0.3 | N16: https://www.fjernkontrollen.no/
B17: NOS0 | C17: dheat | E17: all | F17: =F14+5 -> 2035 | H17: =SUMIFS($N$6:$N$8,$M$6:$M$8,$B17) * SUMIFS($N$11:$S$11,$N$10:$S$10,$F17) / 1000 -> 6.6925557 | I17: =I16 -> 0.3
B18: NOM1 | C18: dheat | E18: all | F18: =F15+5 -> 2035 | H18: =SUMIFS($N$6:$N$8,$M$6:$M$8,$B18) * SUMIFS($N$11:$S$11,$N$10:$S$10,$F18) / 1000 -> 0.964532 | I18: =I17 -> 0.3
B19: NON1 | C19: dheat | E19: all | F19: =F16+5 -> 2035 | H19: =SUMIFS($N$6:$N$8,$M$6:$M$8,$B19) * SUMIFS($N$11:$S$11,$N$10:$S$10,$F19) / 1000 -> 1.0179981 | I19: =I18 -> 0.3
B20: NOS0 | C20: dheat | E20: all | F20: =F17+5 -> 2040 | H20: =SUMIFS($N$6:$N$8,$M$6:$M$8,$B20) * SUMIFS($N$11:$S$11,$N$10:$S$10,$F20) / 1000 -> 6.7831224 | I20: =I19 -> 0.3
B21: NOM1 | C21: dheat | E21: all | F21: =F18+5 -> 2040 | H21: =SUMIFS($N$6:$N$8,$M$6:$M$8,$B21) * SUMIFS($N$11:$S$11,$N$10:$S$10,$F21) / 1000 -> 0.97758449 | I21: =I20 -> 0.3
B22: NON1 | C22: dheat | E22: all | F22: =F19+5 -> 2040 | H22: =SUMIFS($N$6:$N$8,$M$6:$M$8,$B22) * SUMIFS($N$11:$S$11,$N$10:$S$10,$F22) / 1000 -> 1.0317742 | I22: =I21 -> 0.3
A27: https://www.ssb.no/en/befolkning
A28: 11342: Population and area, by contents, region and year
J30: 2007 | K30: 2008 | L30: 2009 | M30: 2010 | N30: 2011 | O30: 2012 | P30: 2013 | Q30: 2014 | R30: 2015 | S30: 2016 | T30: 2017 | U30: 2018 | V30: 2019
A31: Population per 1.1. (persons) | B31: 01 Østfold (-2019) | J31: 262523 | K31: 265458 | L31: 268584 | M31: 271662 | N31: 274827 | O31: 278352 | P31: 282000 | Q31: 284962 | R31: 287198 | S31: 289867 | T31: 292893 | U31: 295420 | V31: 297520
B32: 02 Akershus (-2019) | J32: 509177 | K32: 518567 | L32: 527625 | M32: 536499 | N32: 545653 | O32: 556254 | P32: 566399 | Q32: 575757 | R32: 584899 | S32: 594533 | T32: 604368 | U32: 614026 | V32: 624055
B33: 03 Oslo | J33: 548617 | K33: 560484 | L33: 575475 | M33: 586860 | N33: 599230 | O33: 613285 | P33: 623966 | Q33: 634463 | R33: 647676 | S33: 658390 | T33: 666759 | U33: 673469 | V33: 681067
B34: 04 Hedmark (-2019) | J34: 188692 | K34: 189289 | L34: 190071 | M34: 190709 | N34: 191622 | O34: 192791 | P34: 193719 | Q34: 194433 | R34: 195153 | S34: 195356 | T34: 196190 | U34: 196966 | V34: 197406
B35: 05 Oppland (-2019) | J35: 183037 | K35: 183637 | L35: 184288 | M35: 185216 | N35: 186087 | O35: 187147 | P35: 187254 | Q35: 187820 | R35: 188807 | S35: 188953 | T35: 189479 | U35: 189870 | V35: 189545
B36: 06 Buskerud (-2019) | J36: 247655 | K36: 251220 | L36: 254634 | M36: 257673 | N36: 261110 | O36: 265164 | P36: 269003 | Q36: 272228 | R36: 274737 | S36: 277684 | T36: 279714 | U36: 281769 | V36: 283148
B37: 07 Vestfold (-2019) | J37: 223804 | K37: 226433 | L37: 229134 | M37: 231286 | N37: 233705 | O37: 236424 | P37: 238748 | Q37: 240860 | R37: 242662 | S37: 244967 | T37: 247048 | U37: 249058 | V37: 251084
B38: 08 Telemark (-2019) | J38: 166170 | K38: 166731 | L38: 167548 | M38: 168231 | N38: 169185 | O38: 170023 | P38: 170902 | Q38: 171469 | R38: 171953 | S38: 172494 | T38: 173307 | U38: 173391 | V38: 173318
B39: 09 Aust-Agder (-2019) | J39: 104759 | K39: 106130 | L39: 107359 | M39: 108499 | N39: 110048 | O39: 111495 | P39: 112772 | Q39: 113747 | R39: 114767 | S39: 115785 | T39: 116673 | U39: 117222 | V39: 117655
B40: 10 Vest-Agder (-2019) | J40: 163702 | K40: 165944 | L40: 168233 | M40: 170377 | N40: 172408 | O40: 174324 | P40: 176353 | Q40: 178478 | R40: 180877 | S40: 182701 | T40: 184116 | U40: 186532 | V40: 187589
B41: 11 Rogaland | J41: 404566 | K41: 412687 | L41: 420574 | M41: 427947 | N41: 436087 | O41: 443115 | P41: 452159 | Q41: 459625 | R41: 466302 | S41: 470175 | T41: 472024 | U41: 473526 | V41: 475654
B42: 12 Hordaland (-2019) | J42: 456711 | K42: 462674 | L42: 469681 | M42: 477175 | N42: 484240 | O42: 490570 | P42: 498135 | Q42: 505246 | R42: 511357 | S42: 516497 | T42: 519963 | U42: 522539 | V42: 524495
B43: 14 Sogn og Fjordane (-2019) | J43: 106194 | K43: 106259 | L43: 106457 | M43: 107080 | N43: 107742 | O43: 108201 | P43: 108700 | Q43: 108965 | R43: 109170 | S43: 109530 | T43: 110266 | U43: 110230 | V43: 109774
B44: NOS0 (mil) | J44: =SUM(J31:J43)/1000000 -> 3.565607 | K44: =SUM(K31:K43)/1000000 -> 3.615513 | L44: =SUM(L31:L43)/1000000 -> 3.669663 | M44: =SUM(M31:M43)/1000000 -> 3.719214 | N44: =SUM(N31:N43)/1000000 -> 3.771944 | O44: =SUM(O31:O43)/1000000 -> 3.827145 | P44: =SUM(P31:P43)/1000000 -> 3.88011 | Q44: =SUM(Q31:Q43)/1000000 -> 3.928053 | ... V44: =SUM(V31:V43)/1000000 -> 4.11231
B45: 15 Møre og Romsdal | J45: 245385 | K45: 246772 | L45: 248727 | M45: 251262 | N45: 253904 | O45: 256628 | P45: 259404 | Q45: 261530 | R45: 263719 | S45: 265290 | T45: 266274 | U45: 266856 | V45: 267420
B46: 50 Trøndelag - Trööndelage (red calculated) | J46: =J49+J47 -> 407905 | K46: =K49+K47 -> 412849 | L46: =L49+L47 -> 417437 | M46: =M49+M47 -> 422102 | N46: =N49+N47 -> 426206 | O46: =O49+O47 -> 431340 | P46: =P49+P47 -> 437198 | Q46: =Q49+Q47 -> 441339 | ... T46: =T49+T47 -> 454596 | U46: 458744 | V46: 462032
B47: 16 Sør-Trøndelag (-2017) (red calculated) | J47: 278836 | K47: 282993 | L47: 286729 | M47: 290547 | N47: 294066 | O47: 297950 | P47: 302755 | Q47: 306197 | R47: 310047 | S47: 313370 | T47: 317363 | U47: {=TREND($J47:$T47,$J$30:$T$30,U$30)} -> 321391.33 | V47: {=TREND($J47:$T47,$J$30:$T$30,V$30)} -> 325246.65
...

Sheet Lithuania
B2: Lithuania
B4: Country | C4: Grid | D4: Node_suffix | E4: Scenario | F4: Year | G4: Variant | H4: TWh/year | I4: Constant_share
B5: LT00 | C5: dheat | E5: all | F5: 2015 | H5: {=TRANSPOSE(N17:S17)/1000} -> 7.5753418 | I5: 0.3
B6: LT00 | C6: dheat | E6: all | F6: =F5+5 -> 2020 | H6: 7.8357265 | I6: =I5 -> 0.3
B7: LT00 | C7: dheat | E7: all | F7: =F6+5 -> 2025 | H7: 7.994005 | I7: 0.3
B8: LT00 | C8: dheat | E8: all | F8: =F7+5 -> 2030 | H8: 7.9739675 | I8: =I7 -> 0.3
B9: LT00 | C9: dheat | E9: all | F9: =F8+5 -> 2035 | H9: 7.9907938 | I9: =I8 -> 0.3
B10: LT00 | C10: dheat | E10: all | F10: =F9+5 -> 2040 | H10: 7.9911811 | I10: =I9 -> 0.3
N16: 2015 | O16: 2020 | P16: 2025 | Q16: 2030 | R16: 2035 | S16: 2040
M17: Normal year net production (GWh) | N17: =P35 -> 7575.3418 | O17: =Q35 -> 7835.7265 | P17: =R35 -> 7994.005 | Q17: =S35 -> 7973.9675 | R17: =T35 -> 7990.7938 | S17: =U35 -> 7991.1811
M19: Sto/HD | N19: =0.01*P17 -> 79.94005
B26: Energy commodities balances, Heat GWh, Total gross production
B27: https://osp.stat.gov.lt/statistiniu-rodikliu-analize?indicator=S1R009#/
C30: 2012 | D30: 2013 | E30: 2014 | F30: 2015 | G30: 2016 | H30: 2017 | I30: 2018 | J30: 2019 | K30: 2020 | L30: 2021 | M30: 2022 | N30: 2023 | P30: 2015 | Q30: 2020 | R30: 2025 | S30: 2030 | T30: 2035 | U30: 2040
B31: Sum | C31: 7460 | D31: 7291 | E31: 7151 | F31: 7072 | G31: 8046 | H31: 8330 | I31: 8247 | J31: 7948 | K31: 7514 | L31: 8677 | M31: 7728 | N31: 7167
B35: Total Supply, GWh | C35: =C31 -> 7460 | D35: =D31 -> 7291 | E35: =E31 -> 7151 | F35: =F31 -> 7072 | G35: =G31 -> 8046 | H35: =H31 -> 8330 | I35: =I31 -> 8247 | J35: =J31 -> 7948 | ... N35: =N31 -> 7167 | P35: =P37*P39* P36 / AVERAGE($C$36:$N$36) -> 7575.3418 | Q35: =Q37*Q39* Q36 / AVERAGE($C$36:$N$36) -> 7835.7265 | R35: =R37*R39* R36 / AVERAGE($C$36:$N$36) -> 7994.005 | S35: =S37*S39* S36 / AVERAGE($C$36:$N$36) -> 7973.9675 | T35: =T37*T39* T36 / AVERAGE($C$36:$N$36) -> 7990.7938 | U35: =U37*U39* U36 / AVERAGE($C$36:$N$36) -> 7991.1811
B36: HDD | C36: =HLOOKUP(C$30, HDD!$A$25:$AG$55, MATCH($B$2,HDD!$A$25:$A$55,0), FALSE) -> 4081.27 | D36: =HLOOKUP(D$30, HDD!$A$25:$AG$55, MATCH($B$2,HDD!$A$25:$A$55,0), FALSE) -> 3873.17 | E36: =HLOOKUP(E$30, HDD!$A$25:$AG$55, MATCH($B$2,HDD!$A$25:$A$55,0), FALSE) -> 3729.28 | F36: =HLOOKUP(F$30, HDD!$A$25:$AG$55, MATCH($B$2,HDD!$A$25:$A$55,0), FALSE) -> 3523.32 | G36: =HLOOKUP(G$30, HDD!$A$25:$AG$55, MATCH($B$2,HDD!$A$25:$A$55,0), FALSE) -> 3829.94 | H36: =HLOOKUP(H$30, HDD!$A$25:$AG$55, MATCH($B$2,HDD!$A$25:$A$55,0), FALSE) -> 3761.5 | I36: =HLOOKUP(I$30, HDD!$A$25:$AG$55, MATCH($B$2,HDD!$A$25:$A$55,0), FALSE) -> 3687.57 | J36: =HLOOKUP(J$30, HDD!$A$25:$AG$55, MATCH($B$2,HDD!$A$25:$A$55,0), FALSE) -> 3391.36 | ... N36: =HLOOKUP(N$30, HDD!$A$25:$AG$55, MATCH($B$2,HDD!$A$25:$A$55,0), FALSE) -> 3461.92 | P36: =HLOOKUP(P$30, HDD!$AA$25:$AG$55, MATCH($B$2,HDD!$A$25:$A$55,0), FALSE) -> 3752.6937 | Q36: =HLOOKUP(Q$30, HDD!$AA$25:$AG$55, MATCH($B$2,HDD!$A$25:$A$55,0), FALSE) -> 3676.533 | R36: =HLOOKUP(R$30, HDD!$AA$25:$AG$55, MATCH($B$2,HDD!$A$25:$A$55,0), FALSE) -> 3600.3723 | S36: =HLOOKUP(S$30, HDD!$AA$25:$AG$55, MATCH($B$2,HDD!$A$25:$A$55,0), FALSE) -> 3524.2116 | T36: =HLOOKUP(T$30, HDD!$AA$25:$AG$55, MATCH($B$2,HDD!$A$25:$A$55,0), FALSE) -> 3448.0509 | U36: =HLOOKUP(U$30, HDD!$AA$25:$AG$55, MATCH($B$2,HDD!$A$25:$A$55,0), FALSE) -> 3371.8902
B37: POP | C37: =HLOOKUP(C$30, POP!$A$27:$AC$63, MATCH($B$2, POP!$A$27:$A$63,0), FALSE) -> 2989139 | D37: =HLOOKUP(D$30, POP!$A$27:$AC$63, MATCH($B$2, POP!$A$27:$A$63,0), FALSE) -> 2961250 | E37: =HLOOKUP(E$30, POP!$A$27:$AC$63, MATCH($B$2, POP!$A$27:$A$63,0), FALSE) -> 2937253 | F37: =HLOOKUP(F$30, POP!$A$27:$AC$63, MATCH($B$2, POP!$A$27:$A$63,0), FALSE) -> 2911109 | G37: =HLOOKUP(G$30, POP!$A$27:$AC$63, MATCH($B$2, POP!$A$27:$A$63,0), FALSE) -> 2877325 | H37: =HLOOKUP(H$30, POP!$A$27:$AC$63, MATCH($B$2, POP!$A$27:$A$63,0), FALSE) -> 2842639 | I37: =HLOOKUP(I$30, POP!$A$27:$AC$63, MATCH($B$2, POP!$A$27:$A$63,0), FALSE) -> 2819200 | J37: =HLOOKUP(J$30, POP!$A$27:$AC$63, MATCH($B$2, POP!$A$27:$A$63,0), FALSE) -> 2811089 | ... N37: =HLOOKUP(N$30, POP!$A$27:$AC$63, MATCH($B$2, POP!$A$27:$A$63,0), FALSE) -> 2871585 | P37: =HLOOKUP(P$30, POP!$A$27:$AE$63, MATCH($B$2, POP!$A$27:$A$63,0), FALSE) -> 2911109 | Q37: =HLOOKUP(Q$30, POP!$A$27:$AE$63, MATCH($B$2, POP!$A$27:$A$63,0), FALSE) -> 2810369 | R37: =HLOOKUP(R$30, POP!$A$27:$AE$63, MATCH($B$2, POP!$A$27:$A$63,0), FALSE) -> 2740086.3 | S37: =HLOOKUP(S$30, POP!$A$27:$AE$63, MATCH($B$2, POP!$A$27:$A$63,0), FALSE) -> 2684711.4 | T37: =HLOOKUP(T$30, POP!$A$27:$AE$63, MATCH($B$2, POP!$A$27:$A$63,0), FALSE) -> 2647794.8 | U37: =HLOOKUP(U$30, POP!$A$27:$AE$63, MATCH($B$2, POP!$A$27:$A$63,0), FALSE) -> 2610878.2
B38: Normal year net production | C38: =C35/C36*AVERAGE($C$36:$K$36) -> 6739.1439 | D38: =D35/D36*AVERAGE($C$36:$K$36) -> 6940.3563 | E38: =E35/E36*AVERAGE($C$36:$K$36) -> 7069.733 | F38: =F35/F36*AVERAGE($C$36:$K$36) -> 7400.3352 | G38: =G35/G36*AVERAGE($C$36:$K$36) -> 7745.4969 | H38: =H35/H36*AVERAGE($C$36:$K$36) -> 8164.7927 | I38: =I35/I36*AVERAGE($C$36:$K$36) -> 8245.4991 | J38: =J35/J36*AVERAGE($C$36:$K$36) -> 8640.6257 | ... N38: =N35/N36*AVERAGE($C$36:$K$36) -> 7632.76
B39: Normal year net DH supply / pers | C39: =C38/(C37) -> 0.0022545435 | D39: =D38/(D37) -> 0.0023437252 | E39: =E38/(E37) -> 0.00240692 | F39: =F38/(F37) -> 0.0025421017 | G39: =G38/(G37) -> 0.0026919089 | H39: =H38/(H37) -> 0.002872258 | I39: =I38/(I37) -> 0.0029247656 | J39: =J38/(J37) -> 0.0030737645 | ... N39: =N38/(N37) -> 0.0026580303 | P39: {=TREND($C$39:$N$39,$C$30:$N$30,P$30)} -> 0.0025676105 | Q39: {=TREND($C$39:$N$39,$C$30:$N$30,Q$30)} -> 0.0028080572 | R39: {=(TREND($C$39:$N$39,$C$30:$N$30,R$30)-TREND($C$39:$N$39,$C$30:$N$30,$N$30))/2+TREND($C$39:$N$39,$C$30:$N$30,$N$30)} -> 0.0030004145 | S39: {=(TREND($C$39:$N$39,$C$30:$N$30,S$30)-TREND($C$39:$N$39,$C$30:$N$30,$N$30))/2+TREND($C$39:$N$39,$C$30:$N$30,$N$30)} -> 0.0031206378 | T39: {=(TREND($C$39:$N$39,$C$30:$N$30,T$30)-TREND($C$39:$N$39,$C$30:$N$30,$N$30))/2+TREND($C$39:$N$39,$C$30:$N$30,$N$30)} -> 0.0032408612 | U39: {=(TREND($C$39:$N$39,$C$30:$N$30,U$30)-TREND($C$39:$N$39,$C$30:$N$30,$N$30))/2+TREND($C$39:$N$39,$C$30:$N$30,$N$30)} -> 0.0033610845

Sheet Latvia
B2: Latvia
B4: Country | C4: Grid | D4: Node_suffix | E4: Scenario | F4: Year | G4: Variant | H4: TWh/year | I4: Constant_share
B5: LV00 | C5: dheat | E5: all | F5: 2015 | H5: {=TRANSPOSE(N15:S15)/1000} -> 12.113744 | I5: 0.3
B6: LV00 | C6: dheat | E6: all | F6: =F5+5 -> 2020 | H6: 11.273483 | I6: =I5 -> 0.3
B7: LV00 | C7: dheat | E7: all | F7: =F6+5 -> 2025 | H7: 10.537036 | I7: 0.3
B8: LV00 | C8: dheat | E8: all | F8: =F7+5 -> 2030 | H8: 10.021074 | I8: =I7 -> 0.3
B9: LV00 | C9: dheat | E9: all | F9: =F8+5 -> 2035 | H9: 9.6027728 | I9: =I8 -> 0.3
B10: LV00 | C10: dheat | E10: all | F10: =F9+5 -> 2040 | H10: 9.195687 | I10: =I9 -> 0.3
N14: 2015 | O14: 2020 | P14: 2025 | Q14: 2030 | R14: 2035 | S14: 2040
M15: Normal year net production (GWh) | N15: =Q33 -> 12113.744 | O15: =R33 -> 11273.483 | P15: =S33 -> 10537.036 | Q15: =T33 -> 10021.074 | R15: =U33 -> 9602.7728 | S15: =V33 -> 9195.687
B24: Energy commodities balances, Heat GWh, Total gross production
B25: https://osp.stat.gov.lt/statistiniu-rodikliu-analize?indicator=S1R009#/
C28: 2012 | D28: 2013 | E28: 2014 | F28: 2015 | G28: 2016 | H28: 2017 | I28: 2018 | J28: 2019 | K28: 2020 | L28: 2021 | M28: 2022 | N28: 2023 | Q28: 2015 | R28: 2020 | S28: 2025 | T28: 2030 | U28: 2035 | V28: 2040
B29: Sum | C29: 12904.2 | D29: 12118.2 | E29: 12028 | F29: 11516.7 | G29: 11985.6 | H29: 12984.9 | I29: 12751.4 | J29: 11882.4 | K29: 10533.3 | L29: 12382.7 | M29: 10105.7 | N29: 9638.2
B33: Total Supply, GWh | C33: =C29 -> 12904.2 | D33: =D29 -> 12118.2 | E33: =E29 -> 12028 | F33: =F29 -> 11516.7 | G33: =G29 -> 11985.6 | H33: =H29 -> 12984.9 | I33: =I29 -> 12751.4 | J33: =J29 -> 11882.4 | ... N33: =N29 -> 9638.2 | Q33: =Q35*Q37* Q34 / AVERAGE($C$34:$N$34) -> 12113.744 | R33: =R35*R37* R34 / AVERAGE($C$34:$N$34) -> 11273.483 | S33: =S35*S37* S34 / AVERAGE($C$34:$N$34) -> 10537.036 | T33: =T35*T37* T34 / AVERAGE($C$34:$N$34) -> 10021.074 | U33: =U35*U37* U34 / AVERAGE($C$34:$N$34) -> 9602.7728 | V33: =V35*V37* V34 / AVERAGE($C$34:$N$34) -> 9195.687
B34: HDD | C34: =HLOOKUP(C$28, HDD!$A$25:$AG$55, MATCH($B$2,HDD!$A$25:$A$55,0), FALSE) -> 4322.02 | D34: =HLOOKUP(D$28, HDD!$A$25:$AG$55, MATCH($B$2,HDD!$A$25:$A$55,0), FALSE) -> 4036.79 | E34: =HLOOKUP(E$28, HDD!$A$25:$AG$55, MATCH($B$2,HDD!$A$25:$A$55,0), FALSE) -> 3939.85 | F34: =HLOOKUP(F$28, HDD!$A$25:$AG$55, MATCH($B$2,HDD!$A$25:$A$55,0), FALSE) -> 3657.39 | G34: =HLOOKUP(G$28, HDD!$A$25:$AG$55, MATCH($B$2,HDD!$A$25:$A$55,0), FALSE) -> 4002.81 | H34: =HLOOKUP(H$28, HDD!$A$25:$AG$55, MATCH($B$2,HDD!$A$25:$A$55,0), FALSE) -> 3997.38 | I34: =HLOOKUP(I$28, HDD!$A$25:$AG$55, MATCH($B$2,HDD!$A$25:$A$55,0), FALSE) -> 3862.19 | J34: =HLOOKUP(J$28, HDD!$A$25:$AG$55, MATCH($B$2,HDD!$A$25:$A$55,0), FALSE) -> 3622.92 | ... N34: =HLOOKUP(N$28, HDD!$A$25:$AG$55, MATCH($B$2,HDD!$A$25:$A$55,0), FALSE) -> 3755.06 | Q34: =HLOOKUP(Q$28, HDD!$AA$25:$AG$55, MATCH($B$2,HDD!$A$25:$A$55,0), FALSE) -> 3942.6305 | R34: =HLOOKUP(R$28, HDD!$AA$25:$AG$55, MATCH($B$2,HDD!$A$25:$A$55,0), FALSE) -> 3876.3004 | S34: =HLOOKUP(S$28, HDD!$AA$25:$AG$55, MATCH($B$2,HDD!$A$25:$A$55,0), FALSE) -> 3809.9702 | T34: =HLOOKUP(T$28, HDD!$AA$25:$AG$55, MATCH($B$2,HDD!$A$25:$A$55,0), FALSE) -> 3743.64 | U34: =HLOOKUP(U$28, HDD!$AA$25:$AG$55, MATCH($B$2,HDD!$A$25:$A$55,0), FALSE) -> 3677.3098 | V34: =HLOOKUP(V$28, HDD!$AA$25:$AG$55, MATCH($B$2,HDD!$A$25:$A$55,0), FALSE) -> 3610.9797
B35: POP | C35: =HLOOKUP(C$28, POP!$A$27:$AC$63, MATCH($B$2, POP!$A$27:$A$63,0), FALSE) -> 2034319 | D35: =HLOOKUP(D$28, POP!$A$27:$AC$63, MATCH($B$2, POP!$A$27:$A$63,0), FALSE) -> 2012647 | E35: =HLOOKUP(E$28, POP!$A$27:$AC$63, MATCH($B$2, POP!$A$27:$A$63,0), FALSE) -> 1993782 | F35: =HLOOKUP(F$28, POP!$A$27:$AC$63, MATCH($B$2, POP!$A$27:$A$63,0), FALSE) -> 1977527 | G35: =HLOOKUP(G$28, POP!$A$27:$AC$63, MATCH($B$2, POP!$A$27:$A$63,0), FALSE) -> 1959537 | H35: =HLOOKUP(H$28, POP!$A$27:$AC$63, MATCH($B$2, POP!$A$27:$A$63,0), FALSE) -> 1942248 | I35: =HLOOKUP(I$28, POP!$A$27:$AC$63, MATCH($B$2, POP!$A$27:$A$63,0), FALSE) -> 1927174 | J35: =HLOOKUP(J$28, POP!$A$27:$AC$63, MATCH($B$2, POP!$A$27:$A$63,0), FALSE) -> 1913822 | ... N35: =HLOOKUP(N$28, POP!$A$27:$AC$63, MATCH($B$2, POP!$A$27:$A$63,0), FALSE) -> 1877445 | Q35: =HLOOKUP(Q$28, POP!$A$27:$AE$63, MATCH($B$2, POP!$A$27:$A$63,0), FALSE) -> 1977527 | R35: =HLOOKUP(R$28, POP!$A$27:$AE$63, MATCH($B$2, POP!$A$27:$A$63,0), FALSE) -> 1900449 | S35: =HLOOKUP(S$28, POP!$A$27:$AE$63, MATCH($B$2, POP!$A$27:$A$63,0), FALSE) -> 1829589.1 | T35: =HLOOKUP(T$28, POP!$A$27:$AE$63, MATCH($B$2, POP!$A$27:$A$63,0), FALSE) -> 1784632.5 | U35: =HLOOKUP(U$28, POP!$A$27:$AE$63, MATCH($B$2, POP!$A$27:$A$63,0), FALSE) -> 1754661.4 | V35: =HLOOKUP(V$28, POP!$A$27:$AE$63, MATCH($B$2, POP!$A$27:$A$63,0), FALSE) -> 1724690.3
B36: Normal year net production | C36: =C33/C34*AVERAGE($C$34:$K$34) -> 11559.277 | D36: =D33/D34*AVERAGE($C$34:$K$34) -> 11622.2 | E36: =E33/E34*AVERAGE($C$34:$K$34) -> 11819.527 | F36: =F33/F34*AVERAGE($C$34:$K$34) -> 12191.107 | G36: =G33/G34*AVERAGE($C$34:$K$34) -> 11592.609 | H36: =H33/H34*AVERAGE($C$34:$K$34) -> 12576.203 | I36: =I33/I34*AVERAGE($C$34:$K$34) -> 12782.347 | J36: =J33/J34*AVERAGE($C$34:$K$34) -> 12697.897 | ... N36: =N33/N34*AVERAGE($C$34:$K$34) -> 9937.2318
B37: Normal year net DH supply / pers | C37: =C36/(C35) -> 0.005682136 | D37: =D36/(D35) -> 0.0057745842 | E37: =E36/(E35) -> 0.0059281943 | F37: =F36/(F35) -> 0.0061648246 | G37: =G36/(G35) -> 0.0059159937 | H37: =H36/(H35) -> 0.0064750758 | I37: =I36/(I35) -> 0.0066326896 | J37: =J36/(J35) -> 0.0066348369 | ... N37: =N36/(N35) -> 0.005292955 | Q37: {=TREND($C$37:$N$37,$C$28:$N$28,Q$28)} -> 0.0060553986 | R37: {=TREND($C$37:$N$37,$C$28:$N$28,R$28)} -> 0.0059642705 | S37: {=(TREND($C$37:$N$37,$C$28:$N$28,S$28)-TREND($C$37:$N$37,$C$28:$N$28,$N$28))/2+TREND($C$37:$N$37,$C$28:$N$28,$N$28)} -> 0.0058913681 | T37: {=(TREND($C$37:$N$37,$C$28:$N$28,T$28)-TREND($C$37:$N$37,$C$28:$N$28,$N$28))/2+TREND($C$37:$N$37,$C$28:$N$28,$N$28)} -> 0.005845804 | U37: {=(TREND($C$37:$N$37,$C$28:$N$28,U$28)-TREND($C$37:$N$37,$C$28:$N$28,$N$28))/2+TREND($C$37:$N$37,$C$28:$N$28,$N$28)} -> 0.00580024 | V37: {=(TREND($C$37:$N$37,$C$28:$N$28,V$28)-TREND($C$37:$N$37,$C$28:$N$28,$N$28))/2+TREND($C$37:$N$37,$C$28:$N$28,$N$28)} -> 0.0057546759

Sheet Estonia
B2: Estonia
B4: Country | C4: Grid | D4: Node_suffix | E4: Scenario | F4: Year | G4: Variant | H4: TWh/year | I4: Constant_share
B5: EE00 | C5: dheat | E5: all | F5: 2015 | H5: {=TRANSPOSE(N15:S15)/1000} -> 4.720327 | I5: 0.3
B6: EE00 | C6: dheat | E6: all | F6: =F5+5 -> 2020 | H6: 4.7842652 | I6: =I5 -> 0.3
B7: EE00 | C7: dheat | E7: all | F7: =F6+5 -> 2025 | H7: 4.8362555 | I7: 0.3
B8: EE00 | C8: dheat | E8: all | F8: =F7+5 -> 2030 | H8: 4.8582631 | I8: =I7 -> 0.3
B9: EE00 | C9: dheat | E9: all | F9: =F8+5 -> 2035 | H9: 4.8726943 | I9: =I8 -> 0.3
B10: EE00 | C10: dheat | E10: all | F10: =F9+5 -> 2040 | H10: 4.8842862 | I10: =I9 -> 0.3
N14: 2015 | O14: 2020 | P14: 2025 | Q14: 2030 | R14: 2035 | S14: 2040
M15: Normal year net production (GWh) | N15: =L33 -> 4720.327 | O15: =M33 -> 4784.2652 | P15: =N33 -> 4836.2555 | Q15: =O33 -> 4858.2631 | R15: =P33 -> 4872.6943 | S15: =Q33 -> 4884.2862
B24: Energy removed from district networks by customers, type of networks and efficiency of network
B25: https://ec.europa.eu/eurostat/databrowser/view/nrg_dhdc_e__custom_16147672/default/table?lang=en
C28: 2019 | D28: 2020 | E28: 2021 | F28: 2022 | L28: 2015 | M28: 2020 | N28: 2025 | O28: 2030 | P28: 2035 | Q28: 2040
B29: Sum | C29: 14114 | D29: 12020 | E29: 16059 | F29: 15078
B33: Total Supply, GWh | C33: =(C29/3.6)/0.85 -> 4612.4183 | D33: =(D29/3.6)/0.85 -> 3928.1046 | E33: =(E29/3.6)/0.85 -> 5248.0392 | F33: =(F29/3.6)/0.85 -> 4927.451 | L33: =L35*L37* L34 / AVERAGE($C$34:$F$34) -> 4720.327 | M33: =M35*M37* M34 / AVERAGE($C$34:$F$34) -> 4784.2652 | N33: =N35*N37* N34 / AVERAGE($C$34:$F$34) -> 4836.2555 | O33: =O35*O37* O34 / AVERAGE($C$34:$F$34) -> 4858.2631 | P33: =P35*P37* P34 / AVERAGE($C$34:$F$34) -> 4872.6943 | Q33: =Q35*Q37* Q34 / AVERAGE($C$34:$F$34) -> 4884.2862
B34: HDD | C34: =HLOOKUP(C$28, HDD!$A$25:$AG$55, MATCH($B$2,HDD!$A$25:$A$55,0), FALSE) -> 3883.05 | D34: =HLOOKUP(D$28, HDD!$A$25:$AG$55, MATCH($B$2,HDD!$A$25:$A$55,0), FALSE) -> 3554.43 | E34: =HLOOKUP(E$28, HDD!$A$25:$AG$55, MATCH($B$2,HDD!$A$25:$A$55,0), FALSE) -> 4283.1 | F34: =HLOOKUP(F$28, HDD!$A$25:$AG$55, MATCH($B$2,HDD!$A$25:$A$55,0), FALSE) -> 4117.58 | L34: =HLOOKUP(L$28, HDD!$AA$25:$AG$55, MATCH($B$2,HDD!$A$25:$A$55,0), FALSE) -> 4122.4309 | M34: =HLOOKUP(M$28, HDD!$AA$25:$AG$55, MATCH($B$2,HDD!$A$25:$A$55,0), FALSE) -> 4057.6924 | N34: =HLOOKUP(N$28, HDD!$AA$25:$AG$55, MATCH($B$2,HDD!$A$25:$A$55,0), FALSE) -> 3992.9538 | O34: =HLOOKUP(O$28, HDD!$A$25:$AG$55, MATCH($B$2,HDD!$A$25:$A$55,0), FALSE) -> 3928.2153 | P34: =HLOOKUP(P$28, HDD!$A$25:$AG$55, MATCH($B$2,HDD!$A$25:$A$55,0), FALSE) -> 3863.4768 | Q34: =HLOOKUP(Q$28, HDD!$A$25:$AG$55, MATCH($B$2,HDD!$A$25:$A$55,0), FALSE) -> 3798.7382
B35: POP | C35: =HLOOKUP(C$28, POP!$A$27:$AC$63, MATCH($B$2, POP!$A$27:$A$63,0), FALSE) -> 1326898 | D35: =HLOOKUP(D$28, POP!$A$27:$AC$63, MATCH($B$2, POP!$A$27:$A$63,0), FALSE) -> 1329522 | E35: =HLOOKUP(E$28, POP!$A$27:$AC$63, MATCH($B$2, POP!$A$27:$A$63,0), FALSE) -> 1330932 | F35: =HLOOKUP(F$28, POP!$A$27:$AC$63, MATCH($B$2, POP!$A$27:$A$63,0), FALSE) -> 1348840 | L35: =HLOOKUP(L$28, POP!$A$27:$AE$63, MATCH($B$2, POP!$A$27:$A$63,0), FALSE) -> 1315407 | M35: =HLOOKUP(M$28, POP!$A$27:$AE$63, MATCH($B$2, POP!$A$27:$A$63,0), FALSE) -> 1329522 | N35: =HLOOKUP(N$28, POP!$A$27:$AE$63, MATCH($B$2, POP!$A$27:$A$63,0), FALSE) -> 1341034.5 | O35: =HLOOKUP(O$28, POP!$A$27:$AE$63, MATCH($B$2, POP!$A$27:$A$63,0), FALSE) -> 1344988.9 | P35: =HLOOKUP(P$28, POP!$A$27:$AE$63, MATCH($B$2, POP!$A$27:$A$63,0), FALSE) -> 1347625.3 | Q35: =HLOOKUP(Q$28, POP!$A$27:$AE$63, MATCH($B$2, POP!$A$27:$A$63,0), FALSE) -> 1350261.6
B36: Normal year net production | C36: =C33/C34*AVERAGE($C$34:$K$34) -> 4703.2757 | D36: =D33/D34*AVERAGE($C$34:$K$34) -> 4375.8035 | E36: =E33/E34*AVERAGE($C$34:$K$34) -> 4851.5844 | F36: =F33/F34*AVERAGE($C$34:$K$34) -> 4738.3267
B37: Normal year net DH supply / pers | C37: =C36/(C35) -> 0.0035445646 | D37: =D36/(D35) -> 0.0032912607 | E37: =E36/(E35) -> 0.0036452534 | F37: =F36/(F35) -> 0.0035128901 | L37: {=(TREND($C$37:$F$37,$C$28:$F$28,L$28)-TREND($C$37:$F$37,$C$28:$F$28,$F$28))/2+TREND($C$37:$F$37,$C$28:$F$28,$F$28)} -> 0.0034466984 | M37: {=(TREND($C$37:$F$37,$C$28:$F$28,M$28)-TREND($C$37:$F$37,$C$28:$F$28,$F$28))/2+TREND($C$37:$F$37,$C$28:$F$28,$F$28)} -> 0.0035114407 | N37: {=(TREND($C$37:$F$37,$C$28:$F$28,N$28)-TREND($C$37:$F$37,$C$28:$F$28,$F$28))/2+TREND($C$37:$F$37,$C$28:$F$28,$F$28)} -> 0.003576183 | O37: {=(TREND($C$37:$F$37,$C$28:$F$28,O$28)-TREND($C$37:$F$37,$C$28:$F$28,$F$28))/2+TREND($C$37:$F$37,$C$28:$F$28,$F$28)} -> 0.0036409253 | P37: {=(TREND($C$37:$F$37,$C$28:$F$28,P$28)-TREND($C$37:$F$37,$C$28:$F$28,$F$28))/2+TREND($C$37:$F$37,$C$28:$F$28,$F$28)} -> 0.0037056676 | Q37: {=(TREND($C$37:$F$37,$C$28:$F$28,Q$28)-TREND($C$37:$F$37,$C$28:$F$28,$F$28))/2+TREND($C$37:$F$37,$C$28:$F$28,$F$28)} -> 0.0037704099

Sheet Sweden
B2: Sweden
B4: Country | C4: Grid | D4: Node_suffix | E4: Scenario | F4: Year | G4: Variant | H4: TWh/year | I4: Constant_share
B5: SE01 | C5: dheat | E5: all | F5: 2015 | H5: {=SUMIFS($N$8:$S$8,$N$7:$S$7,$F5) * SUM($N$12:$S$15 * ($N$11:$S$11=$F5) * ($M$12:$M$15=$B5)) / 1000} -> 1.4684667 | I5: 0.3
B6: SE02 | C6: dheat | E6: all | F6: 2015 | H6: {=SUMIFS($N$8:$S$8,$N$7:$S$7,$F6) * SUM($N$12:$S$15 * ($N$11:$S$11=$F6) * ($M$12:$M$15=$B6)) / 1000} -> 5.3582965 | I6: =I5 -> 0.3
B7: SE03 | C7: dheat | E7: all | F7: 2015 | H7: {=SUMIFS($N$8:$S$8,$N$7:$S$7,$F7) * SUM($N$12:$S$15 * ($N$11:$S$11=$F7) * ($M$12:$M$15=$B7)) / 1000} -> 39.018196 | I7: =I6 -> 0.3 | N7: 2015 | O7: 2020 | P7: 2025 | Q7: 2030 | R7: 2035 | S7: 2040
