Workbook

Sheet unitdata
A1: Country | B1: Generator_ID | C1: unit_name_prefix | D1: Scenario | E1: Year | F1: capacity_input1 | G1: node_suffix_input1 | H1: capacity_output1 | I1: node_suffix_output1 | J1: capacity_output2 | K1: node_suffix_output2 | L1: cb | M1: cv | N1: Note | O1: method
A2: =IF(PL00!A2="","",PL00!A2) -> PL00 | B2: =IF(PL00!B2="","",PL00!B2) -> Hard coal old 1 | C2: =IF(PL00!C2="","",PL00!C2) | D2: =IF(PL00!D2="","",PL00!D2) -> all | E2: =IF(PL00!E2="","",PL00!E2) -> 2030 | F2: =IF(PL00!F2="","",PL00!F2) | G2: =IF(PL00!G2="","",PL00!G2) | H2: =IF(PL00!H2="","",PL00!H2) -> -5544.3547 | ... O2: =IF(PL00!O2="","",PL00!O2) -> add-non-negative
A3: =IF(PL00!A3="","",PL00!A3) -> PL00 | B3: =IF(PL00!B3="","",PL00!B3) -> Gas CCGT new | C3: =IF(PL00!C3="","",PL00!C3) | D3: =IF(PL00!D3="","",PL00!D3) -> all | E3: =IF(PL00!E3="","",PL00!E3) -> 2030 | F3: =IF(PL00!F3="","",PL00!F3) | G3: =IF(PL00!G3="","",PL00!G3) | H3: =IF(PL00!H3="","",PL00!H3) -> -6934.6427 | ... O3: =IF(PL00!O3="","",PL00!O3) -> add-non-negative
A4: =IF(PL00!A4="","",PL00!A4) -> PL00 | B4: =IF(PL00!B4="","",PL00!B4) -> Lignite old 1 | C4: =IF(PL00!C4="","",PL00!C4) | D4: =IF(PL00!D4="","",PL00!D4) -> all | E4: =IF(PL00!E4="","",PL00!E4) -> 2030 | F4: =IF(PL00!F4="","",PL00!F4) | G4: =IF(PL00!G4="","",PL00!G4) | H4: =IF(PL00!H4="","",PL00!H4) -> -1110.3194 | ... O4: =IF(PL00!O4="","",PL00!O4) -> add-non-negative
A5: =IF(PL00!A5="","",PL00!A5) -> PL00 | B5: =IF(PL00!B5="","",PL00!B5) -> Hard coal old 2 | C5: =IF(PL00!C5="","",PL00!C5) | D5: =IF(PL00!D5="","",PL00!D5) -> all | E5: =IF(PL00!E5="","",PL00!E5) -> 2040 | F5: =IF(PL00!F5="","",PL00!F5) | G5: =IF(PL00!G5="","",PL00!G5) | H5: =IF(PL00!H5="","",PL00!H5) -> -2172 | ... O5: =IF(PL00!O5="","",PL00!O5) -> add-non-negative
A6: =IF(PL00!A6="","",PL00!A6) -> PL00 | B6: =IF(PL00!B6="","",PL00!B6) -> Hard coal old 1 | C6: =IF(PL00!C6="","",PL00!C6) | D6: =IF(PL00!D6="","",PL00!D6) -> all | E6: =IF(PL00!E6="","",PL00!E6) -> 2040 | F6: =IF(PL00!F6="","",PL00!F6) | G6: =IF(PL00!G6="","",PL00!G6) | H6: =IF(PL00!H6="","",PL00!H6) -> -1193.0715 | ... O6: =IF(PL00!O6="","",PL00!O6) -> add-non-negative
A7: =IF(PL00!A7="","",PL00!A7) -> PL00 | B7: =IF(PL00!B7="","",PL00!B7) -> Gas CCGT new | C7: =IF(PL00!C7="","",PL00!C7) | D7: =IF(PL00!D7="","",PL00!D7) -> all | E7: =IF(PL00!E7="","",PL00!E7) -> 2040 | F7: =IF(PL00!F7="","",PL00!F7) | G7: =IF(PL00!G7="","",PL00!G7) | H7: =IF(PL00!H7="","",PL00!H7) -> -8865.1783 | ... O7: =IF(PL00!O7="","",PL00!O7) -> add-non-negative
A8: =IF(PL00!A8="","",PL00!A8) -> PL00 | B8: =IF(PL00!B8="","",PL00!B8) -> Hard coal new | C8: =IF(PL00!C8="","",PL00!C8) | D8: =IF(PL00!D8="","",PL00!D8) -> all | E8: =IF(PL00!E8="","",PL00!E8) -> 2040 | F8: =IF(PL00!F8="","",PL00!F8) | G8: =IF(PL00!G8="","",PL00!G8) | H8: =IF(PL00!H8="","",PL00!H8) -> -1912.0092 | ... O8: =IF(PL00!O8="","",PL00!O8) -> add-non-negative
A9: =IF(PL00!A9="","",PL00!A9) -> PL00 | B9: =IF(PL00!B9="","",PL00!B9) -> Lignite old 1 | C9: =IF(PL00!C9="","",PL00!C9) | D9: =IF(PL00!D9="","",PL00!D9) -> all | E9: =IF(PL00!E9="","",PL00!E9) -> 2040 | F9: =IF(PL00!F9="","",PL00!F9) | G9: =IF(PL00!G9="","",PL00!G9) | H9: =IF(PL00!H9="","",PL00!H9) -> -237 | ... O9: =IF(PL00!O9="","",PL00!O9) -> add-non-negative
A10: =IF(PL00!A10="","",PL00!A10) -> PL00 | B10: =IF(PL00!B10="","",PL00!B10) -> Lignite old 2 | C10: =IF(PL00!C10="","",PL00!C10) | D10: =IF(PL00!D10="","",PL00!D10) -> all | E10: =IF(PL00!E10="","",PL00!E10) -> 2040 | F10: =IF(PL00!F10="","",PL00!F10) | G10: =IF(PL00!G10="","",PL00!G10) | H10: =IF(PL00!H10="","",PL00!H10) -> -446 | ... O10: =IF(PL00!O10="","",PL00!O10) -> add-non-negative
A11: =IF(PL00!A11="","",PL00!A11) -> PL00 | B11: =IF(PL00!B11="","",PL00!B11) -> Coal CHP | C11: =IF(PL00!C11="","",PL00!C11) | D11: =IF(PL00!D11="","",PL00!D11) -> all | E11: =IF(PL00!E11="","",PL00!E11) -> 2040 | F11: =IF(PL00!F11="","",PL00!F11) | G11: =IF(PL00!G11="","",PL00!G11) | H11: =IF(PL00!H11="","",PL00!H11) -> 3365.0715 | ... O11: =IF(PL00!O11="","",PL00!O11)
A12: =IF(PL00!A12="","",PL00!A12) -> PL00 | B12: =IF(PL00!B12="","",PL00!B12) -> Gas CCGT CHP | C12: =IF(PL00!C12="","",PL00!C12) | D12: =IF(PL00!D12="","",PL00!D12) -> all | E12: =IF(PL00!E12="","",PL00!E12) -> 2040 | F12: =IF(PL00!F12="","",PL00!F12) | G12: =IF(PL00!G12="","",PL00!G12) | H12: =IF(PL00!H12="","",PL00!H12) -> 8865.1783 | ... O12: =IF(PL00!O12="","",PL00!O12)
A13: =IF(PL00!A13="","",PL00!A13) -> PL00 | B13: =IF(PL00!B13="","",PL00!B13) -> Bio CHP | C13: =IF(PL00!C13="","",PL00!C13) | D13: =IF(PL00!D13="","",PL00!D13) -> all | E13: =IF(PL00!E13="","",PL00!E13) -> 2040 | F13: =IF(PL00!F13="","",PL00!F13) | G13: =IF(PL00!G13="","",PL00!G13) | H13: =IF(PL00!H13="","",PL00!H13) -> 1912.0092 | ... O13: =IF(PL00!O13="","",PL00!O13)
... A61: =IF(PL00!A61="","",PL00!A61) -> PL00 | B61: =IF(PL00!B61="","",PL00!B61) -> Bio CHP extraction | C61: =IF(PL00!C61="","",PL00!C61) | D61: =IF(PL00!D61="","",PL00!D61) -> all | E61: =IF(PL00!E61="","",PL00!E61) -> 1 | F61: =IF(PL00!F61="","",PL00!F61) | G61: =IF(PL00!G61="","",PL00!G61) | H61: =IF(PL00!H61="","",PL00!H61) -> 166.5 | ... O61: =IF(PL00!O61="","",PL00!O61)
A62: =IF(DE00!A2="","",DE00!A2) -> DE00 | B62: =IF(DE00!B2="","",DE00!B2) -> Coal CHP | C62: =IF(DE00!C2="","",DE00!C2) | D62: =IF(DE00!D2="","",DE00!D2) -> all | E62: =IF(DE00!E2="","",DE00!E2) -> 2015 | F62: =IF(DE00!F2="","",DE00!F2) | G62: =IF(DE00!G2="","",DE00!G2) | H62: =IF(DE00!H2="","",DE00!H2) -> 4992.2703 | ... O62: =IF(DE00!O2="","",DE00!O2)
A63: =IF(DE00!A3="","",DE00!A3) -> DE00 | B63: =IF(DE00!B3="","",DE00!B3) -> Gas CCGT CHP | C63: =IF(DE00!C3="","",DE00!C3) | D63: =IF(DE00!D3="","",DE00!D3) -> all | E63: =IF(DE00!E3="","",DE00!E3) -> 2015 | F63: =IF(DE00!F3="","",DE00!F3) | G63: =IF(DE00!G3="","",DE00!G3) | H63: =IF(DE00!H3="","",DE00!H3) -> 9358.3496 | ... O63: =IF(DE00!O3="","",DE00!O3)
A64: =IF(DE00!A4="","",DE00!A4) -> DE00 | B64: =IF(DE00!B4="","",DE00!B4) -> Bio CHP | C64: =IF(DE00!C4="","",DE00!C4) | D64: =IF(DE00!D4="","",DE00!D4) -> all | E64: =IF(DE00!E4="","",DE00!E4) -> 2015 | F64: =IF(DE00!F4="","",DE00!F4) | G64: =IF(DE00!G4="","",DE00!G4) | H64: =IF(DE00!H4="","",DE00!H4) -> 809.3731 | ... O64: =IF(DE00!O4="","",DE00!O4)
A65: =IF(DE00!A5="","",DE00!A5) -> DE00 | B65: =IF(DE00!B5="","",DE00!B5) -> Waste CHP | C65: =IF(DE00!C5="","",DE00!C5) | D65: =IF(DE00!D5="","",DE00!D5) -> all | E65: =IF(DE00!E5="","",DE00!E5) -> 2015 | F65: =IF(DE00!F5="","",DE00!F5) | G65: =IF(DE00!G5="","",DE00!G5) | H65: =IF(DE00!H5="","",DE00!H5) -> 483.61574 | ... O65: =IF(DE00!O5="","",DE00!O5)
A66: =IF(DE00!A6="","",DE00!A6) -> DE00 | B66: =IF(DE00!B6="","",DE00!B6) -> Coal HOB | C66: =IF(DE00!C6="","",DE00!C6) | D66: =IF(DE00!D6="","",DE00!D6) -> all | E66: =IF(DE00!E6="","",DE00!E6) -> 2015 | F66: =IF(DE00!F6="","",DE00!F6) | G66: =IF(DE00!G6="","",DE00!G6) | H66: =IF(DE00!H6="","",DE00!H6) -> 3991.1209 | ... O66: =IF(DE00!O6="","",DE00!O6)
A67: =IF(DE00!A7="","",DE00!A7) -> DE00 | B67: =IF(DE00!B7="","",DE00!B7) -> Oil HOB | C67: =IF(DE00!C7="","",DE00!C7) | D67: =IF(DE00!D7="","",DE00!D7) -> all | E67: =IF(DE00!E7="","",DE00!E7) -> 2015 | F67: =IF(DE00!F7="","",DE00!F7) | G67: =IF(DE00!G7="","",DE00!G7) | H67: =IF(DE00!H7="","",DE00!H7) -> 7497.8967 | ... O67: =IF(DE00!O7="","",DE00!O7)
A68: =IF(DE00!A8="","",DE00!A8) -> DE00 | B68: =IF(DE00!B8="","",DE00!B8) -> Gas HOB | C68: =IF(DE00!C8="","",DE00!C8) | D68: =IF(DE00!D8="","",DE00!D8) -> all | E68: =IF(DE00!E8="","",DE00!E8) -> 2015 | F68: =IF(DE00!F8="","",DE00!F8) | G68: =IF(DE00!G8="","",DE00!G8) | H68: =IF(DE00!H8="","",DE00!H8) -> 623.49659 | ... O68: =IF(DE00!O8="","",DE00!O8)
A69: =IF(DE00!A9="","",DE00!A9) -> DE00 | B69: =IF(DE00!B9="","",DE00!B9) -> Bio HOB | C69: =IF(DE00!C9="","",DE00!C9) | D69: =IF(DE00!D9="","",DE00!D9) -> all | E69: =IF(DE00!E9="","",DE00!E9) -> 2015 | F69: =IF(DE00!F9="","",DE00!F9) | G69: =IF(DE00!G9="","",DE00!G9) | H69: =IF(DE00!H9="","",DE00!H9) -> 273.89196 | ... O69: =IF(DE00!O9="","",DE00!O9)
A70: =IF(DE00!A10="","",DE00!A10) -> DE00 | B70: =IF(DE00!B10="","",DE00!B10) -> Coal CHP | C70: =IF(DE00!C10="","",DE00!C10) | D70: =IF(DE00!D10="","",DE00!D10) -> all | E70: =IF(DE00!E10="","",DE00!E10) -> 2020 | F70: =IF(DE00!F10="","",DE00!F10) | G70: =IF(DE00!G10="","",DE00!G10) | H70: =IF(DE00!H10="","",DE00!H10) -> 3397.4675 | ... O70: =IF(DE00!O10="","",DE00!O10)
A71: =IF(DE00!A11="","",DE00!A11) -> DE00 | B71: =IF(DE00!B11="","",DE00!B11) -> Gas CCGT CHP | C71: =IF(DE00!C11="","",DE00!C11) | D71: =IF(DE00!D11="","",DE00!D11) -> all | E71: =IF(DE00!E11="","",DE00!E11) -> 2020 | F71: =IF(DE00!F11="","",DE00!F11) | G71: =IF(DE00!G11="","",DE00!G11) | H71: =IF(DE00!H11="","",DE00!H11) -> 8626.1985 | ... O71: =IF(DE00!O11="","",DE00!O11)
A72: =IF(DE00!A12="","",DE00!A12) -> DE00 | B72: =IF(DE00!B12="","",DE00!B12) -> Bio CHP | C72: =IF(DE00!C12="","",DE00!C12) | D72: =IF(DE00!D12="","",DE00!D12) -> all | E72: =IF(DE00!E12="","",DE00!E12) -> 2020 | F72: =IF(DE00!F12="","",DE00!F12) | G72: =IF(DE00!G12="","",DE00!G12) | H72: =IF(DE00!H12="","",DE00!H12) -> 834.3002 | ... O72: =IF(DE00!O12="","",DE00!O12)
A73: =IF(DE00!A13="","",DE00!A13) -> DE00 | B73: =IF(DE00!B13="","",DE00!B13) -> Waste CHP | C73: =IF(DE00!C13="","",DE00!C13) | D73: =IF(DE00!D13="","",DE00!D13) -> all | E73: =IF(DE00!E13="","",DE00!E13) -> 2020 | F73: =IF(DE00!F13="","",DE00!F13) | G73: =IF(DE00!G13="","",DE00!G13) | H73: =IF(DE00!H13="","",DE00!H13) -> 431.52696 | ... O73: =IF(DE00!O13="","",DE00!O13)
... A143: =IF(DE00!A83="","",DE00!A83) -> DE00 | B143: =IF(DE00!B83="","",DE00!B83) -> Bio CHP extraction | C143: =IF(DE00!C83="","",DE00!C83) | D143: =IF(DE00!D83="","",DE00!D83) -> all | E143: =IF(DE00!E83="","",DE00!E83) -> 1 | F143: =IF(DE00!F83="","",DE00!F83) | G143: =IF(DE00!G83="","",DE00!G83) | H143: =IF(DE00!H83="","",DE00!H83) -> 333 | ... O143: =IF(DE00!O83="","",DE00!O83)
A144: =IF(AT00!A2="","",AT00!A2) -> AT00 | B144: =IF(AT00!B2="","",AT00!B2) -> Coal CHP | C144: =IF(AT00!C2="","",AT00!C2) | D144: =IF(AT00!D2="","",AT00!D2) -> all | E144: =IF(AT00!E2="","",AT00!E2) -> 2015 | F144: =IF(AT00!F2="","",AT00!F2) | G144: =IF(AT00!G2="","",AT00!G2) | H144: =IF(AT00!H2="","",AT00!H2) -> 143.15799 | ... O144: =IF(AT00!O2="","",AT00!O2)
A145: =IF(AT00!A3="","",AT00!A3) -> AT00 | B145: =IF(AT00!B3="","",AT00!B3) -> Gas CCGT CHP | C145: =IF(AT00!C3="","",AT00!C3) | D145: =IF(AT00!D3="","",AT00!D3) -> all | E145: =IF(AT00!E3="","",AT00!E3) -> 2015 | F145: =IF(AT00!F3="","",AT00!F3) | G145: =IF(AT00!G3="","",AT00!G3) | H145: =IF(AT00!H3="","",AT00!H3) -> 1552.9431 | ... O145: =IF(AT00!O3="","",AT00!O3)
A146: =IF(AT00!A4="","",AT00!A4) -> AT00 | B146: =IF(AT00!B4="","",AT00!B4) -> Waste CHP | C146: =IF(AT00!C4="","",AT00!C4) | D146: =IF(AT00!D4="","",AT00!D4) -> all | E146: =IF(AT00!E4="","",AT00!E4) -> 2015 | F146: =IF(AT00!F4="","",AT00!F4) | G146: =IF(AT00!G4="","",AT00!G4) | H146: =IF(AT00!H4="","",AT00!H4) -> 54.206638 | ... O146: =IF(AT00!O4="","",AT00!O4)
A147: =IF(AT00!A5="","",AT00!A5) -> AT00 | B147: =IF(AT00!B5="","",AT00!B5) -> Bio CHP | C147: =IF(AT00!C5="","",AT00!C5) | D147: =IF(AT00!D5="","",AT00!D5) -> all | E147: =IF(AT00!E5="","",AT00!E5) -> 2015 | F147: =IF(AT00!F5="","",AT00!F5) | G147: =IF(AT00!G5="","",AT00!G5) | H147: =IF(AT00!H5="","",AT00!H5) -> 150.53353 | ... O147: =IF(AT00!O5="","",AT00!O5)
A148: =IF(AT00!A6="","",AT00!A6) -> AT00 | B148: =IF(AT00!B6="","",AT00!B6) -> Coal CHP | C148: =IF(AT00!C6="","",AT00!C6) | D148: =IF(AT00!D6="","",AT00!D6) -> all | E148: =IF(AT00!E6="","",AT00!E6) -> 2020 | F148: =IF(AT00!F6="","",AT00!F6) | G148: =IF(AT00!G6="","",AT00!G6) | H148: =IF(AT00!H6="","",AT00!H6) -> 78.087537 | ... O148: =IF(AT00!O6="","",AT00!O6)
A149: =IF(AT00!A7="","",AT00!A7) -> AT00 | B149: =IF(AT00!B7="","",AT00!B7) -> Gas CCGT CHP | C149: =IF(AT00!C7="","",AT00!C7) | D149: =IF(AT00!D7="","",AT00!D7) -> all | E149: =IF(AT00!E7="","",AT00!E7) -> 2020 | F149: =IF(AT00!F7="","",AT00!F7) | G149: =IF(AT00!G7="","",AT00!G7) | H149: =IF(AT00!H7="","",AT00!H7) -> 1540.7457 | ... O149: =IF(AT00!O7="","",AT00!O7)
A150: =IF(AT00!A8="","",AT00!A8) -> AT00 | B150: =IF(AT00!B8="","",AT00!B8) -> Waste CHP | C150: =IF(AT00!C8="","",AT00!C8) | D150: =IF(AT00!D8="","",AT00!D8) -> all | E150: =IF(AT00!E8="","",AT00!E8) -> 2020 | F150: =IF(AT00!F8="","",AT00!F8) | G150: =IF(AT00!G8="","",AT00!G8) | H150: =IF(AT00!H8="","",AT00!H8) -> 58.470494 | ... O150: =IF(AT00!O8="","",AT00!O8)
A151: =IF(AT00!A9="","",AT00!A9) -> AT00 | B151: =IF(AT00!B9="","",AT00!B9) -> Bio CHP | C151: =IF(AT00!C9="","",AT00!C9) | D151: =IF(AT00!D9="","",AT00!D9) -> all | E151: =IF(AT00!E9="","",AT00!E9) -> 2020 | F151: =IF(AT00!F9="","",AT00!F9) | G151: =IF(AT00!G9="","",AT00!G9) | H151: =IF(AT00!H9="","",AT00!H9) -> 149.50617 | ... O151: =IF(AT00!O9="","",AT00!O9)
A152: =IF(AT00!A10="","",AT00!A10) -> AT00 | B152: =IF(AT00!B10="","",AT00!B10) -> Coal CHP | C152: =IF(AT00!C10="","",AT00!C10) | D152: =IF(AT00!D10="","",AT00!D10) -> all | E152: =IF(AT00!E10="","",AT00!E10) -> 2025 | F152: =IF(AT00!F10="","",AT00!F10) | G152: =IF(AT00!G10="","",AT00!G10) | H152: =IF(AT00!H10="","",AT00!H10) -> 13.017084 | ... O152: =IF(AT00!O10="","",AT00!O10)
A153: =IF(AT00!A11="","",AT00!A11) -> AT00 | B153: =IF(AT00!B11="","",AT00!B11) -> Gas CCGT CHP | C153: =IF(AT00!C11="","",AT00!C11) | D153: =IF(AT00!D11="","",AT00!D11) -> all | E153: =IF(AT00!E11="","",AT00!E11) -> 2025 | F153: =IF(AT00!F11="","",AT00!F11) | G153: =IF(AT00!G11="","",AT00!G11) | H153: =IF(AT00!H11="","",AT00!H11) -> 1528.5484 | ... O153: =IF(AT00!O11="","",AT00!O11)
A154: =IF(AT00!A12="","",AT00!A12) -> AT00 | B154: =IF(AT00!B12="","",AT00!B12) -> Waste CHP | C154: =IF(AT00!C12="","",AT00!C12) | D154: =IF(AT00!D12="","",AT00!D12) -> all | E154: =IF(AT00!E12="","",AT00!E12) -> 2025 | F154: =IF(AT00!F12="","",AT00!F12) | G154: =IF(AT00!G12="","",AT00!G12) | H154: =IF(AT00!H12="","",AT00!H12) -> 62.73435 | ... O154: =IF(AT00!O12="","",AT00!O12)
A155: =IF(AT00!A13="","",AT00!A13) -> AT00 | B155: =IF(AT00!B13="","",AT00!B13) -> Bio CHP | C155: =IF(AT00!C13="","",AT00!C13) | D155: =IF(AT00!D13="","",AT00!D13) -> all | E155: =IF(AT00!E13="","",AT00!E13) -> 2025 | F155: =IF(AT00!F13="","",AT00!F13) | G155: =IF(AT00!G13="","",AT00!G13) | H155: =IF(AT00!H13="","",AT00!H13) -> 148.47881 | ... O155: =IF(AT00!O13="","",AT00!O13)
... A216: =IF(AT00!A74="","",AT00!A74) -> AT00 | B216: =IF(AT00!B74="","",AT00!B74) -> Heat storage charger | C216: =IF(AT00!C74="","",AT00!C74) | D216: =IF(AT00!D74="","",AT00!D74) -> all | E216: =IF(AT00!E74="","",AT00!E74) -> 2040 | F216: =IF(AT00!F74="","",AT00!F74) | G216: =IF(AT00!G74="","",AT00!G74) | H216: =IF(AT00!H74="","",AT00!H74) -> 1350 | ... O216: =IF(AT00!O74="","",AT00!O74)

Sheet PL00
A1: Country | B1: Generator_ID | C1: unit_name_prefix | D1: Scenario | E1: Year | F1: capacity_input1 | G1: node_suffix_input1 | H1: capacity_output1 | I1: node_suffix_output1 | J1: capacity_output2 | K1: node_suffix_output2 | L1: cb | M1: cv | N1: Note | O1: method | X1: ## | Y1: ## | Z1: ## | AA1: ## | AB1: ## | AC1: ## | AD1: ## | AE1: ## | AF1: ## | AG1: ## | AH1: ## | AI1: ## | AJ1: ## | AK1: ## | AL1: ## | AM1: ## | AN1: ## | AO1: ## | AP1: ## | AQ1: ## | AR1: ## | AS1: ## | AT1: ## | AU1: ## | AV1: ## | AW1: ## | AX1: ## | AY1: ## | AZ1: ## | BA1: ## | BB1: ## | BC1: ## | BD1: ## | BE1: ## | BF1: ## | BG1: ## | BH1: ## | BI1: ## | BJ1: ## | BK1: ## | BL1: ## | BM1: ## | BN1: ## | BO1: ## | BP1: ## | BQ1: ## | BR1: ## | BS1: ## | BT1: ##
A2: PL00 | B2: Hard coal old 1 | D2: all | E2: 2030 | H2: =-1*BA103 -> -5544.3547 | N2: Reducing ENTSO‑E coal condensing capacity to offset added coal CHP electricity output | O2: add-non-negative
A3: PL00 | B3: Gas CCGT new | D3: all | E3: 2030 | H3: =-1*BA104 -> -6934.6427 | N3: Reducing ENTSO‑E gas condensing capacity to offset added gas CHP electricity output | O3: add-non-negative
A4: PL00 | B4: Lignite old 1 | D4: all | E4: 2030 | H4: =-1*BA105 -> -1110.3194 | N4: Reducing ENTSO‑E coal condensing capacity to offset added bio CHP electricity output | O4: add-non-negative
A5: PL00 | B5: Hard coal old 2 | D5: all | E5: 2040 | H5: =-1*BD91 -> -2172 | N5: Reducing ENTSO‑E coal condensing capacity to offset added coal CHP electricity output | O5: add-non-negative
A6: PL00 | B6: Hard coal old 1 | D6: all | E6: 2040 | H6: =-1*(BB103+H5) -> -1193.0715 | N6: Reducing ENTSO‑E coal condensing capacity to offset added coal CHP electricity output | O6: add-non-negative | Y6: Current (national trends)
A7: PL00 | B7: Gas CCGT new | D7: all | E7: 2040 | H7: =-1*BB104 -> -8865.1783 | N7: Reducing ENTSO‑E gas condensing capacity to offset added gas CHP electricity output | O7: add-non-negative | Y7: grid | Z7: node | AA7: unit | AB7: input_output | AC7: isActive | AD7: capacity | AJ7: https://iea.blob.core.windows.net/assets/b9ea5a7d-3e41-4318-a69e-f7d456ebb118/Poland2022.pdf
A8: PL00 | B8: Hard coal new | D8: all | E8: 2040 | H8: =-1*BB105 -> -1912.0092 | N8: Reducing ENTSO‑E coal condensing capacity to offset added bio CHP electricity output | O8: add-non-negative | Y8: dheat | Z8: PL00_dheat | AA8: PL00_CCGTCHPgas | AB8: output | AC8: 1 | AD8: 960 | AJ8: "In 2019, co-generation accounted for 17% of electricity generation and 65% of district heating supply."
A9: PL00 | B9: Lignite old 1 | D9: all | E9: 2040 | H9: =-1*BD92 -> -237 | N9: Reducing ENTSO‑E coal condensing capacity to offset added bio CHP electricity output | O9: add-non-negative | Y9: dheat | Z9: PL00_dheat | AA9: PL00_CHPcoal | AB9: output | AC9: 1 | AD9: 10650 | AJ9: https://polandinsight.com/ptec-district-heating-transformation-could-cost-up-to-pln-466-billion-by-2050/
A10: PL00 | B10: Lignite old 2 | D10: all | E10: 2040 | H10: =-1*BD93 -> -446 | N10: Reducing ENTSO‑E coal condensing capacity to offset added bio CHP electricity output | O10: add-non-negative | Y10: dheat | Z10: PL00_dheat | AA10: PL00_HeatstorCharger | AB10: input | AC10: 1 | AD10: 2141.4141 | AJ10: “According to data from the Energy Regulatory Office, more than 60 percent of the generation mix in heating still comes from coal. By comparison, gas or renewable energy sources each account for around 10 percent, so the disparity is significant,” said Monika Gruźlewska, director of the Polish District Heating Association, in an interview with Newseria.
A11: PL00 | B11: Coal CHP | D11: all | E11: 2040 | H11: =L11*J11 -> 3365.0715 | J11: =BQ25-BB123 -> 7477.9366 | L11: 0.45 | Y11: dheat | Z11: PL00_dheat | AA11: PL00_HeatstorDischarger | AB11: output | AC11: 1 | AD11: 2120
A12: PL00 | B12: Gas CCGT CHP | D12: all | E12: 2040 | H12: =L12*J12 -> 8865.1783 | J12: =BQ26-BB124 -> 8865.1783 | L12: 1 | Y12: dheat | Z12: PL00_dheat | AA12: PL00_HOBgas | AB12: output | AC12: 1 | AD12: 11000
A13: PL00 | B13: Bio CHP | D13: all | E13: 2040 | H13: =L13*J13 -> 1912.0092 | J13: =BQ27-BB125 -> 3824.0183 | L13: 0.5 | Y13: dheat | Z13: PL00_dheat | AA13: PL00_HOBoil | AB13: output | AC13: 1 | AD13: 22000
A14: PL00 | B14: Waste CHP | D14: all | E14: 2040 | H14: =L14*J14 -> 188.96947 | J14: =BQ28 -> 472.42368 | L14: 0.4 | AD14: =AD8+AD9+AD12+AD13 -> 44610
A15: PL00 | B15: Coal CHP | D15: all | E15: 2035 | H15: =L15*J15 -> 4454.7131 | J15: =BQ29-BB123 -> 9899.3624 | L15: 0.45
A16: PL00 | B16: Gas CCGT CHP | D16: all | E16: 2035 | H16: =L16*J16 -> 7899.9105 | J16: =BQ30-BB124 -> 7899.9105 | L16: 1
A17: PL00 | B17: Bio CHP | D17: all | E17: 2035 | H17: =L17*J17 -> 1511.1643 | J17: =BQ31-BB125 -> 3022.3285 | L17: 0.5
A18: PL00 | B18: Waste CHP | D18: all | E18: 2035 | H18: =L18*J18 -> 185.97418 | J18: =BQ32 -> 464.93545 | L18: 0.4
A19: PL00 | B19: Coal CHP | D19: all | E19: 2030 | H19: =L19*J19 -> 5544.3547 | J19: =BQ33-BB123 -> 12320.788 | L19: 0.45
A20: PL00 | B20: Gas CCGT CHP | D20: all | E20: 2030 | H20: =L20*J20 -> 6934.6427 | J20: =BQ34-BB124 -> 6934.6427 | L20: 1
A21: PL00 | B21: Bio CHP | D21: all | E21: 2030 | H21: =L21*J21 -> 1110.3194 | J21: =BQ35-BB125 -> 2220.6387 | L21: 0.5
A22: PL00 | B22: Waste CHP | D22: all | E22: 2030 | H22: =L22*J22 -> 182.97889 | J22: =BQ36 -> 457.44721 | L22: 0.4 | AJ22: Kapasiteetit vuosille 2015, 2020, 2025, 2030 (min), 2035 ja 2040 (max)
A23: PL00 | B23: Coal CHP | D23: all | E23: 2025 | H23: =L23*J23 -> 6633.9963 | J23: =BQ37-BB123 -> 14742.214 | L23: 0.45
A24: PL00 | B24: Gas CCGT CHP | D24: all | E24: 2025 | H24: =L24*J24 -> 5969.3749 | J24: =BQ38-BB124 -> 5969.3749 | L24: 1 | AJ24: DH demand (produced heat) | BQ24: sorting
A25: PL00 | B25: Bio CHP | D25: all | E25: 2025 | H25: =L25*J25 -> 709.47446 | J25: =BQ39-BB125 -> 1418.9489 | L25: 0.5 | AJ25: year | AK25: 2012 | AL25: 2013 | AM25: 2014 | AN25: 2015 | AO25: 2016 | AP25: 2017 | AQ25: 2018 | AR25: 2019 | AS25: 2020 | AT25: 2021 | AU25: 2022 | AV25: 2023 | AW25: 2024 | BQ25: {=TRANSPOSE(BA53:BD53)} -> 7765.0056
A26: PL00 | B26: Waste CHP | D26: all | E26: 2025 | H26: =L26*J26 -> 179.98359 | J26: =BQ40 -> 449.95898 | L26: 0.4 | AJ26: TJ | AK26: 399674 | AL26: 395035.1 | AM26: 360210.6 | AN26: 359551.6 | AO26: 383783 | AP26: 395596.9 | AQ26: 376010.2 | AR26: 365629 | AS26: 358710 | AT26: 390579.9 | AU26: 370611.3 | AV26: 346087 | AW26: 335486.9 | BQ26: 9012.5234
A27: PL00 | B27: Coal CHP | D27: all | E27: 2020 | H27: =L27*J27 -> 8813.2794 | J27: =BQ41-BB123 -> 19585.065 | L27: 0.45 | AJ27: GWh | AK27: =0.27777777*AK26 -> 111020.55 | AL27: =0.27777777*AL26 -> 109731.97 | AM27: =0.27777777*AM26 -> 100058.5 | AN27: =0.27777777*AN26 -> 99875.442 | AO27: =0.27777777*AO26 -> 106606.39 | AP27: =0.27777777*AP26 -> 109888.02 | AQ27: =0.27777777*AQ26 -> 104447.27 | AR27: =0.27777777*AR26 -> 101563.61 | ... AW27: =0.27777777*AW26 -> 93190.803 | BQ27: 4088.304
A28: PL00 | B28: Gas CCGT CHP | D28: all | E28: 2020 | H28: =L28*J28 -> 5004.1071 | J28: =BQ42-BB124 -> 5004.1071 | L28: 1 | AY28: Based on data | BQ28: 472.42368
A29: PL00 | B29: Bio CHP | D29: all | E29: 2020 | H29: =L29*J29 -> 629.30548 | J29: =BQ43-BB125 -> 1258.611 | L29: 0.5 | AY29: CHP | BA29: Coal | BB29: Oil | BC29: Gas | BD29: Bio | BE29: Waste | BF29: Others | BG29: HOB | BH29: Coal | BI29: Oil | BJ29: Gas | BK29: Bio | BL29: Waste | BM29: Others | BN29: Total CHP + HOB cap [MW] | BQ29: {=TRANSPOSE(BA54:BD54)} -> 10186.431
A30: PL00 | B30: Waste CHP | D30: all | E30: 2020 | H30: =L30*J30 -> 176.9883 | J30: =BQ44 -> 442.47075 | L30: 0.4 | AO30: =AO27/1000 -> 106.60639 | AP30: =AP27/1000 -> 109.88802 | AS30: =AS27/1000 -> 99.641664 | AT30: =AT27/1000 -> 108.49441 | AU30: =AU27/1000 -> 102.94758 | AV30: =AV27/1000 -> 96.135275 | AW30: =AW27/1000 -> 93.190803 | AY30: Trend | AZ30: 2040 | BA30: {=TREND($BA$38:$BA$44,$AZ$38:$AZ$44,AZ30)} -> 596.7598 | BB30: {=TREND($BB$38:$BB$44,$AZ$38:$AZ$44,AZ30)} -> 1892.988 | BC30: {=TREND($BC$38:$BC$44,$AZ$38:$AZ$44,AZ30)} -> 7215.5669 | BD30: {=TREND($BD$38:$BD$44,$AZ$38:$AZ$44,AZ30)} -> 2260.28 | BE30: {=TREND($BE$38:$BE$44,$AZ$38:$AZ$44,AZ30)} -> 568.45514 | BF30: {=TREND($BF$38:$BF$44,$AZ$38:$AZ$44,AZ30)} -> -480.15732 | BH30: {=TREND($BH$38:$BH$44,$AZ$38:$AZ$44,AZ30)} -> 7225.7206 | BI30: {=TREND($BI$38:$BI$44,$AZ$38:$AZ$44,AZ30)} -> 2626.9324 | BJ30: {=TREND($BJ$38:$BJ$44,$AZ$38:$AZ$44,AZ30)} -> 6403.9557 | BK30: {=TREND($BK$38:$BK$44,$AZ$38:$AZ$44,AZ30)} -> 6074.9667 | BL30: {=TREND($BL$38:$BL$44,$AZ$38:$AZ$44,AZ30)} -> 0 | BM30: {=TREND($BM$38:$BM$44,$AZ$38:$AZ$44,AZ30)} -> 1443.6535 | BN30: =SUM(BA30:BM30) -> 35829.121 | BQ30: 8047.2556
A31: PL00 | B31: Coal CHP | D31: all | E31: 2015 | H31: =L31*J31 -> 10992.563 | J31: =BQ45-BB123 -> 24427.917 | L31: 0.45 | AO31: =0.0000002778*SUM(AG122:AG133) -> 121.4234 | AP31: =0.0000002778*SUM(AG108:AG119) -> 122.06744 | AS31: =0.0000002778*SUM(AG80:AG91) -> 117.06171 | AT31: =0.0000002778*SUM(AG66:AG77) -> 108.5031 | AV31: =0.0000002778*SUM(AG52:AG63) -> 115.33914 | AW31: =0.0000002778*SUM(AG38:AG49) -> 111.04239 | AZ31: 2035 | BA31: {=TREND($BA$38:$BA$44,$AZ$38:$AZ$44,AZ31)} -> 5361.1266 | BB31: {=TREND($BB$38:$BB$44,$AZ$38:$AZ$44,AZ31)} -> 1813.3811 | BC31: {=TREND($BC$38:$BC$44,$AZ$38:$AZ$44,AZ31)} -> 6251.4213 | BD31: {=TREND($BD$38:$BD$44,$AZ$38:$AZ$44,AZ31)} -> 2021.4574 | BE31: {=TREND($BE$38:$BE$44,$AZ$38:$AZ$44,AZ31)} -> 482.48224 | BF31: {=TREND($BF$38:$BF$44,$AZ$38:$AZ$44,AZ31)} -> -87.733943 | BH31: {=TREND($BH$38:$BH$44,$AZ$38:$AZ$44,AZ31)} -> 9099.6525 | BI31: {=TREND($BI$38:$BI$44,$AZ$38:$AZ$44,AZ31)} -> 2075.5448 | BJ31: {=TREND($BJ$38:$BJ$44,$AZ$38:$AZ$44,AZ31)} -> 5489.1457 | BK31: {=TREND($BK$38:$BK$44,$AZ$38:$AZ$44,AZ31)} -> 4832.7915 | BL31: {=TREND($BL$38:$BL$44,$AZ$38:$AZ$44,AZ31)} -> 0 | BM31: {=TREND($BM$38:$BM$44,$AZ$38:$AZ$44,AZ31)} -> 1214.7352 | BN31: =SUM(BA31:BM31) -> 38554.004 | BQ31: 3286.6142
A32: PL00 | B32: Gas CCGT CHP | D32: all | E32: 2015 | H32: =L32*J32 -> 4038.8392 | J32: =BQ46-BB124 -> 4038.8392 | L32: 1 | AZ32: 2030 | BA32: {=TREND($BA$38:$BA$44,$AZ$38:$AZ$44,AZ32)} -> 10125.493 | BB32: {=TREND($BB$38:$BB$44,$AZ$38:$AZ$44,AZ32)} -> 1733.7743 | BC32: {=TREND($BC$38:$BC$44,$AZ$38:$AZ$44,AZ32)} -> 5287.2756 | BD32: {=TREND($BD$38:$BD$44,$AZ$38:$AZ$44,AZ32)} -> 1782.6347 | BE32: {=TREND($BE$38:$BE$44,$AZ$38:$AZ$44,AZ32)} -> 396.50933 | BF32: {=TREND($BF$38:$BF$44,$AZ$38:$AZ$44,AZ32)} -> 304.68944 | BH32: {=TREND($BH$38:$BH$44,$AZ$38:$AZ$44,AZ32)} -> 10973.584 | BI32: {=TREND($BI$38:$BI$44,$AZ$38:$AZ$44,AZ32)} -> 1524.1572 | BJ32: {=TREND($BJ$38:$BJ$44,$AZ$38:$AZ$44,AZ32)} -> 4574.3357 | BK32: {=TREND($BK$38:$BK$44,$AZ$38:$AZ$44,AZ32)} -> 3590.6164 | BL32: {=TREND($BL$38:$BL$44,$AZ$38:$AZ$44,AZ32)} -> 0 | BM32: {=TREND($BM$38:$BM$44,$AZ$38:$AZ$44,AZ32)} -> 985.81688 | BN32: =SUM(BA32:BM32) -> 41278.887 | BQ32: 464.93545
A33: PL00 | B33: Bio CHP | D33: all | E33: 2015 | H33: =L33*J33 -> 549.1365 | J33: =BQ47-BB125 -> 1098.273 | L33: 0.5 | AZ33: 2025 | BA33: {=TREND($BA$38:$BA$44,$AZ$38:$AZ$44,AZ33)} -> 14889.86 | BB33: {=TREND($BB$38:$BB$44,$AZ$38:$AZ$44,AZ33)} -> 1654.1675 | BC33: {=TREND($BC$38:$BC$44,$AZ$38:$AZ$44,AZ33)} -> 4323.13 | BD33: {=TREND($BD$38:$BD$44,$AZ$38:$AZ$44,AZ33)} -> 1543.8121 | BE33: {=TREND($BE$38:$BE$44,$AZ$38:$AZ$44,AZ33)} -> 310.53642 | BF33: {=TREND($BF$38:$BF$44,$AZ$38:$AZ$44,AZ33)} -> 697.11281 | BH33: {=TREND($BH$38:$BH$44,$AZ$38:$AZ$44,AZ33)} -> 12847.516 | BI33: {=TREND($BI$38:$BI$44,$AZ$38:$AZ$44,AZ33)} -> 972.76962 | BJ33: {=TREND($BJ$38:$BJ$44,$AZ$38:$AZ$44,AZ33)} -> 3659.5257 | BK33: {=TREND($BK$38:$BK$44,$AZ$38:$AZ$44,AZ33)} -> 2348.4412 | BL33: {=TREND($BL$38:$BL$44,$AZ$38:$AZ$44,AZ33)} -> 0 | BM33: {=TREND($BM$38:$BM$44,$AZ$38:$AZ$44,AZ33)} -> 756.89859 | BN33: =SUM(BA33:BM33) -> 44003.771 | BQ33: {=TRANSPOSE(BA55:BD55)} -> 12607.857
A34: PL00 | B34: Waste CHP | D34: all | E34: 2015 | H34: =L34*J34 -> 173.99301 | J34: =BQ48 -> 434.98252 | L34: 0.4 | AF34: https://www.ure.gov.pl/pl/cieplo/energetyka-cieplna-w-l (2015 and below data N/A) | AZ34: 2020 | BA34: {=TREND($BA$38:$BA$44,$AZ$38:$AZ$44,AZ34)} -> 19654.227 | BB34: {=TREND($BB$38:$BB$44,$AZ$38:$AZ$44,AZ34)} -> 1574.5606 | BC34: {=TREND($BC$38:$BC$44,$AZ$38:$AZ$44,AZ34)} -> 3358.9843 | BD34: {=TREND($BD$38:$BD$44,$AZ$38:$AZ$44,AZ34)} -> 1304.9894 | BE34: {=TREND($BE$38:$BE$44,$AZ$38:$AZ$44,AZ34)} -> 224.56351 | BF34: {=TREND($BF$38:$BF$44,$AZ$38:$AZ$44,AZ34)} -> 1089.5362 | BH34: {=TREND($BH$38:$BH$44,$AZ$38:$AZ$44,AZ34)} -> 14721.448 | BI34: {=TREND($BI$38:$BI$44,$AZ$38:$AZ$44,AZ34)} -> 421.38202 | BJ34: {=TREND($BJ$38:$BJ$44,$AZ$38:$AZ$44,AZ34)} -> 2744.7157 | BK34: {=TREND($BK$38:$BK$44,$AZ$38:$AZ$44,AZ34)} -> 1106.2661 | BL34: {=TREND($BL$38:$BL$44,$AZ$38:$AZ$44,AZ34)} -> 0 | BM34: {=TREND($BM$38:$BM$44,$AZ$38:$AZ$44,AZ34)} -> 527.9803 | BN34: =SUM(BA34:BM34) -> 46728.654 | BQ34: 7081.9878
A35: PL00 | B35: Coal HOB | D35: all | E35: 2040 | H35: {=TRANSPOSE(BF53:BI53)} -> 7586.634 | AF35: DATA | AZ35: 2015 | BA35: {=TREND($BA$38:$BA$44,$AZ$38:$AZ$44,AZ35)} -> 24418.594 | BB35: {=TREND($BB$38:$BB$44,$AZ$38:$AZ$44,AZ35)} -> 1494.9538 | BC35: {=TREND($BC$38:$BC$44,$AZ$38:$AZ$44,AZ35)} -> 2394.8387 | BD35: {=TREND($BD$38:$BD$44,$AZ$38:$AZ$44,AZ35)} -> 1066.1668 | BE35: {=TREND($BE$38:$BE$44,$AZ$38:$AZ$44,AZ35)} -> 138.5906 | BF35: {=TREND($BF$38:$BF$44,$AZ$38:$AZ$44,AZ35)} -> 1481.9596 | BH35: {=TREND($BH$38:$BH$44,$AZ$38:$AZ$44,AZ35)} -> 16595.38 | BI35: {=TREND($BI$38:$BI$44,$AZ$38:$AZ$44,AZ35)} -> -130.00558 | BJ35: {=TREND($BJ$38:$BJ$44,$AZ$38:$AZ$44,AZ35)} -> 1829.9056 | BK35: {=TREND($BK$38:$BK$44,$AZ$38:$AZ$44,AZ35)} -> -135.90908 | BL35: {=TREND($BL$38:$BL$44,$AZ$38:$AZ$44,AZ35)} -> 0 | BM35: {=TREND($BM$38:$BM$44,$AZ$38:$AZ$44,AZ35)} -> 299.062 | BN35: =SUM(BA35:BM35) -> 49453.537 | BQ35: 2484.9244
A36: PL00 | B36: Oil HOB | D36: all | E36: 2040 | H36: 2987.8458 | AF36: Fuel type | AG36: Total [GJ] | AH36: In cogeneration [GJ] | AI36: Share total [%] | AJ36: Share in cogeneration [%] | AK36: In cogeneration [TWh] | AL36: Rests (HOB) [TWh] | AM36: CHP | AT36: HOB | BQ36: 457.44721
A37: PL00 | B37: Gas HOB | D37: all | E37: 2040 | H37: 6764.869 | AF37: 2024 | AM37: FLH [hours/year] | AN37: eff [%] | AO37: heat cap [MW] | AP37: power-to-heat | AQ37: elec cap [MW] | AR37: fuel cap [MW] | AT37: FLH [hours/year] | AU37: eff[%] | AV37: heat cap [MW] | BQ37: {=TRANSPOSE(BA56:BD56)} -> 15029.283
A38: PL00 | B38: Bio HOB | D38: all | E38: 2040 | H38: 6435.8801 | AF38: Hard coal | AG38: 2.2588032e+08 | AH38: 1.4745939e+08 | AI38: 56.51 | AJ38: 52.69 | AK38: =0.0000002778*AH38 -> 40.964218 | AL38: =0.0000002778*(AG38-AH38) -> 21.785335 | AM38: 2500 | AN38: 0.89 | AO38: =$AK38*10^6*$AN38 /$AM38 -> 14583.262 | AP38: 0.45 | AQ38: =AO38*AP38 -> 6562.4677 | AR38: =(AO38+AQ38)/AN38 -> 23759.247 | AT38: 1500 | AU38: 0.9 | AV38: =$AL38*10^6*$AU38 /$AT38 -> 13071.201 | AY38: Historical | AZ38: =AF37 -> 2024 | BA38: =SUM(AO38:AO39) -> 14876.725 | BB38: =SUM(AO40:AO41) -> 1740.7443 | BC38: =SUM(AO41:AO42) -> 4311.5088 | BD38: =SUM(AO44:AO46) -> 1544.1989 | BE38: =SUM(AO47:AO48) -> 307.74363 | BF38: =AO49 -> 901.02195 | BH38: =SUM(AV38:AV39) -> 13154.066 | BI38: =SUM(AV40:AV41) -> 1084.623 | BJ38: =SUM(AV42:AV43) -> 4285.9802 | BK38: =SUM(AV44:AV46) -> 2291.9236 | BL38: =SUM(AV47:AV48) -> 0 | BM38: =SUM(AV49) -> 829.53925 | BN38: =SUM(BA38:BM38) -> 45328.074 | BQ38: 6116.72
A39: PL00 | B39: Coal HOB | D39: all | E39: 2035 | H39: {=TRANSPOSE(BF54:BI54)} -> 9403.3363 | AF39: Lignite | AG39: 3464517.6 | AH39: 2967368.5 | AI39: 0.87 | AJ39: 1.06 | AK39: =0.0000002778*AH39 -> 0.82433497 | AL39: =0.0000002778*(AG39-AH39) -> 0.13810803 | AM39: 2500 | AN39: 0.89 | AO39: =$AK39*10^6*$AN39 /$AM39 -> 293.46325 | AP39: 0.45 | AQ39: =AO39*AP39 -> 132.05846 | AR39: =(AO39+AQ39)/AN39 -> 478.11429 | AT39: 1500 | AU39: 0.9 | AV39: =$AL39*10^6*$AU39 /$AT39 -> 82.864815 | AZ39: =AF51 -> 2023 | BA39: =SUM(AO52:AO53) -> 16375.327 | BB39: =SUM(AO54:AO55) -> 1728.1097 | BC39: =SUM(AO55:AO56) -> 4017.6254 | BD39: =SUM(AO58:AO60) -> 1585.6598 | BE39: =SUM(AO61:AO62) -> 263.67911 | BF39: =AO63 -> 784.48513 | BH39: =SUM(AV52:AV53) -> 14723.18 | BI39: =SUM(AV54:AV55) -> 862.07791 | BJ39: =SUM(AV56:AV57) -> 3523.3972 | BK39: =SUM(AV58:AV60) -> 2264.791 | BL39: =SUM(AV61:AV62) -> 0 | BM39: =SUM(AV63) -> 811.21493 | BN39: =SUM(BA39:BM39) -> 46939.547 | BQ39: 1683.2346
A40: PL00 | B40: Oil HOB | D40: all | E40: 2035 | H40: 2379.2286 | AF40: Light fuel oil | AG40: 2385366.2 | AH40: 348518.68 | AI40: 0.6 | AJ40: 0.12 | AK40: =0.0000002778*AH40 -> 0.096818489 | AL40: =0.0000002778*(AG40-AH40) -> 0.56583624 | AM40: 3500 | AN40: 0.9 | AO40: =$AK40*10^6*$AN40 /$AM40 -> 24.896183 | AP40: 0.6 | AQ40: =AO40*AP40 -> 14.93771 | AR40: =(AO40+AQ40)/AN40 -> 44.259881 | AT40: 500 | AU40: 0.9 | AV40: =$AL40*10^6*$AU40 /$AT40 -> 1018.5052 | AZ40: =AF65 -> 2021 | BA40: =SUM(AO66:AO67) -> 20193.368 | BB40: =SUM(AO68:AO69) -> 1435.9603 | BC40: =SUM(AO69:AO70) -> 3082.3661 | BD40: =SUM(AO72:AO74) -> 987.98108 | BE40: =SUM(AO75:AO76) -> 167.30446 | BF40: =AO77 -> 815.82588 | BH40: =SUM(AV66:AV67) -> 13170.088 | BI40: =SUM(AV68:AV69) -> 279.74982 | BJ40: =SUM(AV70:AV71) -> 1963.22 | BK40: =SUM(AV72:AV74) -> 825.18133 | BL40: =SUM(AV75:AV76) -> 0 | BM40: =SUM(AV77) -> 309.23261 | BN40: =SUM(BA40:BM40) -> 43230.278 | BQ40: 449.95898
...

Sheet PL00_sanity check
C4: Testing with couple different climate years if the new dheat capacities can match the maximum dheat demand. FLH were changed in the way that capacity satisfies the CY 1987's max demand so thats why current CY2105 dheat capacity is much over the peak demand
C8: year | D8: CY | E8: Max demand | F8: Total cap | G8: peak power vs demand | H8: demand
