Workbook

Sheet Overview
A1: Type | B1: Variable | C1: Grid | D1: Evidence | E1: Significance | F1: Inputs | G1: Assumptions | H1: Limitations
A2: Scalar | B2: Demand | C2: El | D2: H | E2: H | F2: D_2023(region, sector), D_2035(sector) | G2: D_ind grows due to electrification of existing D_ind D_ ind electrification and D_res,com growth is spatially uniform | H2: Projected growth reverses two-decade-long trends: ind % and total D decline, centralization. FinGrid also expects D_ind growth from new industries (data centers, E-fuels, battery production).
C3: DH | D3: H | E3: M | F3: D_2023(region), D_2035 | G3: Historic distribution
C4: IH | D4: M | E4: M | F4: D_ind_unelectrified(region), D_ih | G4: Proportional to unelectrified D_el
C5: H2 | D5: L | E5: M | F5: D_ind_unelectrified(region), D_h2 | G5: Proportional to unelectrified D_el, except for East | H5: Kirsikka list includes only projects for self-consumption, which is inconsistent with tyndp2024 scenario
B6: Generation | C6: El | D6: H | E6: H | F6: Power plant register, manual identification | G6: Historic distribution, Lovissa nuclear retirement | H6: Wind capacity increases 6-fold. Alternative basis - existing list of proposed wind power projects
C7: El_PV | D7: H | E7: M | F7: Development projects
C8: EL_DR | D8: M | E8: L | F8: - | G8: Omitted because of (1) small capacity and (2) old data in H2 heavy (predates even tyndp2020)
C9: H2 | D9: L | E9: M | F9: P_nonCHP(region), P_h2 | G9: Proportional to P_el_non-CHP, except for East | H9: No strong reason this to be the case
C10: DH | D10: H | E10: M | F10: Power plant register, manual identification | H10: Pauli data could be used dirrectly to identify spatial distribution
C11: IH | D11: H | E11: M | F11: Power plant register, manual identification | G11: All non-RE remains in Uusimaa while the rest is converted to RE
B12: Storage | C12: El_batteries | D12: L | E12: L | F12: P_nonCHP(region), P_h2 | G12: Proportional to P_el_non-CHP, except for East
C13: H2 | D13: L | E13: M | F13: D_ind_unelectrified(region), D_h2 | G13: Proportional to unelectrified D_el, except for East | H13: No strong reason this to be the case
C14: Heat | D14: H | E14: M | F14: Unit specific district heating data from Finnish Energy | G14: Municipality in company or unit name is muncipality where unit is located
B15: Transmission | C15: El | D15: H | E15: H | F15: FinGrid map of existing and future powerlines | G15: Visual mapping to model connections, kV to MW conversions | H15: Sufficiency needs to be tested. Regional model retains same set of cross-border connections, but we now know individual lines - could have multiple connections between individual pairs of nodes.
C16: H2 | D16: H | E16: H | F16: GasGrid map | G16: Extending cross-border capacities along path in GasGrid map | H16: Grid does not reach eastern region
A17: Vector | B17: Demand | C17: El | D17: H | E17: H | F17: D(region), D(customer type, t)
C18: H2, IH | D18: H | E18: M | F18: Constant
C19: DH | D19: M | E19: M | F19: Copy national
B20: Inflow | C20: Hydro | D20: M | E20: M | F20: Copy national
C21: Wind | D21: M | E21: H | F21: Copy national because Copernicus have only 2 regions for FI at highest granularity | H21: Major determinant of system dynamics
C22: Solar | D22: M | E22: H | F22: Copy national because Copernicus have only Nuts2 regions for FI at highest granularity or gridded data
B23: Limits | C23: Hydro | D23: M | E23: M | F23: Copy national
D25: High
D26: Medium
D27: Low

Sheet Geography
A1: Regions | H1: Municipalities | M1: Municipality by region explained
A2: Model | B2: Administrative | C2: Administrative (FI) | E2: Population | H2: Municipality | I2: Region 1990 | J2: Administrative | K2: Model | M2: Source | N2: Kunnat 1990 | Tilastokeskus | Q2: (Statistics Finland)
A3: North | B3: Lapland | C3: Lappi | E3: 176494 | F3: =SUM(E3:E4) -> 592097 | H3: Alahärmä | I3: Etelä-Pohjanmaa | J3: =IF(Municipality[[#This Row],[Region 1990]]=$M$13,$O$13,IF(Municipality[[#This Row],[Region 1990]]=$M$14,$O$14,Municipality[[#This Row],[Region 1990]])) -> Etelä-Pohjanmaa | K3: =_xlfn.XLOOKUP(Municipality[[#This Row],[Administrative]],Region[Administrative (FI)],Region[Model],"") -> West | M3: Aim | N3: Powerplant and other unit allocation to model regions based on their name or their company name
A4: North | B4: North Ostrobothnia | C4: Pohjois-Pohjanmaa | E4: 415603 | H4: Alajärvi | I4: Etelä-Pohjanmaa | J4: =IF(Municipality[[#This Row],[Region 1990]]=$M$13,$O$13,IF(Municipality[[#This Row],[Region 1990]]=$M$14,$O$14,Municipality[[#This Row],[Region 1990]])) -> Etelä-Pohjanmaa | K4: =_xlfn.XLOOKUP(Municipality[[#This Row],[Administrative]],Region[Administrative (FI)],Region[Model],"") -> West | M4: Selection | N4: The most fitting table is assumed to be in:
A5: West | B5: Central Ostrobothnia | C5: Keski-Pohjanmaa | E5: 67915 | F5: =SUM(E5:E8) -> 649999 | H5: Alastaro | I5: Varsinais-Suomi | J5: =IF(Municipality[[#This Row],[Region 1990]]=$M$13,$O$13,IF(Municipality[[#This Row],[Region 1990]]=$M$14,$O$14,Municipality[[#This Row],[Region 1990]])) -> Varsinais-Suomi | K5: =_xlfn.XLOOKUP(Municipality[[#This Row],[Administrative]],Region[Administrative (FI)],Region[Model],"") -> South West | N5: Year | O5: 1990 - earliest municipality by region table available
A6: West | B6: Ostrobothnia | C6: Pohjanmaa | E6: 176041 | H6: Alavieska | I6: Pohjois-Pohjanmaa | J6: =IF(Municipality[[#This Row],[Region 1990]]=$M$13,$O$13,IF(Municipality[[#This Row],[Region 1990]]=$M$14,$O$14,Municipality[[#This Row],[Region 1990]])) -> Pohjois-Pohjanmaa | K6: =_xlfn.XLOOKUP(Municipality[[#This Row],[Administrative]],Region[Administrative (FI)],Region[Model],"") -> North | O6: Municipality merges during 1990-2026 period has reduced municipality list by a thrid
A7: West | B7: South Ostrobothnia | C7: Etelä-Pohjanmaa | E7: 191762 | H7: Alavus | I7: Etelä-Pohjanmaa | J7: =IF(Municipality[[#This Row],[Region 1990]]=$M$13,$O$13,IF(Municipality[[#This Row],[Region 1990]]=$M$14,$O$14,Municipality[[#This Row],[Region 1990]])) -> Etelä-Pohjanmaa | K7: =_xlfn.XLOOKUP(Municipality[[#This Row],[Administrative]],Region[Administrative (FI)],Region[Model],"") -> West | N7: Language | O7: Finnish - instead of English or Swedish
A8: West | B8: Satakunta | C8: Satakunta | E8: 214281 | H8: Anjalankoski | I8: Kymenlaakso | J8: =IF(Municipality[[#This Row],[Region 1990]]=$M$13,$O$13,IF(Municipality[[#This Row],[Region 1990]]=$M$14,$O$14,Municipality[[#This Row],[Region 1990]])) -> Kymenlaakso | K8: =_xlfn.XLOOKUP(Municipality[[#This Row],[Administrative]],Region[Administrative (FI)],Region[Model],"") -> South East | M8: Regional changes
A9: Center | B9: Pirkanmaa | C9: Pirkanmaa | E9: 527478 | F9: =SUM(E9:E10) -> 800161 | H9: Anttola | I9: Etelä-Savo | J9: =IF(Municipality[[#This Row],[Region 1990]]=$M$13,$O$13,IF(Municipality[[#This Row],[Region 1990]]=$M$14,$O$14,Municipality[[#This Row],[Region 1990]])) -> Etelä-Savo | K9: =_xlfn.XLOOKUP(Municipality[[#This Row],[Administrative]],Region[Administrative (FI)],Region[Model],"") -> East | N9: Boundaries | O9: Known to be minor only - here ignored
A10: Center | B10: Central Finland | C10: Keski-Suomi | E10: 272683 | H10: Artjärvi | I10: Uusimaa | J10: =IF(Municipality[[#This Row],[Region 1990]]=$M$13,$O$13,IF(Municipality[[#This Row],[Region 1990]]=$M$14,$O$14,Municipality[[#This Row],[Region 1990]])) -> Uusimaa | K10: =_xlfn.XLOOKUP(Municipality[[#This Row],[Administrative]],Region[Administrative (FI)],Region[Model],"") -> Uusimaa | N10: Names | O10: Two names shown bellow are replaced
A11: East | B11: Kainuu | C11: Kainuu | E11: 71255 | F11: =SUM(E11:E14) -> 614587 | H11: Asikkala | I11: Päijät-Häme | J11: =IF(Municipality[[#This Row],[Region 1990]]=$M$13,$O$13,IF(Municipality[[#This Row],[Region 1990]]=$M$14,$O$14,Municipality[[#This Row],[Region 1990]])) -> Päijät-Häme | K11: =_xlfn.XLOOKUP(Municipality[[#This Row],[Administrative]],Region[Administrative (FI)],Region[Model],"") -> South East
A12: East | B12: North Savo | C12: Pohjois-Savo | E12: 248363 | H12: Askola | I12: Uusimaa | J12: =IF(Municipality[[#This Row],[Region 1990]]=$M$13,$O$13,IF(Municipality[[#This Row],[Region 1990]]=$M$14,$O$14,Municipality[[#This Row],[Region 1990]])) -> Uusimaa | K12: =_xlfn.XLOOKUP(Municipality[[#This Row],[Administrative]],Region[Administrative (FI)],Region[Model],"") -> Uusimaa | M12: 1990 name | O12: 2026 name
A13: East | B13: South Savo | C13: Etelä-Savo | E13: 131688 | H13: Aura | I13: Varsinais-Suomi | J13: =IF(Municipality[[#This Row],[Region 1990]]=$M$13,$O$13,IF(Municipality[[#This Row],[Region 1990]]=$M$14,$O$14,Municipality[[#This Row],[Region 1990]])) -> Varsinais-Suomi | K13: =_xlfn.XLOOKUP(Municipality[[#This Row],[Administrative]],Region[Administrative (FI)],Region[Model],"") -> South West | M13: Häme | O13: Kanta-Häme
A14: East | B14: North Karelia | C14: Pohjois-Karjala | E14: 163281 | H14: Pirkkala | I14: Pirkanmaa | J14: =IF(Municipality[[#This Row],[Region 1990]]=$M$13,$O$13,IF(Municipality[[#This Row],[Region 1990]]=$M$14,$O$14,Municipality[[#This Row],[Region 1990]])) -> Pirkanmaa | K14: =_xlfn.XLOOKUP(Municipality[[#This Row],[Administrative]],Region[Administrative (FI)],Region[Model],"") -> Center | M14: Vaasan rannikkoseutu | O14: Pohjanmaa
A15: South West | B15: Åland | C15: Ahvenanmaa | E15: 30344 | F15: =SUM(E15:E17) -> 684034 | H15: Perniö | I15: Varsinais-Suomi | J15: =IF(Municipality[[#This Row],[Region 1990]]=$M$13,$O$13,IF(Municipality[[#This Row],[Region 1990]]=$M$14,$O$14,Municipality[[#This Row],[Region 1990]])) -> Varsinais-Suomi | K15: =_xlfn.XLOOKUP(Municipality[[#This Row],[Administrative]],Region[Administrative (FI)],Region[Model],"") -> South West
A16: South West | B16: Southwest Finland | C16: Varsinais-Suomi | E16: 483477 | H16: Pori | I16: Satakunta | J16: =IF(Municipality[[#This Row],[Region 1990]]=$M$13,$O$13,IF(Municipality[[#This Row],[Region 1990]]=$M$14,$O$14,Municipality[[#This Row],[Region 1990]])) -> Satakunta | K16: =_xlfn.XLOOKUP(Municipality[[#This Row],[Administrative]],Region[Administrative (FI)],Region[Model],"") -> West | M16: FIN0 | N16: FIW0 | O16: FIC0 | P16: FIE0 | Q16: FISW | R16: FISE | S16: FIUU
A17: South West | B17: Kanta-Häme | C17: Kanta-Häme | E17: 170213 | H17: Pornainen | I17: Uusimaa | J17: =IF(Municipality[[#This Row],[Region 1990]]=$M$13,$O$13,IF(Municipality[[#This Row],[Region 1990]]=$M$14,$O$14,Municipality[[#This Row],[Region 1990]])) -> Uusimaa | K17: =_xlfn.XLOOKUP(Municipality[[#This Row],[Administrative]],Region[Administrative (FI)],Region[Model],"") -> Uusimaa
A18: South East | B18: Päijät-Häme | C18: Päijät-Häme | E18: 205124 | F18: =SUM(E18:E20) -> 492622 | H18: Porvoo | I18: Uusimaa | J18: =IF(Municipality[[#This Row],[Region 1990]]=$M$13,$O$13,IF(Municipality[[#This Row],[Region 1990]]=$M$14,$O$14,Municipality[[#This Row],[Region 1990]])) -> Uusimaa | K18: =_xlfn.XLOOKUP(Municipality[[#This Row],[Administrative]],Region[Administrative (FI)],Region[Model],"") -> Uusimaa
A19: South East | B19: Kymenlaakso | C19: Kymenlaakso | E19: 161391 | H19: Porvoon | I19: Uusimaa | J19: =IF(Municipality[[#This Row],[Region 1990]]=$M$13,$O$13,IF(Municipality[[#This Row],[Region 1990]]=$M$14,$O$14,Municipality[[#This Row],[Region 1990]])) -> Uusimaa | K19: =_xlfn.XLOOKUP(Municipality[[#This Row],[Administrative]],Region[Administrative (FI)],Region[Model],"") -> Uusimaa
A20: South East | B20: South Karelia | C20: Etelä-Karjala | E20: 126107 | H20: Raahe | I20: Pohjois-Pohjanmaa | J20: =IF(Municipality[[#This Row],[Region 1990]]=$M$13,$O$13,IF(Municipality[[#This Row],[Region 1990]]=$M$14,$O$14,Municipality[[#This Row],[Region 1990]])) -> Pohjois-Pohjanmaa | K20: =_xlfn.XLOOKUP(Municipality[[#This Row],[Administrative]],Region[Administrative (FI)],Region[Model],"") -> North
A21: Uusimaa | B21: Uusimaa | C21: Uusimaa | E21: 1714741 | F21: =E21 -> 1714741 | H21: Brändö | I21: Ahvenanmaa | J21: =IF(Municipality[[#This Row],[Region 1990]]=$M$13,$O$13,IF(Municipality[[#This Row],[Region 1990]]=$M$14,$O$14,Municipality[[#This Row],[Region 1990]])) -> Ahvenanmaa | K21: =_xlfn.XLOOKUP(Municipality[[#This Row],[Administrative]],Region[Administrative (FI)],Region[Model],"") -> South West
H22: Karijoki | I22: Etelä-Pohjanmaa | J22: =IF(Municipality[[#This Row],[Region 1990]]=$M$13,$O$13,IF(Municipality[[#This Row],[Region 1990]]=$M$14,$O$14,Municipality[[#This Row],[Region 1990]])) -> Etelä-Pohjanmaa | K22: =_xlfn.XLOOKUP(Municipality[[#This Row],[Administrative]],Region[Administrative (FI)],Region[Model],"") -> West
H23: Dragsfjärd | I23: Varsinais-Suomi | J23: =IF(Municipality[[#This Row],[Region 1990]]=$M$13,$O$13,IF(Municipality[[#This Row],[Region 1990]]=$M$14,$O$14,Municipality[[#This Row],[Region 1990]])) -> Varsinais-Suomi | K23: =_xlfn.XLOOKUP(Municipality[[#This Row],[Administrative]],Region[Administrative (FI)],Region[Model],"") -> South West
H24: Eckerö | I24: Ahvenanmaa | J24: =IF(Municipality[[#This Row],[Region 1990]]=$M$13,$O$13,IF(Municipality[[#This Row],[Region 1990]]=$M$14,$O$14,Municipality[[#This Row],[Region 1990]])) -> Ahvenanmaa | K24: =_xlfn.XLOOKUP(Municipality[[#This Row],[Administrative]],Region[Administrative (FI)],Region[Model],"") -> South West
H25: Tammisaari | I25: Uusimaa | J25: =IF(Municipality[[#This Row],[Region 1990]]=$M$13,$O$13,IF(Municipality[[#This Row],[Region 1990]]=$M$14,$O$14,Municipality[[#This Row],[Region 1990]])) -> Uusimaa | K25: =_xlfn.XLOOKUP(Municipality[[#This Row],[Administrative]],Region[Administrative (FI)],Region[Model],"") -> Uusimaa
H26: Elimäki | I26: Kymenlaakso | J26: =IF(Municipality[[#This Row],[Region 1990]]=$M$13,$O$13,IF(Municipality[[#This Row],[Region 1990]]=$M$14,$O$14,Municipality[[#This Row],[Region 1990]])) -> Kymenlaakso | K26: =_xlfn.XLOOKUP(Municipality[[#This Row],[Administrative]],Region[Administrative (FI)],Region[Model],"") -> South East
H27: Inari | I27: Lappi | J27: =IF(Municipality[[#This Row],[Region 1990]]=$M$13,$O$13,IF(Municipality[[#This Row],[Region 1990]]=$M$14,$O$14,Municipality[[#This Row],[Region 1990]])) -> Lappi | K27: =_xlfn.XLOOKUP(Municipality[[#This Row],[Administrative]],Region[Administrative (FI)],Region[Model],"") -> North
H28: Eno | I28: Pohjois-Karjala | J28: =IF(Municipality[[#This Row],[Region 1990]]=$M$13,$O$13,IF(Municipality[[#This Row],[Region 1990]]=$M$14,$O$14,Municipality[[#This Row],[Region 1990]])) -> Pohjois-Karjala | K28: =_xlfn.XLOOKUP(Municipality[[#This Row],[Administrative]],Region[Administrative (FI)],Region[Model],"") -> East
H29: Enonkoski | I29: Etelä-Savo | J29: =IF(Municipality[[#This Row],[Region 1990]]=$M$13,$O$13,IF(Municipality[[#This Row],[Region 1990]]=$M$14,$O$14,Municipality[[#This Row],[Region 1990]])) -> Etelä-Savo | K29: =_xlfn.XLOOKUP(Municipality[[#This Row],[Administrative]],Region[Administrative (FI)],Region[Model],"") -> East
H30: Enontekiö | I30: Lappi | J30: =IF(Municipality[[#This Row],[Region 1990]]=$M$13,$O$13,IF(Municipality[[#This Row],[Region 1990]]=$M$14,$O$14,Municipality[[#This Row],[Region 1990]])) -> Lappi | K30: =_xlfn.XLOOKUP(Municipality[[#This Row],[Administrative]],Region[Administrative (FI)],Region[Model],"") -> North
H31: Espoo | I31: Uusimaa | J31: =IF(Municipality[[#This Row],[Region 1990]]=$M$13,$O$13,IF(Municipality[[#This Row],[Region 1990]]=$M$14,$O$14,Municipality[[#This Row],[Region 1990]])) -> Uusimaa | K31: =_xlfn.XLOOKUP(Municipality[[#This Row],[Administrative]],Region[Administrative (FI)],Region[Model],"") -> Uusimaa
H32: Ähtäri | I32: Etelä-Pohjanmaa | J32: =IF(Municipality[[#This Row],[Region 1990]]=$M$13,$O$13,IF(Municipality[[#This Row],[Region 1990]]=$M$14,$O$14,Municipality[[#This Row],[Region 1990]])) -> Etelä-Pohjanmaa | K32: =_xlfn.XLOOKUP(Municipality[[#This Row],[Administrative]],Region[Administrative (FI)],Region[Model],"") -> West
H33: Eura | I33: Satakunta | J33: =IF(Municipality[[#This Row],[Region 1990]]=$M$13,$O$13,IF(Municipality[[#This Row],[Region 1990]]=$M$14,$O$14,Municipality[[#This Row],[Region 1990]])) -> Satakunta | K33: =_xlfn.XLOOKUP(Municipality[[#This Row],[Administrative]],Region[Administrative (FI)],Region[Model],"") -> West
... H462: Ylitornio | I462: Lappi | J462: =IF(Municipality[[#This Row],[Region 1990]]=$M$13,$O$13,IF(Municipality[[#This Row],[Region 1990]]=$M$14,$O$14,Municipality[[#This Row],[Region 1990]])) -> Lappi | K462: =_xlfn.XLOOKUP(Municipality[[#This Row],[Administrative]],Region[Administrative (FI)],Region[Model],"") -> North

Sheet D_el
A1: 1. Data
A2: Source [1] | B2: Sahkonkulutus-maakunnittain-2007-2023.xlsx | G2: (Finnish Energy) | L2: Source [2] | M2: Demand Scenarios TYNDP 2024 After Public Consultation.xslx | U2: Statistics Finland (2023) | AA2: Industry | AB2: Commerce | AC2: Residence | AF2: Industry | AG2: Commerce | AH2: Residence
A3: Terminology simplifications: residence - housing and agriculture, commerce - service and buildings | L3: Notations: REF - reference of 2019, DE - Distributed Energy 2035 scenario | T3: Source [4] | U3: Energy use in manufacturing by Year, Region and Information. PxWeb | Z3: 2007 | AA3: =C26 -> 47677 | AB3: =D26 -> 17263 | AC3: =E26 -> 22391 | AE3: Uusimaa | AF3: 4073 | AG3: 6791 | AH3: 5840 | AI3: =W6-V6 -> 16161
A4: [GWh] | C4: 2007 | G4: 2023 | L4: [GWh] | M4: REF | N4: DE | T4: Source [5] | U4: Total electricity consumption by Year, Region, Manufacturing branch and Information. PxWeb | Z4: 2023 | AA4: =G26 -> 34100 | AB4: =H26 -> 19428 | AC4: =I26 -> 23575 | AE4: Southwest Finland | AF4: 1041 | AG4: 1661 | AH4: 2146 | AI4: =W7-V7 -> 1887
C5: Industry | D5: Commerce | E5: Residence | F5: Total | G5: Industry | H5: Commerce | I5: Residence | J5: Total | L5: Households | M5: 24142.483 | N5: 29821.687 | O5: =N5/$N$13 -> 0.22609788 | V5: Electricity | W5: Energy | X5: Electfication | Z5: 2035* | AA5: =N7 -> 85806.024 | AB5: =N6 -> 16269.531 | AC5: =N5 -> 29821.687 | AE5: Satakunta | AF5: 3334 | AG5: 707 | AH5: 1040 | AI5: =W8-V8 -> 6114
A6: Uusimaa | C6: 2912 | D6: 5497 | E6: 4658 | F6: 13066 | G6: 4073 | H6: 6791 | I6: 5840 | J6: 16704 | L6: Buildings | M6: 18496.723 | N6: 16269.531 | O6: =N6/$N$13 -> 0.12335005 | T6: Uusimaa | V6: 4650 | W6: 20811 | X6: =V6/W6 -> 0.22343953 | AA6: =AA5/AA4 -> 2.5163057 | AE6: Kanta-Häme | AF6: 753 | AG6: 578 | AH6: 800 | AI6: =W9-V9 -> 1033
A7: Varsinais-Suomi | C7: 1477 | D7: 1356 | E7: 2018 | F7: 4852 | G7: 1041 | H7: 1661 | I7: 2146 | J7: 4847 | L7: Industry | M7: 41166.333 | N7: 85806.024 | O7: =N7/$N$13 -> 0.65055207 | T7: Varsinais-Suomi | V7: 955 | W7: 2842 | X7: =V7/W7 -> 0.33603096 | AE7: Pirkanmaa | AF7: 1972 | AG7: 1643 | AH7: 2188 | AI7: =W10-V10 -> 2663
A8: Satakunta | C8: 4946 | D8: 574 | E8: 995 | F8: 6514 | G8: 3334 | H8: 707 | I8: 1040 | J8: 5080 | L8: Transport | M8: 859 | N8: 9937.3888 | T8: Satakunta | V8: 3123 | W8: 9237 | X8: =V8/W8 -> 0.33809678 | AE8: Päijät-Häme | AF8: 741 | AG8: 566 | AH8: 848 | AI8: =W11-V11 -> 1551
A9: Kanta-Häme | C9: 803 | D9: 566 | E9: 766 | F9: 2136 | G9: 753 | H9: 578 | I9: 800 | J9: 2130 | L9: Agriculture | M9: 1475 | N9: 1980.3154 | T9: Kanta-Häme | V9: 668 | W9: 1701 | X9: =V9/W9 -> 0.39271017 | AE9: Kymenlaakso | AF9: 2023 | AG9: 945 | AH9: 713 | AI9: =W12-V12 -> 7929
A10: Pirkanmaa | C10: 3170 | D10: 1336 | E10: 1854 | F10: 6360 | G10: 1972 | H10: 1643 | I10: 2188 | J10: 5804 | L10: Other | M10: 0 | N10: 0 | T10: Pirkanmaa | V10: 2012 | W10: 4675 | X10: =V10/W10 -> 0.43037433 | AE10: South Karelia | AF10: 3933 | AG10: 417 | AH10: 492 | AI10: =W13-V13 -> 14579
A11: Päijät-Häme | C11: 873 | D11: 607 | E11: 851 | F11: 2331 | G11: 741 | H11: 566 | I11: 848 | J11: 2154 | L11: Energy | M11: 2597 | N11: 2597 | T11: Päijät-Häme | V11: 706 | W11: 2257 | X11: =V11/W11 -> 0.31280461 | AE11: South Savo | AF11: 332 | AG11: 429 | AH11: 654 | AI11: =W14-V14 -> 869
A12: Kymenlaakso | C12: 5234 | D12: 671 | E12: 790 | F12: 6694 | G12: 2023 | H12: 945 | I12: 713 | J12: 3681 | L12: Total | M12: =SUM(M5:M11) -> 88736.54 | N12: =SUM(N5:N11) -> 146411.95 | T12: Kymenlaakso | V12: 2214 | W12: 10143 | X12: =V12/W12 -> 0.21827862 | AE12: North Savo | AF12: 1569 | AG12: 765 | AH12: 1015 | AI12: =W15-V15 -> 3102
A13: Etelä-Karjala | C13: 4967 | D13: 435 | E13: 551 | F13: 5953 | G13: 3933 | H13: 417 | I13: 492 | J13: 4842 | L13: Total main | M13: =SUM(M5:M7) -> 83805.54 | N13: =SUM(N5:N7) -> 131897.24 | T13: South Karelia | V13: 3580 | W13: 18159 | X13: =V13/W13 -> 0.19714742 | AE13: North Karelia | AF13: 1254 | AG13: 433 | AH13: 701 | AI13: =W16-V16 -> 3665
A14: Etelä-Savo | C14: 411 | D14: 468 | E14: 769 | F14: 1649 | G14: 332 | H14: 429 | I14: 654 | J14: 1415 | T14: Etelä-Savo | V14: 341 | W14: 1210 | X14: =V14/W14 -> 0.28181818 | AE14: Central Finland | AF14: 2365 | AG14: 791 | AH14: 1209 | AI14: =W17-V17 -> 9119
A15: Pohjois-Savo | C15: 2194 | D15: 709 | E15: 1078 | F15: 3981 | G15: 1569 | H15: 765 | I15: 1015 | J15: 3349 | L15: Source [3] TYNDP 2024 Visualization platfrom (DE 2035 scenario) | T15: Pohjois-Savo | V15: 1357 | W15: 4459 | X15: =V15/W15 -> 0.30432832 | AE15: South Ostrobothnia | AF15: 545 | AG15: 622 | AH15: 925 | AI15: =W18-V18 -> 751
A16: Pohjois-Karjala | C16: 1053 | D16: 464 | E16: 734 | F16: 2251 | G16: 1254 | H16: 433 | I16: 701 | J16: 2388 | L16: Native | M16: 132860 | T16: North Karelia | V16: 788 | W16: 4453 | X16: =V16/W16 -> 0.17695935 | AE16: Ostrobothnia | AF16: 1125 | AG16: 619 | AH16: 1250 | AI16: =W19-V19 -> 5358
A17: Keski-Suomi | C17: 4749 | D17: 778 | E17: 1252 | F17: 6779 | G17: 2365 | H17: 791 | I17: 1209 | J17: 4365 | L17: Electrolyser | M17: 72580 | T17: Central Finland | V17: 2226 | W17: 11345 | X17: =V17/W17 -> 0.19620978 | AE17: Central Ostrobothnia | AF17: 1525 | AG17: 176 | AH17: 341 | AI17: =W20-V20 -> 852
A18: Etelä-Pohjanmaa | C18: 538 | D18: 542 | E18: 878 | F18: 1957 | G18: 545 | H18: 622 | I18: 925 | J18: 2092 | L18: EV | M18: 4920 | T18: South Ostrobothnia | V18: 625 | W18: 1376 | X18: =V18/W18 -> 0.45421512 | AE18: North Ostrobothnia | AF18: 2419 | AG18: 1254 | AH18: 1784 | AI18: =W21-V21 -> 10151
A19: Pohjanmaa | C19: 2043 | D19: 462 | E19: 968 | F19: 3474 | G19: 1125 | H19: 619 | I19: 1250 | J19: 2994 | L19: Battery | M19: 1050 | T19: Ostrobothnia | V19: 1477 | W19: 6835 | X19: =V19/W19 -> 0.21609364 | AE19: Kainuu | AF19: 713 | AG19: 249 | AH19: 310 | AI19: =W22-V22 -> 323
A20: Keski-Pohjanmaa | C20: 1507 | D20: 214 | E20: 335 | F20: 2057 | G20: 1525 | H20: 176 | I20: 341 | J20: 2042 | L20: Total | M20: =SUM(M16:M19) -> 211410 | T20: Central Ostrobothnia | V20: 1497 | W20: 2349 | X20: =V20/W20 -> 0.63729246 | AE20: Lapland | AF20: 4357 | AG20: 677 | AH20: 1190 | AI20: =W23-V23 -> 6899
A21: Pohjois-Pohjanmaa | C21: 3129 | D21: 1231 | E21: 1774 | F21: 6135 | G21: 2419 | H21: 1254 | I21: 1784 | J21: 5456 | T21: North Ostrobothnia | V21: 1852 | W21: 12003 | X21: =V21/W21 -> 0.15429476 | AE21: Åland | AF21: 26 | AG21: 106 | AH21: 132 | AI21: =W24-V24 -> 41
A22: Kainuu | C22: 1772 | D22: 291 | E22: 371 | F22: 2433 | G22: 713 | H22: 249 | I22: 310 | J22: 1272 | T22: Kainuu | V22: 694 | W22: 1017 | X22: =V22/W22 -> 0.68239921
A23: Lappi | C23: 4035 | D23: 726 | E23: 1121 | F23: 5882 | G23: 4357 | H23: 677 | I23: 1190 | J23: 6223 | T23: Lapland | V23: 4163 | W23: 11062 | X23: =V23/W23 -> 0.37633339
A24: Itä-Uusimaa | C24: 1831 | D24: 237 | E24: 508 | F24: 2576 | T24: Åland | V24: 31 | W24: 72 | X24: =V24/W24 -> 0.43055556
A25: Ahvenanmaa | C25: 30 | D25: 99 | E25: 120 | F25: 249 | G25: 26 | H25: 106 | I25: 132 | J25: 264 | T25: Total | V25: 32959 | W25: 126006 | X25: =V25/W25 -> 0.26156691
A26: Total | C26: 47677 | D26: 17263 | E26: 22391 | F26: 87330 | G26: 34100 | H26: 19428 | I26: 23575 | J26: 77103 | K26: =N7/G26 -> 2.5163057
C27: =C26/$F$26 -> 0.54594068 | D27: =D26/$F$26 -> 0.19767548 | E27: =E26/$F$26 -> 0.25639528 | G27: =G26/$J$26 -> 0.44226554 | H27: =H26/$J$26 -> 0.25197463 | I27: =I26/$J$26 -> 0.30575983
A29: 2. Assessment of trends
A31: Assessment of national trends | J31: Trends were initially observed by tinkering with regional values (present bellow in hidden rows), but are much more clearly visible when comparing national values.
A32: Trend observed | C32: Coresponding demand | E32: Absolute | G32: Relative
E33: Historic | F33: Projected | G33: Historic | H33: Projected
A34: Total growth | C34: Total | E34: =J26-F26 -> -10227 | F34: =N13-M13 -> 48091.703 | G34: =E34/F26 -> -0.11710752 | H34: =F34/M13 -> 0.57384873
A35: Deindustriliaziation | C35: Industrial | E35: =G26-C26 -> -13577 | F35: =N7-M7 -> 44639.691 | G35: =(G26/J26)-(C26/F26) -> -0.10367514 | H35: =(N7/N13)-(M7/M13) -> 0.15933952
A36: Centralization | C36: Uusimaa | E36: =F6+F24-J6 -> -1062 | F36: =G84-J6 -> 9857.4787 | G36: =(J6/J26)-((F6+F24)/F26) -> 0.03753156 | H36: =(G84/G103)-(J6/J26) -> -0.015232547 | J36: Projected change for Uusimaa demand are based on regional breakdown assumed in part 3
A38: Assessment of historic regional trends | N38: Order: in tables - 2023 values on top of 2007 ones, bar charts - 2007 (in brighter colors) on top of 2023
A39: Administrative regions | F39: Model regions
C40: Industry | D40: Comerce | E40: Residence | F40: Aggregated region | H40: Region | J40: Industry | K40: Commerce | L40: Residence
A41: Uusimaa | C41: 4073 | D41: 6791 | E41: 5840 | F41: North | H41: Lappi | J41: 4357 | K41: 677 | L41: 1190
C42: 4743 | D42: 5734 | E42: 5166 | J42: 4035 | K42: 726 | L42: 1121
A43: Lappi | C43: 4357 | D43: 677 | E43: 1190 | H43: Pohjois-Pohjanmaa | J43: 2419 | K43: 1254 | L43: 1784
...

Sheet D_heat
A1: 1. DH Data | U1: 3. Industiral heat
A2: Breakdown in National Trends scenario | G2: Regional breakdown from Finnish Energy | L2: DH_Regional_2023.xlsx | V2: TWh | X2: Source | Y2: Other (non)RES sheet in "H2 heavy.xlsx", values derived from near-constant output of "other (non)RES" technology output
A3: Source | B3: demanddata_DH_own_projection.xlsx | G3: [GWh] | I3: SUPPLY | L3: CONSUMPTION | P3: Assume that delivery between dh could be ignored | U3: FI | V3: 20.740078 | X3: Assumption | Y3: Industrial demand consumption is distributed among regions proportionally to distribution of unelectrified industrial demand
B4: Primary source is not specified | I4: DH production (net) by fuels | J4: Heat recovery and heat produced by heat pumps | K4: Purchased from outside | L4: DH delivery | M4: Delivery to other dh company | N4: Network losses and metering errors | O4: Delivery and losses | U4: North | V4: =$V$3*D_el!K88/D_el!$K$95 -> 3.6748372 | Y4: This is obviously inperfect proxy (e.g., sawmill needs a lot of electricity but no steam), but no regional data or better proxy was found
A5: [TWh] | B5: 2025 | C5: 2035 | U5: West | V5: =$V$3*D_el!K89/D_el!$K$95 -> 2.9932924
A6: HKI | B6: 6.5466202 | C6: 6.8940564 | U6: Center | V6: =$V$3*D_el!K90/D_el!$K$95 -> 2.6357126
A7: ESP | B7: 2.2342093 | C7: 2.3116653 | U7: East | V7: =$V$3*D_el!K91/D_el!$K$95 -> 1.6403549
A8: VAN | B8: 1.8913769 | C8: 1.9534343 | U8: South West | V8: =$V$3*D_el!K92/D_el!$K$95 -> 0.63642432 | X8: =V8/0.00876 -> 72.651178
A9: TKU | B9: 2.0784623 | C9: 2.0619271 | U9: South East | V9: =$V$3*D_el!K93/D_el!$K$95 -> 5.383324
A10: TRE | B10: 2.1785868 | C10: 2.2303642 | G10: Uusimaa | I10: 10144 | J10: 2449.8 | K10: 929.3 | L10: 11908.7 | M10: 616.9 | N10: 997.5 | O10: =L10+N10 -> 12906.2 | U10: Uusimaa | V10: =$V$3*D_el!K94/D_el!$K$95 -> 3.7761327
A11: OUL | B11: 1.9651786 | C11: 1.9174791 | G11: Varsinais-Suomi | I11: 2073.8 | J11: 757.3 | K11: 2257.1 | L11: 2596.4 | M11: 2257.1 | N11: 234.7 | O11: =L11+N11 -> 2831.1
A12: JKL | B12: 1.2152906 | C12: 1.2125036 | G12: Satakunta | I12: 1229.6 | J12: 96.6 | K12: 431.9 | L12: 1165.8 | M12: 431.9 | N12: 160.4 | O12: =L12+N12 -> 1326.2
A13: ROF | B13: 20.381214 | C13: 20.045263 | G13: Kanta-Häme | I13: 1088.3 | J13: 214.3 | K13: 237.9 | L13: 855.9 | M13: 549.8 | N13: 134.8 | O13: =L13+N13 -> 990.7
A14: FI | B14: =SUM(B6:B13) -> 38.490939 | C14: =SUM(C6:C13) -> 38.626693 | G14: Pirkanmaa | I14: 2583.3 | J14: 468.1 | K14: 513.1 | L14: 2816.7 | M14: 513.1 | N14: 234.7 | O14: =L14+N14 -> 3051.4
G15: Päijät-Häme | I15: 1277.8 | J15: 231.1 | K15: 134.1 | L15: 1328.9 | M15: 128.2 | N15: 185.9 | O15: =L15+N15 -> 1514.8
G16: Kymenlaakso | I16: 820.4 | J16: 112.2 | K16: 794.3 | L16: 815.6 | M16: 794.3 | N16: 117 | O16: =L16+N16 -> 932.6
G17: Etelä-Karjala | I17: 775.5 | J17: 34.8 | K17: 610.1 | L17: 698.3 | M17: 610.1 | N17: 112 | O17: =L17+N17 -> 810.3
G18: Etelä-Savo | I18: 840.6 | J18: 25.9 | K18: 184 | L18: 751.6 | M18: 191.3 | N18: 107.6 | O18: =L18+N18 -> 859.2
G19: Pohjois-Savo | I19: 1476.9 | J19: 305.2 | K19: 264.7 | L19: 1616.8 | M19: 246.8 | N19: 183.2 | O19: =L19+N19 -> 1800
G20: Pohjois-Karjala | I20: 802.1 | J20: 185.5 | K20: 28.3 | L20: 874.7 | M20: 28.3 | N20: 112.9 | O20: =L20+N20 -> 987.6
G21: Keski-Suomi | I21: 1533.5 | J21: 113.1 | K21: 1578.8 | L21: 1530.6 | M21: 1482.5 | N21: 212.3 | O21: =L21+N21 -> 1742.9
G22: Etelä-Pohjanmaa | I22: 961.5 | J22: 85.3 | K22: 588.1 | L22: 912.1 | M22: 579.5 | N22: 143.3 | O22: =L22+N22 -> 1055.4
G23: Pohjanmaa | I23: 999.5 | J23: 68.6 | K23: 1004.6 | L23: 940.1 | M23: 1004.6 | N23: 128 | O23: =L23+N23 -> 1068.1
G24: Keski-Pohjanmaa | I24: 321.1 | J24: 113.7 | K24: 9 | L24: 379.9 | N24: 63.9 | O24: =L24+N24 -> 443.8
G25: Pohjois-Pohjanmaa | I25: 2004.2 | J25: 793.7 | K25: 498.8 | L25: 2496.2 | M25: 496.3 | N25: 304.2 | O25: =L25+N25 -> 2800.4
G26: Kainuu | I26: 404 | J26: 58 | K26: 304.8 | L26: 396.4 | M26: 304.8 | N26: 65.6 | O26: =L26+N26 -> 462
G27: Lappi | I27: 1045.8 | J27: 121.8 | K27: 140 | L27: 1035.1 | M27: 144.4 | N27: 128.1 | O27: =L27+N27 -> 1163.2
G28: Ahvenanmaa | I28: 108.4 | J28: 13.9 | K28: 108.1 | L28: 107.6 | M28: 108.1 | N28: 14.7 | O28: =L28+N28 -> 122.3
G29: Total | I29: 30490.3 | J29: 6248.9 | K29: 10617 | L29: 33227.4 | M29: 10488 | N29: 3640.8 | O29: =L29+N29 -> 36868.2
A31: 2. DH Processing [TWh]
A32: Scaling | E32: Aggregating regions | I32: Disaggregating cities from regions | M32: North | O32: Lappi
A33: Uusimaa | C33: =O10*$C$14/$O$29 -> 13.521784 | E33: North | G33: =C50+C48 -> 4.1526508 | I33: HKI | K33: =C6 -> 6.8940564 | O33: Pohjois-Pohjanmaa
A34: Varsinais-Suomi | C34: =O11*$C$14/$O$29 -> 2.9661342 | E34: West | G34: =C47+C46+C45+C35 -> 4.0792072 | I34: ESP | K34: =C7 -> 2.3116653 | M34: West | O34: Keski-Pohjanmaa
A35: Satakunta | C35: =O12*$C$14/$O$29 -> 1.3894554 | E35: Center | G35: =C37+C44 -> 5.0229724 | I35: VAN | K35: =C8 -> 1.9534343 | O35: Pohjanmaa
A36: Kanta-Häme | C36: =O13*$C$14/$O$29 -> 1.0379532 | E36: East | G36: =C49+C42+C41+C43 -> 4.3047763 | I36: TKU | K36: =C9 -> 2.0619271 | O36: Etlä-Pohjanmaa
A37: Pirkanmaa | C37: =O14*$C$14/$O$29 -> 3.1969418 | E37: South West | G37: =C51+C34+C36 -> 4.1322207 | I37: TRE | K37: =C10 -> 2.2303642 | O37: Satakunta
A38: Päijät-Häme | C38: =O15*$C$14/$O$29 -> 1.587051 | E38: South East | G38: =C38+C39+C40 -> 3.4130816 | I38: OUL | K38: =C11 -> 1.9174791 | M38: Center | O38: Pirkanmaa
A39: Kymenlaakso | C39: =O16*$C$14/$O$29 -> 0.97708197 | E39: Uusimaa | G39: =C33 -> 13.521784 | I39: JKL | K39: =C12 -> 1.2125036 | O39: Keski-Suomi
A40: Etelä-Karjala | C40: =O17*$C$14/$O$29 -> 0.84894866 | E40: Total | G40: =SUM(G33:G39) -> 38.626693 | I40: North | K40: =G33-K38 -> 2.2351716 | M40: East | O40: Kainuu
A41: Etelä-Savo | C41: =O18*$C$14/$O$29 -> 0.90018103 | I41: West | K41: =G34 -> 4.0792072 | O41: Pohjois-Savo
...

Sheet Tr_el
A1: Cross border
A2: Existing | H2: Future
A3: Sources | B3: Part of the Nordic power system - Fingrid | H3: Consideration 1: | K3: Consideration 2: TYNDP 2024 data | T3: Consideration 3: Fingrid data
B4: fingrid_kehittamissuunnitelma_syksy23_en.pdf | H4: Possible connections | K4: Modeled | M4: Ref | O4: DE 2035 | Q4: Increase | T4: Best source found: | V4: Main grid developments 2024-2033
C5: [MW] | D5: [MW] | E5: [kV] | H5: FINO | I5: NON1 | K5: FIN0 | L5: SE01 | M5: 2000 | N5: 2000 | O5: 4400 | P5: 4500 | Q5: =O5-M5 -> 2400 | R5: =P5-N5 -> 2500 | V5: Figue 2
A6: FINO | B6: NON1 | C6: 100 | E6: 220 | F6: AC | H6: FINO | I6: SE01 | K6: FISW | L6: SE03 | M6: 1200 | N6: 1200 | O6: 1700 | P6: 1700 | Q6: =O6-M6 -> 500 | R6: =P6-N6 -> 500 | T6: New Line | U6: Nodes | W6: Capacity [MW] | X6: Required to match [MW] | Y6: Likely in single line
A7: FINO | B7: SE01 | C7: 1100 | D7: 1200 | E7: 400x2 | F7: AC | H7: FINO | I7: SE02 | K7: FIUU | L7: EE00 | M7: 1016 | N7: 1016 | O7: 1716 | P7: 1716 | Q7: =O7-M7 -> 700 | R7: =P7-N7 -> 700
A8: FIWE | B8: SE03 | C8: 400 | F8: DC | H8: FIW0 | I8: SE01 | K8: Investment candidates
A9: FIWE | B9: SE03 | C9: 800 | F9: DC | H9: FIW0 | I9: SE02 | K9: FI00 | L9: NON1 | M9: Concept 1 | N9: 2040 | O9: 500 | P9: 500 | T9: EstLink 3 | U9: FIUU | V9: EE00 | W9: Not yet known | X9: =R7 -> 700 | Y9: Y
A10: FIUU | B10: EE00 | C10: 350 | F10: DC | H10: FIW0 | I10: SE03 | K10: FI00 | L10: NON1 | M10: Concept 2 | N10: 2040 | O10: 500 | P10: 500 | T10: Aurora 1 | U10: FINO | V10: SE04 | W10: 800 / 900 | Y10: Y
A11: FIUU | B11: EE00 | C11: 650 | F11: DC | H11: FISW | I11: SE03 | K11: FI00 | L11: SE01 | M11: Real 1 | N11: 2035 | O11: 800 | P11: 800 | T11: Aurora 2 | U11: FINO | V11: SE04 | W11: Not yet known | X11: =Q5-800 -> 1600 | Y11: N
H12: FISW | I12: IBFI | K12: FI00 | L12: SE01 | M12: Real 2 | N12: 2030 | O12: 800 | P12: 900 | U12: FINO | V12: NON1 | W12: ~150 MW | Y12: Y
H13: FIUU | I13: EE00 | K13: FI00 | L13: SE01 | M13: Concept 1 | N13: 2030 | O13: 800 | P13: 800
H14: FISE | I14: EE00 | K14: FI00 | L14: SE01 | M14: Concept 2 | N14: 2040 | O14: 800 | P14: 800 | T14: Conclusion - new capacities will connect the same regions
K15: FI00 | L15: SE01 | M15: Concept 3 | N15: 2040 | O15: 800 | P15: 800
K16: FI00 | L16: SE02 | M16: Concept 1 | N16: 2030 | O16: 500 | P16: 500
K17: FI00 | L17: SE02 | M17: Concept 2 | N17: 2040 | O17: 500 | P17: 500
K18: FI00 | L18: SE02 | M18: Concept 3 | N18: 2040 | O18: 500 | P18: 500
K19: FI00 | L19: SE02 | M19: Concept 4 | N19: 2040 | O19: 500 | P19: 500
K20: FI00 | L20: SE03 | M20: Real 1 | N20: 2040 | O20: 800 | P20: 800
K21: FI00 | L21: SE03 | M21: Concept 1 | N21: 2030 | O21: 500 | P21: 500
K22: FI00 | L22: SE03 | M22: Concept 2 | N22: 2040 | O22: 500 | P22: 500
K23: FI00 | L23: SE03 | M23: Concept 3 | N23: 2040 | O23: 500 | P23: 500
K24: FI00 | L24: SE03 | M24: Concept 4 | N24: 2040 | O24: 500 | P24: 500
K25: FI00 | L25: EE00 | M25: Real 1 | N25: 2035 | O25: 700 | P25: 700
K26: FI00 | L26: EE00 | M26: Concept 1 | N26: 2030 | O26: 700 | P26: 700
K27: FI00 | L27: EE00 | M27: Concept 2 | N27: 2040 | O27: 700 | P27: 700
K28: Investment candidates aggregated
K29: FI00 | L29: NON1 | O29: =SUM(O9:O10) -> 1000 | P29: =SUM(P9:P10) -> 1000
K30: FI00 | L30: SE01 | O30: =SUM(O11:O15) -> 4000 | P30: =SUM(P11:P15) -> 4100
K31: FI00 | L31: SE02 | O31: =SUM(O16:O19) -> 2000 | P31: =SUM(P16:P19) -> 2000
K32: FI00 | L32: SE03 | O32: =SUM(O20:O24) -> 2800 | P32: =SUM(P20:P24) -> 2800
K33: FI00 | L33: EE00 | O33: =SUM(O25:O27) -> 2100 | P33: =SUM(P25:P27) -> 2100
A35: Domestic
A36: Source | B36: FinGrid map | Q36: Dirrect Copilot answer. It's assumptions:
C37: Current | G37: Investment projects | J37: Planned routes | L37: Future | Q37: 400 kV single main corridor ≈ 1,200 MW
C38: 400 kV | D38: 220 kV | E38: 100 kV | F38: MW | G38: Changes | I38: New | L38: 400 kV | M38: 220 kV | N38: 100 kV | O38: MW | Q38: 2 strong corridors / upgrade completed ≈ 1,800–2,400 MW
A39: FIN0 | B39: FIW0 | C39: 2 | D39: 1 | F39: =C39*$C$59+D39*$D$59+E39*$E$59 -> 2300 | G39: 220 -> 400 | L39: 3 | O39: =L39*$C$59+M39*$D$59+N39*$E$59 -> 3000 | Q39: Major reinforced trunk (2035 north–south) up to 3,000 MW
A40: FIN0 | B40: FIC0 | C40: 1 | F40: =C40*$C$59+D40*$D$59+E40*$E$59 -> 1000 | G40: 400 -> ? | I40: +400 | L40: 2 | O40: =L40*$C$59+M40*$D$59+N40*$E$59 -> 2000 | S40: 2025 | T40: 2035 | U40: Δ
A41: FIN0 | B41: FIE0 | C41: 1 | D41: 1 | E41: 1 | F41: =C41*$C$59+D41*$D$59+E41*$E$59 -> 1400 | G41: 220 -> ? | L41: 1 | M41: 1 | N41: 1 | O41: =L41*$C$59+M41*$D$59+N41*$E$59 -> 1400 | Q41: FIN0 | R41: FIW0 | S41: 1200 | T41: 1600 | U41: =T41-S41 -> 400
...

Sheet H2
A1: 1. National data | L1: 3. Transmission
A2: Source | C2: [1] Visual Platform. TYNDP 2024 release - Distributed Energy 2035 scenario. | L2: Existing h2 connections
C3: [2] H2 Storages.xlsx | L3: FINO | M3: SE01 | N3: 7899 | O3: 7546
A4: Simplifications | C4: No H2 inports and production from CH4 -> demand is scaled down to production capacity of electrolyser over all countries present in North European model | L4: FISW | M4: IBFI | N4: 21000 | O4: 21000
L5: FIUU | M5: EE00 | N5: 8330 | O5: 4205
C6: H2 supply is determined by the model. H2 demand sectors are not modeled.
E7: FI | F7: NE | L7: Extending tyndp2024 cross-border lines internally
A8: Capacity [1] | B8: Electrolyser | D8: MW_h2 | E8: 15300 | F8: 146690 | L8: FINO | M8: FIW0 | N8: 8000
B9: Imports | E9: 55310 | F9: 326130 | L9: FIW0 | M9: FISW | N9: 8000
B10: Steam CH4 reformer | E10: 500 | F10: 21860 | L10: FISW | M10: FIC0 | N10: 8000
A11: Supply [1] | B11: Electrolyser | D11: TWh_h2 | E11: 50.48 | F11: 397.6 | L11: FIC0 | M11: FISE | N11: 8000
B12: Imports | E12: -28.74 | F12: 175.8 | L12: FISE | M12: FIUU | N12: 8000
B13: Steam CH4 reformer | E13: 2.2 | F13: 156.96
B14: Total | E14: =SUMIF(E11:E13,">0",E11:E13) -> 52.68 | F14: =SUM(F11:F13) -> 730.36
A15: Demand [1] | B15: E-diesel | D15: TWh_h2 | E15: 3.2 | F15: 108.9
B16: E-kerosene | E16: 3.18 | F16: 108.27
B17: H2 boiler | F17: 7.14
B18: H2P | F18: 3.53
B19: Native | E19: 14.91 | F19: 588
B20: SNG | E20: 2.66 | F20: 93.92
B21: Total | E21: =SUM(E15:E20) -> 23.95 | F21: =SUM(F15:F20) -> 909.76
B22: Native share | E22: =E19/E21 -> 0.62254697 | F22: =F19/F21 -> 0.64632431
B23: Total (normalized) | E23: =E21*$F$11/$F$21 -> 10.467068
A24: Storage [2] | B24: ST (dis)charge | D24: MW_h2 | E24: 266.7168 | F24: 8048.5537
B25: LT charge | E25: 3129.4252 | F25: 56360.978
B26: LT discharge | E26: 1659.0324 | F26: 29879.189
A28: 2. Regional breakdown
A29: Assumtions | B29: Electrolyser capacity is distributed proportionally to projectected non-CHP electricity production capacity
B31: H2 demand and storage capacities are distributed proportionally to non-electrified demand
B32: Both omit East as H2 grid does not reach it
B33: [MW] | C33: [TWh_h2] | D33: [MW_h2]
A34: Column1 | B34: Electrolyser | C34: Demand | D34: Store_short | E34: Store_long_in | F34: Store_long_out | G34: Valve
A35: North | B35: =$E$8*B46/$B$54 -> 5878.5239 | C35: =$E$23*D_el!$K88/(D_el!$K$95-D_el!$K$91) -> 2.0138916 | D35: =$E$24*D_el!$K88/(D_el!$K$95-D_el!$K$91) -> 51.317017 | E35: =$E$25*D_el!$K88/(D_el!$K$95-D_el!$K$91) -> 602.10968 | F35: =$E$26*D_el!$K88/(D_el!$K$95-D_el!$K$91) -> 319.20221 | G35: =P_H2[[#This Row],[Demand]]/0.00876*1.01 -> 232.19526
A36: West | B36: =$E$8*B47/$B$54 -> 6753.5638 | C36: =$E$23*D_el!$K89/(D_el!$K$95-D_el!$K$91) -> 1.64039 | D36: =$E$24*D_el!$K89/(D_el!$K$95-D_el!$K$91) -> 41.79963 | E36: =$E$25*D_el!$K89/(D_el!$K$95-D_el!$K$91) -> 490.44086 | F36: =$E$26*D_el!$K89/(D_el!$K$95-D_el!$K$91) -> 260.00214 | G36: =P_H2[[#This Row],[Demand]]/0.00876*1.01 -> 189.13173
A37: Center | B37: =$E$8*B48/$B$54 -> 571.70859 | C37: =$E$23*D_el!$K90/(D_el!$K$95-D_el!$K$91) -> 1.4444285 | D37: =$E$24*D_el!$K90/(D_el!$K$95-D_el!$K$91) -> 36.806232 | E37: =$E$25*D_el!$K90/(D_el!$K$95-D_el!$K$91) -> 431.85262 | F37: =$E$26*D_el!$K90/(D_el!$K$95-D_el!$K$91) -> 228.94219 | G37: =P_H2[[#This Row],[Demand]]/0.00876*1.01 -> 166.53799
A38: East
A39: South West | B39: =$E$8*B50/$B$54 -> 831.65527 | C39: =$E$23*D_el!$K92/(D_el!$K$95-D_el!$K$91) -> 0.34877452 | D39: =$E$24*D_el!$K92/(D_el!$K$95-D_el!$K$91) -> 8.8873046 | E39: =$E$25*D_el!$K92/(D_el!$K$95-D_el!$K$91) -> 104.27598 | F39: =$E$26*D_el!$K92/(D_el!$K$95-D_el!$K$91) -> 55.280829 | G39: =P_H2[[#This Row],[Demand]]/0.00876*1.01 -> 40.212587
A40: South East | B40: =$E$8*B51/$B$54 -> 828.01815 | C40: =$E$23*D_el!$K93/(D_el!$K$95-D_el!$K$91) -> 2.9501799 | D40: =$E$24*D_el!$K93/(D_el!$K$95-D_el!$K$91) -> 75.175066 | E40: =$E$25*D_el!$K93/(D_el!$K$95-D_el!$K$91) -> 882.03948 | F40: =$E$26*D_el!$K93/(D_el!$K$95-D_el!$K$91) -> 467.6041 | G40: =P_H2[[#This Row],[Demand]]/0.00876*1.01 -> 340.14632
A41: Uusimaa | B41: =$E$8*B52/$B$54 -> 436.53023 | C41: =$E$23*D_el!$K94/(D_el!$K$95-D_el!$K$91) -> 2.0694037 | D41: =$E$24*D_el!$K94/(D_el!$K$95-D_el!$K$91) -> 52.731551 | E41: =$E$25*D_el!$K94/(D_el!$K$95-D_el!$K$91) -> 618.7066 | F41: =$E$26*D_el!$K94/(D_el!$K$95-D_el!$K$91) -> 328.00089 | G41: =P_H2[[#This Row],[Demand]]/0.00876*1.01 -> 238.59563
B42: =SUM(B35:B41) -> 15300 | C42: =SUM(C35:C41) -> 10.467068 | D42: =SUM(D35:D41) -> 266.7168 | E42: =SUM(E35:E41) -> 3129.4252 | F42: =SUM(F35:F41) -> 1659.0324
...

Sheet P_el1
A1: Source [1] | B1: Power plant register (latest update 27.6.2025) | D1: Delivery reliability | Energy Authority | P1: Sources | Q1: [2] Visual Platform, [3] Plexos output | V1: Source [4] | W1: Global Energy Monitor | AA1: Source [5] | AB1: Renewables Finland | AF1: Merging sources [1-5] | AT1: Batteries
A2: Capacity column selection | B2: Capacities are taken from column "Maximum, total, MW" | Q2: Distributed Energy 2035 scenario | V2: Checking pages of individual thermal plants (from plant register with over 50 MW) to determine their type more precise matching with data from Plexos output. | AA2: Selection | AF2: Assumptions are unit type specific | AT2: Assume proportional distribution to non-CHP generation capacity
B3: Taking "Maximum, total, MW" as it contains no zero values, unlike "Hour, total, MW" | P3: Type [2] | R3: Capacity | AA3: The most easy-to-use data in Rewnewables Finland website is in "PV development projects" report. It contains exact capacities only for top 10/19 regions with 80+% of all capacities. It also contains % of capacities for all regions, but less precisely. To fill the absolute values of remaining regions, I need total capacity. I chose to compute it for sataukunta, region with the largest regional capacity, by dividing regional capacity from regional share. Note that same computation for other regions give different values beyond possible error bounds from rounding of regional share percentage. | AF3: Nuclear | AG3: Decrease of 1 119 MW match closure of two Loviisa units
A4: Region search | B4: Performed with Copilot, which provides one of three basis: | P4: Solar | R4: 21270 | AF4: Wind | AG4: While capacity increases 6-fold, there already a lot of wind capacity to be representative for making following assumptions
B5: [1] Municipality in Location mapped to administrative region | F5: sources: sheet "Regions", Statistics Finland municipal → region mapping | P5: Wind Onshore | R5: 46000 | V5: Name | W5: Capacity | X5: Technology | Y5: Fuel | AG5: - Onshore wind is distributed proportionally to existing wind capacity distribution | AT5: Capacity from Visual Platform | AW5: 1270
B6: [2] Project/plant name mapped to region | F6: sources: Energy Authority register, developer/operator sites, Wikipedia; cross-checked with sheet "Regions" | P6: Wind Offshore | R6: 3600 | V6: Meri-Pori | W6: 565 | X6: supercritical | Y6: coal: bituminous | AG6: - Offshore wind is distributed proportionally to existing wind capacity on the west coast regions (i.e., no Offshore wind in Gulf of Finland)
B7: [3] Heuristic assignment using Location/Name tokens and public plant lists | F7: sources: Energy Authority register, developer/operator sites, Wikipedia, sheet "Regions" | P7: Type [3] | R7: Capacity | V7: Forssa kt | W7: 352 | X7: gas turbine | Y7: heavy fuel oil | AF7: Thernal | AG7: Total differs only by 5% -> using current (i.e., plant register) values. Unit type separation followed these considerations: | AT7: Region | AU7: non-CHP | AV7: Battery
B8: In case plant site is in the boundary of region, two regions are listed | P8: Nuclear | R8: 3250 | V8: Huutokoski kt | W8: 180 | X8: gas turbine | Y8: heavy fuel oil | AG8: - Global energy monitor info allows distinction only of two unit types that nonetheless captures major distinctions present in Plexos output | AT8: North | AU8: =_xlfn.XLOOKUP(Battery[[#This Row],[Region]],P_el_final[Region],P_el_final[Total])+_xlfn.XLOOKUP(Battery[[#This Row],[Region]],P_hydro_3[Region],P_hydro_3[Capacity]) -> 28516.768 | AV8: =$AW$5*AU8/$AU$15 -> 458.3816
B9: Manually checked for validation: plants with >200 MW representing 46% of total capacity (no corrections), plants with two regions (most reduced to one region) | P9: Hard coal new Bio | R9: 928 | V9: Kellosaari | W9: 118 | X9: gas turbine | Y9: light fuel oil | AG9: dataset (burning gas vs solid). | AT9: West | AU9: =_xlfn.XLOOKUP(Battery[[#This Row],[Region]],P_el_final[Region],P_el_final[Total])+_xlfn.XLOOKUP(Battery[[#This Row],[Region]],P_hydro_3[Region],P_hydro_3[Capacity]) -> 32761.593 | AV9: =$AW$5*AU9/$AU$15 -> 526.61339
A10: Omissions | B10: Region 2, capacities bellow 100 MW in the final table | P10: Gas OCGT old | R10: 38 | V10: Mertaniemi 1 ja 2 | W10: 102 | X10: gas turbine | Y10: light fuel oil, natural gas | AG10: - Identified coal plants are separated manually while the remaining capacity is allocated to gas plants | AT10: Center | AU10: =_xlfn.XLOOKUP(Battery[[#This Row],[Region]],P_el_final[Region],P_el_final[Total])+_xlfn.XLOOKUP(Battery[[#This Row],[Region]],P_hydro_3[Region],P_hydro_3[Capacity]) -> 2773.363 | AV10: =$AW$5*AU10/$AU$15 -> 44.579337
A11: Notations | B11: For simplicity all power plant register types are renamed: nuclear energy > nuclear, wind power > wind, separate electricity production > thermal | P11: Gas CCGT old 2 | R11: 640 | V11: Olkiluoto kt | W11: 100.5 | X11: gas turbine | Y11: heavy fuel oil | AG11: - All gas capacity is assigned to unit type present in Plexos output with the largest capacity | AT11: East | AU11: =_xlfn.XLOOKUP(Battery[[#This Row],[Region]],P_el_final[Region],P_el_final[Total])+_xlfn.XLOOKUP(Battery[[#This Row],[Region]],P_hydro_3[Region],P_hydro_3[Capacity]) -> 4788.625 | AV11: =$AW$5*AU11/$AU$15 -> 76.972875
A12: Units | B12: MW | P12: Gas CCGT present 1 | R12: 234 | V12: Porvoo Tolkkinen | W12: 80 | X12: gas turbine | Y12: heavy fuel oil | AF12: Solar | AG12: Using proposed instead of built project capacities as the latter is too small to serve as a reasonable proxy for expected future capacity distribution. | AT12: South West | AU12: =_xlfn.XLOOKUP(Battery[[#This Row],[Region]],P_el_final[Region],P_el_final[Total])+_xlfn.XLOOKUP(Battery[[#This Row],[Region]],P_hydro_3[Region],P_hydro_3[Capacity]) -> 4034.3665 | AV12: =$AW$5*AU12/$AU$15 -> 64.848843
P13: Gas OCGT new | R13: 87 | V13: Kristiinankaupunki kt | W13: 60 | X13: subcritical | Y13: coal: bituminous | AT13: South East | AU13: =_xlfn.XLOOKUP(Battery[[#This Row],[Region]],P_el_final[Region],P_el_final[Total])+_xlfn.XLOOKUP(Battery[[#This Row],[Region]],P_hydro_3[Region],P_hydro_3[Capacity]) -> 4016.7228 | AV13: =$AW$5*AU13/$AU$15 -> 64.565236
A14: Powerplant register subset | E14: Region search | I14: Aggregated by region and unit type | V14: Tahkoluoto kt | W14: 52 | X14: gas turbine | Y14: heavy fuel oil | AA14: Project stages | AF14: Region | AG14: Nuclear | AH14: Wind Onshore | AI14: Wind Offshore | AJ14: Hard coal new bio | AK14: Gass CCGT old 2 | AL14: Solar | AM14: Total | AT14: Uusimaa | AU14: =_xlfn.XLOOKUP(Battery[[#This Row],[Region]],P_el_final[Region],P_el_final[Total])+_xlfn.XLOOKUP(Battery[[#This Row],[Region]],P_hydro_3[Region],P_hydro_3[Capacity]) -> 2117.6117 | AV14: =$AW$5*AU14/$AU$15 -> 34.038719
A15: Name | B15: Location | C15: Type | D15: Capacity | E15: Region 1 | F15: Region 2 | G15: Basis | I15: Region | J15: Nuclear | K15: Wind | L15: Thermal | M15: Solar | N15: Total | V15: Vanaja kt 1 | W15: 50 | X15: gas turbine | Y15: heavy fuel oil | AA15: "PV development report" does not explicitly specify for which project stages are regional values given. The closest, but not exact, national total in the report is for projects in "permitting / studies ongoing" category. It is preferable to account first "operating" and "under construction" project capacities, but they alone are not enough given their low capacities. Rewnewables Finland website does contain project specific information, but only in interactive map. Extraction of this information is deemed too time consuming and therefore not undertaken. | AF15: North | AG15: 0 | AH15: =K38/$K$45*$R$5 -> 22638.198 | AI15: =K38/SUM($K$38,$K$39,$K$42)*R$6 -> 1925.077 | AK15: =L38-AJ15 -> 120.1 | AL15: =AB49/$AB$56*$R$4 -> 2066.393 | AM15: =SUM(AG15:AL15) -> 26749.768 | AT15: Finland | AU15: =SUM(Battery[non-CHP]) -> 79009.05 | AV15: =SUM(Battery[Battery]) -> 1270
A16: Olkiluoto 3 | B16: Olkiluoto 3 | C16: Nuclear | D16: 1575 | E16: Satakunta | G16: [2] | I16: Uusimaa | J16: =SUMIFS(P_el[Capacity], P_el[Type], J$15, P_el[Region 1], P_el_2[[#This Row],[Region]]) -> 1014 | K16: =SUMIFS(P_el[Capacity], P_el[Type], K$15, P_el[Region 1], P_el_2[[#This Row],[Region]]) -> 26.65 | L16: =SUMIFS(P_el[Capacity], P_el[Type], L$15, P_el[Region 1], P_el_2[[#This Row],[Region]]) -> 226.25 | M16: =SUMIFS(P_el[Capacity], P_el[Type], M$15, P_el[Region 1], P_el_2[[#This Row],[Region]]) -> 10.33 | N16: =SUM(P_el_2[[#This Row],[Nuclear]:[Thermal]]) -> 1266.9 | V16: Naantali kt | W16: 40 | AF16: West | AG16: =J39 -> 3355 | AH16: =K39/$K$45*$R$5 -> 18945.898 | AI16: =K39/SUM($K$38,$K$39,$K$42)*R$6 -> 1611.0962 | AJ16: =W6+W13 -> 625 | AK16: =L39-AJ16 -> 205.1 | AL16: =AB50/$AB$56*$R$4 -> 7869.4987 | AM16: =SUM(AG16:AL16) -> 32611.593
A17: Olkiluoto 1 | B17: Olkiluoto 1 | C17: Nuclear | D17: 890 | E17: Satakunta | G17: [2] | I17: Southwest Finland | J17: =SUMIFS(P_el[Capacity], P_el[Type], J$15, P_el[Region 1], P_el_2[[#This Row],[Region]]) -> 0 | K17: =SUMIFS(P_el[Capacity], P_el[Type], K$15, P_el[Region 1], P_el_2[[#This Row],[Region]]) -> 83.55 | L17: =SUMIFS(P_el[Capacity], P_el[Type], L$15, P_el[Region 1], P_el_2[[#This Row],[Region]]) -> 41.1 | M17: =SUMIFS(P_el[Capacity], P_el[Type], M$15, P_el[Region 1], P_el_2[[#This Row],[Region]]) -> 0 | N17: =SUM(P_el_2[[#This Row],[Nuclear]:[Thermal]]) -> 124.65 | V17: Porvoo Kilpilahti | W17: 27 | AF17: Center | AG17: 0 | AH17: =K40/$K$45*$R$5 -> 2004.428 | AI17: 0 | AK17: =L40-AJ17 -> 7 | AL17: =AB51/$AB$56*$R$4 -> 645.83509 | AM17: =SUM(AG17:AL17) -> 2657.263
A18: Olkiluoto 2 | B18: Olkiluoto 2 | C18: Nuclear | D18: 890 | E18: Satakunta | G18: [2] | I18: Satakunta | J18: =SUMIFS(P_el[Capacity], P_el[Type], J$15, P_el[Region 1], P_el_2[[#This Row],[Region]]) -> 3355 | K18: =SUMIFS(P_el[Capacity], P_el[Type], K$15, P_el[Region 1], P_el_2[[#This Row],[Region]]) -> 452.1 | L18: =SUMIFS(P_el[Capacity], P_el[Type], L$15, P_el[Region 1], P_el_2[[#This Row],[Region]]) -> 725.9 | M18: =SUMIFS(P_el[Capacity], P_el[Type], M$15, P_el[Region 1], P_el_2[[#This Row],[Region]]) -> 27.7 | N18: =SUM(P_el_2[[#This Row],[Nuclear]:[Thermal]]) -> 4533 | P18: Aggregated comparison | V18: Vaskiluoto kt | W18: 26 | AF18: East | AG18: 0 | AH18: =K41/$K$45*$R$5 -> 1253.0378 | AI18: 0 | AK18: =L41-AJ18 -> 182.6 | AL18: =AB52/$AB$56*$R$4 -> 2895.0872 | AM18: =SUM(AG18:AL18) -> 4330.725
A19: Meri-Pori | B19: Meri-Pori | C19: Thermal | D19: 565 | E19: Satakunta | G19: [1] | I19: Kanta-Häme | J19: =SUMIFS(P_el[Capacity], P_el[Type], J$15, P_el[Region 1], P_el_2[[#This Row],[Region]]) -> 0 | K19: =SUMIFS(P_el[Capacity], P_el[Type], K$15, P_el[Region 1], P_el_2[[#This Row],[Region]]) -> 55.3 | L19: =SUMIFS(P_el[Capacity], P_el[Type], L$15, P_el[Region 1], P_el_2[[#This Row],[Region]]) -> 402 | M19: =SUMIFS(P_el[Capacity], P_el[Type], M$15, P_el[Region 1], P_el_2[[#This Row],[Region]]) -> 0 | N19: =SUM(P_el_2[[#This Row],[Nuclear]:[Thermal]]) -> 457.3 | Q19: Plant register | R19: DE 2035 | V19: Röyttä, Tornion tehtaat, 11 generaattoria | W19: 16 | AF19: South West | AG19: 0 | AH19: =K42/$K$45*$R$5 -> 750.57935 | AI19: =K42/SUM($K$38,$K$39,$K$42)*R$6 -> 63.826772 | AK19: =L42-AJ19 -> 443.1 | AL19: =AB53/$AB$56*$R$4 -> 2762.8604 | AM19: =SUM(AG19:AL19) -> 4020.3665
A20: Loviisa Y1 | B20: Loviisa I | C20: Nuclear | D20: 507 | E20: Uusimaa | G20: [1] | I20: Pirkanmaa | J20: =SUMIFS(P_el[Capacity], P_el[Type], J$15, P_el[Region 1], P_el_2[[#This Row],[Region]]) -> 0 | K20: =SUMIFS(P_el[Capacity], P_el[Type], K$15, P_el[Region 1], P_el_2[[#This Row],[Region]]) -> 20.1 | L20: =SUMIFS(P_el[Capacity], P_el[Type], L$15, P_el[Region 1], P_el_2[[#This Row],[Region]]) -> 7 | M20: =SUMIFS(P_el[Capacity], P_el[Type], M$15, P_el[Region 1], P_el_2[[#This Row],[Region]]) -> 4.6 | N20: =SUM(P_el_2[[#This Row],[Nuclear]:[Thermal]]) -> 27.1 | P20: Nuclear | Q20: =J45 -> 4369 | R20: =R8 -> 3250 | V20: Sopenkorpi | W20: 14.5 | AF20: South East | AG20: 0 | AH20: =K43/$K$45*$R$5 -> 263.79742 | AI20: 0 | AK20: =L43-AJ20 -> 17.2 | AL20: =AB54/$AB$56*$R$4 -> 3283.0254 | AM20: =SUM(AG20:AL20) -> 3564.0228
A21: Loviisa Y2 | B21: Loviisa 2 | C21: Nuclear | D21: 507 | E21: Uusimaa | G21: [1] | I21: Päijät-Häme | J21: =SUMIFS(P_el[Capacity], P_el[Type], J$15, P_el[Region 1], P_el_2[[#This Row],[Region]]) -> 0 | K21: =SUMIFS(P_el[Capacity], P_el[Type], K$15, P_el[Region 1], P_el_2[[#This Row],[Region]]) -> 19.8 | L21: =SUMIFS(P_el[Capacity], P_el[Type], L$15, P_el[Region 1], P_el_2[[#This Row],[Region]]) -> 14.5 | M21: =SUMIFS(P_el[Capacity], P_el[Type], M$15, P_el[Region 1], P_el_2[[#This Row],[Region]]) -> 2.31 | N21: =SUM(P_el_2[[#This Row],[Nuclear]:[Thermal]]) -> 34.3 | P21: Wind | Q21: =K45 -> 8509.56 | R21: =R5+R6 -> 49600 | V21: Wärtsilä tehdas | W21: 10.4 | AF21: Uusimaa | AG21: 0 | AH21: =K44/$K$45*$R$5 -> 144.0615 | AI21: 0 | AK21: =L44-AJ21 -> 226.25 | AL21: =AB55/$AB$56*$R$4 -> 1747.3002 | AM21: =SUM(AG21:AL21) -> 2117.6117
A22: Pjelax-tuulipuisto | B22: Riksåtten 664, 64200 Närpes | C22: Wind | D22: 380 | E22: Ostrobothnia | G22: [3] | I22: Kymenlaakso | J22: =SUMIFS(P_el[Capacity], P_el[Type], J$15, P_el[Region 1], P_el_2[[#This Row],[Region]]) -> 0 | K22: =SUMIFS(P_el[Capacity], P_el[Type], K$15, P_el[Region 1], P_el_2[[#This Row],[Region]]) -> 8 | L22: =SUMIFS(P_el[Capacity], P_el[Type], L$15, P_el[Region 1], P_el_2[[#This Row],[Region]]) -> 2.7 | M22: =SUMIFS(P_el[Capacity], P_el[Type], M$15, P_el[Region 1], P_el_2[[#This Row],[Region]]) -> 0 | N22: =SUM(P_el_2[[#This Row],[Nuclear]:[Thermal]]) -> 10.7 | P22: Thermal | Q22: =L45 -> 1826.35 | R22: =SUM(R9:R13) -> 1927 | V22: Kankaanpää | W22: 7 | AF22: Finland | AG22: 0 | AH22: =SUM(AH15:AH21) -> 46000 | AI22: =SUM(AI15:AI21) -> 3600 | AJ22: =SUM(AJ15:AJ21) -> 625 | AK22: =SUM(AK15:AK21) -> 1201.35 | AL22: =SUM(AL15:AL21) -> 21270 | AM22: =SUM(AM15:AM21) -> 76051.35
A23: Forssa kt | B23: Varavoimalantie 6, 30420 Forssa | C23: Thermal | D23: 352 | E23: Kanta-Häme | G23: [3] | I23: South Karelia | J23: =SUMIFS(P_el[Capacity], P_el[Type], J$15, P_el[Region 1], P_el_2[[#This Row],[Region]]) -> 0 | K23: =SUMIFS(P_el[Capacity], P_el[Type], K$15, P_el[Region 1], P_el_2[[#This Row],[Region]]) -> 21 | L23: =SUMIFS(P_el[Capacity], P_el[Type], L$15, P_el[Region 1], P_el_2[[#This Row],[Region]]) -> 0 | M23: =SUMIFS(P_el[Capacity], P_el[Type], M$15, P_el[Region 1], P_el_2[[#This Row],[Region]]) -> 0 | N23: =SUM(P_el_2[[#This Row],[Nuclear]:[Thermal]]) -> 21 | P23: Solar | Q23: =M45 -> 133.02 | R23: =R4 -> 21270 | V23: Harjavalta | W23: 6.3
A24: Lappfjärdin tuulipuisto | B24: Kristiinankaupunki | C24: Wind | D24: 241.8 | E24: Ostrobothnia | G24: [1] | I24: South Savo | J24: =SUMIFS(P_el[Capacity], P_el[Type], J$15, P_el[Region 1], P_el_2[[#This Row],[Region]]) -> 0 | K24: =SUMIFS(P_el[Capacity], P_el[Type], K$15, P_el[Region 1], P_el_2[[#This Row],[Region]]) -> 0 | L24: =SUMIFS(P_el[Capacity], P_el[Type], L$15, P_el[Region 1], P_el_2[[#This Row],[Region]]) -> 0 | M24: =SUMIFS(P_el[Capacity], P_el[Type], M$15, P_el[Region 1], P_el_2[[#This Row],[Region]]) -> 12.08 | N24: =SUM(P_el_2[[#This Row],[Nuclear]:[Thermal]]) -> 0 | V24: Waskiluoto Validation Center | W24: 5.5
A25: Karhukankaan ja Navettakankaan tuulipuisto, Siikajoki | B25: Karhukankaan ja Navettakankaan tuulipuisto, Siikajoki | C25: Wind | D25: 235.6 | E25: North Ostrobothnia | G25: [1] | I25: North Savo | J25: =SUMIFS(P_el[Capacity], P_el[Type], J$15, P_el[Region 1], P_el_2[[#This Row],[Region]]) -> 0 | K25: =SUMIFS(P_el[Capacity], P_el[Type], K$15, P_el[Region 1], P_el_2[[#This Row],[Region]]) -> 10.5 | L25: =SUMIFS(P_el[Capacity], P_el[Type], L$15, P_el[Region 1], P_el_2[[#This Row],[Region]]) -> 181.1 | M25: =SUMIFS(P_el[Capacity], P_el[Type], M$15, P_el[Region 1], P_el_2[[#This Row],[Region]]) -> 4.9 | N25: =SUM(P_el_2[[#This Row],[Nuclear]:[Thermal]]) -> 191.6 | V25: Ruusutarhat | W25: 2.7
A26: Piiparinmäen tuulipuisto | B26: Piiparinmäki, Pyhäntä/Kajaani. Piiparinmäen tuulipuisto | C26: Wind | D26: 211.4 | E26: North Ostrobothnia | F26: Kainuu | G26: [1] | I26: North Karelia | J26: =SUMIFS(P_el[Capacity], P_el[Type], J$15, P_el[Region 1], P_el_2[[#This Row],[Region]]) -> 0 | K26: =SUMIFS(P_el[Capacity], P_el[Type], K$15, P_el[Region 1], P_el_2[[#This Row],[Region]]) -> 0 | L26: =SUMIFS(P_el[Capacity], P_el[Type], L$15, P_el[Region 1], P_el_2[[#This Row],[Region]]) -> 0 | M26: =SUMIFS(P_el[Capacity], P_el[Type], M$15, P_el[Region 1], P_el_2[[#This Row],[Region]]) -> 0 | N26: =SUM(P_el_2[[#This Row],[Nuclear]:[Thermal]]) -> 0 | V26: Sänkiaho | W26: 2.1 | AA26: Region | AB26: Regional | AC26: Regional% | AD26: National
A27: Mutkalampi tuulipuisto north | B27: Kannus/Kalajoki | C27: Wind | D27: 203.8 | E27: North Ostrobothnia | F27: Central Ostrobothnia | G27: [1] | I27: Central Finland | J27: =SUMIFS(P_el[Capacity], P_el[Type], J$15, P_el[Region 1], P_el_2[[#This Row],[Region]]) -> 0 | K27: =SUMIFS(P_el[Capacity], P_el[Type], K$15, P_el[Region 1], P_el_2[[#This Row],[Region]]) -> 350.7 | L27: =SUMIFS(P_el[Capacity], P_el[Type], L$15, P_el[Region 1], P_el_2[[#This Row],[Region]]) -> 0 | M27: =SUMIFS(P_el[Capacity], P_el[Type], M$15, P_el[Region 1], P_el_2[[#This Row],[Region]]) -> 0 | N27: =SUM(P_el_2[[#This Row],[Nuclear]:[Thermal]]) -> 350.7 | V27: Hoikankangas, Kajaanin sähkölaitos | W27: 1.5 | AA27: Uusimaa | AB27: 1693 | AC27: 0.08 | AD27: =AB27/AC27 -> 21162.5
A28: Mutkalampi tuulipuisto south | B28: Kannus/Kalajoki | C28: Wind | D28: 200 | E28: North Ostrobothnia | F28: Central Ostrobothnia | G28: [1] | I28: South Ostrobothnia | J28: =SUMIFS(P_el[Capacity], P_el[Type], J$15, P_el[Region 1], P_el_2[[#This Row],[Region]]) -> 0 | K28: =SUMIFS(P_el[Capacity], P_el[Type], K$15, P_el[Region 1], P_el_2[[#This Row],[Region]]) -> 1209.91 | L28: =SUMIFS(P_el[Capacity], P_el[Type], L$15, P_el[Region 1], P_el_2[[#This Row],[Region]]) -> 1 | M28: =SUMIFS(P_el[Capacity], P_el[Type], M$15, P_el[Region 1], P_el_2[[#This Row],[Region]]) -> 44.2 | N28: =SUM(P_el_2[[#This Row],[Nuclear]:[Thermal]]) -> 1210.91 | V28: Lestijärvi | W28: 1.3 | AA28: Southwest Finland | AB28: 1542 | AC28: 0.07 | AD28: =AB28/AC28 -> 22028.571
A29: Karhunnevankankaan tuulipuisto | B29: Karhunnevankankaan tuulipuisto | C29: Wind | D29: 188.1 | E29: North Ostrobothnia | G29: [2] | I29: Ostrobothnia | J29: =SUMIFS(P_el[Capacity], P_el[Type], J$15, P_el[Region 1], P_el_2[[#This Row],[Region]]) -> 0 | K29: =SUMIFS(P_el[Capacity], P_el[Type], K$15, P_el[Region 1], P_el_2[[#This Row],[Region]]) -> 1587.2 | L29: =SUMIFS(P_el[Capacity], P_el[Type], L$15, P_el[Region 1], P_el_2[[#This Row],[Region]]) -> 101.9 | M29: =SUMIFS(P_el[Capacity], P_el[Type], M$15, P_el[Region 1], P_el_2[[#This Row],[Region]]) -> 3.6 | N29: =SUM(P_el_2[[#This Row],[Nuclear]:[Thermal]]) -> 1689.1 | V29: Kantvik | W29: 1.25 | AA29: Satakunta | AB29: 3546 | AC29: 0.17 | AD29: =AB29/AC29 -> 20858.824
