Workbook
Name Slicer_Climate_Year: #N/A
Name Slicer_Generator_ID: #N/A
Name Slicer_Parameter: #N/A
Name Slicer_Sector: #N/A

Sheet demanddata_FI-industry
A1: Country | B1: Grid | C1: Node_suffix | D1: Scenario | E1: Year | F1: TWh/year | G1: Constant_share
A2: FI00 | B2: steam | C2: industry | D2: all | E2: 1 | F2: =elec_gen!I35/1000 -> 16.6674

Sheet elec_gen
C9: https://pxdata.stat.fi/PxWeb/pxweb/fi/StatFin/StatFin__salatuo/statfin_salatuo_pxt_11sr.px/
D11: Vesivoima | E11: Tuulivoima | F11: Aurinkovoima | G11: Ydinvoima | H11: Tavallinen lauhdevoima | I11: Yhteistuotanto, teollisuus | J11: Yhteistuotanto, kaukolämpö | K11: Yhteistuotanto, pien-CHP | L11: SÄHKÖN TUOTANTO YHTEENSÄ | M11: Sähkön tuonti | N11: Sähkön vienti | O11: Nettotuonti | P11: SÄHKÖN KOKONAISKULUTUS
C12: Määrä, GWh
C13: 2005 | D13: 13428 | E13: 168 | F13: 3 | G13: 22356 | H13: 5326 | I13: 10734 | J13: 15644 | K13: 11 | L13: 67670 | M13: 17947 | N13: 933 | O13: 17014 | P13: 84684
C14: 2006 | D14: 11313 | E14: 153 | F14: 3 | G14: 22004 | H14: 17577 | I14: 12030 | J14: 15547 | K14: 14 | L14: 78641 | M14: 14117 | N14: 2716 | O14: 11401 | P14: 90042
C15: 2007 | D15: 13991 | E15: 188 | F15: 4 | G15: 22501 | H15: 14377 | I15: 11639 | J15: 15120 | K15: 10 | L15: 77831 | M15: 15419 | N15: 2862 | O15: 12557 | P15: 90388
C16: 2008 | D16: 16909 | E16: 261 | F16: 4 | G16: 22050 | H16: 8779 | I16: 11194 | J16: 15282 | K16: 16 | L16: 74495 | M16: 16107 | N16: 3335 | O16: 12772 | P16: 87267
C17: 2009 | D17: 12573 | E17: 277 | F17: 4 | G17: 22601 | H17: 8963 | I17: 9041 | J17: 15752 | K17: 15 | L17: 69226 | M17: 15460 | N17: 3375 | O17: 12085 | P17: 81311
C18: 2010 | D18: 12743 | E18: 294 | F18: 5 | G18: 21889 | H18: 14179 | I18: 10405 | J18: 17693 | K18: 17 | L18: 77225 | M18: 15719 | N18: 5218 | O18: 10501 | P18: 87726
C19: 2011 | D19: 12278 | E19: 481 | F19: 5 | G19: 22266 | H19: 9822 | I19: 10132 | J19: 15410 | K19: 25 | L19: 70420 | M19: 17656 | N19: 3805 | O19: 13851 | P19: 84271
C20: 2012 | D20: 16667 | E20: 494 | F20: 6 | G20: 22063 | H20: 5177 | I20: 8891 | J20: 14395 | K20: 21 | L20: 67714 | M20: 19089 | N20: 1645 | O20: 17443 | P20: 85157
C21: 2013 | D21: 12672 | E21: 774 | F21: 7 | G21: 22673 | H21: 8883 | I21: 9147 | J21: 14179 | K21: 18 | L21: 68354 | M21: 17591 | N21: 1876 | O21: 15715 | P21: 84069
C22: 2014 | D22: 13240 | E22: 1107 | F22: 8 | G22: 22646 | H22: 6379 | I22: 8694 | J22: 13367 | K22: 18 | L22: 65459 | M22: 21622 | N22: 3655 | O22: 17966 | P22: 83425
C23: 2015 | D23: 16584 | E23: 2327 | F23: 11 | G23: 22326 | H23: 4062 | I23: 8288 | J23: 12542 | K23: 16 | L23: 66156 | M23: 21459 | N23: 5122 | O23: 16337 | P23: 82493
C24: 2016 | D24: 15634 | E24: 3068 | F24: 22 | G24: 22280 | H24: 4319 | I24: 8474 | J24: 12392 | K24: 14 | L24: 66204 | M24: 22110 | N24: 3159 | O24: 18951 | P24: 85155
... C31: 2023 | D31: 15026 | E31: 14465 | F31: 716 | G31: 32759 | H31: 1813 | I31: 6587 | J31: 6897 | K31: 19 | L31: 78283 | M31: 9644 | N31: 7920 | O31: 1724 | P31: 80007
H34: elec | I34: =AVERAGE(I22:I31) -> 8333.7
H35: steam | I35: =I34*2 -> 16667.4

Sheet transferdata_dheat
A1: from_country | B1: from_suffix | C1: to_country | D1: to_suffix | E1: grid | F1: scenario | G1: Year | H1: Variant | I1: transferCap | J1: rampLimit | K1: variableTransCost | L1: transferLoss
A2: FI00 | B2: VAN | C2: FI00 | D2: HKI | E2: dheat | F2: all | G2: 1 | H2: dh-level:cities | I2: 130 | K2: 2.1
A3: FI00 | B3: HKI | C3: FI00 | D3: VAN | E3: dheat | F3: all | G3: 1 | H3: dh-level:cities | I3: 130 | K3: 2.2
A4: FI00 | B4: ESP | C4: FI00 | D4: HKI | E4: dheat | F4: all | G4: 1 | H4: dh-level:cities | I4: 120 | K4: 1.9
A5: FI00 | B5: HKI | C5: FI00 | D5: ESP | E5: dheat | F5: all | G5: 1 | H5: dh-level:cities | I5: 120 | K5: 2
A6: FI00 | B6: ESP | C6: FI00 | D6: VAN | E6: dheat | F6: all | G6: 1 | H6: dh-level:cities | I6: 50 | K6: 2.3
A7: FI00 | B7: VAN | C7: FI00 | D7: ESP | E7: dheat | F7: all | G7: 1 | H7: dh-level:cities | I7: 50 | K7: 2.4

Sheet unitdata_Finland
A1: Country | B1: unittype | C1: unit_name_prefix | D1: Scenario | E1: Year | F1: variant | G1: capacity_input1 | H1: node_suffix_input1 | I1: capacity_output1 | J1: node_suffix_output1 | K1: capacity_output2 | L1: node_suffix_output2 | M1: cb | N1: cv | O1: eff00 | P1: eff01 | Q1: vomCosts | R1: Note | S1: method | V1: ## capitals mapping | W1: ## | X1: ## | Y1: ## | Z1: ## | AA1: ## | AB1: ## | AC1: ## | AD1: ## | AE1: ## | AF1: ## | AG1: ## | AH1: ## | AI1: ## | AJ1: ## | AK1: ## | AL1: ## | AM1: ## | AN1: ## | AO1: ##
A2: ## City level data
A3: FI00 | B3: oilHOB | C3: HKI | D3: all | E3: 1 | F3: dh-level:cities | G3: =IF(ISTEXT($B3),IF(COUNTIF($B3,"*Industry*"),SUMIF('Industry-capacity'!$A$2:$A$6,$B3,'Industry-capacity'!$D$2:$D$6),IF(SUMIF(INDIRECT($C3&"!A$2:A$20"),$B3,INDIRECT($C3&"!D$2:D$20"))>0,SUMIF(INDIRECT($C3&"!A$2:A$20"),$B3,INDIRECT($C3&"!D$2:D$20")),"")),"") | H3: =IF(COUNTIF($B3,"*charger*")+COUNTIF($B3,"*disch*"),$C3,"") | I3: =IF(ISTEXT($B3),IF(COUNTIF($B3,"*Industry*"),SUMIF('Industry-capacity'!$A$2:$A$6,$B3,'Industry-capacity'!$B$2:$B$6),SUMIF(INDIRECT($C3&"!A$2:A$20"),$B3,INDIRECT($C3&"!B$2:B$20"))),"") -> 671 | J3: =IF(COUNTIF($B3,"*HOB*")+COUNTIF($B3,"*charger*")+COUNTIF($B3,"*disch*")+COUNTIF($B3,"GSHP")+COUNTIF($B3,"EBoil"),C3,"") -> HKI | K3: =IF(ISTEXT($B3),IF(COUNTIF($B3,"*Industry*"),SUMIF('Industry-capacity'!$A$2:$A$6,$B3,'Industry-capacity'!$C$2:$C$6),SUMIF(INDIRECT($C3&"!A$2:A$20"),$B3,INDIRECT($C3&"!C$2:C$20"))),"") -> 0 | L3: =IF(K3=0,"",IF(ISTEXT($B3),IF(COUNTIF($B3,"*Industry*"),"industry",$C3),"")) | M3: =IF(ISTEXT($B3),IF($K3>0,$I3/$K3,""),"") | O3: =IF(SUM($G3)>0,($I3+$K3)/$G3,"") | P3: =IF(SUM($G3)>0,($I3+$K3)/$G3,"") | Q3: =ROUND(VLOOKUP($B3, $Z$6:$AA$32,2,FALSE) * (1+$AD$6) * (1 + IF(C3="",1, VLOOKUP($C3,$AC$8:$AD$15,2,FALSE))), 2) -> 2.5 | S3: =IF(I3<10, "remove", "") | V3: =_xlfn.XLOOKUP(C3,$W$6:$W$13,$X$6:$X$13) -> HKI
A4: FI00 | B4: gasHOB | C4: HKI | D4: all | E4: 1 | F4: dh-level:cities | G4: =IF(ISTEXT($B4),IF(COUNTIF($B4,"*Industry*"),SUMIF('Industry-capacity'!$A$2:$A$6,$B4,'Industry-capacity'!$D$2:$D$6),IF(SUMIF(INDIRECT($C4&"!A$2:A$20"),$B4,INDIRECT($C4&"!D$2:D$20"))>0,SUMIF(INDIRECT($C4&"!A$2:A$20"),$B4,INDIRECT($C4&"!D$2:D$20")),"")),"") | H4: =IF(COUNTIF($B4,"*charger*")+COUNTIF($B4,"*disch*"),$C4,"") | I4: =IF(ISTEXT($B4),IF(COUNTIF($B4,"*Industry*"),SUMIF('Industry-capacity'!$A$2:$A$6,$B4,'Industry-capacity'!$B$2:$B$6),SUMIF(INDIRECT($C4&"!A$2:A$20"),$B4,INDIRECT($C4&"!B$2:B$20"))),"") -> 912 | J4: =IF(COUNTIF($B4,"*HOB*")+COUNTIF($B4,"*charger*")+COUNTIF($B4,"*disch*")+COUNTIF($B4,"GSHP")+COUNTIF($B4,"EBoil"),C4,"") -> HKI | K4: =IF(ISTEXT($B4),IF(COUNTIF($B4,"*Industry*"),SUMIF('Industry-capacity'!$A$2:$A$6,$B4,'Industry-capacity'!$C$2:$C$6),SUMIF(INDIRECT($C4&"!A$2:A$20"),$B4,INDIRECT($C4&"!C$2:C$20"))),"") -> 0 | L4: =IF(K4=0,"",IF(ISTEXT($B4),IF(COUNTIF($B4,"*Industry*"),"industry",$C4),"")) | M4: =IF(ISTEXT($B4),IF($K4>0,$I4/$K4,""),"") | O4: =IF(SUM($G4)>0,($I4+$K4)/$G4,"") | P4: =IF(SUM($G4)>0,($I4+$K4)/$G4,"") | Q4: =ROUND(VLOOKUP($B4, $Z$6:$AA$32,2,FALSE) * (1+$AD$6) * (1 + IF(C4="",1, VLOOKUP($C4,$AC$8:$AD$15,2,FALSE))), 2) -> 2.5 | S4: =IF(I4<10, "remove", "") | V4: =_xlfn.XLOOKUP(C4,$W$6:$W$13,$X$6:$X$13) -> HKI
A5: FI00 | B5: bioHOB | C5: HKI | D5: all | E5: 1 | F5: dh-level:cities | G5: =IF(ISTEXT($B5),IF(COUNTIF($B5,"*Industry*"),SUMIF('Industry-capacity'!$A$2:$A$6,$B5,'Industry-capacity'!$D$2:$D$6),IF(SUMIF(INDIRECT($C5&"!A$2:A$20"),$B5,INDIRECT($C5&"!D$2:D$20"))>0,SUMIF(INDIRECT($C5&"!A$2:A$20"),$B5,INDIRECT($C5&"!D$2:D$20")),"")),"") | H5: =IF(COUNTIF($B5,"*charger*")+COUNTIF($B5,"*disch*"),$C5,"") | I5: =IF(ISTEXT($B5),IF(COUNTIF($B5,"*Industry*"),SUMIF('Industry-capacity'!$A$2:$A$6,$B5,'Industry-capacity'!$B$2:$B$6),SUMIF(INDIRECT($C5&"!A$2:A$20"),$B5,INDIRECT($C5&"!B$2:B$20"))),"") -> 527 | J5: =IF(COUNTIF($B5,"*HOB*")+COUNTIF($B5,"*charger*")+COUNTIF($B5,"*disch*")+COUNTIF($B5,"GSHP")+COUNTIF($B5,"EBoil"),C5,"") -> HKI | K5: =IF(ISTEXT($B5),IF(COUNTIF($B5,"*Industry*"),SUMIF('Industry-capacity'!$A$2:$A$6,$B5,'Industry-capacity'!$C$2:$C$6),SUMIF(INDIRECT($C5&"!A$2:A$20"),$B5,INDIRECT($C5&"!C$2:C$20"))),"") -> 0 | L5: =IF(K5=0,"",IF(ISTEXT($B5),IF(COUNTIF($B5,"*Industry*"),"industry",$C5),"")) | M5: =IF(ISTEXT($B5),IF($K5>0,$I5/$K5,""),"") | O5: =IF(SUM($G5)>0,($I5+$K5)/$G5,"") | P5: =IF(SUM($G5)>0,($I5+$K5)/$G5,"") | Q5: =ROUND(VLOOKUP($B5, $Z$6:$AA$32,2,FALSE) * (1+$AD$6) * (1 + IF(C5="",1, VLOOKUP($C5,$AC$8:$AD$15,2,FALSE))), 2) -> 2.5 | S5: =IF(I5<10, "remove", "") | V5: =_xlfn.XLOOKUP(C5,$W$6:$W$13,$X$6:$X$13) -> HKI | W5: cities | X5: capitals | AA5: vomCosts | AC5: vomCost multiplier | AH5: Bruttokansantuote henkeä kohden kohden alueittain, vuosittain muuttujina Alue, Tiedot ja Vuosi
A6: FI00 | B6: GSHP | C6: HKI | D6: all | E6: 1 | F6: dh-level:cities | G6: =IF(ISTEXT($B6),IF(COUNTIF($B6,"*Industry*"),SUMIF('Industry-capacity'!$A$2:$A$6,$B6,'Industry-capacity'!$D$2:$D$6),IF(SUMIF(INDIRECT($C6&"!A$2:A$20"),$B6,INDIRECT($C6&"!D$2:D$20"))>0,SUMIF(INDIRECT($C6&"!A$2:A$20"),$B6,INDIRECT($C6&"!D$2:D$20")),"")),"") | H6: =IF(COUNTIF($B6,"*charger*")+COUNTIF($B6,"*disch*"),$C6,"") | I6: =IF(ISTEXT($B6),IF(COUNTIF($B6,"*Industry*"),SUMIF('Industry-capacity'!$A$2:$A$6,$B6,'Industry-capacity'!$B$2:$B$6),SUMIF(INDIRECT($C6&"!A$2:A$20"),$B6,INDIRECT($C6&"!B$2:B$20"))),"") -> 343.2 | J6: =IF(COUNTIF($B6,"*HOB*")+COUNTIF($B6,"*charger*")+COUNTIF($B6,"*disch*")+COUNTIF($B6,"GSHP")+COUNTIF($B6,"EBoil"),C6,"") -> HKI | K6: =IF(ISTEXT($B6),IF(COUNTIF($B6,"*Industry*"),SUMIF('Industry-capacity'!$A$2:$A$6,$B6,'Industry-capacity'!$C$2:$C$6),SUMIF(INDIRECT($C6&"!A$2:A$20"),$B6,INDIRECT($C6&"!C$2:C$20"))),"") -> 0 | L6: =IF(K6=0,"",IF(ISTEXT($B6),IF(COUNTIF($B6,"*Industry*"),"industry",$C6),"")) | M6: =IF(ISTEXT($B6),IF($K6>0,$I6/$K6,""),"") | O6: =IF(SUM($G6)>0,($I6+$K6)/$G6,"") | P6: =IF(SUM($G6)>0,($I6+$K6)/$G6,"") | Q6: =ROUND(VLOOKUP($B6, $Z$6:$AA$32,2,FALSE) * (1+$AD$6) * (1 + IF(C6="",1, VLOOKUP($C6,$AC$8:$AD$15,2,FALSE))), 2) -> 7.5 | S6: =IF(I6<10, "remove", "") | V6: =_xlfn.XLOOKUP(C6,$W$6:$W$13,$X$6:$X$13) -> HKI | W6: HKI | X6: HKI | Z6: oilHOB | AA6: =SUMIFS([1]unittypedata!$S:$S, [1]unittypedata!$D:$D, Z6) -> 2 | AC6: FI00 | AD6: ='[2]vomcost mult'!$R$19 -> 0.108 | AI6: Käypiin hintoihin, euroa
A7: FI00 | B7: gasCCGTCHP | C7: HKI | D7: all | E7: 1 | F7: dh-level:cities | G7: =IF(ISTEXT($B7),IF(COUNTIF($B7,"*Industry*"),SUMIF('Industry-capacity'!$A$2:$A$6,$B7,'Industry-capacity'!$D$2:$D$6),IF(SUMIF(INDIRECT($C7&"!A$2:A$20"),$B7,INDIRECT($C7&"!D$2:D$20"))>0,SUMIF(INDIRECT($C7&"!A$2:A$20"),$B7,INDIRECT($C7&"!D$2:D$20")),"")),"") -> 1343 | H7: =IF(COUNTIF($B7,"*charger*")+COUNTIF($B7,"*disch*"),$C7,"") | I7: =IF(ISTEXT($B7),IF(COUNTIF($B7,"*Industry*"),SUMIF('Industry-capacity'!$A$2:$A$6,$B7,'Industry-capacity'!$B$2:$B$6),SUMIF(INDIRECT($C7&"!A$2:A$20"),$B7,INDIRECT($C7&"!B$2:B$20"))),"") -> 630 | J7: =IF(COUNTIF($B7,"*HOB*")+COUNTIF($B7,"*charger*")+COUNTIF($B7,"*disch*")+COUNTIF($B7,"GSHP")+COUNTIF($B7,"EBoil"),C7,"") | K7: =IF(ISTEXT($B7),IF(COUNTIF($B7,"*Industry*"),SUMIF('Industry-capacity'!$A$2:$A$6,$B7,'Industry-capacity'!$C$2:$C$6),SUMIF(INDIRECT($C7&"!A$2:A$20"),$B7,INDIRECT($C7&"!C$2:C$20"))),"") -> 587 | L7: =IF(K7=0,"",IF(ISTEXT($B7),IF(COUNTIF($B7,"*Industry*"),"industry",$C7),"")) -> HKI | M7: =IF(ISTEXT($B7),IF($K7>0,$I7/$K7,""),"") -> 1.0732538 | O7: =IF(SUM($G7)>0,($I7+$K7)/$G7,"") -> 0.90618019 | P7: =IF(SUM($G7)>0,($I7+$K7)/$G7,"") -> 0.90618019 | Q7: =ROUND(VLOOKUP($B7, $Z$6:$AA$32,2,FALSE) * (1+$AD$6) * (1 + IF(C7="",1, VLOOKUP($C7,$AC$8:$AD$15,2,FALSE))), 2) -> 2 | S7: =IF(I7<10, "remove", "") | V7: =_xlfn.XLOOKUP(C7,$W$6:$W$13,$X$6:$X$13) -> HKI | W7: ESP | X7: HKI | Z7: gasHOB | AA7: =SUMIFS([1]unittypedata!$S:$S, [1]unittypedata!$D:$D, Z7) -> 2 | AI7: 2020 | AJ7: 2021 | AK7: 2022 | AL7: 2023 | AN7: avg
A8: FI00 | B8: elecHOB | C8: HKI | D8: all | E8: 1 | F8: dh-level:cities | G8: =IF(ISTEXT($B8),IF(COUNTIF($B8,"*Industry*"),SUMIF('Industry-capacity'!$A$2:$A$6,$B8,'Industry-capacity'!$D$2:$D$6),IF(SUMIF(INDIRECT($C8&"!A$2:A$20"),$B8,INDIRECT($C8&"!D$2:D$20"))>0,SUMIF(INDIRECT($C8&"!A$2:A$20"),$B8,INDIRECT($C8&"!D$2:D$20")),"")),"") | H8: =IF(COUNTIF($B8,"*charger*")+COUNTIF($B8,"*disch*"),$C8,"") | I8: =IF(ISTEXT($B8),IF(COUNTIF($B8,"*Industry*"),SUMIF('Industry-capacity'!$A$2:$A$6,$B8,'Industry-capacity'!$B$2:$B$6),SUMIF(INDIRECT($C8&"!A$2:A$20"),$B8,INDIRECT($C8&"!B$2:B$20"))),"") -> 540 | J8: =IF(COUNTIF($B8,"*HOB*")+COUNTIF($B8,"*charger*")+COUNTIF($B8,"*disch*")+COUNTIF($B8,"GSHP")+COUNTIF($B8,"EBoil"),C8,"") -> HKI | K8: =IF(ISTEXT($B8),IF(COUNTIF($B8,"*Industry*"),SUMIF('Industry-capacity'!$A$2:$A$6,$B8,'Industry-capacity'!$C$2:$C$6),SUMIF(INDIRECT($C8&"!A$2:A$20"),$B8,INDIRECT($C8&"!C$2:C$20"))),"") -> 0 | L8: =IF(K8=0,"",IF(ISTEXT($B8),IF(COUNTIF($B8,"*Industry*"),"industry",$C8),"")) | M8: =IF(ISTEXT($B8),IF($K8>0,$I8/$K8,""),"") | O8: =IF(SUM($G8)>0,($I8+$K8)/$G8,"") | P8: =IF(SUM($G8)>0,($I8+$K8)/$G8,"") | Q8: =ROUND(VLOOKUP($B8, $Z$6:$AA$32,2,FALSE) * (1+$AD$6) * (1 + IF(C8="",1, VLOOKUP($C8,$AC$8:$AD$15,2,FALSE))), 2) -> 1.87 | S8: =IF(I8<10, "remove", "") | V8: =_xlfn.XLOOKUP(C8,$W$6:$W$13,$X$6:$X$13) -> HKI | W8: VAN | X8: HKI | Z8: bioHOB | AA8: =SUMIFS([1]unittypedata!$S:$S, [1]unittypedata!$D:$D, Z8) -> 2 | AC8: HKI | AD8: =LOG(AE8/$AN$8) -> 0.12747054 | AE8: =AN9*1.05 -> 61828.594 | AH8: KOKO MAA | AI8: 42749.8 | AJ8: 44895 | AK8: 47899.6 | AL8: 48863.2 | AN8: =AVERAGE(AI8:AL8) -> 46101.9
A9: FI00 | B9: HeatStorageCharger | C9: HKI | D9: all | E9: 1 | F9: dh-level:cities | G9: =IF(ISTEXT($B9),IF(COUNTIF($B9,"*Industry*"),SUMIF('Industry-capacity'!$A$2:$A$6,$B9,'Industry-capacity'!$D$2:$D$6),IF(SUMIF(INDIRECT($C9&"!A$2:A$20"),$B9,INDIRECT($C9&"!D$2:D$20"))>0,SUMIF(INDIRECT($C9&"!A$2:A$20"),$B9,INDIRECT($C9&"!D$2:D$20")),"")),"") | H9: =IF(COUNTIF($B9,"*charger*")+COUNTIF($B9,"*disch*"),$C9,"") -> HKI | I9: =IF(ISTEXT($B9),IF(COUNTIF($B9,"*Industry*"),SUMIF('Industry-capacity'!$A$2:$A$6,$B9,'Industry-capacity'!$B$2:$B$6),SUMIF(INDIRECT($C9&"!A$2:A$20"),$B9,INDIRECT($C9&"!B$2:B$20"))),"") -> 340 | J9: =IF(COUNTIF($B9,"*HOB*")+COUNTIF($B9,"*charger*")+COUNTIF($B9,"*disch*")+COUNTIF($B9,"GSHP")+COUNTIF($B9,"EBoil"),C9,"") -> HKI | K9: =IF(ISTEXT($B9),IF(COUNTIF($B9,"*Industry*"),SUMIF('Industry-capacity'!$A$2:$A$6,$B9,'Industry-capacity'!$C$2:$C$6),SUMIF(INDIRECT($C9&"!A$2:A$20"),$B9,INDIRECT($C9&"!C$2:C$20"))),"") -> 0 | L9: =IF(K9=0,"",IF(ISTEXT($B9),IF(COUNTIF($B9,"*Industry*"),"industry",$C9),"")) | M9: =IF(ISTEXT($B9),IF($K9>0,$I9/$K9,""),"") | O9: =IF(SUM($G9)>0,($I9+$K9)/$G9,"") | P9: =IF(SUM($G9)>0,($I9+$K9)/$G9,"") | Q9: =ROUND(VLOOKUP($B9, $Z$6:$AA$32,2,FALSE) * (1+$AD$6) * (1 + IF(C9="",1, VLOOKUP($C9,$AC$8:$AD$15,2,FALSE))), 2) -> 1.75 | S9: =IF(I9<10, "remove", "") | V9: =_xlfn.XLOOKUP(C9,$W$6:$W$13,$X$6:$X$13) -> HKI | W9: TKU | X9: ROF | Z9: GSHP | AA9: =SUMIFS([1]unittypedata!$S:$S, [1]unittypedata!$D:$D, Z9) -> 6 | AC9: ESP | AD9: =LOG(AE9/$AN$8) -> 0.10628125 | AE9: =AN9 -> 58884.375 | AH9: MK01 Uusimaa | AI9: 55424.5 | AJ9: 57622.9 | AK9: 60396.7 | AL9: 62093.4 | AN9: =AVERAGE(AI9:AL9) -> 58884.375
A10: FI00 | B10: HeatStorageDisch | C10: HKI | D10: all | E10: 1 | F10: dh-level:cities | G10: =IF(ISTEXT($B10),IF(COUNTIF($B10,"*Industry*"),SUMIF('Industry-capacity'!$A$2:$A$6,$B10,'Industry-capacity'!$D$2:$D$6),IF(SUMIF(INDIRECT($C10&"!A$2:A$20"),$B10,INDIRECT($C10&"!D$2:D$20"))>0,SUMIF(INDIRECT($C10&"!A$2:A$20"),$B10,INDIRECT($C10&"!D$2:D$20")),"")),"") | H10: =IF(COUNTIF($B10,"*charger*")+COUNTIF($B10,"*disch*"),$C10,"") -> HKI | I10: =IF(ISTEXT($B10),IF(COUNTIF($B10,"*Industry*"),SUMIF('Industry-capacity'!$A$2:$A$6,$B10,'Industry-capacity'!$B$2:$B$6),SUMIF(INDIRECT($C10&"!A$2:A$20"),$B10,INDIRECT($C10&"!B$2:B$20"))),"") -> 340 | J10: =IF(COUNTIF($B10,"*HOB*")+COUNTIF($B10,"*charger*")+COUNTIF($B10,"*disch*")+COUNTIF($B10,"GSHP")+COUNTIF($B10,"EBoil"),C10,"") -> HKI | K10: =IF(ISTEXT($B10),IF(COUNTIF($B10,"*Industry*"),SUMIF('Industry-capacity'!$A$2:$A$6,$B10,'Industry-capacity'!$C$2:$C$6),SUMIF(INDIRECT($C10&"!A$2:A$20"),$B10,INDIRECT($C10&"!C$2:C$20"))),"") -> 0 | L10: =IF(K10=0,"",IF(ISTEXT($B10),IF(COUNTIF($B10,"*Industry*"),"industry",$C10),"")) | M10: =IF(ISTEXT($B10),IF($K10>0,$I10/$K10,""),"") | O10: =IF(SUM($G10)>0,($I10+$K10)/$G10,"") | P10: =IF(SUM($G10)>0,($I10+$K10)/$G10,"") | Q10: =ROUND(VLOOKUP($B10, $Z$6:$AA$32,2,FALSE) * (1+$AD$6) * (1 + IF(C10="",1, VLOOKUP($C10,$AC$8:$AD$15,2,FALSE))), 2) -> 1.75 | S10: =IF(I10<10, "remove", "") | V10: =_xlfn.XLOOKUP(C10,$W$6:$W$13,$X$6:$X$13) -> HKI | W10: TRE | X10: ROF | Z10: gasCCGTCHP | AA10: =SUMIFS([1]unittypedata!$S:$S, [1]unittypedata!$D:$D, Z10) -> 1.6 | AC10: VAN | AD10: =LOG(AE10/$AN$8) -> 0.084004851 | AE10: =AN9*0.95 -> 55940.156 | AH10: MK02 Varsinais-Suomi | AI10: 39752 | AJ10: 41181 | AK10: 44607.9 | AL10: 45556.1 | AN10: =AVERAGE(AI10:AL10) -> 42774.25
A11: FI00 | B11: heatStorageChargerLarge | C11: HKI | D11: all | E11: 1 | F11: dh-level:cities | G11: =IF(ISTEXT($B11),IF(COUNTIF($B11,"*Industry*"),SUMIF('Industry-capacity'!$A$2:$A$6,$B11,'Industry-capacity'!$D$2:$D$6),IF(SUMIF(INDIRECT($C11&"!A$2:A$20"),$B11,INDIRECT($C11&"!D$2:D$20"))>0,SUMIF(INDIRECT($C11&"!A$2:A$20"),$B11,INDIRECT($C11&"!D$2:D$20")),"")),"") | H11: =IF(COUNTIF($B11,"*charger*")+COUNTIF($B11,"*disch*"),$C11,"") -> HKI | I11: =IF(ISTEXT($B11),IF(COUNTIF($B11,"*Industry*"),SUMIF('Industry-capacity'!$A$2:$A$6,$B11,'Industry-capacity'!$B$2:$B$6),SUMIF(INDIRECT($C11&"!A$2:A$20"),$B11,INDIRECT($C11&"!B$2:B$20"))),"") -> 120 | J11: =IF(COUNTIF($B11,"*HOB*")+COUNTIF($B11,"*charger*")+COUNTIF($B11,"*disch*")+COUNTIF($B11,"GSHP")+COUNTIF($B11,"EBoil"),C11,"") -> HKI | K11: =IF(ISTEXT($B11),IF(COUNTIF($B11,"*Industry*"),SUMIF('Industry-capacity'!$A$2:$A$6,$B11,'Industry-capacity'!$C$2:$C$6),SUMIF(INDIRECT($C11&"!A$2:A$20"),$B11,INDIRECT($C11&"!C$2:C$20"))),"") -> 0 | L11: =IF(K11=0,"",IF(ISTEXT($B11),IF(COUNTIF($B11,"*Industry*"),"industry",$C11),"")) | M11: =IF(ISTEXT($B11),IF($K11>0,$I11/$K11,""),"") | O11: =IF(SUM($G11)>0,($I11+$K11)/$G11,"") | P11: =IF(SUM($G11)>0,($I11+$K11)/$G11,"") | Q11: =ROUND(VLOOKUP($B11, $Z$6:$AA$32,2,FALSE) * (1+$AD$6) * (1 + IF(C11="",1, VLOOKUP($C11,$AC$8:$AD$15,2,FALSE))), 2) -> 2.12 | S11: =IF(I11<10, "remove", "") | V11: =_xlfn.XLOOKUP(C11,$W$6:$W$13,$X$6:$X$13) -> HKI | W11: OUL | X11: ROF | Z11: elecHOB | AA11: =SUMIFS([1]unittypedata!$S:$S, [1]unittypedata!$D:$D, Z11) -> 1.5 | AC11: TRE | AD11: =LOG(AE11/$AN$8) -> -0.030544122 | AE11: =AN13 -> 42970.925 | AH11: MK04 Satakunta | AI11: 37034.6 | AJ11: 39248 | AK11: 42468.8 | AL11: 46184.5 | AN11: =AVERAGE(AI11:AL11) -> 41233.975
A12: FI00 | B12: heatStorageDischLarge | C12: HKI | D12: all | E12: 1 | F12: dh-level:cities | G12: =IF(ISTEXT($B12),IF(COUNTIF($B12,"*Industry*"),SUMIF('Industry-capacity'!$A$2:$A$6,$B12,'Industry-capacity'!$D$2:$D$6),IF(SUMIF(INDIRECT($C12&"!A$2:A$20"),$B12,INDIRECT($C12&"!D$2:D$20"))>0,SUMIF(INDIRECT($C12&"!A$2:A$20"),$B12,INDIRECT($C12&"!D$2:D$20")),"")),"") | H12: =IF(COUNTIF($B12,"*charger*")+COUNTIF($B12,"*disch*"),$C12,"") -> HKI | I12: =IF(ISTEXT($B12),IF(COUNTIF($B12,"*Industry*"),SUMIF('Industry-capacity'!$A$2:$A$6,$B12,'Industry-capacity'!$B$2:$B$6),SUMIF(INDIRECT($C12&"!A$2:A$20"),$B12,INDIRECT($C12&"!B$2:B$20"))),"") -> 120 | J12: =IF(COUNTIF($B12,"*HOB*")+COUNTIF($B12,"*charger*")+COUNTIF($B12,"*disch*")+COUNTIF($B12,"GSHP")+COUNTIF($B12,"EBoil"),C12,"") -> HKI | K12: =IF(ISTEXT($B12),IF(COUNTIF($B12,"*Industry*"),SUMIF('Industry-capacity'!$A$2:$A$6,$B12,'Industry-capacity'!$C$2:$C$6),SUMIF(INDIRECT($C12&"!A$2:A$20"),$B12,INDIRECT($C12&"!C$2:C$20"))),"") -> 0 | L12: =IF(K12=0,"",IF(ISTEXT($B12),IF(COUNTIF($B12,"*Industry*"),"industry",$C12),"")) | M12: =IF(ISTEXT($B12),IF($K12>0,$I12/$K12,""),"") | O12: =IF(SUM($G12)>0,($I12+$K12)/$G12,"") | P12: =IF(SUM($G12)>0,($I12+$K12)/$G12,"") | Q12: =ROUND(VLOOKUP($B12, $Z$6:$AA$32,2,FALSE) * (1+$AD$6) * (1 + IF(C12="",1, VLOOKUP($C12,$AC$8:$AD$15,2,FALSE))), 2) -> 2.12 | S12: =IF(I12<10, "remove", "") | V12: =_xlfn.XLOOKUP(C12,$W$6:$W$13,$X$6:$X$13) -> HKI | W12: JKL | X12: ROF | Z12: HeatStorageCharger | AA12: =SUMIFS([1]unittypedata!$S:$S, [1]unittypedata!$D:$D, Z12) -> 1.4 | AC12: OUL | AD12: =LOG(AE12/$AN$8) -> -0.037945052 | AE12: =AN26 -> 42244.85 | AH12: MK05 Kanta-Häme | AI12: 35522.7 | AJ12: 37967 | AK12: 38825.3 | AL12: 41105.3 | AN12: =AVERAGE(AI12:AL12) -> 38355.075
A13: FI00 | B13: bioHOB | C13: ESP | D13: all | E13: 1 | F13: dh-level:cities | G13: =IF(ISTEXT($B13),IF(COUNTIF($B13,"*Industry*"),SUMIF('Industry-capacity'!$A$2:$A$6,$B13,'Industry-capacity'!$D$2:$D$6),IF(SUMIF(INDIRECT($C13&"!A$2:A$20"),$B13,INDIRECT($C13&"!D$2:D$20"))>0,SUMIF(INDIRECT($C13&"!A$2:A$20"),$B13,INDIRECT($C13&"!D$2:D$20")),"")),"") | H13: =IF(COUNTIF($B13,"*charger*")+COUNTIF($B13,"*disch*"),$C13,"") | I13: =IF(ISTEXT($B13),IF(COUNTIF($B13,"*Industry*"),SUMIF('Industry-capacity'!$A$2:$A$6,$B13,'Industry-capacity'!$B$2:$B$6),SUMIF(INDIRECT($C13&"!A$2:A$20"),$B13,INDIRECT($C13&"!B$2:B$20"))),"") -> 139 | J13: =IF(COUNTIF($B13,"*HOB*")+COUNTIF($B13,"*charger*")+COUNTIF($B13,"*disch*")+COUNTIF($B13,"GSHP")+COUNTIF($B13,"EBoil"),C13,"") -> ESP | K13: =IF(ISTEXT($B13),IF(COUNTIF($B13,"*Industry*"),SUMIF('Industry-capacity'!$A$2:$A$6,$B13,'Industry-capacity'!$C$2:$C$6),SUMIF(INDIRECT($C13&"!A$2:A$20"),$B13,INDIRECT($C13&"!C$2:C$20"))),"") -> 0 | L13: =IF(K13=0,"",IF(ISTEXT($B13),IF(COUNTIF($B13,"*Industry*"),"industry",$C13),"")) | M13: =IF(ISTEXT($B13),IF($K13>0,$I13/$K13,""),"") | O13: =IF(SUM($G13)>0,($I13+$K13)/$G13,"") | P13: =IF(SUM($G13)>0,($I13+$K13)/$G13,"") | Q13: =ROUND(VLOOKUP($B13, $Z$6:$AA$32,2,FALSE) * (1+$AD$6) * (1 + IF(C13="",1, VLOOKUP($C13,$AC$8:$AD$15,2,FALSE))), 2) -> 2.45 | S13: =IF(I13<10, "remove", "") | V13: =_xlfn.XLOOKUP(C13,$W$6:$W$13,$X$6:$X$13) -> HKI | W13: ROF | X13: ROF | Z13: HeatStorageDisch | AA13: =SUMIFS([1]unittypedata!$S:$S, [1]unittypedata!$D:$D, Z13) -> 1.4 | AC13: TKU | AD13: =LOG(AE13/$AN$8) -> -0.031701111 | AE13: =AN15 -> 42856.6 | AH13: MK06 Pirkanmaa | AI13: 40148.2 | AJ13: 41910.2 | AK13: 44119.8 | AL13: 45705.5 | AN13: =AVERAGE(AI13:AL13) -> 42970.925
A14: FI00 | B14: gasHOB | C14: ESP | D14: all | E14: 1 | F14: dh-level:cities | G14: =IF(ISTEXT($B14),IF(COUNTIF($B14,"*Industry*"),SUMIF('Industry-capacity'!$A$2:$A$6,$B14,'Industry-capacity'!$D$2:$D$6),IF(SUMIF(INDIRECT($C14&"!A$2:A$20"),$B14,INDIRECT($C14&"!D$2:D$20"))>0,SUMIF(INDIRECT($C14&"!A$2:A$20"),$B14,INDIRECT($C14&"!D$2:D$20")),"")),"") | H14: =IF(COUNTIF($B14,"*charger*")+COUNTIF($B14,"*disch*"),$C14,"") | I14: =IF(ISTEXT($B14),IF(COUNTIF($B14,"*Industry*"),SUMIF('Industry-capacity'!$A$2:$A$6,$B14,'Industry-capacity'!$B$2:$B$6),SUMIF(INDIRECT($C14&"!A$2:A$20"),$B14,INDIRECT($C14&"!B$2:B$20"))),"") -> 757.4 | J14: =IF(COUNTIF($B14,"*HOB*")+COUNTIF($B14,"*charger*")+COUNTIF($B14,"*disch*")+COUNTIF($B14,"GSHP")+COUNTIF($B14,"EBoil"),C14,"") -> ESP | K14: =IF(ISTEXT($B14),IF(COUNTIF($B14,"*Industry*"),SUMIF('Industry-capacity'!$A$2:$A$6,$B14,'Industry-capacity'!$C$2:$C$6),SUMIF(INDIRECT($C14&"!A$2:A$20"),$B14,INDIRECT($C14&"!C$2:C$20"))),"") -> 0 | L14: =IF(K14=0,"",IF(ISTEXT($B14),IF(COUNTIF($B14,"*Industry*"),"industry",$C14),"")) | M14: =IF(ISTEXT($B14),IF($K14>0,$I14/$K14,""),"") | O14: =IF(SUM($G14)>0,($I14+$K14)/$G14,"") | P14: =IF(SUM($G14)>0,($I14+$K14)/$G14,"") | Q14: =ROUND(VLOOKUP($B14, $Z$6:$AA$32,2,FALSE) * (1+$AD$6) * (1 + IF(C14="",1, VLOOKUP($C14,$AC$8:$AD$15,2,FALSE))), 2) -> 2.45 | S14: =IF(I14<10, "remove", "") | V14: =_xlfn.XLOOKUP(C14,$W$6:$W$13,$X$6:$X$13) -> HKI | Z14: heatStorageChargerLarge | AA14: =SUMIFS([1]unittypedata!$S:$S, [1]unittypedata!$D:$D, Z14) -> 1.7 | AC14: JKL | AD14: =LOG(AE14/$AN$8) -> -0.080313724 | AE14: =AN20 -> 38318.2 | AH14: MK07 Päijät-Häme | AI14: 32745.5 | AJ14: 34467.9 | AK14: 37686.7 | AL14: 37213.3 | AN14: =AVERAGE(AI14:AL14) -> 35528.35
A15: FI00 | B15: oilHOB | C15: ESP | D15: all | E15: 1 | F15: dh-level:cities | G15: =IF(ISTEXT($B15),IF(COUNTIF($B15,"*Industry*"),SUMIF('Industry-capacity'!$A$2:$A$6,$B15,'Industry-capacity'!$D$2:$D$6),IF(SUMIF(INDIRECT($C15&"!A$2:A$20"),$B15,INDIRECT($C15&"!D$2:D$20"))>0,SUMIF(INDIRECT($C15&"!A$2:A$20"),$B15,INDIRECT($C15&"!D$2:D$20")),"")),"") | H15: =IF(COUNTIF($B15,"*charger*")+COUNTIF($B15,"*disch*"),$C15,"") | I15: =IF(ISTEXT($B15),IF(COUNTIF($B15,"*Industry*"),SUMIF('Industry-capacity'!$A$2:$A$6,$B15,'Industry-capacity'!$B$2:$B$6),SUMIF(INDIRECT($C15&"!A$2:A$20"),$B15,INDIRECT($C15&"!B$2:B$20"))),"") -> 88 | J15: =IF(COUNTIF($B15,"*HOB*")+COUNTIF($B15,"*charger*")+COUNTIF($B15,"*disch*")+COUNTIF($B15,"GSHP")+COUNTIF($B15,"EBoil"),C15,"") -> ESP | K15: =IF(ISTEXT($B15),IF(COUNTIF($B15,"*Industry*"),SUMIF('Industry-capacity'!$A$2:$A$6,$B15,'Industry-capacity'!$C$2:$C$6),SUMIF(INDIRECT($C15&"!A$2:A$20"),$B15,INDIRECT($C15&"!C$2:C$20"))),"") -> 0 | L15: =IF(K15=0,"",IF(ISTEXT($B15),IF(COUNTIF($B15,"*Industry*"),"industry",$C15),"")) | M15: =IF(ISTEXT($B15),IF($K15>0,$I15/$K15,""),"") | O15: =IF(SUM($G15)>0,($I15+$K15)/$G15,"") | P15: =IF(SUM($G15)>0,($I15+$K15)/$G15,"") | Q15: =ROUND(VLOOKUP($B15, $Z$6:$AA$32,2,FALSE) * (1+$AD$6) * (1 + IF(C15="",1, VLOOKUP($C15,$AC$8:$AD$15,2,FALSE))), 2) -> 2.45 | S15: =IF(I15<10, "remove", "") | V15: =_xlfn.XLOOKUP(C15,$W$6:$W$13,$X$6:$X$13) -> HKI | Z15: heatStorageDischLarge | AA15: =SUMIFS([1]unittypedata!$S:$S, [1]unittypedata!$D:$D, Z15) -> 1.7 | AC15: ROF | AD15: =LOG(AE15/$AN$8) -> -0.073056428 | AE15: =AVERAGE(AN14:AN25) -> 38963.898 | AH15: MK08 Kymenlaakso | AI15: 41506.5 | AJ15: 42936.9 | AK15: 44142.6 | AL15: 42840.4 | AN15: =AVERAGE(AI15:AL15) -> 42856.6
A16: FI00 | B16: GSHP | C16: ESP | D16: all | E16: 1 | F16: dh-level:cities | G16: =IF(ISTEXT($B16),IF(COUNTIF($B16,"*Industry*"),SUMIF('Industry-capacity'!$A$2:$A$6,$B16,'Industry-capacity'!$D$2:$D$6),IF(SUMIF(INDIRECT($C16&"!A$2:A$20"),$B16,INDIRECT($C16&"!D$2:D$20"))>0,SUMIF(INDIRECT($C16&"!A$2:A$20"),$B16,INDIRECT($C16&"!D$2:D$20")),"")),"") | H16: =IF(COUNTIF($B16,"*charger*")+COUNTIF($B16,"*disch*"),$C16,"") | I16: =IF(ISTEXT($B16),IF(COUNTIF($B16,"*Industry*"),SUMIF('Industry-capacity'!$A$2:$A$6,$B16,'Industry-capacity'!$B$2:$B$6),SUMIF(INDIRECT($C16&"!A$2:A$20"),$B16,INDIRECT($C16&"!B$2:B$20"))),"") -> 295 | J16: =IF(COUNTIF($B16,"*HOB*")+COUNTIF($B16,"*charger*")+COUNTIF($B16,"*disch*")+COUNTIF($B16,"GSHP")+COUNTIF($B16,"EBoil"),C16,"") -> ESP | K16: =IF(ISTEXT($B16),IF(COUNTIF($B16,"*Industry*"),SUMIF('Industry-capacity'!$A$2:$A$6,$B16,'Industry-capacity'!$C$2:$C$6),SUMIF(INDIRECT($C16&"!A$2:A$20"),$B16,INDIRECT($C16&"!C$2:C$20"))),"") -> 0 | L16: =IF(K16=0,"",IF(ISTEXT($B16),IF(COUNTIF($B16,"*Industry*"),"industry",$C16),"")) | M16: =IF(ISTEXT($B16),IF($K16>0,$I16/$K16,""),"") | O16: =IF(SUM($G16)>0,($I16+$K16)/$G16,"") | P16: =IF(SUM($G16)>0,($I16+$K16)/$G16,"") | Q16: =ROUND(VLOOKUP($B16, $Z$6:$AA$32,2,FALSE) * (1+$AD$6) * (1 + IF(C16="",1, VLOOKUP($C16,$AC$8:$AD$15,2,FALSE))), 2) -> 7.35 | S16: =IF(I16<10, "remove", "") | V16: =_xlfn.XLOOKUP(C16,$W$6:$W$13,$X$6:$X$13) -> HKI | Z16: gasOCGTCHP | AA16: =SUMIFS([1]unittypedata!$S:$S, [1]unittypedata!$D:$D, Z16) -> 1.6 | AH16: MK09 Etelä-Karjala | AI16: 37378.9 | AJ16: 41539.3 | AK16: 43680.1 | AL16: 37688.1 | AN16: =AVERAGE(AI16:AL16) -> 40071.6
A17: FI00 | B17: gasCCGTCHP | C17: ESP | D17: all | E17: 1 | F17: dh-level:cities | G17: =IF(ISTEXT($B17),IF(COUNTIF($B17,"*Industry*"),SUMIF('Industry-capacity'!$A$2:$A$6,$B17,'Industry-capacity'!$D$2:$D$6),IF(SUMIF(INDIRECT($C17&"!A$2:A$20"),$B17,INDIRECT($C17&"!D$2:D$20"))>0,SUMIF(INDIRECT($C17&"!A$2:A$20"),$B17,INDIRECT($C17&"!D$2:D$20")),"")),"") -> 498 | H17: =IF(COUNTIF($B17,"*charger*")+COUNTIF($B17,"*disch*"),$C17,"") | I17: =IF(ISTEXT($B17),IF(COUNTIF($B17,"*Industry*"),SUMIF('Industry-capacity'!$A$2:$A$6,$B17,'Industry-capacity'!$B$2:$B$6),SUMIF(INDIRECT($C17&"!A$2:A$20"),$B17,INDIRECT($C17&"!B$2:B$20"))),"") -> 234 | J17: =IF(COUNTIF($B17,"*HOB*")+COUNTIF($B17,"*charger*")+COUNTIF($B17,"*disch*")+COUNTIF($B17,"GSHP")+COUNTIF($B17,"EBoil"),C17,"") | K17: =IF(ISTEXT($B17),IF(COUNTIF($B17,"*Industry*"),SUMIF('Industry-capacity'!$A$2:$A$6,$B17,'Industry-capacity'!$C$2:$C$6),SUMIF(INDIRECT($C17&"!A$2:A$20"),$B17,INDIRECT($C17&"!C$2:C$20"))),"") -> 213 | L17: =IF(K17=0,"",IF(ISTEXT($B17),IF(COUNTIF($B17,"*Industry*"),"industry",$C17),"")) -> ESP | M17: =IF(ISTEXT($B17),IF($K17>0,$I17/$K17,""),"") -> 1.0985915 | O17: =IF(SUM($G17)>0,($I17+$K17)/$G17,"") -> 0.89759036 | P17: =IF(SUM($G17)>0,($I17+$K17)/$G17,"") -> 0.89759036 | Q17: =ROUND(VLOOKUP($B17, $Z$6:$AA$32,2,FALSE) * (1+$AD$6) * (1 + IF(C17="",1, VLOOKUP($C17,$AC$8:$AD$15,2,FALSE))), 2) -> 1.96 | S17: =IF(I17<10, "remove", "") | V17: =_xlfn.XLOOKUP(C17,$W$6:$W$13,$X$6:$X$13) -> HKI | Z17: wasteHOB | AA17: =SUMIFS([1]unittypedata!$S:$S, [1]unittypedata!$D:$D, Z17) -> 2 | AH17: MK10 Etelä-Savo | AI17: 33034.8 | AJ17: 34167.4 | AK17: 37851 | AL17: 38404.2 | AN17: =AVERAGE(AI17:AL17) -> 35864.35
A18: FI00 | B18: gasOCGTCHP | C18: ESP | D18: all | E18: 1 | F18: dh-level:cities | G18: =IF(ISTEXT($B18),IF(COUNTIF($B18,"*Industry*"),SUMIF('Industry-capacity'!$A$2:$A$6,$B18,'Industry-capacity'!$D$2:$D$6),IF(SUMIF(INDIRECT($C18&"!A$2:A$20"),$B18,INDIRECT($C18&"!D$2:D$20"))>0,SUMIF(INDIRECT($C18&"!A$2:A$20"),$B18,INDIRECT($C18&"!D$2:D$20")),"")),"") -> 132 | H18: =IF(COUNTIF($B18,"*charger*")+COUNTIF($B18,"*disch*"),$C18,"") | I18: =IF(ISTEXT($B18),IF(COUNTIF($B18,"*Industry*"),SUMIF('Industry-capacity'!$A$2:$A$6,$B18,'Industry-capacity'!$B$2:$B$6),SUMIF(INDIRECT($C18&"!A$2:A$20"),$B18,INDIRECT($C18&"!B$2:B$20"))),"") -> 49 | J18: =IF(COUNTIF($B18,"*HOB*")+COUNTIF($B18,"*charger*")+COUNTIF($B18,"*disch*")+COUNTIF($B18,"GSHP")+COUNTIF($B18,"EBoil"),C18,"") | K18: =IF(ISTEXT($B18),IF(COUNTIF($B18,"*Industry*"),SUMIF('Industry-capacity'!$A$2:$A$6,$B18,'Industry-capacity'!$C$2:$C$6),SUMIF(INDIRECT($C18&"!A$2:A$20"),$B18,INDIRECT($C18&"!C$2:C$20"))),"") -> 80 | L18: =IF(K18=0,"",IF(ISTEXT($B18),IF(COUNTIF($B18,"*Industry*"),"industry",$C18),"")) -> ESP | M18: =IF(ISTEXT($B18),IF($K18>0,$I18/$K18,""),"") -> 0.6125 | O18: =IF(SUM($G18)>0,($I18+$K18)/$G18,"") -> 0.97727273 | P18: =IF(SUM($G18)>0,($I18+$K18)/$G18,"") -> 0.97727273 | Q18: =ROUND(VLOOKUP($B18, $Z$6:$AA$32,2,FALSE) * (1+$AD$6) * (1 + IF(C18="",1, VLOOKUP($C18,$AC$8:$AD$15,2,FALSE))), 2) -> 1.96 | S18: =IF(I18<10, "remove", "") | V18: =_xlfn.XLOOKUP(C18,$W$6:$W$13,$X$6:$X$13) -> HKI | Z18: bioCHP | AA18: =SUMIFS([1]unittypedata!$S:$S, [1]unittypedata!$D:$D, Z18) -> 2 | AH18: MK11 Pohjois-Savo | AI18: 35762.4 | AJ18: 37853.5 | AK18: 42190.9 | AL18: 41361.4 | AN18: =AVERAGE(AI18:AL18) -> 39292.05
A19: FI00 | B19: elecHOB | C19: ESP | D19: all | E19: 1 | F19: dh-level:cities | G19: =IF(ISTEXT($B19),IF(COUNTIF($B19,"*Industry*"),SUMIF('Industry-capacity'!$A$2:$A$6,$B19,'Industry-capacity'!$D$2:$D$6),IF(SUMIF(INDIRECT($C19&"!A$2:A$20"),$B19,INDIRECT($C19&"!D$2:D$20"))>0,SUMIF(INDIRECT($C19&"!A$2:A$20"),$B19,INDIRECT($C19&"!D$2:D$20")),"")),"") | H19: =IF(COUNTIF($B19,"*charger*")+COUNTIF($B19,"*disch*"),$C19,"") | I19: =IF(ISTEXT($B19),IF(COUNTIF($B19,"*Industry*"),SUMIF('Industry-capacity'!$A$2:$A$6,$B19,'Industry-capacity'!$B$2:$B$6),SUMIF(INDIRECT($C19&"!A$2:A$20"),$B19,INDIRECT($C19&"!B$2:B$20"))),"") -> 150 | J19: =IF(COUNTIF($B19,"*HOB*")+COUNTIF($B19,"*charger*")+COUNTIF($B19,"*disch*")+COUNTIF($B19,"GSHP")+COUNTIF($B19,"EBoil"),C19,"") -> ESP | K19: =IF(ISTEXT($B19),IF(COUNTIF($B19,"*Industry*"),SUMIF('Industry-capacity'!$A$2:$A$6,$B19,'Industry-capacity'!$C$2:$C$6),SUMIF(INDIRECT($C19&"!A$2:A$20"),$B19,INDIRECT($C19&"!C$2:C$20"))),"") -> 0 | L19: =IF(K19=0,"",IF(ISTEXT($B19),IF(COUNTIF($B19,"*Industry*"),"industry",$C19),"")) | M19: =IF(ISTEXT($B19),IF($K19>0,$I19/$K19,""),"") | O19: =IF(SUM($G19)>0,($I19+$K19)/$G19,"") | P19: =IF(SUM($G19)>0,($I19+$K19)/$G19,"") | Q19: =ROUND(VLOOKUP($B19, $Z$6:$AA$32,2,FALSE) * (1+$AD$6) * (1 + IF(C19="",1, VLOOKUP($C19,$AC$8:$AD$15,2,FALSE))), 2) -> 1.84 | S19: =IF(I19<10, "remove", "") | V19: =_xlfn.XLOOKUP(C19,$W$6:$W$13,$X$6:$X$13) -> HKI | Z19: wasteCHP | AA19: =SUMIFS([1]unittypedata!$S:$S, [1]unittypedata!$D:$D, Z19) -> 2 | AH19: MK12 Pohjois-Karjala | AI19: 32441.6 | AJ19: 35017 | AK19: 37992.4 | AL19: 37688 | AN19: =AVERAGE(AI19:AL19) -> 35784.75
A20: FI00 | B20: HeatStorageCharger | C20: ESP | D20: all | E20: 1 | F20: dh-level:cities | G20: =IF(ISTEXT($B20),IF(COUNTIF($B20,"*Industry*"),SUMIF('Industry-capacity'!$A$2:$A$6,$B20,'Industry-capacity'!$D$2:$D$6),IF(SUMIF(INDIRECT($C20&"!A$2:A$20"),$B20,INDIRECT($C20&"!D$2:D$20"))>0,SUMIF(INDIRECT($C20&"!A$2:A$20"),$B20,INDIRECT($C20&"!D$2:D$20")),"")),"") | H20: =IF(COUNTIF($B20,"*charger*")+COUNTIF($B20,"*disch*"),$C20,"") -> ESP | I20: =IF(ISTEXT($B20),IF(COUNTIF($B20,"*Industry*"),SUMIF('Industry-capacity'!$A$2:$A$6,$B20,'Industry-capacity'!$B$2:$B$6),SUMIF(INDIRECT($C20&"!A$2:A$20"),$B20,INDIRECT($C20&"!B$2:B$20"))),"") -> 280 | J20: =IF(COUNTIF($B20,"*HOB*")+COUNTIF($B20,"*charger*")+COUNTIF($B20,"*disch*")+COUNTIF($B20,"GSHP")+COUNTIF($B20,"EBoil"),C20,"") -> ESP | K20: =IF(ISTEXT($B20),IF(COUNTIF($B20,"*Industry*"),SUMIF('Industry-capacity'!$A$2:$A$6,$B20,'Industry-capacity'!$C$2:$C$6),SUMIF(INDIRECT($C20&"!A$2:A$20"),$B20,INDIRECT($C20&"!C$2:C$20"))),"") -> 0 | L20: =IF(K20=0,"",IF(ISTEXT($B20),IF(COUNTIF($B20,"*Industry*"),"industry",$C20),"")) | M20: =IF(ISTEXT($B20),IF($K20>0,$I20/$K20,""),"") | O20: =IF(SUM($G20)>0,($I20+$K20)/$G20,"") | P20: =IF(SUM($G20)>0,($I20+$K20)/$G20,"") | Q20: =ROUND(VLOOKUP($B20, $Z$6:$AA$32,2,FALSE) * (1+$AD$6) * (1 + IF(C20="",1, VLOOKUP($C20,$AC$8:$AD$15,2,FALSE))), 2) -> 1.72 | S20: =IF(I20<10, "remove", "") | V20: =_xlfn.XLOOKUP(C20,$W$6:$W$13,$X$6:$X$13) -> HKI | Z20: heatStorageChargerSeasonal | AA20: =SUMIFS([1]unittypedata!$S:$S, [1]unittypedata!$D:$D, Z20) -> 2 | AH20: MK13 Keski-Suomi | AI20: 35079.4 | AJ20: 37388.2 | AK20: 40637.5 | AL20: 40167.7 | AN20: =AVERAGE(AI20:AL20) -> 38318.2
A21: FI00 | B21: HeatStorageDisch | C21: ESP | D21: all | E21: 1 | F21: dh-level:cities | G21: =IF(ISTEXT($B21),IF(COUNTIF($B21,"*Industry*"),SUMIF('Industry-capacity'!$A$2:$A$6,$B21,'Industry-capacity'!$D$2:$D$6),IF(SUMIF(INDIRECT($C21&"!A$2:A$20"),$B21,INDIRECT($C21&"!D$2:D$20"))>0,SUMIF(INDIRECT($C21&"!A$2:A$20"),$B21,INDIRECT($C21&"!D$2:D$20")),"")),"") | H21: =IF(COUNTIF($B21,"*charger*")+COUNTIF($B21,"*disch*"),$C21,"") -> ESP | I21: =IF(ISTEXT($B21),IF(COUNTIF($B21,"*Industry*"),SUMIF('Industry-capacity'!$A$2:$A$6,$B21,'Industry-capacity'!$B$2:$B$6),SUMIF(INDIRECT($C21&"!A$2:A$20"),$B21,INDIRECT($C21&"!B$2:B$20"))),"") -> 280 | J21: =IF(COUNTIF($B21,"*HOB*")+COUNTIF($B21,"*charger*")+COUNTIF($B21,"*disch*")+COUNTIF($B21,"GSHP")+COUNTIF($B21,"EBoil"),C21,"") -> ESP | K21: =IF(ISTEXT($B21),IF(COUNTIF($B21,"*Industry*"),SUMIF('Industry-capacity'!$A$2:$A$6,$B21,'Industry-capacity'!$C$2:$C$6),SUMIF(INDIRECT($C21&"!A$2:A$20"),$B21,INDIRECT($C21&"!C$2:C$20"))),"") -> 0 | L21: =IF(K21=0,"",IF(ISTEXT($B21),IF(COUNTIF($B21,"*Industry*"),"industry",$C21),"")) | M21: =IF(ISTEXT($B21),IF($K21>0,$I21/$K21,""),"") | O21: =IF(SUM($G21)>0,($I21+$K21)/$G21,"") | P21: =IF(SUM($G21)>0,($I21+$K21)/$G21,"") | Q21: =ROUND(VLOOKUP($B21, $Z$6:$AA$32,2,FALSE) * (1+$AD$6) * (1 + IF(C21="",1, VLOOKUP($C21,$AC$8:$AD$15,2,FALSE))), 2) -> 1.72 | S21: =IF(I21<10, "remove", "") | V21: =_xlfn.XLOOKUP(C21,$W$6:$W$13,$X$6:$X$13) -> HKI | Z21: heatStorageDischSeasonal | AA21: =SUMIFS([1]unittypedata!$S:$S, [1]unittypedata!$D:$D, Z21) -> 2 | AH21: MK14 Etelä-Pohjanmaa | AI21: 34185.9 | AJ21: 36042.7 | AK21: 38398.4 | AL21: 39673.1 | AN21: =AVERAGE(AI21:AL21) -> 37075.025
A22: FI00 | B22: gasHOB | C22: VAN | D22: all | E22: 1 | F22: dh-level:cities | G22: =IF(ISTEXT($B22),IF(COUNTIF($B22,"*Industry*"),SUMIF('Industry-capacity'!$A$2:$A$6,$B22,'Industry-capacity'!$D$2:$D$6),IF(SUMIF(INDIRECT($C22&"!A$2:A$20"),$B22,INDIRECT($C22&"!D$2:D$20"))>0,SUMIF(INDIRECT($C22&"!A$2:A$20"),$B22,INDIRECT($C22&"!D$2:D$20")),"")),"") | H22: =IF(COUNTIF($B22,"*charger*")+COUNTIF($B22,"*disch*"),$C22,"") | I22: =IF(ISTEXT($B22),IF(COUNTIF($B22,"*Industry*"),SUMIF('Industry-capacity'!$A$2:$A$6,$B22,'Industry-capacity'!$B$2:$B$6),SUMIF(INDIRECT($C22&"!A$2:A$20"),$B22,INDIRECT($C22&"!B$2:B$20"))),"") -> 427 | J22: =IF(COUNTIF($B22,"*HOB*")+COUNTIF($B22,"*charger*")+COUNTIF($B22,"*disch*")+COUNTIF($B22,"GSHP")+COUNTIF($B22,"EBoil"),C22,"") -> VAN | K22: =IF(ISTEXT($B22),IF(COUNTIF($B22,"*Industry*"),SUMIF('Industry-capacity'!$A$2:$A$6,$B22,'Industry-capacity'!$C$2:$C$6),SUMIF(INDIRECT($C22&"!A$2:A$20"),$B22,INDIRECT($C22&"!C$2:C$20"))),"") -> 0 | L22: =IF(K22=0,"",IF(ISTEXT($B22),IF(COUNTIF($B22,"*Industry*"),"industry",$C22),"")) | M22: =IF(ISTEXT($B22),IF($K22>0,$I22/$K22,""),"") | O22: =IF(SUM($G22)>0,($I22+$K22)/$G22,"") | P22: =IF(SUM($G22)>0,($I22+$K22)/$G22,"") | Q22: =ROUND(VLOOKUP($B22, $Z$6:$AA$32,2,FALSE) * (1+$AD$6) * (1 + IF(C22="",1, VLOOKUP($C22,$AC$8:$AD$15,2,FALSE))), 2) -> 2.4 | S22: =IF(I22<10, "remove", "") | V22: =_xlfn.XLOOKUP(C22,$W$6:$W$13,$X$6:$X$13) -> HKI | Z22: bioCHPIndustry | AA22: =SUMIFS([1]unittypedata!$S:$S, [1]unittypedata!$D:$D, Z22) -> 2 | AH22: MK15 Pohjanmaa | AI22: 40232.3 | AJ22: 44224.1 | AK22: 46377.6 | AL22: 49187.3 | AN22: =AVERAGE(AI22:AL22) -> 45005.325
A23: FI00 | B23: oilHOB | C23: VAN | D23: all | E23: 1 | F23: dh-level:cities | G23: =IF(ISTEXT($B23),IF(COUNTIF($B23,"*Industry*"),SUMIF('Industry-capacity'!$A$2:$A$6,$B23,'Industry-capacity'!$D$2:$D$6),IF(SUMIF(INDIRECT($C23&"!A$2:A$20"),$B23,INDIRECT($C23&"!D$2:D$20"))>0,SUMIF(INDIRECT($C23&"!A$2:A$20"),$B23,INDIRECT($C23&"!D$2:D$20")),"")),"") | H23: =IF(COUNTIF($B23,"*charger*")+COUNTIF($B23,"*disch*"),$C23,"") | I23: =IF(ISTEXT($B23),IF(COUNTIF($B23,"*Industry*"),SUMIF('Industry-capacity'!$A$2:$A$6,$B23,'Industry-capacity'!$B$2:$B$6),SUMIF(INDIRECT($C23&"!A$2:A$20"),$B23,INDIRECT($C23&"!B$2:B$20"))),"") -> 92 | J23: =IF(COUNTIF($B23,"*HOB*")+COUNTIF($B23,"*charger*")+COUNTIF($B23,"*disch*")+COUNTIF($B23,"GSHP")+COUNTIF($B23,"EBoil"),C23,"") -> VAN | K23: =IF(ISTEXT($B23),IF(COUNTIF($B23,"*Industry*"),SUMIF('Industry-capacity'!$A$2:$A$6,$B23,'Industry-capacity'!$C$2:$C$6),SUMIF(INDIRECT($C23&"!A$2:A$20"),$B23,INDIRECT($C23&"!C$2:C$20"))),"") -> 0 | L23: =IF(K23=0,"",IF(ISTEXT($B23),IF(COUNTIF($B23,"*Industry*"),"industry",$C23),"")) | M23: =IF(ISTEXT($B23),IF($K23>0,$I23/$K23,""),"") | O23: =IF(SUM($G23)>0,($I23+$K23)/$G23,"") | P23: =IF(SUM($G23)>0,($I23+$K23)/$G23,"") | Q23: =ROUND(VLOOKUP($B23, $Z$6:$AA$32,2,FALSE) * (1+$AD$6) * (1 + IF(C23="",1, VLOOKUP($C23,$AC$8:$AD$15,2,FALSE))), 2) -> 2.4 | S23: =IF(I23<10, "remove", "") | V23: =_xlfn.XLOOKUP(C23,$W$6:$W$13,$X$6:$X$13) -> HKI | Z23: coalCHPIndustry | AA23: =SUMIFS([1]unittypedata!$S:$S, [1]unittypedata!$D:$D, Z23) -> 2 | AH23: MK16 Keski-Pohjanmaa | AI23: 38099.4 | AJ23: 38338 | AK23: 40380.7 | AL23: 45675.7 | AN23: =AVERAGE(AI23:AL23) -> 40623.45
A24: FI00 | B24: wasteHOB | C24: VAN | D24: all | E24: 1 | F24: dh-level:cities | G24: =IF(ISTEXT($B24),IF(COUNTIF($B24,"*Industry*"),SUMIF('Industry-capacity'!$A$2:$A$6,$B24,'Industry-capacity'!$D$2:$D$6),IF(SUMIF(INDIRECT($C24&"!A$2:A$20"),$B24,INDIRECT($C24&"!D$2:D$20"))>0,SUMIF(INDIRECT($C24&"!A$2:A$20"),$B24,INDIRECT($C24&"!D$2:D$20")),"")),"") | H24: =IF(COUNTIF($B24,"*charger*")+COUNTIF($B24,"*disch*"),$C24,"") | I24: =IF(ISTEXT($B24),IF(COUNTIF($B24,"*Industry*"),SUMIF('Industry-capacity'!$A$2:$A$6,$B24,'Industry-capacity'!$B$2:$B$6),SUMIF(INDIRECT($C24&"!A$2:A$20"),$B24,INDIRECT($C24&"!B$2:B$20"))),"") -> 80 | J24: =IF(COUNTIF($B24,"*HOB*")+COUNTIF($B24,"*charger*")+COUNTIF($B24,"*disch*")+COUNTIF($B24,"GSHP")+COUNTIF($B24,"EBoil"),C24,"") -> VAN | K24: =IF(ISTEXT($B24),IF(COUNTIF($B24,"*Industry*"),SUMIF('Industry-capacity'!$A$2:$A$6,$B24,'Industry-capacity'!$C$2:$C$6),SUMIF(INDIRECT($C24&"!A$2:A$20"),$B24,INDIRECT($C24&"!C$2:C$20"))),"") -> 0 | L24: =IF(K24=0,"",IF(ISTEXT($B24),IF(COUNTIF($B24,"*Industry*"),"industry",$C24),"")) | M24: =IF(ISTEXT($B24),IF($K24>0,$I24/$K24,""),"") | O24: =IF(SUM($G24)>0,($I24+$K24)/$G24,"") | P24: =IF(SUM($G24)>0,($I24+$K24)/$G24,"") | Q24: =ROUND(VLOOKUP($B24, $Z$6:$AA$32,2,FALSE) * (1+$AD$6) * (1 + IF(C24="",1, VLOOKUP($C24,$AC$8:$AD$15,2,FALSE))), 2) -> 2.4 | S24: =IF(I24<10, "remove", "") | V24: =_xlfn.XLOOKUP(C24,$W$6:$W$13,$X$6:$X$13) -> HKI | Z24: gasCHPIndustry | AA24: =SUMIFS([1]unittypedata!$S:$S, [1]unittypedata!$D:$D, Z24) -> 2 | AH24: MK17 Pohjois-Pohjanmaa | AI24: 36433.7 | AJ24: 39159.1 | AK24: 41654.2 | AL24: 42483.9 | AN24: =AVERAGE(AI24:AL24) -> 39932.725
A25: FI00 | B25: gasCCGTCHP | C25: VAN | D25: all | E25: 1 | F25: dh-level:cities | G25: =IF(ISTEXT($B25),IF(COUNTIF($B25,"*Industry*"),SUMIF('Industry-capacity'!$A$2:$A$6,$B25,'Industry-capacity'!$D$2:$D$6),IF(SUMIF(INDIRECT($C25&"!A$2:A$20"),$B25,INDIRECT($C25&"!D$2:D$20"))>0,SUMIF(INDIRECT($C25&"!A$2:A$20"),$B25,INDIRECT($C25&"!D$2:D$20")),"")),"") -> 220 | H25: =IF(COUNTIF($B25,"*charger*")+COUNTIF($B25,"*disch*"),$C25,"") | I25: =IF(ISTEXT($B25),IF(COUNTIF($B25,"*Industry*"),SUMIF('Industry-capacity'!$A$2:$A$6,$B25,'Industry-capacity'!$B$2:$B$6),SUMIF(INDIRECT($C25&"!A$2:A$20"),$B25,INDIRECT($C25&"!B$2:B$20"))),"") -> 88 | J25: =IF(COUNTIF($B25,"*HOB*")+COUNTIF($B25,"*charger*")+COUNTIF($B25,"*disch*")+COUNTIF($B25,"GSHP")+COUNTIF($B25,"EBoil"),C25,"") | K25: =IF(ISTEXT($B25),IF(COUNTIF($B25,"*Industry*"),SUMIF('Industry-capacity'!$A$2:$A$6,$B25,'Industry-capacity'!$C$2:$C$6),SUMIF(INDIRECT($C25&"!A$2:A$20"),$B25,INDIRECT($C25&"!C$2:C$20"))),"") -> 90 | L25: =IF(K25=0,"",IF(ISTEXT($B25),IF(COUNTIF($B25,"*Industry*"),"industry",$C25),"")) -> VAN | M25: =IF(ISTEXT($B25),IF($K25>0,$I25/$K25,""),"") -> 0.97777778 | O25: =IF(SUM($G25)>0,($I25+$K25)/$G25,"") -> 0.80909091 | P25: =IF(SUM($G25)>0,($I25+$K25)/$G25,"") -> 0.80909091 | Q25: =ROUND(VLOOKUP($B25, $Z$6:$AA$32,2,FALSE) * (1+$AD$6) * (1 + IF(C25="",1, VLOOKUP($C25,$AC$8:$AD$15,2,FALSE))), 2) -> 1.92 | S25: =IF(I25<10, "remove", "") | V25: =_xlfn.XLOOKUP(C25,$W$6:$W$13,$X$6:$X$13) -> HKI | Z25: gasCCGTOld2 | AA25: =SUMIFS([1]unittypedata!$S:$S, [1]unittypedata!$D:$D, Z25) -> 2.6 | AH25: MK18 Kainuu | AI25: 33797.5 | AJ25: 35109.9 | AK25: 42144.7 | AL25: 37805.3 | AN25: =AVERAGE(AI25:AL25) -> 37214.35
A26: FI00 | B26: bioCHP | C26: VAN | D26: all | E26: 1 | F26: dh-level:cities | G26: =IF(ISTEXT($B26),IF(COUNTIF($B26,"*Industry*"),SUMIF('Industry-capacity'!$A$2:$A$6,$B26,'Industry-capacity'!$D$2:$D$6),IF(SUMIF(INDIRECT($C26&"!A$2:A$20"),$B26,INDIRECT($C26&"!D$2:D$20"))>0,SUMIF(INDIRECT($C26&"!A$2:A$20"),$B26,INDIRECT($C26&"!D$2:D$20")),"")),"") -> 120 | H26: =IF(COUNTIF($B26,"*charger*")+COUNTIF($B26,"*disch*"),$C26,"") | I26: =IF(ISTEXT($B26),IF(COUNTIF($B26,"*Industry*"),SUMIF('Industry-capacity'!$A$2:$A$6,$B26,'Industry-capacity'!$B$2:$B$6),SUMIF(INDIRECT($C26&"!A$2:A$20"),$B26,INDIRECT($C26&"!B$2:B$20"))),"") -> 28 | J26: =IF(COUNTIF($B26,"*HOB*")+COUNTIF($B26,"*charger*")+COUNTIF($B26,"*disch*")+COUNTIF($B26,"GSHP")+COUNTIF($B26,"EBoil"),C26,"") | K26: =IF(ISTEXT($B26),IF(COUNTIF($B26,"*Industry*"),SUMIF('Industry-capacity'!$A$2:$A$6,$B26,'Industry-capacity'!$C$2:$C$6),SUMIF(INDIRECT($C26&"!A$2:A$20"),$B26,INDIRECT($C26&"!C$2:C$20"))),"") -> 105 | L26: =IF(K26=0,"",IF(ISTEXT($B26),IF(COUNTIF($B26,"*Industry*"),"industry",$C26),"")) -> VAN | M26: =IF(ISTEXT($B26),IF($K26>0,$I26/$K26,""),"") -> 0.26666667 | O26: =IF(SUM($G26)>0,($I26+$K26)/$G26,"") -> 1.1083333 | P26: =IF(SUM($G26)>0,($I26+$K26)/$G26,"") -> 1.1083333 | Q26: =ROUND(VLOOKUP($B26, $Z$6:$AA$32,2,FALSE) * (1+$AD$6) * (1 + IF(C26="",1, VLOOKUP($C26,$AC$8:$AD$15,2,FALSE))), 2) -> 2.4 | S26: =IF(I26<10, "remove", "") | V26: =_xlfn.XLOOKUP(C26,$W$6:$W$13,$X$6:$X$13) -> HKI | Z26: gasCCGTpresent1 | AA26: =SUMIFS([1]unittypedata!$S:$S, [1]unittypedata!$D:$D, Z26) -> 2.6 | AH26: MK19 Lappi | AI26: 38277.2 | AJ26: 39167.2 | AK26: 46665.3 | AL26: 44869.7 | AN26: =AVERAGE(AI26:AL26) -> 42244.85
A27: FI00 | B27: wasteCHP | C27: VAN | D27: all | E27: 1 | F27: dh-level:cities | G27: =IF(ISTEXT($B27),IF(COUNTIF($B27,"*Industry*"),SUMIF('Industry-capacity'!$A$2:$A$6,$B27,'Industry-capacity'!$D$2:$D$6),IF(SUMIF(INDIRECT($C27&"!A$2:A$20"),$B27,INDIRECT($C27&"!D$2:D$20"))>0,SUMIF(INDIRECT($C27&"!A$2:A$20"),$B27,INDIRECT($C27&"!D$2:D$20")),"")),"") -> 202 | H27: =IF(COUNTIF($B27,"*charger*")+COUNTIF($B27,"*disch*"),$C27,"") | I27: =IF(ISTEXT($B27),IF(COUNTIF($B27,"*Industry*"),SUMIF('Industry-capacity'!$A$2:$A$6,$B27,'Industry-capacity'!$B$2:$B$6),SUMIF(INDIRECT($C27&"!A$2:A$20"),$B27,INDIRECT($C27&"!B$2:B$20"))),"") -> 76.4 | J27: =IF(COUNTIF($B27,"*HOB*")+COUNTIF($B27,"*charger*")+COUNTIF($B27,"*disch*")+COUNTIF($B27,"GSHP")+COUNTIF($B27,"EBoil"),C27,"") | K27: =IF(ISTEXT($B27),IF(COUNTIF($B27,"*Industry*"),SUMIF('Industry-capacity'!$A$2:$A$6,$B27,'Industry-capacity'!$C$2:$C$6),SUMIF(INDIRECT($C27&"!A$2:A$20"),$B27,INDIRECT($C27&"!C$2:C$20"))),"") -> 147 | L27: =IF(K27=0,"",IF(ISTEXT($B27),IF(COUNTIF($B27,"*Industry*"),"industry",$C27),"")) -> VAN | M27: =IF(ISTEXT($B27),IF($K27>0,$I27/$K27,""),"") -> 0.51972789 | O27: =IF(SUM($G27)>0,($I27+$K27)/$G27,"") -> 1.1059406 | P27: =IF(SUM($G27)>0,($I27+$K27)/$G27,"") -> 1.1059406 | Q27: =ROUND(VLOOKUP($B27, $Z$6:$AA$32,2,FALSE) * (1+$AD$6) * (1 + IF(C27="",1, VLOOKUP($C27,$AC$8:$AD$15,2,FALSE))), 2) -> 2.4 | S27: =IF(I27<10, "remove", "") | V27: =_xlfn.XLOOKUP(C27,$W$6:$W$13,$X$6:$X$13) -> HKI | Z27: gasOCGTnew | AA27: =SUMIFS([1]unittypedata!$S:$S, [1]unittypedata!$D:$D, Z27) -> 2.6 | AH27: MK21 Ahvenanmaa | AI27: 39532.8 | AJ27: 44250.6 | AK27: 48917.6 | AL27: 53681.8 | AN27: =AVERAGE(AI27:AL27) -> 46595.7
A28: FI00 | B28: elecHOB | C28: VAN | D28: all | E28: 1 | F28: dh-level:cities | G28: =IF(ISTEXT($B28),IF(COUNTIF($B28,"*Industry*"),SUMIF('Industry-capacity'!$A$2:$A$6,$B28,'Industry-capacity'!$D$2:$D$6),IF(SUMIF(INDIRECT($C28&"!A$2:A$20"),$B28,INDIRECT($C28&"!D$2:D$20"))>0,SUMIF(INDIRECT($C28&"!A$2:A$20"),$B28,INDIRECT($C28&"!D$2:D$20")),"")),"") | H28: =IF(COUNTIF($B28,"*charger*")+COUNTIF($B28,"*disch*"),$C28,"") | I28: =IF(ISTEXT($B28),IF(COUNTIF($B28,"*Industry*"),SUMIF('Industry-capacity'!$A$2:$A$6,$B28,'Industry-capacity'!$B$2:$B$6),SUMIF(INDIRECT($C28&"!A$2:A$20"),$B28,INDIRECT($C28&"!B$2:B$20"))),"") -> 180 | J28: =IF(COUNTIF($B28,"*HOB*")+COUNTIF($B28,"*charger*")+COUNTIF($B28,"*disch*")+COUNTIF($B28,"GSHP")+COUNTIF($B28,"EBoil"),C28,"") -> VAN | K28: =IF(ISTEXT($B28),IF(COUNTIF($B28,"*Industry*"),SUMIF('Industry-capacity'!$A$2:$A$6,$B28,'Industry-capacity'!$C$2:$C$6),SUMIF(INDIRECT($C28&"!A$2:A$20"),$B28,INDIRECT($C28&"!C$2:C$20"))),"") -> 0 | L28: =IF(K28=0,"",IF(ISTEXT($B28),IF(COUNTIF($B28,"*Industry*"),"industry",$C28),"")) | M28: =IF(ISTEXT($B28),IF($K28>0,$I28/$K28,""),"") | O28: =IF(SUM($G28)>0,($I28+$K28)/$G28,"") | P28: =IF(SUM($G28)>0,($I28+$K28)/$G28,"") | Q28: =ROUND(VLOOKUP($B28, $Z$6:$AA$32,2,FALSE) * (1+$AD$6) * (1 + IF(C28="",1, VLOOKUP($C28,$AC$8:$AD$15,2,FALSE))), 2) -> 1.8 | S28: =IF(I28<10, "remove", "") | V28: =_xlfn.XLOOKUP(C28,$W$6:$W$13,$X$6:$X$13) -> HKI | Z28: gasOCGTold | AA28: =SUMIFS([1]unittypedata!$S:$S, [1]unittypedata!$D:$D, Z28) -> 2.6
A29: FI00 | B29: GSHP | C29: VAN | D29: all | E29: 1 | F29: dh-level:cities | G29: =IF(ISTEXT($B29),IF(COUNTIF($B29,"*Industry*"),SUMIF('Industry-capacity'!$A$2:$A$6,$B29,'Industry-capacity'!$D$2:$D$6),IF(SUMIF(INDIRECT($C29&"!A$2:A$20"),$B29,INDIRECT($C29&"!D$2:D$20"))>0,SUMIF(INDIRECT($C29&"!A$2:A$20"),$B29,INDIRECT($C29&"!D$2:D$20")),"")),"") | H29: =IF(COUNTIF($B29,"*charger*")+COUNTIF($B29,"*disch*"),$C29,"") | I29: =IF(ISTEXT($B29),IF(COUNTIF($B29,"*Industry*"),SUMIF('Industry-capacity'!$A$2:$A$6,$B29,'Industry-capacity'!$B$2:$B$6),SUMIF(INDIRECT($C29&"!A$2:A$20"),$B29,INDIRECT($C29&"!B$2:B$20"))),"") -> 35 | J29: =IF(COUNTIF($B29,"*HOB*")+COUNTIF($B29,"*charger*")+COUNTIF($B29,"*disch*")+COUNTIF($B29,"GSHP")+COUNTIF($B29,"EBoil"),C29,"") -> VAN | K29: =IF(ISTEXT($B29),IF(COUNTIF($B29,"*Industry*"),SUMIF('Industry-capacity'!$A$2:$A$6,$B29,'Industry-capacity'!$C$2:$C$6),SUMIF(INDIRECT($C29&"!A$2:A$20"),$B29,INDIRECT($C29&"!C$2:C$20"))),"") -> 0 | L29: =IF(K29=0,"",IF(ISTEXT($B29),IF(COUNTIF($B29,"*Industry*"),"industry",$C29),"")) | M29: =IF(ISTEXT($B29),IF($K29>0,$I29/$K29,""),"") | O29: =IF(SUM($G29)>0,($I29+$K29)/$G29,"") | P29: =IF(SUM($G29)>0,($I29+$K29)/$G29,"") | Q29: =ROUND(VLOOKUP($B29, $Z$6:$AA$32,2,FALSE) * (1+$AD$6) * (1 + IF(C29="",1, VLOOKUP($C29,$AC$8:$AD$15,2,FALSE))), 2) -> 7.21 | S29: =IF(I29<10, "remove", "") | V29: =_xlfn.XLOOKUP(C29,$W$6:$W$13,$X$6:$X$13) -> HKI | Z29: coalOld1 | AA29: =SUMIFS([1]unittypedata!$S:$S, [1]unittypedata!$D:$D, Z29) -> 3.3
A30: FI00 | B30: bioHOB | C30: VAN | D30: all | E30: 1 | F30: dh-level:cities | G30: =IF(ISTEXT($B30),IF(COUNTIF($B30,"*Industry*"),SUMIF('Industry-capacity'!$A$2:$A$6,$B30,'Industry-capacity'!$D$2:$D$6),IF(SUMIF(INDIRECT($C30&"!A$2:A$20"),$B30,INDIRECT($C30&"!D$2:D$20"))>0,SUMIF(INDIRECT($C30&"!A$2:A$20"),$B30,INDIRECT($C30&"!D$2:D$20")),"")),"") | H30: =IF(COUNTIF($B30,"*charger*")+COUNTIF($B30,"*disch*"),$C30,"") | I30: =IF(ISTEXT($B30),IF(COUNTIF($B30,"*Industry*"),SUMIF('Industry-capacity'!$A$2:$A$6,$B30,'Industry-capacity'!$B$2:$B$6),SUMIF(INDIRECT($C30&"!A$2:A$20"),$B30,INDIRECT($C30&"!B$2:B$20"))),"") -> 23 | J30: =IF(COUNTIF($B30,"*HOB*")+COUNTIF($B30,"*charger*")+COUNTIF($B30,"*disch*")+COUNTIF($B30,"GSHP")+COUNTIF($B30,"EBoil"),C30,"") -> VAN | K30: =IF(ISTEXT($B30),IF(COUNTIF($B30,"*Industry*"),SUMIF('Industry-capacity'!$A$2:$A$6,$B30,'Industry-capacity'!$C$2:$C$6),SUMIF(INDIRECT($C30&"!A$2:A$20"),$B30,INDIRECT($C30&"!C$2:C$20"))),"") -> 0 | L30: =IF(K30=0,"",IF(ISTEXT($B30),IF(COUNTIF($B30,"*Industry*"),"industry",$C30),"")) | M30: =IF(ISTEXT($B30),IF($K30>0,$I30/$K30,""),"") | O30: =IF(SUM($G30)>0,($I30+$K30)/$G30,"") | P30: =IF(SUM($G30)>0,($I30+$K30)/$G30,"") | Q30: =ROUND(VLOOKUP($B30, $Z$6:$AA$32,2,FALSE) * (1+$AD$6) * (1 + IF(C30="",1, VLOOKUP($C30,$AC$8:$AD$15,2,FALSE))), 2) -> 2.4 | S30: =IF(I30<10, "remove", "") | V30: =_xlfn.XLOOKUP(C30,$W$6:$W$13,$X$6:$X$13) -> HKI | Z30: bioCoalNew | AA30: =SUMIFS([1]unittypedata!$S:$S, [1]unittypedata!$D:$D, Z30) -> 3.3
A31: FI00 | B31: HeatStorageCharger | C31: VAN | D31: all | E31: 1 | F31: dh-level:cities | G31: =IF(ISTEXT($B31),IF(COUNTIF($B31,"*Industry*"),SUMIF('Industry-capacity'!$A$2:$A$6,$B31,'Industry-capacity'!$D$2:$D$6),IF(SUMIF(INDIRECT($C31&"!A$2:A$20"),$B31,INDIRECT($C31&"!D$2:D$20"))>0,SUMIF(INDIRECT($C31&"!A$2:A$20"),$B31,INDIRECT($C31&"!D$2:D$20")),"")),"") | H31: =IF(COUNTIF($B31,"*charger*")+COUNTIF($B31,"*disch*"),$C31,"") -> VAN | I31: =IF(ISTEXT($B31),IF(COUNTIF($B31,"*Industry*"),SUMIF('Industry-capacity'!$A$2:$A$6,$B31,'Industry-capacity'!$B$2:$B$6),SUMIF(INDIRECT($C31&"!A$2:A$20"),$B31,INDIRECT($C31&"!B$2:B$20"))),"") -> 180 | J31: =IF(COUNTIF($B31,"*HOB*")+COUNTIF($B31,"*charger*")+COUNTIF($B31,"*disch*")+COUNTIF($B31,"GSHP")+COUNTIF($B31,"EBoil"),C31,"") -> VAN | K31: =IF(ISTEXT($B31),IF(COUNTIF($B31,"*Industry*"),SUMIF('Industry-capacity'!$A$2:$A$6,$B31,'Industry-capacity'!$C$2:$C$6),SUMIF(INDIRECT($C31&"!A$2:A$20"),$B31,INDIRECT($C31&"!C$2:C$20"))),"") -> 0 | L31: =IF(K31=0,"",IF(ISTEXT($B31),IF(COUNTIF($B31,"*Industry*"),"industry",$C31),"")) | M31: =IF(ISTEXT($B31),IF($K31>0,$I31/$K31,""),"") | O31: =IF(SUM($G31)>0,($I31+$K31)/$G31,"") | P31: =IF(SUM($G31)>0,($I31+$K31)/$G31,"") | Q31: =ROUND(VLOOKUP($B31, $Z$6:$AA$32,2,FALSE) * (1+$AD$6) * (1 + IF(C31="",1, VLOOKUP($C31,$AC$8:$AD$15,2,FALSE))), 2) -> 1.68 | S31: =IF(I31<10, "remove", "") | V31: =_xlfn.XLOOKUP(C31,$W$6:$W$13,$X$6:$X$13) -> HKI | Z31: bioCoalOld | AA31: =SUMIFS([1]unittypedata!$S:$S, [1]unittypedata!$D:$D, Z31) -> 3.3
A32: FI00 | B32: HeatStorageDisch | C32: VAN | D32: all | E32: 1 | F32: dh-level:cities | G32: =IF(ISTEXT($B32),IF(COUNTIF($B32,"*Industry*"),SUMIF('Industry-capacity'!$A$2:$A$6,$B32,'Industry-capacity'!$D$2:$D$6),IF(SUMIF(INDIRECT($C32&"!A$2:A$20"),$B32,INDIRECT($C32&"!D$2:D$20"))>0,SUMIF(INDIRECT($C32&"!A$2:A$20"),$B32,INDIRECT($C32&"!D$2:D$20")),"")),"") | H32: =IF(COUNTIF($B32,"*charger*")+COUNTIF($B32,"*disch*"),$C32,"") -> VAN | I32: =IF(ISTEXT($B32),IF(COUNTIF($B32,"*Industry*"),SUMIF('Industry-capacity'!$A$2:$A$6,$B32,'Industry-capacity'!$B$2:$B$6),SUMIF(INDIRECT($C32&"!A$2:A$20"),$B32,INDIRECT($C32&"!B$2:B$20"))),"") -> 180 | J32: =IF(COUNTIF($B32,"*HOB*")+COUNTIF($B32,"*charger*")+COUNTIF($B32,"*disch*")+COUNTIF($B32,"GSHP")+COUNTIF($B32,"EBoil"),C32,"") -> VAN | K32: =IF(ISTEXT($B32),IF(COUNTIF($B32,"*Industry*"),SUMIF('Industry-capacity'!$A$2:$A$6,$B32,'Industry-capacity'!$C$2:$C$6),SUMIF(INDIRECT($C32&"!A$2:A$20"),$B32,INDIRECT($C32&"!C$2:C$20"))),"") -> 0 | L32: =IF(K32=0,"",IF(ISTEXT($B32),IF(COUNTIF($B32,"*Industry*"),"industry",$C32),"")) | M32: =IF(ISTEXT($B32),IF($K32>0,$I32/$K32,""),"") | O32: =IF(SUM($G32)>0,($I32+$K32)/$G32,"") | P32: =IF(SUM($G32)>0,($I32+$K32)/$G32,"") | Q32: =ROUND(VLOOKUP($B32, $Z$6:$AA$32,2,FALSE) * (1+$AD$6) * (1 + IF(C32="",1, VLOOKUP($C32,$AC$8:$AD$15,2,FALSE))), 2) -> 1.68 | S32: =IF(I32<10, "remove", "") | V32: =_xlfn.XLOOKUP(C32,$W$6:$W$13,$X$6:$X$13) -> HKI | Z32: bioCoalOld2 | AA32: =SUMIFS([1]unittypedata!$S:$S, [1]unittypedata!$D:$D, Z32) -> 3.3
A33: FI00 | B33: heatStorageChargerSeasonal | C33: VAN | D33: all | E33: 1 | F33: dh-level:cities | G33: =IF(ISTEXT($B33),IF(COUNTIF($B33,"*Industry*"),SUMIF('Industry-capacity'!$A$2:$A$6,$B33,'Industry-capacity'!$D$2:$D$6),IF(SUMIF(INDIRECT($C33&"!A$2:A$20"),$B33,INDIRECT($C33&"!D$2:D$20"))>0,SUMIF(INDIRECT($C33&"!A$2:A$20"),$B33,INDIRECT($C33&"!D$2:D$20")),"")),"") | H33: =IF(COUNTIF($B33,"*charger*")+COUNTIF($B33,"*disch*"),$C33,"") -> VAN | I33: =IF(ISTEXT($B33),IF(COUNTIF($B33,"*Industry*"),SUMIF('Industry-capacity'!$A$2:$A$6,$B33,'Industry-capacity'!$B$2:$B$6),SUMIF(INDIRECT($C33&"!A$2:A$20"),$B33,INDIRECT($C33&"!B$2:B$20"))),"") -> 200 | J33: =IF(COUNTIF($B33,"*HOB*")+COUNTIF($B33,"*charger*")+COUNTIF($B33,"*disch*")+COUNTIF($B33,"GSHP")+COUNTIF($B33,"EBoil"),C33,"") -> VAN | K33: =IF(ISTEXT($B33),IF(COUNTIF($B33,"*Industry*"),SUMIF('Industry-capacity'!$A$2:$A$6,$B33,'Industry-capacity'!$C$2:$C$6),SUMIF(INDIRECT($C33&"!A$2:A$20"),$B33,INDIRECT($C33&"!C$2:C$20"))),"") -> 0 | L33: =IF(K33=0,"",IF(ISTEXT($B33),IF(COUNTIF($B33,"*Industry*"),"industry",$C33),"")) | M33: =IF(ISTEXT($B33),IF($K33>0,$I33/$K33,""),"") | O33: =IF(SUM($G33)>0,($I33+$K33)/$G33,"") | P33: =IF(SUM($G33)>0,($I33+$K33)/$G33,"") | Q33: =ROUND(VLOOKUP($B33, $Z$6:$AA$32,2,FALSE) * (1+$AD$6) * (1 + IF(C33="",1, VLOOKUP($C33,$AC$8:$AD$15,2,FALSE))), 2) -> 2.4 | S33: =IF(I33<10, "remove", "") | V33: =_xlfn.XLOOKUP(C33,$W$6:$W$13,$X$6:$X$13) -> HKI
A34: FI00 | B34: heatStorageDischSeasonal | C34: VAN | D34: all | E34: 1 | F34: dh-level:cities | G34: =IF(ISTEXT($B34),IF(COUNTIF($B34,"*Industry*"),SUMIF('Industry-capacity'!$A$2:$A$6,$B34,'Industry-capacity'!$D$2:$D$6),IF(SUMIF(INDIRECT($C34&"!A$2:A$20"),$B34,INDIRECT($C34&"!D$2:D$20"))>0,SUMIF(INDIRECT($C34&"!A$2:A$20"),$B34,INDIRECT($C34&"!D$2:D$20")),"")),"") | H34: =IF(COUNTIF($B34,"*charger*")+COUNTIF($B34,"*disch*"),$C34,"") -> VAN | I34: =IF(ISTEXT($B34),IF(COUNTIF($B34,"*Industry*"),SUMIF('Industry-capacity'!$A$2:$A$6,$B34,'Industry-capacity'!$B$2:$B$6),SUMIF(INDIRECT($C34&"!A$2:A$20"),$B34,INDIRECT($C34&"!B$2:B$20"))),"") -> 200 | J34: =IF(COUNTIF($B34,"*HOB*")+COUNTIF($B34,"*charger*")+COUNTIF($B34,"*disch*")+COUNTIF($B34,"GSHP")+COUNTIF($B34,"EBoil"),C34,"") -> VAN | K34: =IF(ISTEXT($B34),IF(COUNTIF($B34,"*Industry*"),SUMIF('Industry-capacity'!$A$2:$A$6,$B34,'Industry-capacity'!$C$2:$C$6),SUMIF(INDIRECT($C34&"!A$2:A$20"),$B34,INDIRECT($C34&"!C$2:C$20"))),"") -> 0 | L34: =IF(K34=0,"",IF(ISTEXT($B34),IF(COUNTIF($B34,"*Industry*"),"industry",$C34),"")) | M34: =IF(ISTEXT($B34),IF($K34>0,$I34/$K34,""),"") | O34: =IF(SUM($G34)>0,($I34+$K34)/$G34,"") | P34: =IF(SUM($G34)>0,($I34+$K34)/$G34,"") | Q34: =ROUND(VLOOKUP($B34, $Z$6:$AA$32,2,FALSE) * (1+$AD$6) * (1 + IF(C34="",1, VLOOKUP($C34,$AC$8:$AD$15,2,FALSE))), 2) -> 2.4 | S34: =IF(I34<10, "remove", "") | V34: =_xlfn.XLOOKUP(C34,$W$6:$W$13,$X$6:$X$13) -> HKI
A35: FI00 | B35: gasHOB | C35: TRE | D35: all | E35: 1 | F35: dh-level:cities | G35: =IF(ISTEXT($B35),IF(COUNTIF($B35,"*Industry*"),SUMIF('Industry-capacity'!$A$2:$A$6,$B35,'Industry-capacity'!$D$2:$D$6),IF(SUMIF(INDIRECT($C35&"!A$2:A$20"),$B35,INDIRECT($C35&"!D$2:D$20"))>0,SUMIF(INDIRECT($C35&"!A$2:A$20"),$B35,INDIRECT($C35&"!D$2:D$20")),"")),"") | H35: =IF(COUNTIF($B35,"*charger*")+COUNTIF($B35,"*disch*"),$C35,"") | I35: =IF(ISTEXT($B35),IF(COUNTIF($B35,"*Industry*"),SUMIF('Industry-capacity'!$A$2:$A$6,$B35,'Industry-capacity'!$B$2:$B$6),SUMIF(INDIRECT($C35&"!A$2:A$20"),$B35,INDIRECT($C35&"!B$2:B$20"))),"") -> 235 | J35: =IF(COUNTIF($B35,"*HOB*")+COUNTIF($B35,"*charger*")+COUNTIF($B35,"*disch*")+COUNTIF($B35,"GSHP")+COUNTIF($B35,"EBoil"),C35,"") -> TRE | K35: =IF(ISTEXT($B35),IF(COUNTIF($B35,"*Industry*"),SUMIF('Industry-capacity'!$A$2:$A$6,$B35,'Industry-capacity'!$C$2:$C$6),SUMIF(INDIRECT($C35&"!A$2:A$20"),$B35,INDIRECT($C35&"!C$2:C$20"))),"") -> 0 | L35: =IF(K35=0,"",IF(ISTEXT($B35),IF(COUNTIF($B35,"*Industry*"),"industry",$C35),"")) | M35: =IF(ISTEXT($B35),IF($K35>0,$I35/$K35,""),"") | O35: =IF(SUM($G35)>0,($I35+$K35)/$G35,"") | P35: =IF(SUM($G35)>0,($I35+$K35)/$G35,"") | Q35: =ROUND(VLOOKUP($B35, $Z$6:$AA$32,2,FALSE) * (1+$AD$6) * (1 + IF(C35="",1, VLOOKUP($C35,$AC$8:$AD$15,2,FALSE))), 2) -> 2.15 | S35: =IF(I35<10, "remove", "") | V35: =_xlfn.XLOOKUP(C35,$W$6:$W$13,$X$6:$X$13) -> ROF
A36: FI00 | B36: oilHOB | C36: TRE | D36: all | E36: 1 | F36: dh-level:cities | G36: =IF(ISTEXT($B36),IF(COUNTIF($B36,"*Industry*"),SUMIF('Industry-capacity'!$A$2:$A$6,$B36,'Industry-capacity'!$D$2:$D$6),IF(SUMIF(INDIRECT($C36&"!A$2:A$20"),$B36,INDIRECT($C36&"!D$2:D$20"))>0,SUMIF(INDIRECT($C36&"!A$2:A$20"),$B36,INDIRECT($C36&"!D$2:D$20")),"")),"") | H36: =IF(COUNTIF($B36,"*charger*")+COUNTIF($B36,"*disch*"),$C36,"") | I36: =IF(ISTEXT($B36),IF(COUNTIF($B36,"*Industry*"),SUMIF('Industry-capacity'!$A$2:$A$6,$B36,'Industry-capacity'!$B$2:$B$6),SUMIF(INDIRECT($C36&"!A$2:A$20"),$B36,INDIRECT($C36&"!B$2:B$20"))),"") -> 305 | J36: =IF(COUNTIF($B36,"*HOB*")+COUNTIF($B36,"*charger*")+COUNTIF($B36,"*disch*")+COUNTIF($B36,"GSHP")+COUNTIF($B36,"EBoil"),C36,"") -> TRE | K36: =IF(ISTEXT($B36),IF(COUNTIF($B36,"*Industry*"),SUMIF('Industry-capacity'!$A$2:$A$6,$B36,'Industry-capacity'!$C$2:$C$6),SUMIF(INDIRECT($C36&"!A$2:A$20"),$B36,INDIRECT($C36&"!C$2:C$20"))),"") -> 0 | L36: =IF(K36=0,"",IF(ISTEXT($B36),IF(COUNTIF($B36,"*Industry*"),"industry",$C36),"")) | M36: =IF(ISTEXT($B36),IF($K36>0,$I36/$K36,""),"") | O36: =IF(SUM($G36)>0,($I36+$K36)/$G36,"") | P36: =IF(SUM($G36)>0,($I36+$K36)/$G36,"") | Q36: =ROUND(VLOOKUP($B36, $Z$6:$AA$32,2,FALSE) * (1+$AD$6) * (1 + IF(C36="",1, VLOOKUP($C36,$AC$8:$AD$15,2,FALSE))), 2) -> 2.15 | S36: =IF(I36<10, "remove", "") | V36: =_xlfn.XLOOKUP(C36,$W$6:$W$13,$X$6:$X$13) -> ROF
