Workbook

Sheet unitdata
A1: Country | B1: unittype | C1: Scenario | D1: Year | E1: capacity_input1 | F1: capacity_output1 | G1: capacity_output2 | H1: node_suffix_output2 | I1: Note | J1: method
A2: AT00 | B2: coalCHPIndustry | C2: all | D2: 1 | E2: =F2/0.4 -> 1901.5 | F2: =ROUND(SUMIFS(Summary!$W:$W,Summary!$I:$I, $A2), 1) -> 760.6 | G2: =ROUND(F2/(0.5+0.16666), 1) -> 1140.9 | H2: industry | J2: =IF(SUM(E2:G2)=0, "remove", "")
A3: BE00 | B3: coalCHPIndustry | C3: all | D3: 1 | E3: =F3/0.4 -> 10712.75 | F3: =ROUND(SUMIFS(Summary!$W:$W,Summary!$I:$I, $A3), 1) -> 4285.1 | G3: =ROUND(F3/(0.5+0.16666), 1) -> 6427.7 | H3: industry | J3: =IF(SUM(E3:G3)=0, "remove", "")
A4: CH00 | B4: coalCHPIndustry | C4: all | D4: 1 | E4: =F4/0.4 -> 1064.75 | F4: =ROUND(SUMIFS(Summary!$W:$W,Summary!$I:$I, $A4), 1) -> 425.9 | G4: =ROUND(F4/(0.5+0.16666), 1) -> 638.9 | H4: industry | J4: =IF(SUM(E4:G4)=0, "remove", "")
A5: DE00 | B5: coalCHPIndustry | C5: all | D5: 1 | E5: =F5/0.4 -> 32669 | F5: =ROUND(SUMIFS(Summary!$W:$W,Summary!$I:$I, $A5), 1) -> 13067.6 | G5: =ROUND(F5/(0.5+0.16666), 1) -> 19601.6 | H5: industry | J5: =IF(SUM(E5:G5)=0, "remove", "")
A6: DKE1 | B6: coalCHPIndustry | C6: all | D6: 1 | E6: =F6/0.4 -> 0 | F6: =ROUND(SUMIFS(Summary!$W:$W,Summary!$I:$I, $A6), 1) -> 0 | G6: =ROUND(F6/(0.5+0.16666), 1) -> 0 | H6: industry | J6: =IF(SUM(E6:G6)=0, "remove", "") -> remove
A7: DKW1 | B7: coalCHPIndustry | C7: all | D7: 1 | E7: =F7/0.4 -> 0 | F7: =ROUND(SUMIFS(Summary!$W:$W,Summary!$I:$I, $A7), 1) -> 0 | G7: =ROUND(F7/(0.5+0.16666), 1) -> 0 | H7: industry | J7: =IF(SUM(E7:G7)=0, "remove", "") -> remove
A8: EE00 | B8: coalCHPIndustry | C8: all | D8: 1 | E8: =F8/0.4 -> 663.25 | F8: =ROUND(SUMIFS(Summary!$W:$W,Summary!$I:$I, $A8), 1) -> 265.3 | G8: =ROUND(F8/(0.5+0.16666), 1) -> 398 | H8: industry | J8: =IF(SUM(E8:G8)=0, "remove", "")
A9: ES00 | B9: coalCHPIndustry | C9: all | D9: 1 | E9: =F9/0.4 -> 4325 | F9: =ROUND(SUMIFS(Summary!$W:$W,Summary!$I:$I, $A9), 1) -> 1730 | G9: =ROUND(F9/(0.5+0.16666), 1) -> 2595 | H9: industry | J9: =IF(SUM(E9:G9)=0, "remove", "")
A10: FI00 | B10: coalCHPIndustry | C10: all | D10: 1 | E10: =F10/0.4 -> 6562 | F10: =ROUND(SUMIFS(Summary!$W:$W,Summary!$I:$I, $A10), 1) -> 2624.8 | G10: =ROUND(F10/(0.5+0.16666), 1) -> 3937.2 | H10: industry | J10: =IF(SUM(E10:G10)=0, "remove", "")
A11: FR00 | B11: coalCHPIndustry | C11: all | D11: 1 | E11: =F11/0.4 -> 6065 | F11: =ROUND(SUMIFS(Summary!$W:$W,Summary!$I:$I, $A11), 1) -> 2426 | G11: =ROUND(F11/(0.5+0.16666), 1) -> 3639 | H11: industry | J11: =IF(SUM(E11:G11)=0, "remove", "")
A12: LT00 | B12: coalCHPIndustry | C12: all | D12: 1 | E12: =F12/0.4 -> 622 | F12: =ROUND(SUMIFS(Summary!$W:$W,Summary!$I:$I, $A12), 1) -> 248.8 | G12: =ROUND(F12/(0.5+0.16666), 1) -> 373.2 | H12: industry | J12: =IF(SUM(E12:G12)=0, "remove", "")
A13: LV00 | B13: coalCHPIndustry | C13: all | D13: 1 | E13: =F13/0.4 -> 198.75 | F13: =ROUND(SUMIFS(Summary!$W:$W,Summary!$I:$I, $A13), 1) -> 79.5 | G13: =ROUND(F13/(0.5+0.16666), 1) -> 119.3 | H13: industry | J13: =IF(SUM(E13:G13)=0, "remove", "")
... A23: UK00 | B23: coalCHPIndustry | C23: all | D23: 1 | E23: =F23/0.4 -> 116676.75 | F23: =ROUND(SUMIFS(Summary!$W:$W,Summary!$I:$I, $A23), 1) -> 46670.7 | G23: =ROUND(F23/(0.5+0.16666), 1) -> 70006.8 | H23: industry | J23: =IF(SUM(E23:G23)=0, "remove", "")
A24: AT00 | B24: bioCHPIndustry | C24: all | D24: 1 | E24: =F24/0.4 -> 2113 | F24: =ROUND(SUMIFS(Summary!$V:$V,Summary!$I:$I, $A24), 1) -> 845.2 | G24: =ROUND(F24/(0.5+0.16666), 1) -> 1267.8 | H24: industry | J24: =IF(SUM(E24:G24)=0, "remove", "")
A25: BE00 | B25: bioCHPIndustry | C25: all | D25: 1 | E25: =F25/0.4 -> 4133.25 | F25: =ROUND(SUMIFS(Summary!$V:$V,Summary!$I:$I, $A25), 1) -> 1653.3 | G25: =ROUND(F25/(0.5+0.16666), 1) -> 2480 | H25: industry | J25: =IF(SUM(E25:G25)=0, "remove", "")
A26: CH00 | B26: bioCHPIndustry | C26: all | D26: 1 | E26: =F26/0.4 -> 1416.5 | F26: =ROUND(SUMIFS(Summary!$V:$V,Summary!$I:$I, $A26), 1) -> 566.6 | G26: =ROUND(F26/(0.5+0.16666), 1) -> 849.9 | H26: industry | J26: =IF(SUM(E26:G26)=0, "remove", "")
A27: DE00 | B27: bioCHPIndustry | C27: all | D27: 1 | E27: =F27/0.4 -> 18200 | F27: =ROUND(SUMIFS(Summary!$V:$V,Summary!$I:$I, $A27), 1) -> 7280 | G27: =ROUND(F27/(0.5+0.16666), 1) -> 10920.1 | H27: industry | J27: =IF(SUM(E27:G27)=0, "remove", "")
A28: DKE1 | B28: bioCHPIndustry | C28: all | D28: 1 | E28: =F28/0.4 -> 0 | F28: =ROUND(SUMIFS(Summary!$V:$V,Summary!$I:$I, $A28), 1) -> 0 | G28: =ROUND(F28/(0.5+0.16666), 1) -> 0 | H28: industry | J28: =IF(SUM(E28:G28)=0, "remove", "") -> remove
A29: DKW1 | B29: bioCHPIndustry | C29: all | D29: 1 | E29: =F29/0.4 -> 0 | F29: =ROUND(SUMIFS(Summary!$V:$V,Summary!$I:$I, $A29), 1) -> 0 | G29: =ROUND(F29/(0.5+0.16666), 1) -> 0 | H29: industry | J29: =IF(SUM(E29:G29)=0, "remove", "") -> remove
A30: EE00 | B30: bioCHPIndustry | C30: all | D30: 1 | E30: =F30/0.4 -> 733.25 | F30: =ROUND(SUMIFS(Summary!$V:$V,Summary!$I:$I, $A30), 1) -> 293.3 | G30: =ROUND(F30/(0.5+0.16666), 1) -> 440 | H30: industry | J30: =IF(SUM(E30:G30)=0, "remove", "")
A31: ES00 | B31: bioCHPIndustry | C31: all | D31: 1 | E31: =F31/0.4 -> 9950 | F31: =ROUND(SUMIFS(Summary!$V:$V,Summary!$I:$I, $A31), 1) -> 3980 | G31: =ROUND(F31/(0.5+0.16666), 1) -> 5970.1 | H31: industry | J31: =IF(SUM(E31:G31)=0, "remove", "")
A32: FI00 | B32: bioCHPIndustry | C32: all | D32: 1 | E32: =F32/0.4 -> 976.25 | F32: =ROUND(SUMIFS(Summary!$V:$V,Summary!$I:$I, $A32), 1) -> 390.5 | G32: =ROUND(F32/(0.5+0.16666), 1) -> 585.8 | H32: industry | J32: =IF(SUM(E32:G32)=0, "remove", "")
A33: FR00 | B33: bioCHPIndustry | C33: all | D33: 1 | E33: =F33/0.4 -> 11000 | F33: =ROUND(SUMIFS(Summary!$V:$V,Summary!$I:$I, $A33), 1) -> 4400 | G33: =ROUND(F33/(0.5+0.16666), 1) -> 6600.1 | H33: industry | J33: =IF(SUM(E33:G33)=0, "remove", "")
A34: LT00 | B34: bioCHPIndustry | C34: all | D34: 1 | E34: =F34/0.4 -> 839.25 | F34: =ROUND(SUMIFS(Summary!$V:$V,Summary!$I:$I, $A34), 1) -> 335.7 | G34: =ROUND(F34/(0.5+0.16666), 1) -> 503.6 | H34: industry | J34: =IF(SUM(E34:G34)=0, "remove", "")
A35: LV00 | B35: bioCHPIndustry | C35: all | D35: 1 | E35: =F35/0.4 -> 534.25 | F35: =ROUND(SUMIFS(Summary!$V:$V,Summary!$I:$I, $A35), 1) -> 213.7 | G35: =ROUND(F35/(0.5+0.16666), 1) -> 320.6 | H35: industry | J35: =IF(SUM(E35:G35)=0, "remove", "")
... A45: UK00 | B45: bioCHPIndustry | C45: all | D45: 1 | E45: =F45/0.4 -> 20518 | F45: =ROUND(SUMIFS(Summary!$V:$V,Summary!$I:$I, $A45), 1) -> 8207.2 | G45: =ROUND(F45/(0.5+0.16666), 1) -> 12310.9 | H45: industry | J45: =IF(SUM(E45:G45)=0, "remove", "")

Sheet demanddata
A1: Country | B1: Grid | C1: Node_suffix | D1: Scenario | E1: Year | F1: TWh/year | G1: Constant_share
A2: AT00 | B2: steam | C2: industry | D2: all | E2: 1 | F2: =SUMIFS(Summary!$L:$L,Summary!$I:$I,demanddata!A2) -> 18.899486
A3: BE00 | B3: steam | C3: industry | D3: all | E3: 1 | F3: =SUMIFS(Summary!$L:$L,Summary!$I:$I,demanddata!A3) -> 27.839204
A4: CH00 | B4: steam | C4: industry | D4: all | E4: 1 | F4: =SUMIFS(Summary!$L:$L,Summary!$I:$I,demanddata!A4) -> 3.2188081
A5: DE00 | B5: steam | C5: industry | D5: all | E5: 1 | F5: =SUMIFS(Summary!$L:$L,Summary!$I:$I,demanddata!A5) -> 68.400874
A6: DKE1 | B6: steam | C6: industry | D6: all | E6: 1 | F6: =SUMIFS(Summary!$L:$L,Summary!$I:$I,demanddata!A6) -> 0
A7: DKW1 | B7: steam | C7: industry | D7: all | E7: 1 | F7: =SUMIFS(Summary!$L:$L,Summary!$I:$I,demanddata!A7) -> 0
A8: EE00 | B8: steam | C8: industry | D8: all | E8: 1 | F8: =SUMIFS(Summary!$L:$L,Summary!$I:$I,demanddata!A8) -> 0.85807818
A9: ES00 | B9: steam | C9: industry | D9: all | E9: 1 | F9: =SUMIFS(Summary!$L:$L,Summary!$I:$I,demanddata!A9) -> 49.067177
A10: FI00 | B10: steam | C10: industry | D10: all | E10: 1 | F10: =SUMIFS(Summary!$L:$L,Summary!$I:$I,demanddata!A10) -> 15.239274
A11: FR00 | B11: steam | C11: industry | D11: all | E11: 1 | F11: =SUMIFS(Summary!$L:$L,Summary!$I:$I,demanddata!A11) -> 34.606931
A12: LT00 | B12: steam | C12: industry | D12: all | E12: 1 | F12: =SUMIFS(Summary!$L:$L,Summary!$I:$I,demanddata!A12) -> 2.3796773
A13: LV00 | B13: steam | C13: industry | D13: all | E13: 1 | F13: =SUMIFS(Summary!$L:$L,Summary!$I:$I,demanddata!A13) -> 1.2953918
... A23: UK00 | B23: steam | C23: industry | D23: all | E23: 1 | F23: =SUMIFS(Summary!$L:$L,Summary!$I:$I,demanddata!A23) -> 147.36626

Sheet nodedata
A1: Country | B1: Grid | C1: Node_suffix | D1: Scenario | E1: Year | F1: nodeBalance | G1: upwardLimit | H1: reference | I1: balancePenalty | J1: selfDischargeLoss | K1: maxSpill
A2: AT00 | B2: steam | C2: industry | D2: all | E2: 1 | F2: 1 | I2: 4000
A3: BE00 | B3: steam | C3: industry | D3: all | E3: 1 | F3: 1 | I3: 4000
A4: CH00 | B4: steam | C4: industry | D4: all | E4: 1 | F4: 1 | I4: 4000
A5: DE00 | B5: steam | C5: industry | D5: all | E5: 1 | F5: 1 | I5: 4000
A6: DKE1 | B6: steam | C6: industry | D6: all | E6: 1 | F6: 1 | I6: 4000
A7: DKW1 | B7: steam | C7: industry | D7: all | E7: 1 | F7: 1 | I7: 4000
A8: EE00 | B8: steam | C8: industry | D8: all | E8: 1 | F8: 1 | I8: 4000
A9: ES00 | B9: steam | C9: industry | D9: all | E9: 1 | F9: 1 | I9: 4000
A10: FI00 | B10: steam | C10: industry | D10: all | E10: 1 | F10: 1 | I10: 4000
A11: FR00 | B11: steam | C11: industry | D11: all | E11: 1 | F11: 1 | I11: 4000
A12: LT00 | B12: steam | C12: industry | D12: all | E12: 1 | F12: 1 | I12: 4000
A13: LV00 | B13: steam | C13: industry | D13: all | E13: 1 | F13: 1 | I13: 4000
... A23: UK00 | B23: steam | C23: industry | D23: all | E23: 1 | F23: 1 | I23: 4000

Sheet Summary
P2: Hard-coded names | Q2: Hard-coded names | S2: Hard-coded names | T2: Hard-coded names | V2: Hard-coded names | W2: Hard-coded names | Y2: Hard-coded names | Z2: Hard-coded names
C3: H2 Heavy | D3: Eurostat 2030 | F3: summary | J3: H2 Heavy | K3: Eurostat 2030 | L3: summary | N3: H2 Heavy | R3: TYNDP2024, NT2030 | U3: summary
C4: H2 Heavy | D4: H2 Heavy | F4: summary | J4: demand (TWh) | K4: demand (TWh) | L4: demand (TWh) | N4: Capacity (MW) | O4: Capacity (MW) | P4: coalCHPIndustry | Q4: bioCHPIndustry | R4: Capacity (MW) | S4: coalCHPIndustry | T4: bioCHPIndustry | U4: Capacity (MW) | V4: coalCHPIndustry | W4: bioCHPIndustry | X4: Capacity (MW) | Y4: coalCHPIndustry | Z4: bioCHPIndustry
C5: cf | D5: cf | F5: cf | J5: Steam | K5: Steam | L5: Steam | N5: Elec | O5: Steam | P5: Elec | Q5: Elec | R5: Elec | S5: Elec | T5: Elec | U5: Elec | V5: Elec | W5: Elec | X5: Steam | Y5: Steam | Z5: Steam
B6: AT00 | C6: =J6*10^6/$O6 / 8760 -> #DIV/0! | D6: =K6*10^6/$O6 / 8760 -> #DIV/0! | F6: =IFERROR(L6*10^6/$X6 / 8760, "-") -> 0.89564488 | I6: AT00 | J6: =SUMIFS('H2Heavy, demands'!$F$2:$F$15,'H2Heavy, demands'!$A$2:$A$15,Summary!$I6) -> 0 | K6: =SUMIFS(Eurostat!$P:$P,Eurostat!$M:$M,Summary!$I6) / 10^3 * 1.5 -> 18.899486 | L6: =K6 -> 18.899486 | N6: =SUMIFS('H2Heavy, capacities'!$E:$E,'H2Heavy, capacities'!$A:$A,Summary!$I6) -> 0 | O6: =SUMIFS('H2Heavy, capacities'!$H:$H,'H2Heavy, capacities'!$A:$A,Summary!$I6) -> 0 | P6: =SUMIFS('H2Heavy, capacities'!$E:$E,'H2Heavy, capacities'!$A:$A,Summary!$I6, 'H2Heavy, capacities'!$B:$B, P$4) -> 0 | Q6: =SUMIFS('H2Heavy, capacities'!$E:$E,'H2Heavy, capacities'!$A:$A,Summary!$I6, 'H2Heavy, capacities'!$B:$B, Q$4) -> 0 | R6: =SUMIFS(TYNDP2024!$C:$C,TYNDP2024!$A:$A,Summary!$I6) -> 1605.885 | S6: =SUMIFS(TYNDP2024!$C:$C,TYNDP2024!$A:$A,Summary!$I6, TYNDP2024!$B:$B,S$4) -> 845.24 | T6: =SUMIFS(TYNDP2024!$C:$C,TYNDP2024!$A:$A,Summary!$I6, TYNDP2024!$B:$B,T$4) -> 760.645 | U6: =R6 -> 1605.885 | V6: =S6 -> 845.24 | W6: =T6 -> 760.645 | X6: =IF(ISNUMBER(U6), U6/(0.5+0.16666), "-") -> 2408.8516 | Y6: =IF(ISNUMBER(V6), V6/(0.5+0.16666), "-") -> 1267.8727 | Z6: =IF(ISNUMBER(W6), W6/(0.5+0.16666), "-") -> 1140.9789
B7: BE00 | C7: =J7*10^6/$O7 / 8760 -> 0.30345104 | D7: =K7*10^6/$O7 / 8760 -> 0.89194095 | F7: =IFERROR(L7*10^6/$X7 / 8760, "-") -> 0.35677281 | I7: BE00 | J7: =SUMIFS('H2Heavy, demands'!$F$2:$F$15,'H2Heavy, demands'!$A$2:$A$15,Summary!$I7) -> 9.4712948 | K7: =SUMIFS(Eurostat!$P:$P,Eurostat!$M:$M,Summary!$I7) / 10^3 * 1.5 -> 27.839204 | L7: =K7 -> 27.839204 | N7: =SUMIFS('H2Heavy, capacities'!$E:$E,'H2Heavy, capacities'!$A:$A,Summary!$I7) -> 5938.3441 | O7: =SUMIFS('H2Heavy, capacities'!$H:$H,'H2Heavy, capacities'!$A:$A,Summary!$I7) -> 3563.0065 | P7: =SUMIFS('H2Heavy, capacities'!$E:$E,'H2Heavy, capacities'!$A:$A,Summary!$I7, 'H2Heavy, capacities'!$B:$B, P$4) -> 1653.2737 | Q7: =SUMIFS('H2Heavy, capacities'!$E:$E,'H2Heavy, capacities'!$A:$A,Summary!$I7, 'H2Heavy, capacities'!$B:$B, Q$4) -> 4285.0704 | R7: =SUMIFS(TYNDP2024!$C:$C,TYNDP2024!$A:$A,Summary!$I7) -> 2208.625 | S7: =SUMIFS(TYNDP2024!$C:$C,TYNDP2024!$A:$A,Summary!$I7, TYNDP2024!$B:$B,S$4) -> 1594 | T7: =SUMIFS(TYNDP2024!$C:$C,TYNDP2024!$A:$A,Summary!$I7, TYNDP2024!$B:$B,T$4) -> 614.625 | U7: =N7 -> 5938.3441 | V7: =P7 -> 1653.2737 | W7: =Q7 -> 4285.0704 | X7: =IF(ISNUMBER(U7), U7/(0.5+0.16666), "-") -> 8907.6053 | Y7: =IF(ISNUMBER(V7), V7/(0.5+0.16666), "-") -> 2479.9354 | Z7: =IF(ISNUMBER(W7), W7/(0.5+0.16666), "-") -> 6427.6699
B8: CH00 | C8: =J8*10^6/$O8 / 8760 -> #DIV/0! | D8: =K8*10^6/$O8 / 8760 -> #DIV/0! | F8: =IFERROR(L8*10^6/$X8 / 8760, "-") -> 0.24681418 | I8: =B8 -> CH00 | J8: =SUMIFS('H2Heavy, demands'!$F$2:$F$15,'H2Heavy, demands'!$A$2:$A$15,Summary!$I8) -> 0 | K8: =SUMIFS(Eurostat!$P:$P,Eurostat!$M:$M,Summary!$I8) / 10^3 * 1.5 -> 0 | L8: =SUM(L6:L7,L13:L30)/SUM(U6:U7,U9:U30)*U8 -> 3.2188081 | N8: =SUMIFS('H2Heavy, capacities'!$E:$E,'H2Heavy, capacities'!$A:$A,Summary!$I8) -> 0 | O8: =SUMIFS('H2Heavy, capacities'!$H:$H,'H2Heavy, capacities'!$A:$A,Summary!$I8) -> 0 | P8: =SUMIFS('H2Heavy, capacities'!$E:$E,'H2Heavy, capacities'!$A:$A,Summary!$I8, 'H2Heavy, capacities'!$B:$B, P$4) -> 0 | Q8: =SUMIFS('H2Heavy, capacities'!$E:$E,'H2Heavy, capacities'!$A:$A,Summary!$I8, 'H2Heavy, capacities'!$B:$B, Q$4) -> 0 | R8: =SUMIFS(TYNDP2024!$C:$C,TYNDP2024!$A:$A,Summary!$I8) -> 992.488 | S8: =SUMIFS(TYNDP2024!$C:$C,TYNDP2024!$A:$A,Summary!$I8, TYNDP2024!$B:$B,S$4) -> 566.599 | T8: =SUMIFS(TYNDP2024!$C:$C,TYNDP2024!$A:$A,Summary!$I8, TYNDP2024!$B:$B,T$4) -> 425.889 | U8: =R8 -> 992.488 | V8: =S8 -> 566.599 | W8: =T8 -> 425.889 | X8: =IF(ISNUMBER(U8), U8/(0.5+0.16666), "-") -> 1488.7469 | Y8: =IF(ISNUMBER(V8), V8/(0.5+0.16666), "-") -> 849.907 | Z8: =IF(ISNUMBER(W8), W8/(0.5+0.16666), "-") -> 638.83989
B9: DE00 | C9: =J9*10^6/$O9 / 8760 -> 0.47251825 | D9: =K9*10^6/$O9 / 8760 -> 0.36156677 | F9: =IFERROR(L9*10^6/$X9 / 8760, "-") -> 0.25582832 | I9: DE00 | J9: =SUMIFS('H2Heavy, demands'!$F$2:$F$15,'H2Heavy, demands'!$A$2:$A$15,Summary!$I9) -> 89.390576 | K9: =SUMIFS(Eurostat!$P:$P,Eurostat!$M:$M,Summary!$I9) / 10^3 * 1.5 -> 68.400874 | L9: =K9 -> 68.400874 | N9: =SUMIFS('H2Heavy, capacities'!$E:$E,'H2Heavy, capacities'!$A:$A,Summary!$I9) -> 35992.978 | O9: =SUMIFS('H2Heavy, capacities'!$H:$H,'H2Heavy, capacities'!$A:$A,Summary!$I9) -> 21595.787 | P9: =SUMIFS('H2Heavy, capacities'!$E:$E,'H2Heavy, capacities'!$A:$A,Summary!$I9, 'H2Heavy, capacities'!$B:$B, P$4) -> 23022.173 | Q9: =SUMIFS('H2Heavy, capacities'!$E:$E,'H2Heavy, capacities'!$A:$A,Summary!$I9, 'H2Heavy, capacities'!$B:$B, Q$4) -> 12970.806 | R9: =SUMIFS(TYNDP2024!$C:$C,TYNDP2024!$A:$A,Summary!$I9) -> 20347.606 | S9: =SUMIFS(TYNDP2024!$C:$C,TYNDP2024!$A:$A,Summary!$I9, TYNDP2024!$B:$B,S$4) -> 7280.02 | T9: =SUMIFS(TYNDP2024!$C:$C,TYNDP2024!$A:$A,Summary!$I9, TYNDP2024!$B:$B,T$4) -> 13067.586 | U9: =R9 -> 20347.606 | V9: =S9 -> 7280.02 | W9: =T9 -> 13067.586 | X9: =IF(ISNUMBER(U9), U9/(0.5+0.16666), "-") -> 30521.714 | Y9: =IF(ISNUMBER(V9), V9/(0.5+0.16666), "-") -> 10920.139 | Z9: =IF(ISNUMBER(W9), W9/(0.5+0.16666), "-") -> 19601.575
B10: DK | C10: =J10*10^6/$O10 / 8760 -> #DIV/0! | D10: =K10*10^6/$O10 / 8760 -> #DIV/0! | F10: =IFERROR(L10*10^6/$X10 / 8760, "-") -> - | I10: DK | K10: =SUMIFS(Eurostat!$P:$P,Eurostat!$M:$M,Summary!$I10) / 10^3 * 1.5 -> 7.9047772 | N10: =SUMIFS('H2Heavy, capacities'!$E:$E,'H2Heavy, capacities'!$A:$A,Summary!$I10) -> 0 | O10: =SUMIFS('H2Heavy, capacities'!$H:$H,'H2Heavy, capacities'!$A:$A,Summary!$I10) -> 0 | P10: =SUMIFS('H2Heavy, capacities'!$E:$E,'H2Heavy, capacities'!$A:$A,Summary!$I10, 'H2Heavy, capacities'!$B:$B, P$4) -> 0 | Q10: =SUMIFS('H2Heavy, capacities'!$E:$E,'H2Heavy, capacities'!$A:$A,Summary!$I10, 'H2Heavy, capacities'!$B:$B, Q$4) -> 0 | R10: =SUMIFS(TYNDP2024!$C:$C,TYNDP2024!$A:$A,Summary!$I10) -> 0 | S10: =SUMIFS(TYNDP2024!$C:$C,TYNDP2024!$A:$A,Summary!$I10, TYNDP2024!$B:$B,S$4) -> 0 | T10: =SUMIFS(TYNDP2024!$C:$C,TYNDP2024!$A:$A,Summary!$I10, TYNDP2024!$B:$B,T$4) -> 0 | X10: =IF(ISNUMBER(U10), U10/(0.5+0.16666), "-") -> - | Y10: =IF(ISNUMBER(V10), V10/(0.5+0.16666), "-") -> - | Z10: =IF(ISNUMBER(W10), W10/(0.5+0.16666), "-") -> -
B11: DKE1 | C11: =J11*10^6/$O11 / 8760 -> #DIV/0! | D11: =K11*10^6/$O11 / 8760 -> #DIV/0! | F11: =IFERROR(L11*10^6/$X11 / 8760, "-") -> - | I11: DKE1 | K11: =SUMIFS(Eurostat!$P:$P,Eurostat!$M:$M,Summary!$I11) / 10^3 * 1.5 -> 0 | L11: - | N11: =SUMIFS('H2Heavy, capacities'!$E:$E,'H2Heavy, capacities'!$A:$A,Summary!$I11) -> 0 | O11: =SUMIFS('H2Heavy, capacities'!$H:$H,'H2Heavy, capacities'!$A:$A,Summary!$I11) -> 0 | P11: =SUMIFS('H2Heavy, capacities'!$E:$E,'H2Heavy, capacities'!$A:$A,Summary!$I11, 'H2Heavy, capacities'!$B:$B, P$4) -> 0 | Q11: =SUMIFS('H2Heavy, capacities'!$E:$E,'H2Heavy, capacities'!$A:$A,Summary!$I11, 'H2Heavy, capacities'!$B:$B, Q$4) -> 0 | R11: =SUMIFS(TYNDP2024!$C:$C,TYNDP2024!$A:$A,Summary!$I11) -> 0 | S11: =SUMIFS(TYNDP2024!$C:$C,TYNDP2024!$A:$A,Summary!$I11, TYNDP2024!$B:$B,S$4) -> 0 | T11: =SUMIFS(TYNDP2024!$C:$C,TYNDP2024!$A:$A,Summary!$I11, TYNDP2024!$B:$B,T$4) -> 0 | U11: - | V11: - | W11: - | X11: =IF(ISNUMBER(U11), U11/(0.5+0.16666), "-") -> - | Y11: =IF(ISNUMBER(V11), V11/(0.5+0.16666), "-") -> - | Z11: =IF(ISNUMBER(W11), W11/(0.5+0.16666), "-") -> -
B12: DKW1 | C12: =J12*10^6/$O12 / 8760 -> 0 | D12: =K12*10^6/$O12 / 8760 -> 0 | F12: =IFERROR(L12*10^6/$X12 / 8760, "-") -> - | I12: DKW1 | J12: =SUMIFS('H2Heavy, demands'!$F$2:$F$15,'H2Heavy, demands'!$A$2:$A$15,Summary!$I12) -> 0 | K12: =SUMIFS(Eurostat!$P:$P,Eurostat!$M:$M,Summary!$I12) / 10^3 * 1.5 -> 0 | L12: - | N12: =SUMIFS('H2Heavy, capacities'!$E:$E,'H2Heavy, capacities'!$A:$A,Summary!$I12) -> 18.81775 | O12: =SUMIFS('H2Heavy, capacities'!$H:$H,'H2Heavy, capacities'!$A:$A,Summary!$I12) -> 11.29065 | P12: =SUMIFS('H2Heavy, capacities'!$E:$E,'H2Heavy, capacities'!$A:$A,Summary!$I12, 'H2Heavy, capacities'!$B:$B, P$4) -> 18.81775 | Q12: =SUMIFS('H2Heavy, capacities'!$E:$E,'H2Heavy, capacities'!$A:$A,Summary!$I12, 'H2Heavy, capacities'!$B:$B, Q$4) -> 0 | R12: =SUMIFS(TYNDP2024!$C:$C,TYNDP2024!$A:$A,Summary!$I12) -> 7.26 | S12: =SUMIFS(TYNDP2024!$C:$C,TYNDP2024!$A:$A,Summary!$I12, TYNDP2024!$B:$B,S$4) -> 0 | T12: =SUMIFS(TYNDP2024!$C:$C,TYNDP2024!$A:$A,Summary!$I12, TYNDP2024!$B:$B,T$4) -> 7.26 | U12: - | V12: - | W12: - | X12: =IF(ISNUMBER(U12), U12/(0.5+0.16666), "-") -> - | Y12: =IF(ISNUMBER(V12), V12/(0.5+0.16666), "-") -> - | Z12: =IF(ISNUMBER(W12), W12/(0.5+0.16666), "-") -> -
B13: EE00 | C13: =J13*10^6/$O13 / 8760 -> 0.35857573 | D13: =K13*10^6/$O13 / 8760 -> 0.042281045 | F13: =IFERROR(L13*10^6/$X13 / 8760, "-") -> 0.11690925 | I13: EE00 | J13: =SUMIFS('H2Heavy, demands'!$F$2:$F$15,'H2Heavy, demands'!$A$2:$A$15,Summary!$I13) -> 1.5351419 | K13: =SUMIFS(Eurostat!$P:$P,Eurostat!$M:$M,Summary!$I13) / 10^3 * 1.5 -> 0.18101449 | L13: =AVERAGE(J13:K13) -> 0.85807818 | N13: =SUMIFS('H2Heavy, capacities'!$E:$E,'H2Heavy, capacities'!$A:$A,Summary!$I13) -> 814.53973 | O13: =SUMIFS('H2Heavy, capacities'!$H:$H,'H2Heavy, capacities'!$A:$A,Summary!$I13) -> 488.72384 | P13: =SUMIFS('H2Heavy, capacities'!$E:$E,'H2Heavy, capacities'!$A:$A,Summary!$I13, 'H2Heavy, capacities'!$B:$B, P$4) -> 451.62599 | Q13: =SUMIFS('H2Heavy, capacities'!$E:$E,'H2Heavy, capacities'!$A:$A,Summary!$I13, 'H2Heavy, capacities'!$B:$B, Q$4) -> 362.91374 | R13: =SUMIFS(TYNDP2024!$C:$C,TYNDP2024!$A:$A,Summary!$I13) -> 302.602 | S13: =SUMIFS(TYNDP2024!$C:$C,TYNDP2024!$A:$A,Summary!$I13, TYNDP2024!$B:$B,S$4) -> 134.952 | T13: =SUMIFS(TYNDP2024!$C:$C,TYNDP2024!$A:$A,Summary!$I13, TYNDP2024!$B:$B,T$4) -> 167.65 | U13: =AVERAGE(N13,R13) -> 558.57087 | V13: =AVERAGE(P13,S13) -> 293.289 | W13: =AVERAGE(Q13,T13) -> 265.28187 | X13: =IF(ISNUMBER(U13), U13/(0.5+0.16666), "-") -> 837.86468 | Y13: =IF(ISNUMBER(V13), V13/(0.5+0.16666), "-") -> 439.93789 | Z13: =IF(ISNUMBER(W13), W13/(0.5+0.16666), "-") -> 397.92679
B14: ES00 | C14: =J14*10^6/$O14 / 8760 -> 0.19047085 | D14: =K14*10^6/$O14 / 8760 -> 0.60817695 | F14: =IFERROR(L14*10^6/$X14 / 8760, "-") -> 0.65396487 | I14: ES00 | J14: =SUMIFS('H2Heavy, demands'!$F$2:$F$15,'H2Heavy, demands'!$A$2:$A$15,Summary!$I14) -> 15.367019 | K14: =SUMIFS(Eurostat!$P:$P,Eurostat!$M:$M,Summary!$I14) / 10^3 * 1.5 -> 49.067177 | L14: =K14 -> 49.067177 | N14: =SUMIFS('H2Heavy, capacities'!$E:$E,'H2Heavy, capacities'!$A:$A,Summary!$I14) -> 15349.907 | O14: =SUMIFS('H2Heavy, capacities'!$H:$H,'H2Heavy, capacities'!$A:$A,Summary!$I14) -> 9209.9443 | P14: =SUMIFS('H2Heavy, capacities'!$E:$E,'H2Heavy, capacities'!$A:$A,Summary!$I14, 'H2Heavy, capacities'!$B:$B, P$4) -> 4650.6724 | Q14: =SUMIFS('H2Heavy, capacities'!$E:$E,'H2Heavy, capacities'!$A:$A,Summary!$I14, 'H2Heavy, capacities'!$B:$B, Q$4) -> 10699.235 | R14: =SUMIFS(TYNDP2024!$C:$C,TYNDP2024!$A:$A,Summary!$I14) -> 5710.011 | S14: =SUMIFS(TYNDP2024!$C:$C,TYNDP2024!$A:$A,Summary!$I14, TYNDP2024!$B:$B,S$4) -> 3980.011 | T14: =SUMIFS(TYNDP2024!$C:$C,TYNDP2024!$A:$A,Summary!$I14, TYNDP2024!$B:$B,T$4) -> 1730 | U14: =R14 -> 5710.011 | V14: =S14 -> 3980.011 | W14: =T14 -> 1730 | X14: =IF(ISNUMBER(U14), U14/(0.5+0.16666), "-") -> 8565.1022 | Y14: =IF(ISNUMBER(V14), V14/(0.5+0.16666), "-") -> 5970.0762 | Z14: =IF(ISNUMBER(W14), W14/(0.5+0.16666), "-") -> 2595.026
B15: FI00 | C15: =J15*10^6/$O15 / 8760 -> #DIV/0! | D15: =K15*10^6/$O15 / 8760 -> #DIV/0! | F15: =IFERROR(L15*10^6/$X15 / 8760, "-") -> 0.38461937 | I15: FI00 | J15: =SUMIFS('H2Heavy, demands'!$F$2:$F$15,'H2Heavy, demands'!$A$2:$A$15,Summary!$I15) -> 0 | K15: =SUMIFS(Eurostat!$P:$P,Eurostat!$M:$M,Summary!$I15) / 10^3 * 1.5 -> 15.239274 | L15: =K15 -> 15.239274 | N15: =SUMIFS('H2Heavy, capacities'!$E:$E,'H2Heavy, capacities'!$A:$A,Summary!$I15) -> 0 | O15: =SUMIFS('H2Heavy, capacities'!$H:$H,'H2Heavy, capacities'!$A:$A,Summary!$I15) -> 0 | P15: =SUMIFS('H2Heavy, capacities'!$E:$E,'H2Heavy, capacities'!$A:$A,Summary!$I15, 'H2Heavy, capacities'!$B:$B, P$4) -> 0 | Q15: =SUMIFS('H2Heavy, capacities'!$E:$E,'H2Heavy, capacities'!$A:$A,Summary!$I15, 'H2Heavy, capacities'!$B:$B, Q$4) -> 0 | R15: =SUMIFS(TYNDP2024!$C:$C,TYNDP2024!$A:$A,Summary!$I15) -> 3015.32 | S15: =SUMIFS(TYNDP2024!$C:$C,TYNDP2024!$A:$A,Summary!$I15, TYNDP2024!$B:$B,S$4) -> 390.5 | T15: =SUMIFS(TYNDP2024!$C:$C,TYNDP2024!$A:$A,Summary!$I15, TYNDP2024!$B:$B,T$4) -> 2624.82 | U15: =R15 -> 3015.32 | V15: =S15 -> 390.5 | W15: =T15 -> 2624.82 | X15: =IF(ISNUMBER(U15), U15/(0.5+0.16666), "-") -> 4523.0252 | Y15: =IF(ISNUMBER(V15), V15/(0.5+0.16666), "-") -> 585.75586 | Z15: =IF(ISNUMBER(W15), W15/(0.5+0.16666), "-") -> 3937.2694
B16: FR00 | C16: =J16*10^6/$O16 / 8760 -> 0.38805966 | D16: =K16*10^6/$O16 / 8760 -> 0.48839044 | F16: =IFERROR(L16*10^6/$X16 / 8760, "-") -> 0.38583098 | I16: FR00 | J16: =SUMIFS('H2Heavy, demands'!$F$2:$F$15,'H2Heavy, demands'!$A$2:$A$15,Summary!$I16) -> 27.497578 | K16: =SUMIFS(Eurostat!$P:$P,Eurostat!$M:$M,Summary!$I16) / 10^3 * 1.5 -> 34.606931 | L16: =K16 -> 34.606931 | N16: =SUMIFS('H2Heavy, capacities'!$E:$E,'H2Heavy, capacities'!$A:$A,Summary!$I16) -> 13481.573 | O16: =SUMIFS('H2Heavy, capacities'!$H:$H,'H2Heavy, capacities'!$A:$A,Summary!$I16) -> 8088.9441 | P16: =SUMIFS('H2Heavy, capacities'!$E:$E,'H2Heavy, capacities'!$A:$A,Summary!$I16, 'H2Heavy, capacities'!$B:$B, P$4) -> 6492.1236 | Q16: =SUMIFS('H2Heavy, capacities'!$E:$E,'H2Heavy, capacities'!$A:$A,Summary!$I16, 'H2Heavy, capacities'!$B:$B, Q$4) -> 6989.4498 | R16: =SUMIFS(TYNDP2024!$C:$C,TYNDP2024!$A:$A,Summary!$I16) -> 6826 | S16: =SUMIFS(TYNDP2024!$C:$C,TYNDP2024!$A:$A,Summary!$I16, TYNDP2024!$B:$B,S$4) -> 4400 | T16: =SUMIFS(TYNDP2024!$C:$C,TYNDP2024!$A:$A,Summary!$I16, TYNDP2024!$B:$B,T$4) -> 2426 | U16: =R16 -> 6826 | V16: =S16 -> 4400 | W16: =T16 -> 2426 | X16: =IF(ISNUMBER(U16), U16/(0.5+0.16666), "-") -> 10239.102 | Y16: =IF(ISNUMBER(V16), V16/(0.5+0.16666), "-") -> 6600.066 | Z16: =IF(ISNUMBER(W16), W16/(0.5+0.16666), "-") -> 3639.0364
B17: LT00 | C17: =J17*10^6/$O17 / 8760 -> 0.88110409 | D17: =K17*10^6/$O17 / 8760 -> 0.18148119 | F17: =IFERROR(L17*10^6/$X17 / 8760, "-") -> 0.30984927 | I17: LT00 | J17: =SUMIFS('H2Heavy, demands'!$F$2:$F$15,'H2Heavy, demands'!$A$2:$A$15,Summary!$I17) -> 3.9464943 | K17: =SUMIFS(Eurostat!$P:$P,Eurostat!$M:$M,Summary!$I17) / 10^3 * 1.5 -> 0.81286023 | L17: =AVERAGE(J17:K17) -> 2.3796773 | N17: =SUMIFS('H2Heavy, capacities'!$E:$E,'H2Heavy, capacities'!$A:$A,Summary!$I17) -> 852.17523 | O17: =SUMIFS('H2Heavy, capacities'!$H:$H,'H2Heavy, capacities'!$A:$A,Summary!$I17) -> 511.30514 | P17: =SUMIFS('H2Heavy, capacities'!$E:$E,'H2Heavy, capacities'!$A:$A,Summary!$I17, 'H2Heavy, capacities'!$B:$B, P$4) -> 564.53249 | Q17: =SUMIFS('H2Heavy, capacities'!$E:$E,'H2Heavy, capacities'!$A:$A,Summary!$I17, 'H2Heavy, capacities'!$B:$B, Q$4) -> 287.64274 | R17: =SUMIFS(TYNDP2024!$C:$C,TYNDP2024!$A:$A,Summary!$I17) -> 316.78 | S17: =SUMIFS(TYNDP2024!$C:$C,TYNDP2024!$A:$A,Summary!$I17, TYNDP2024!$B:$B,S$4) -> 106.89 | T17: =SUMIFS(TYNDP2024!$C:$C,TYNDP2024!$A:$A,Summary!$I17, TYNDP2024!$B:$B,T$4) -> 209.89 | U17: =AVERAGE(N17,R17) -> 584.47762 | V17: =AVERAGE(P17,S17) -> 335.71124 | W17: =AVERAGE(Q17,T17) -> 248.76637 | X17: =IF(ISNUMBER(U17), U17/(0.5+0.16666), "-") -> 876.72519 | Y17: =IF(ISNUMBER(V17), V17/(0.5+0.16666), "-") -> 503.5719 | Z17: =IF(ISNUMBER(W17), W17/(0.5+0.16666), "-") -> 373.15329
B18: LV00 | C18: =J18*10^6/$O18 / 8760 -> 0.99610074 | D18: =K18*10^6/$O18 / 8760 -> 0.15711089 | F18: =IFERROR(L18*10^6/$X18 / 8760, "-") -> 0.33620226 | I18: LV00 | J18: =SUMIFS('H2Heavy, demands'!$F$2:$F$15,'H2Heavy, demands'!$A$2:$A$15,Summary!$I18) -> 2.2378212 | K18: =SUMIFS(Eurostat!$P:$P,Eurostat!$M:$M,Summary!$I18) / 10^3 * 1.5 -> 0.35296238 | L18: =AVERAGE(J18:K18) -> 1.2953918 | N18: =SUMIFS('H2Heavy, capacities'!$E:$E,'H2Heavy, capacities'!$A:$A,Summary!$I18) -> 427.43174 | O18: =SUMIFS('H2Heavy, capacities'!$H:$H,'H2Heavy, capacities'!$A:$A,Summary!$I18) -> 256.45904 | P18: =SUMIFS('H2Heavy, capacities'!$E:$E,'H2Heavy, capacities'!$A:$A,Summary!$I18, 'H2Heavy, capacities'!$B:$B, P$4) -> 427.43174 | Q18: =SUMIFS('H2Heavy, capacities'!$E:$E,'H2Heavy, capacities'!$A:$A,Summary!$I18, 'H2Heavy, capacities'!$B:$B, Q$4) -> 0 | R18: =SUMIFS(TYNDP2024!$C:$C,TYNDP2024!$A:$A,Summary!$I18) -> 159.018 | S18: =SUMIFS(TYNDP2024!$C:$C,TYNDP2024!$A:$A,Summary!$I18, TYNDP2024!$B:$B,S$4) -> 0 | T18: =SUMIFS(TYNDP2024!$C:$C,TYNDP2024!$A:$A,Summary!$I18, TYNDP2024!$B:$B,T$4) -> 159.018 | U18: =AVERAGE(N18,R18) -> 293.22487 | V18: =AVERAGE(P18,S18) -> 213.71587 | W18: =AVERAGE(Q18,T18) -> 79.509 | X18: =IF(ISNUMBER(U18), U18/(0.5+0.16666), "-") -> 439.8417 | Y18: =IF(ISNUMBER(V18), V18/(0.5+0.16666), "-") -> 320.57701 | Z18: =IF(ISNUMBER(W18), W18/(0.5+0.16666), "-") -> 119.26469
B19: NL00 | C19: =J19*10^6/$O19 / 8760 -> 0.20980759 | D19: =K19*10^6/$O19 / 8760 -> 0.9607294 | F19: =IFERROR(L19*10^6/$X19 / 8760, "-") -> 0.38428792 | I19: NL00 | J19: =SUMIFS('H2Heavy, demands'!$F$2:$F$15,'H2Heavy, demands'!$A$2:$A$15,Summary!$I19) -> 12.092049 | K19: =SUMIFS(Eurostat!$P:$P,Eurostat!$M:$M,Summary!$I19) / 10^3 * 1.5 -> 55.370671 | L19: =K19 -> 55.370671 | N19: =SUMIFS('H2Heavy, capacities'!$E:$E,'H2Heavy, capacities'!$A:$A,Summary!$I19) -> 10965.372 | O19: =SUMIFS('H2Heavy, capacities'!$H:$H,'H2Heavy, capacities'!$A:$A,Summary!$I19) -> 6579.2229 | P19: =SUMIFS('H2Heavy, capacities'!$E:$E,'H2Heavy, capacities'!$A:$A,Summary!$I19, 'H2Heavy, capacities'!$B:$B, P$4) -> 1115.6237 | Q19: =SUMIFS('H2Heavy, capacities'!$E:$E,'H2Heavy, capacities'!$A:$A,Summary!$I19, 'H2Heavy, capacities'!$B:$B, Q$4) -> 9849.7478 | R19: =SUMIFS(TYNDP2024!$C:$C,TYNDP2024!$A:$A,Summary!$I19) -> 4796.5 | S19: =SUMIFS(TYNDP2024!$C:$C,TYNDP2024!$A:$A,Summary!$I19, TYNDP2024!$B:$B,S$4) -> 4381.5 | T19: =SUMIFS(TYNDP2024!$C:$C,TYNDP2024!$A:$A,Summary!$I19, TYNDP2024!$B:$B,T$4) -> 415 | U19: =N19 -> 10965.372 | V19: =P19 -> 1115.6237 | W19: =Q19 -> 9849.7478 | X19: =IF(ISNUMBER(U19), U19/(0.5+0.16666), "-") -> 16448.222 | Y19: =IF(ISNUMBER(V19), V19/(0.5+0.16666), "-") -> 1673.4523 | Z19: =IF(ISNUMBER(W19), W19/(0.5+0.16666), "-") -> 14774.769
B20: NO | C20: =J20*10^6/$O20 / 8760 -> #DIV/0! | D20: =K20*10^6/$O20 / 8760 -> #DIV/0! | F20: =IFERROR(L20*10^6/$X20 / 8760, "-") -> - | I20: NO | K20: =SUMIFS(Eurostat!$P:$P,Eurostat!$M:$M,Summary!$I20) / 10^3 * 1.5 -> 2.3465667 | N20: =SUMIFS('H2Heavy, capacities'!$E:$E,'H2Heavy, capacities'!$A:$A,Summary!$I20) -> 0 | O20: =SUMIFS('H2Heavy, capacities'!$H:$H,'H2Heavy, capacities'!$A:$A,Summary!$I20) -> 0 | P20: =SUMIFS('H2Heavy, capacities'!$E:$E,'H2Heavy, capacities'!$A:$A,Summary!$I20, 'H2Heavy, capacities'!$B:$B, P$4) -> 0 | Q20: =SUMIFS('H2Heavy, capacities'!$E:$E,'H2Heavy, capacities'!$A:$A,Summary!$I20, 'H2Heavy, capacities'!$B:$B, Q$4) -> 0 | R20: =SUMIFS(TYNDP2024!$C:$C,TYNDP2024!$A:$A,Summary!$I20) -> 0 | S20: =SUMIFS(TYNDP2024!$C:$C,TYNDP2024!$A:$A,Summary!$I20, TYNDP2024!$B:$B,S$4) -> 0 | T20: =SUMIFS(TYNDP2024!$C:$C,TYNDP2024!$A:$A,Summary!$I20, TYNDP2024!$B:$B,T$4) -> 0 | X20: =IF(ISNUMBER(U20), U20/(0.5+0.16666), "-") -> - | Y20: =IF(ISNUMBER(V20), V20/(0.5+0.16666), "-") -> - | Z20: =IF(ISNUMBER(W20), W20/(0.5+0.16666), "-") -> -
B21: NOM1 | C21: =J21*10^6/$O21 / 8760 -> 0 | D21: =K21*10^6/$O21 / 8760 -> 0 | F21: =IFERROR(L21*10^6/$X21 / 8760, "-") -> 0.67388736 | I21: NOM1 | J21: =SUMIFS('H2Heavy, demands'!$F$2:$F$15,'H2Heavy, demands'!$A$2:$A$15,Summary!$I21) -> 0 | K21: =SUMIFS(Eurostat!$P:$P,Eurostat!$M:$M,Summary!$I21) / 10^3 * 1.5 -> 0 | L21: =$K$20/SUM($R$21:$R$23)*R21 -> 0.17709937 | N21: =SUMIFS('H2Heavy, capacities'!$E:$E,'H2Heavy, capacities'!$A:$A,Summary!$I21) -> 53.764999 | O21: =SUMIFS('H2Heavy, capacities'!$H:$H,'H2Heavy, capacities'!$A:$A,Summary!$I21) -> 32.258999 | P21: =SUMIFS('H2Heavy, capacities'!$E:$E,'H2Heavy, capacities'!$A:$A,Summary!$I21, 'H2Heavy, capacities'!$B:$B, P$4) -> 0 | Q21: =SUMIFS('H2Heavy, capacities'!$E:$E,'H2Heavy, capacities'!$A:$A,Summary!$I21, 'H2Heavy, capacities'!$B:$B, Q$4) -> 53.764999 | R21: =SUMIFS(TYNDP2024!$C:$C,TYNDP2024!$A:$A,Summary!$I21) -> 20 | S21: =SUMIFS(TYNDP2024!$C:$C,TYNDP2024!$A:$A,Summary!$I21, TYNDP2024!$B:$B,S$4) -> 20 | T21: =SUMIFS(TYNDP2024!$C:$C,TYNDP2024!$A:$A,Summary!$I21, TYNDP2024!$B:$B,T$4) -> 0 | U21: =R21 -> 20 | V21: =S21 -> 20 | W21: =T21 -> 0 | X21: =IF(ISNUMBER(U21), U21/(0.5+0.16666), "-") -> 30.0003 | Y21: =IF(ISNUMBER(V21), V21/(0.5+0.16666), "-") -> 30.0003 | Z21: =IF(ISNUMBER(W21), W21/(0.5+0.16666), "-") -> 0
B22: NON1 | C22: =J22*10^6/$O22 / 8760 -> 0 | D22: =K22*10^6/$O22 / 8760 -> 0 | F22: =IFERROR(L22*10^6/$X22 / 8760, "-") -> 0.67388736 | I22: NON1 | J22: =SUMIFS('H2Heavy, demands'!$F$2:$F$15,'H2Heavy, demands'!$A$2:$A$15,Summary!$I22) -> 0 | K22: =SUMIFS(Eurostat!$P:$P,Eurostat!$M:$M,Summary!$I22) / 10^3 * 1.5 -> 0 | L22: =$K$20/SUM($R$21:$R$23)*R22 -> 1.7267189 | N22: =SUMIFS('H2Heavy, capacities'!$E:$E,'H2Heavy, capacities'!$A:$A,Summary!$I22) -> 524.20874 | O22: =SUMIFS('H2Heavy, capacities'!$H:$H,'H2Heavy, capacities'!$A:$A,Summary!$I22) -> 314.52524 | P22: =SUMIFS('H2Heavy, capacities'!$E:$E,'H2Heavy, capacities'!$A:$A,Summary!$I22, 'H2Heavy, capacities'!$B:$B, P$4) -> 0 | Q22: =SUMIFS('H2Heavy, capacities'!$E:$E,'H2Heavy, capacities'!$A:$A,Summary!$I22, 'H2Heavy, capacities'!$B:$B, Q$4) -> 524.20874 | R22: =SUMIFS(TYNDP2024!$C:$C,TYNDP2024!$A:$A,Summary!$I22) -> 195 | S22: =SUMIFS(TYNDP2024!$C:$C,TYNDP2024!$A:$A,Summary!$I22, TYNDP2024!$B:$B,S$4) -> 195 | T22: =SUMIFS(TYNDP2024!$C:$C,TYNDP2024!$A:$A,Summary!$I22, TYNDP2024!$B:$B,T$4) -> 0 | U22: =R22 -> 195 | V22: =S22 -> 195 | W22: =T22 -> 0 | X22: =IF(ISNUMBER(U22), U22/(0.5+0.16666), "-") -> 292.50293 | Y22: =IF(ISNUMBER(V22), V22/(0.5+0.16666), "-") -> 292.50293 | Z22: =IF(ISNUMBER(W22), W22/(0.5+0.16666), "-") -> 0
B23: NOS0 | C23: =J23*10^6/$O23 / 8760 -> 0 | D23: =K23*10^6/$O23 / 8760 -> 0 | F23: =IFERROR(L23*10^6/$X23 / 8760, "-") -> 0.67388736 | I23: NOS0 | J23: =SUMIFS('H2Heavy, demands'!$F$2:$F$15,'H2Heavy, demands'!$A$2:$A$15,Summary!$I23) -> 0 | K23: =SUMIFS(Eurostat!$P:$P,Eurostat!$M:$M,Summary!$I23) / 10^3 * 1.5 -> 0 | L23: =$K$20/SUM($R$21:$R$23)*R23 -> 0.44274843 | N23: =SUMIFS('H2Heavy, capacities'!$E:$E,'H2Heavy, capacities'!$A:$A,Summary!$I23) -> 134.4125 | O23: =SUMIFS('H2Heavy, capacities'!$H:$H,'H2Heavy, capacities'!$A:$A,Summary!$I23) -> 80.647498 | P23: =SUMIFS('H2Heavy, capacities'!$E:$E,'H2Heavy, capacities'!$A:$A,Summary!$I23, 'H2Heavy, capacities'!$B:$B, P$4) -> 0 | Q23: =SUMIFS('H2Heavy, capacities'!$E:$E,'H2Heavy, capacities'!$A:$A,Summary!$I23, 'H2Heavy, capacities'!$B:$B, Q$4) -> 134.4125 | R23: =SUMIFS(TYNDP2024!$C:$C,TYNDP2024!$A:$A,Summary!$I23) -> 50 | S23: =SUMIFS(TYNDP2024!$C:$C,TYNDP2024!$A:$A,Summary!$I23, TYNDP2024!$B:$B,S$4) -> 50 | T23: =SUMIFS(TYNDP2024!$C:$C,TYNDP2024!$A:$A,Summary!$I23, TYNDP2024!$B:$B,T$4) -> 0 | U23: =R23 -> 50 | V23: =S23 -> 50 | W23: =T23 -> 0 | X23: =IF(ISNUMBER(U23), U23/(0.5+0.16666), "-") -> 75.00075 | Y23: =IF(ISNUMBER(V23), V23/(0.5+0.16666), "-") -> 75.00075 | Z23: =IF(ISNUMBER(W23), W23/(0.5+0.16666), "-") -> 0
B24: PL00 | C24: =J24*10^6/$O24 / 8760 -> 0.25966535 | D24: =K24*10^6/$O24 / 8760 -> 0.33129857 | F24: =IFERROR(L24*10^6/$X24 / 8760, "-") -> 0.31459092 | I24: PL00 | J24: =SUMIFS('H2Heavy, demands'!$F$2:$F$15,'H2Heavy, demands'!$A$2:$A$15,Summary!$I24) -> 25.172504 | K24: =SUMIFS(Eurostat!$P:$P,Eurostat!$M:$M,Summary!$I24) / 10^3 * 1.5 -> 32.116779 | L24: =K24 -> 32.116779 | N24: =SUMIFS('H2Heavy, capacities'!$E:$E,'H2Heavy, capacities'!$A:$A,Summary!$I24) -> 18444.083 | O24: =SUMIFS('H2Heavy, capacities'!$H:$H,'H2Heavy, capacities'!$A:$A,Summary!$I24) -> 11066.45 | P24: =SUMIFS('H2Heavy, capacities'!$E:$E,'H2Heavy, capacities'!$A:$A,Summary!$I24, 'H2Heavy, capacities'!$B:$B, P$4) -> 5868.4496 | Q24: =SUMIFS('H2Heavy, capacities'!$E:$E,'H2Heavy, capacities'!$A:$A,Summary!$I24, 'H2Heavy, capacities'!$B:$B, Q$4) -> 12575.633 | R24: =SUMIFS(TYNDP2024!$C:$C,TYNDP2024!$A:$A,Summary!$I24) -> 7769.375 | S24: =SUMIFS(TYNDP2024!$C:$C,TYNDP2024!$A:$A,Summary!$I24, TYNDP2024!$B:$B,S$4) -> 5614.321 | T24: =SUMIFS(TYNDP2024!$C:$C,TYNDP2024!$A:$A,Summary!$I24, TYNDP2024!$B:$B,T$4) -> 2155.054 | U24: =R24 -> 7769.375 | V24: =S24 -> 5614.321 | W24: =T24 -> 2155.054 | X24: =IF(ISNUMBER(U24), U24/(0.5+0.16666), "-") -> 11654.179 | Y24: =IF(ISNUMBER(V24), V24/(0.5+0.16666), "-") -> 8421.5657 | Z24: =IF(ISNUMBER(W24), W24/(0.5+0.16666), "-") -> 3232.6133
B25: SE | C25: =J25*10^6/$O25 / 8760 -> #DIV/0! | D25: =K25*10^6/$O25 / 8760 -> #DIV/0! | F25: =IFERROR(L25*10^6/$X25 / 8760, "-") -> - | I25: SE | K25: =SUMIFS(Eurostat!$P:$P,Eurostat!$M:$M,Summary!$I25) / 10^3 * 1.5 -> 12.243905 | N25: =SUMIFS('H2Heavy, capacities'!$E:$E,'H2Heavy, capacities'!$A:$A,Summary!$I25) -> 0 | O25: =SUMIFS('H2Heavy, capacities'!$H:$H,'H2Heavy, capacities'!$A:$A,Summary!$I25) -> 0 | P25: =SUMIFS('H2Heavy, capacities'!$E:$E,'H2Heavy, capacities'!$A:$A,Summary!$I25, 'H2Heavy, capacities'!$B:$B, P$4) -> 0 | Q25: =SUMIFS('H2Heavy, capacities'!$E:$E,'H2Heavy, capacities'!$A:$A,Summary!$I25, 'H2Heavy, capacities'!$B:$B, Q$4) -> 0 | R25: =SUMIFS(TYNDP2024!$C:$C,TYNDP2024!$A:$A,Summary!$I25) -> 0 | S25: =SUMIFS(TYNDP2024!$C:$C,TYNDP2024!$A:$A,Summary!$I25, TYNDP2024!$B:$B,S$4) -> 0 | T25: =SUMIFS(TYNDP2024!$C:$C,TYNDP2024!$A:$A,Summary!$I25, TYNDP2024!$B:$B,T$4) -> 0 | X25: =IF(ISNUMBER(U25), U25/(0.5+0.16666), "-") -> - | Y25: =IF(ISNUMBER(V25), V25/(0.5+0.16666), "-") -> - | Z25: =IF(ISNUMBER(W25), W25/(0.5+0.16666), "-") -> -
B26: SE01 | C26: =J26*10^6/$O26 / 8760 -> 0.40555118 | D26: =K26*10^6/$O26 / 8760 -> 0 | F26: =IFERROR(L26*10^6/$X26 / 8760, "-") -> 0.16221885 | I26: SE01 | J26: =SUMIFS('H2Heavy, demands'!$F$2:$F$15,'H2Heavy, demands'!$A$2:$A$15,Summary!$I26) -> 1.1403121 | K26: =SUMIFS(Eurostat!$P:$P,Eurostat!$M:$M,Summary!$I26) / 10^3 * 1.5 -> 0 | L26: =J26 -> 1.1403121 | N26: =SUMIFS('H2Heavy, capacities'!$E:$E,'H2Heavy, capacities'!$A:$A,Summary!$I26) -> 534.96174 | O26: =SUMIFS('H2Heavy, capacities'!$H:$H,'H2Heavy, capacities'!$A:$A,Summary!$I26) -> 320.97704 | P26: =SUMIFS('H2Heavy, capacities'!$E:$E,'H2Heavy, capacities'!$A:$A,Summary!$I26, 'H2Heavy, capacities'!$B:$B, P$4) -> 534.96174 | Q26: =SUMIFS('H2Heavy, capacities'!$E:$E,'H2Heavy, capacities'!$A:$A,Summary!$I26, 'H2Heavy, capacities'!$B:$B, Q$4) -> 0 | R26: =SUMIFS(TYNDP2024!$C:$C,TYNDP2024!$A:$A,Summary!$I26) -> 198.7 | S26: =SUMIFS(TYNDP2024!$C:$C,TYNDP2024!$A:$A,Summary!$I26, TYNDP2024!$B:$B,S$4) -> 0 | T26: =SUMIFS(TYNDP2024!$C:$C,TYNDP2024!$A:$A,Summary!$I26, TYNDP2024!$B:$B,T$4) -> 198.7 | U26: =N26 -> 534.96174 | V26: =P26 -> 534.96174 | W26: =Q26 -> 0 | X26: =IF(ISNUMBER(U26), U26/(0.5+0.16666), "-") -> 802.45063 | Y26: =IF(ISNUMBER(V26), V26/(0.5+0.16666), "-") -> 802.45063 | Z26: =IF(ISNUMBER(W26), W26/(0.5+0.16666), "-") -> 0
B27: SE02 | C27: =J27*10^6/$O27 / 8760 -> 0.48494855 | D27: =K27*10^6/$O27 / 8760 -> 0 | F27: =IFERROR(L27*10^6/$X27 / 8760, "-") -> 0.19397748 | I27: SE02 | J27: =SUMIFS('H2Heavy, demands'!$F$2:$F$15,'H2Heavy, demands'!$A$2:$A$15,Summary!$I27) -> 5.0979269 | K27: =SUMIFS(Eurostat!$P:$P,Eurostat!$M:$M,Summary!$I27) / 10^3 * 1.5 -> 0 | L27: =J27 -> 5.0979269 | N27: =SUMIFS('H2Heavy, capacities'!$E:$E,'H2Heavy, capacities'!$A:$A,Summary!$I27) -> 2000.058 | O27: =SUMIFS('H2Heavy, capacities'!$H:$H,'H2Heavy, capacities'!$A:$A,Summary!$I27) -> 1200.0348 | P27: =SUMIFS('H2Heavy, capacities'!$E:$E,'H2Heavy, capacities'!$A:$A,Summary!$I27, 'H2Heavy, capacities'!$B:$B, P$4) -> 2000.058 | Q27: =SUMIFS('H2Heavy, capacities'!$E:$E,'H2Heavy, capacities'!$A:$A,Summary!$I27, 'H2Heavy, capacities'!$B:$B, Q$4) -> 0 | R27: =SUMIFS(TYNDP2024!$C:$C,TYNDP2024!$A:$A,Summary!$I27) -> 743.57 | S27: =SUMIFS(TYNDP2024!$C:$C,TYNDP2024!$A:$A,Summary!$I27, TYNDP2024!$B:$B,S$4) -> 0 | T27: =SUMIFS(TYNDP2024!$C:$C,TYNDP2024!$A:$A,Summary!$I27, TYNDP2024!$B:$B,T$4) -> 743.57 | U27: =N27 -> 2000.058 | V27: =P27 -> 2000.058 | W27: =Q27 -> 0 | X27: =IF(ISNUMBER(U27), U27/(0.5+0.16666), "-") -> 3000.1169 | Y27: =IF(ISNUMBER(V27), V27/(0.5+0.16666), "-") -> 3000.1169 | Z27: =IF(ISNUMBER(W27), W27/(0.5+0.16666), "-") -> 0
B28: SE03 | C28: =J28*10^6/$O28 / 8760 -> 0.63416659 | D28: =K28*10^6/$O28 / 8760 -> 0 | F28: =IFERROR(L28*10^6/$X28 / 8760, "-") -> 0.2536641 | I28: SE03 | J28: =SUMIFS('H2Heavy, demands'!$F$2:$F$15,'H2Heavy, demands'!$A$2:$A$15,Summary!$I28) -> 22.884912 | K28: =SUMIFS(Eurostat!$P:$P,Eurostat!$M:$M,Summary!$I28) / 10^3 * 1.5 -> 0 | L28: =J28 -> 22.884912 | N28: =SUMIFS('H2Heavy, capacities'!$E:$E,'H2Heavy, capacities'!$A:$A,Summary!$I28) -> 6865.7904 | O28: =SUMIFS('H2Heavy, capacities'!$H:$H,'H2Heavy, capacities'!$A:$A,Summary!$I28) -> 4119.4742 | P28: =SUMIFS('H2Heavy, capacities'!$E:$E,'H2Heavy, capacities'!$A:$A,Summary!$I28, 'H2Heavy, capacities'!$B:$B, P$4) -> 6865.7904 | Q28: =SUMIFS('H2Heavy, capacities'!$E:$E,'H2Heavy, capacities'!$A:$A,Summary!$I28, 'H2Heavy, capacities'!$B:$B, Q$4) -> 0 | R28: =SUMIFS(TYNDP2024!$C:$C,TYNDP2024!$A:$A,Summary!$I28) -> 2818.055 | S28: =SUMIFS(TYNDP2024!$C:$C,TYNDP2024!$A:$A,Summary!$I28, TYNDP2024!$B:$B,S$4) -> 0 | T28: =SUMIFS(TYNDP2024!$C:$C,TYNDP2024!$A:$A,Summary!$I28, TYNDP2024!$B:$B,T$4) -> 2818.055 | U28: =N28 -> 6865.7904 | V28: =P28 -> 6865.7904 | W28: =Q28 -> 0 | X28: =IF(ISNUMBER(U28), U28/(0.5+0.16666), "-") -> 10298.789 | Y28: =IF(ISNUMBER(V28), V28/(0.5+0.16666), "-") -> 10298.789 | Z28: =IF(ISNUMBER(W28), W28/(0.5+0.16666), "-") -> 0
B29: SE04 | C29: =J29*10^6/$O29 / 8760 -> 0.52876801 | D29: =K29*10^6/$O29 / 8760 -> 0 | F29: =IFERROR(L29*10^6/$X29 / 8760, "-") -> 0.21150509 | I29: SE04 | J29: =SUMIFS('H2Heavy, demands'!$F$2:$F$15,'H2Heavy, demands'!$A$2:$A$15,Summary!$I29) -> 5.2148954 | K29: =SUMIFS(Eurostat!$P:$P,Eurostat!$M:$M,Summary!$I29) / 10^3 * 1.5 -> 0 | L29: =J29 -> 5.2148954 | N29: =SUMIFS('H2Heavy, capacities'!$E:$E,'H2Heavy, capacities'!$A:$A,Summary!$I29) -> 1876.3985 | O29: =SUMIFS('H2Heavy, capacities'!$H:$H,'H2Heavy, capacities'!$A:$A,Summary!$I29) -> 1125.8391 | P29: =SUMIFS('H2Heavy, capacities'!$E:$E,'H2Heavy, capacities'!$A:$A,Summary!$I29, 'H2Heavy, capacities'!$B:$B, P$4) -> 1876.3985 | Q29: =SUMIFS('H2Heavy, capacities'!$E:$E,'H2Heavy, capacities'!$A:$A,Summary!$I29, 'H2Heavy, capacities'!$B:$B, Q$4) -> 0 | R29: =SUMIFS(TYNDP2024!$C:$C,TYNDP2024!$A:$A,Summary!$I29) -> 698.09 | S29: =SUMIFS(TYNDP2024!$C:$C,TYNDP2024!$A:$A,Summary!$I29, TYNDP2024!$B:$B,S$4) -> 0 | T29: =SUMIFS(TYNDP2024!$C:$C,TYNDP2024!$A:$A,Summary!$I29, TYNDP2024!$B:$B,T$4) -> 698.09 | U29: =N29 -> 1876.3985 | V29: =P29 -> 1876.3985 | W29: =Q29 -> 0 | X29: =IF(ISNUMBER(U29), U29/(0.5+0.16666), "-") -> 2814.6258 | Y29: =IF(ISNUMBER(V29), V29/(0.5+0.16666), "-") -> 2814.6258 | Z29: =IF(ISNUMBER(W29), W29/(0.5+0.16666), "-") -> 0
B30: UK00 | C30: =J30*10^6/$O30 / 8760 -> 0.51091063 | D30: =K30*10^6/$O30 / 8760 -> 0 | F30: =IFERROR(L30*10^6/$X30 / 8760, "-") -> 0.20436221 | I30: UK00 | J30: =SUMIFS('H2Heavy, demands'!$F$2:$F$15,'H2Heavy, demands'!$A$2:$A$15,Summary!$I30) -> 147.36626 | K30: =SUMIFS(Eurostat!$P:$P,Eurostat!$M:$M,Summary!$I30) / 10^3 * 1.5 -> 0 | L30: =J30 -> 147.36626 | N30: =SUMIFS('H2Heavy, capacities'!$E:$E,'H2Heavy, capacities'!$A:$A,Summary!$I30) -> 54877.934 | O30: =SUMIFS('H2Heavy, capacities'!$H:$H,'H2Heavy, capacities'!$A:$A,Summary!$I30) -> 32926.761 | P30: =SUMIFS('H2Heavy, capacities'!$E:$E,'H2Heavy, capacities'!$A:$A,Summary!$I30, 'H2Heavy, capacities'!$B:$B, P$4) -> 8207.2271 | Q30: =SUMIFS('H2Heavy, capacities'!$E:$E,'H2Heavy, capacities'!$A:$A,Summary!$I30, 'H2Heavy, capacities'!$B:$B, Q$4) -> 46670.707 | R30: =SUMIFS(TYNDP2024!$C:$C,TYNDP2024!$A:$A,Summary!$I30) -> 11563.359 | S30: =SUMIFS(TYNDP2024!$C:$C,TYNDP2024!$A:$A,Summary!$I30, TYNDP2024!$B:$B,S$4) -> 8657.193 | T30: =SUMIFS(TYNDP2024!$C:$C,TYNDP2024!$A:$A,Summary!$I30, TYNDP2024!$B:$B,T$4) -> 2906.166 | U30: =N30 -> 54877.934 | V30: =P30 -> 8207.2271 | W30: =Q30 -> 46670.707 | X30: =IF(ISNUMBER(U30), U30/(0.5+0.16666), "-") -> 82317.725 | Y30: =IF(ISNUMBER(V30), V30/(0.5+0.16666), "-") -> 12310.964 | Z30: =IF(ISNUMBER(W30), W30/(0.5+0.16666), "-") -> 70006.761

Sheet H2Heavy, capacities
A1: Country | B1: unittype | C1: Scenario | D1: Year | E1: capacity_input1 | F1: capacity_output1 | G1: node_suffix_output2 | H1: capacity_output2 | I1: Note
A2: DE00 | B2: coalCHPIndustry | C2: all | D2: 1 | E2: 23022.173 | F2: 9208.869 | G2: industry | H2: 13813.304
A3: FR00 | B3: coalCHPIndustry | C3: all | D3: 1 | E3: 6492.1236 | F3: 2596.8494 | G3: industry | H3: 3895.2742
A4: UK00 | B4: coalCHPIndustry | C4: all | D4: 1 | E4: 8207.2271 | F4: 3282.8908 | G4: industry | H4: 4924.3362
A5: ES00 | B5: coalCHPIndustry | C5: all | D5: 1 | E5: 4650.6724 | F5: 1860.269 | G5: industry | H5: 2790.4034
A6: PL00 | B6: coalCHPIndustry | C6: all | D6: 1 | E6: 5868.4496 | F6: 2347.3798 | G6: industry | H6: 3521.0698
A7: NL00 | B7: coalCHPIndustry | C7: all | D7: 1 | E7: 1115.6237 | F7: 446.24949 | G7: industry | H7: 669.37424
A8: BE00 | B8: coalCHPIndustry | C8: all | D8: 1 | E8: 1653.2737 | F8: 661.30949 | G8: industry | H8: 991.96423
A9: SE01 | B9: coalCHPIndustry | C9: all | D9: 1 | E9: 534.96174 | F9: 213.9847 | G9: industry | H9: 320.97704
A10: SE02 | B10: coalCHPIndustry | C10: all | D10: 1 | E10: 2000.058 | F10: 800.02318 | G10: industry | H10: 1200.0348
A11: SE03 | B11: coalCHPIndustry | C11: all | D11: 1 | E11: 6865.7904 | F11: 2746.3161 | G11: industry | H11: 4119.4742
A12: SE04 | B12: coalCHPIndustry | C12: all | D12: 1 | E12: 1876.3985 | F12: 750.55938 | G12: industry | H12: 1125.8391
A13: DKW1 | B13: coalCHPIndustry | C13: all | D13: 1 | E13: 18.81775 | F13: 7.5270998 | G13: industry | H13: 11.29065
... A28: EE00 | B28: bioCHPIndustry | C28: all | D28: 1 | E28: 362.91374 | F28: 145.1655 | G28: industry | H28: 217.74825

Sheet H2Heavy, demands
A1: Country | B1: Grid | C1: Node_suffix | D1: Scenario | E1: Year | F1: TWh/year | G1: Constant_share
A2: DE00 | B2: steam | C2: industry | D2: all | E2: 1 | F2: 89.390576
A3: FR00 | B3: steam | C3: industry | D3: all | E3: 1 | F3: 27.497578
A4: UK00 | B4: steam | C4: industry | D4: all | E4: 1 | F4: 147.36626
A5: ES00 | B5: steam | C5: industry | D5: all | E5: 1 | F5: 15.367019
A6: PL00 | B6: steam | C6: industry | D6: all | E6: 1 | F6: 25.172504
A7: NL00 | B7: steam | C7: industry | D7: all | E7: 1 | F7: 12.092049
A8: BE00 | B8: steam | C8: industry | D8: all | E8: 1 | F8: 9.4712948
A9: SE01 | B9: steam | C9: industry | D9: all | E9: 1 | F9: 1.1403121
A10: SE02 | B10: steam | C10: industry | D10: all | E10: 1 | F10: 5.0979269
A11: SE03 | B11: steam | C11: industry | D11: all | E11: 1 | F11: 22.884912
A12: SE04 | B12: steam | C12: industry | D12: all | E12: 1 | F12: 5.2148954
A13: LT00 | B13: steam | C13: industry | D13: all | E13: 1 | F13: 3.9464943
... A15: EE00 | B15: steam | C15: industry | D15: all | E15: 1 | F15: 1.5351419

Sheet TYNDP2024
A1: Country | B1: unittype | C1: 2030 | D1: 2040
C2: MW | D2: MW
A3: AT00 | B3: coalCHPIndustry | C3: =SUMIFS($N:$N,$J:$J,$A3,$K:$K,$B3,$M:$M,C$1) -> 845.24 | D3: =SUMIFS($N:$N,$J:$J,$A3,$K:$K,$B3,$M:$M,D$1) -> 845.24 | J3: Country | K3: Generator_ID | L3: Scenario | M3: Year | N3: capacity_output1
A4: BE00 | B4: coalCHPIndustry | C4: =SUMIFS($N:$N,$J:$J,$A4,$K:$K,$B4,$M:$M,C$1) -> 1594 | D4: =SUMIFS($N:$N,$J:$J,$A4,$K:$K,$B4,$M:$M,D$1) -> 1594 | J4: AT00 | K4: coalCHPIndustry | L4: National Trends | M4: 2030 | N4: 845.24
A5: CH00 | B5: coalCHPIndustry | C5: =SUMIFS($N:$N,$J:$J,$A5,$K:$K,$B5,$M:$M,C$1) -> 566.599 | D5: =SUMIFS($N:$N,$J:$J,$A5,$K:$K,$B5,$M:$M,D$1) -> 440.442 | J5: AT00 | K5: bioCHPIndustry | L5: National Trends | M5: 2030 | N5: 760.645
A6: DE00 | B6: coalCHPIndustry | C6: =SUMIFS($N:$N,$J:$J,$A6,$K:$K,$B6,$M:$M,C$1) -> 7280.02 | D6: =SUMIFS($N:$N,$J:$J,$A6,$K:$K,$B6,$M:$M,D$1) -> 2340.1 | J6: BE00 | K6: coalCHPIndustry | L6: National Trends | M6: 2030 | N6: 1594
A7: DKE1 | B7: coalCHPIndustry | C7: =SUMIFS($N:$N,$J:$J,$A7,$K:$K,$B7,$M:$M,C$1) -> 0 | D7: =SUMIFS($N:$N,$J:$J,$A7,$K:$K,$B7,$M:$M,D$1) -> 0 | J7: BE00 | K7: bioCHPIndustry | L7: National Trends | M7: 2030 | N7: 614.625
A8: DKW1 | B8: coalCHPIndustry | C8: =SUMIFS($N:$N,$J:$J,$A8,$K:$K,$B8,$M:$M,C$1) -> 0 | D8: =SUMIFS($N:$N,$J:$J,$A8,$K:$K,$B8,$M:$M,D$1) -> 0 | J8: CH00 | K8: coalCHPIndustry | L8: National Trends | M8: 2030 | N8: 566.599
A9: EE00 | B9: coalCHPIndustry | C9: =SUMIFS($N:$N,$J:$J,$A9,$K:$K,$B9,$M:$M,C$1) -> 134.952 | D9: =SUMIFS($N:$N,$J:$J,$A9,$K:$K,$B9,$M:$M,D$1) -> 134.952 | J9: CH00 | K9: bioCHPIndustry | L9: National Trends | M9: 2030 | N9: 425.889
A10: ES00 | B10: coalCHPIndustry | C10: =SUMIFS($N:$N,$J:$J,$A10,$K:$K,$B10,$M:$M,C$1) -> 3980.011 | D10: =SUMIFS($N:$N,$J:$J,$A10,$K:$K,$B10,$M:$M,D$1) -> 3980.011 | J10: DE00 | K10: coalCHPIndustry | L10: National Trends | M10: 2030 | N10: 7280.02
A11: FI00 | B11: coalCHPIndustry | C11: =SUMIFS($N:$N,$J:$J,$A11,$K:$K,$B11,$M:$M,C$1) -> 390.5 | D11: =SUMIFS($N:$N,$J:$J,$A11,$K:$K,$B11,$M:$M,D$1) -> 133 | J11: DE00 | K11: bioCHPIndustry | L11: National Trends | M11: 2030 | N11: 13067.586
A12: FR00 | B12: coalCHPIndustry | C12: =SUMIFS($N:$N,$J:$J,$A12,$K:$K,$B12,$M:$M,C$1) -> 4400 | D12: =SUMIFS($N:$N,$J:$J,$A12,$K:$K,$B12,$M:$M,D$1) -> 600.04 | J12: DKW1 | K12: bioCHPIndustry | L12: National Trends | M12: 2030 | N12: 7.26
A13: LT00 | B13: coalCHPIndustry | C13: =SUMIFS($N:$N,$J:$J,$A13,$K:$K,$B13,$M:$M,C$1) -> 106.89 | D13: =SUMIFS($N:$N,$J:$J,$A13,$K:$K,$B13,$M:$M,D$1) -> 106.89 | J13: EE00 | K13: coalCHPIndustry | L13: National Trends | M13: 2030 | N13: 134.952
A14: LV00 | B14: coalCHPIndustry | C14: =SUMIFS($N:$N,$J:$J,$A14,$K:$K,$B14,$M:$M,C$1) -> 0 | D14: =SUMIFS($N:$N,$J:$J,$A14,$K:$K,$B14,$M:$M,D$1) -> 0 | J14: EE00 | K14: bioCHPIndustry | L14: National Trends | M14: 2030 | N14: 167.65
A15: NL00 | B15: coalCHPIndustry | C15: =SUMIFS($N:$N,$J:$J,$A15,$K:$K,$B15,$M:$M,C$1) -> 4381.5 | D15: =SUMIFS($N:$N,$J:$J,$A15,$K:$K,$B15,$M:$M,D$1) -> 1722.5 | J15: ES00 | K15: coalCHPIndustry | L15: National Trends | M15: 2030 | N15: 3980.011
... A46: UK00 | B46: bioCHPIndustry | C46: =SUMIFS($N:$N,$J:$J,$A46,$K:$K,$B46,$M:$M,C$1) -> 2906.166 | D46: =SUMIFS($N:$N,$J:$J,$A46,$K:$K,$B46,$M:$M,D$1) -> 8155.727 | J46: EE00 | K46: coalCHPIndustry | L46: National Trends | M46: 2040 | N46: 134.952
J47: EE00 | K47: bioCHPIndustry | L47: National Trends | M47: 2040 | N47: 134.65
J48: ES00 | K48: coalCHPIndustry | L48: National Trends | M48: 2040 | N48: 3980.011
J49: ES00 | K49: bioCHPIndustry | L49: National Trends | M49: 2040 | N49: 1730
J50: FI00 | K50: coalCHPIndustry | L50: National Trends | M50: 2040 | N50: 133
J51: FI00 | K51: bioCHPIndustry | L51: National Trends | M51: 2040 | N51: 2624.82
J52: FR00 | K52: coalCHPIndustry | L52: National Trends | M52: 2040 | N52: 600.04
J53: FR00 | K53: bioCHPIndustry | L53: National Trends | M53: 2040 | N53: 2451.06
J54: LT00 | K54: coalCHPIndustry | L54: National Trends | M54: 2040 | N54: 106.89
J55: LT00 | K55: bioCHPIndustry | L55: National Trends | M55: 2040 | N55: 209.89
J56: LV00 | K56: bioCHPIndustry | L56: National Trends | M56: 2040 | N56: 299.927
J57: NL00 | K57: coalCHPIndustry | L57: National Trends | M57: 2040 | N57: 1722.5
J58: NL00 | K58: bioCHPIndustry | L58: National Trends | M58: 2040 | N58: 208.6
... J69: UK00 | K69: bioCHPIndustry | L69: National Trends | M69: 2040 | N69: 8155.727

Sheet Eurostat
A2: Source:
A3: https://ec.europa.eu/eurostat/databrowser/view/nrg_ind_peh__custom_16800527/default/table?lang=en
A5: Data extracted on 21/05/2025 13:00:30 from [ESTAT]
A6: Dataset: | B6: Gross and net production of electricity and derived heat by type of plant and operator [nrg_ind_peh__custom_16800527]
A7: Last updated: | B7: 24/04/2025 23:00
A9: Time frequency | C9: Annual
A10: Type of plant | C10: Total
A11: Operator/Trader | C11: Autoproducers
A12: Energy balance | C12: Net electricity production
A13: Standard international energy product classification (SIEC) | C13: Total
A14: Unit of measure | C14: Gigawatt-hour
A16: TIME | B16: 2014 | C16: 2015 | D16: 2016 | E16: 2017 | F16: 2018 | G16: 2019 | H16: 2020 | I16: 2021 | J16: 2022 | K16: 2023 | M16: NEBB country | N16: 2023 | O16: 2025 | P16: 2030 | Q16: 2035
A17: GEO (Labels)
A18: European Union - 27 countries (from 2020) | B18: 199505.28 | C18: 213682.07 | D18: 218359.9 | E18: 229663.6 | F18: 242427.19 | G18: 249629.64 | H18: 253090.35 | I18: 293507.51 | J18: 291387.14 | K18: 301611.94
A19: Euro area – 20 countries (from 2023) | B19: 168075.03 | C19: 179857.75 | D19: 183518.11 | E19: 193147.69 | F19: 202222.39 | G19: 206643.77 | H19: 207127.16 | I19: 245409.02 | J19: 239814.33 | K19: 244794.17
A20: Belgium | B20: 9510.5 | C20: 9745.3 | D20: 10199 | E20: 11154.1 | F20: 11837.9 | G20: 13541.8 | H20: 14746.6 | I20: 15238.4 | J20: 15683.4 | K20: 16723.9 | M20: BE00 | N20: {=TREND($E20:$K20,$E$16:$K$16,N$16)} -> 16928.407 | O20: {=(TREND($E20:$K20,$E$16:$K$16,O$16) - TREND($E20:$K20,$E$16:$K$16,$N$16))/4 + $N20} -> 17394.425 | P20: {=(TREND($E20:$K20,$E$16:$K$16,P$16) - TREND($E20:$K20,$E$16:$K$16,$N$16))/4 + $N20} -> 18559.47 | Q20: {=(TREND($E20:$K20,$E$16:$K$16,Q$16) - TREND($E20:$K20,$E$16:$K$16,$N$16))/4 + $N20} -> 19724.514
A21: Bulgaria | B21: 244 | C21: 353 | D21: 432 | E21: 585.849 | F21: 579.407 | G21: 602.752 | H21: 643.23 | I21: 797.813 | J21: 787.513 | K21: 821.72 | N21: {=TREND($B21:$K21,$B$16:$K$16,N$16)} -> 864.69996 | O21: {=(TREND($E21:$K21,$E$16:$K$16,O$16) - TREND($E21:$K21,$E$16:$K$16,$N$16))/4 + $N21} -> 888.2515 | P21: {=(TREND($E21:$K21,$E$16:$K$16,P$16) - TREND($E21:$K21,$E$16:$K$16,$N$16))/4 + $N21} -> 947.13034 | Q21: {=(TREND($E21:$K21,$E$16:$K$16,Q$16) - TREND($E21:$K21,$E$16:$K$16,$N$16))/4 + $N21} -> 1006.0092
A22: Czechia | B22: 8267 | C22: 8398 | D22: 8513 | E22: 8154.542 | F22: 7886.856 | G22: 7833.055 | H22: 8084.031 | I22: 8414.379 | J22: 6609.859 | K22: 7211.711 | M22: CZ00 | N22: {=TREND($B22:$K22,$B$16:$K$16,N$16)} -> 7316.1607 | O22: {=(TREND($E22:$K22,$E$16:$K$16,O$16) - TREND($E22:$K22,$E$16:$K$16,$N$16))/4 + $N22} -> 7230.4257 | P22: {=(TREND($E22:$K22,$E$16:$K$16,P$16) - TREND($E22:$K22,$E$16:$K$16,$N$16))/4 + $N22} -> 7016.0881 | Q22: {=(TREND($E22:$K22,$E$16:$K$16,Q$16) - TREND($E22:$K22,$E$16:$K$16,$N$16))/4 + $N22} -> 6801.7504
A23: Denmark | B23: 2602.249 | C23: 2793.327 | D23: 2777.789 | E23: 2830.822 | F23: 3097.156 | G23: 3202.224 | H23: 3418.779 | I23: 3563.583 | J23: 4469.026 | K23: 5425.921 | M23: DK | N23: {=TREND($B23:$K23,$B$16:$K$16,N$16)} -> 4589.2017 | O23: {=(TREND($E23:$K23,$E$16:$K$16,O$16) - TREND($E23:$K23,$E$16:$K$16,$N$16))/4 + $N23} -> 4783.673 | P23: {=(TREND($E23:$K23,$E$16:$K$16,P$16) - TREND($E23:$K23,$E$16:$K$16,$N$16))/4 + $N23} -> 5269.8514 | Q23: {=(TREND($E23:$K23,$E$16:$K$16,Q$16) - TREND($E23:$K23,$E$16:$K$16,$N$16))/4 + $N23} -> 5756.0298
A24: Germany | B24: 42176 | C24: 46716 | D24: 50899 | E24: 52778 | F24: 50942 | G24: 49358 | H24: 49107 | I24: 50465 | J24: 45456 | K24: 43754 | M24: DE00 | N24: {=TREND($B24:$K24,$B$16:$K$16,N$16)} -> 47909.145 | O24: {=(TREND($E24:$K24,$E$16:$K$16,O$16) - TREND($E24:$K24,$E$16:$K$16,$N$16))/4 + $N24} -> 47249.556 | P24: {=(TREND($E24:$K24,$E$16:$K$16,P$16) - TREND($E24:$K24,$E$16:$K$16,$N$16))/4 + $N24} -> 45600.583 | Q24: {=(TREND($E24:$K24,$E$16:$K$16,Q$16) - TREND($E24:$K24,$E$16:$K$16,$N$16))/4 + $N24} -> 43951.61
A25: Estonia | B25: 52 | C25: 138 | D25: 136 | E25: 101 | F25: 105 | G25: 80.6 | H25: 158.518 | I25: 154.658 | J25: 152.662 | K25: 46.089 | M25: EE00 | N25: {=TREND($B25:$K25,$B$16:$K$16,N$16)} -> 120.38576 | O25: {=(TREND($E25:$K25,$E$16:$K$16,O$16) - TREND($E25:$K25,$E$16:$K$16,$N$16))/4 + $N25} -> 120.46878 | P25: {=(TREND($E25:$K25,$E$16:$K$16,P$16) - TREND($E25:$K25,$E$16:$K$16,$N$16))/4 + $N25} -> 120.67633 | Q25: {=(TREND($E25:$K25,$E$16:$K$16,Q$16) - TREND($E25:$K25,$E$16:$K$16,$N$16))/4 + $N25} -> 120.88387
A26: Ireland | B26: 2037.197 | C26: 2134.069 | D26: 2172.434 | E26: 2175.469 | F26: 2148.292 | G26: 2112.973 | H26: 2139.648 | I26: 2155.432 | J26: 2205.823 | K26: 2150.654 | N26: {=TREND($B26:$K26,$B$16:$K$16,N$16)} -> 2178.5336 | O26: {=(TREND($E26:$K26,$E$16:$K$16,O$16) - TREND($E26:$K26,$E$16:$K$16,$N$16))/4 + $N26} -> 2180.0171 | P26: {=(TREND($E26:$K26,$E$16:$K$16,P$16) - TREND($E26:$K26,$E$16:$K$16,$N$16))/4 + $N26} -> 2183.7259 | Q26: {=(TREND($E26:$K26,$E$16:$K$16,Q$16) - TREND($E26:$K26,$E$16:$K$16,$N$16))/4 + $N26} -> 2187.4346
A27: Greece | B27: 1680 | C27: 2124 | D27: 1767 | E27: 1677.751 | F27: 2122.604 | G27: 2282.178 | H27: 1944.982 | I27: 2014.389 | J27: 2280.46 | K27: 2727.4 | N27: {=TREND($B27:$K27,$B$16:$K$16,N$16)} -> 2408.9864 | O27: {=(TREND($E27:$K27,$E$16:$K$16,O$16) - TREND($E27:$K27,$E$16:$K$16,$N$16))/4 + $N27} -> 2466.0733 | P27: {=(TREND($E27:$K27,$E$16:$K$16,P$16) - TREND($E27:$K27,$E$16:$K$16,$N$16))/4 + $N27} -> 2608.7907 | Q27: {=(TREND($E27:$K27,$E$16:$K$16,Q$16) - TREND($E27:$K27,$E$16:$K$16,$N$16))/4 + $N27} -> 2751.5081
A28: Spain | B28: 30870 | C28: 32280 | D28: 32913 | E28: 34958 | F28: 36162 | G28: 36899 | H28: 34345 | I28: 36402 | J28: 29643 | K28: 32460 | M28: ES00 | N28: {=TREND($B28:$K28,$B$16:$K$16,N$16)} -> 34025.764 | O28: {=(TREND($E28:$K28,$E$16:$K$16,O$16) - TREND($E28:$K28,$E$16:$K$16,$N$16))/4 + $N28} -> 33650.246 | P28: {=(TREND($E28:$K28,$E$16:$K$16,P$16) - TREND($E28:$K28,$E$16:$K$16,$N$16))/4 + $N28} -> 32711.451 | Q28: {=(TREND($E28:$K28,$E$16:$K$16,Q$16) - TREND($E28:$K28,$E$16:$K$16,$N$16))/4 + $N28} -> 31772.656
A29: France | B29: 15474.469 | C29: 16119.91 | D29: 15693.455 | E29: 16301.897 | F29: 19749.308 | G29: 21210.55 | H29: 20523.791 | I29: 20166.675 | J29: 21775.627 | K29: 20567.54 | M29: FR00 | N29: {=TREND($B29:$K29,$B$16:$K$16,N$16)} -> 22083.432 | O29: {=(TREND($E29:$K29,$E$16:$K$16,O$16) - TREND($E29:$K29,$E$16:$K$16,$N$16))/4 + $N29} -> 22365.676 | P29: {=(TREND($E29:$K29,$E$16:$K$16,P$16) - TREND($E29:$K29,$E$16:$K$16,$N$16))/4 + $N29} -> 23071.287 | Q29: {=(TREND($E29:$K29,$E$16:$K$16,Q$16) - TREND($E29:$K29,$E$16:$K$16,$N$16))/4 + $N29} -> 23776.899
A30: Croatia | B30: 326 | C30: 300 | D30: 321 | E30: 399 | F30: 354 | G30: 356.6 | H30: 384.5 | I30: 328.5 | J30: 269.3 | K30: 262.8 | N30: {=TREND($B30:$K30,$B$16:$K$16,N$16)} -> 308.70364 | O30: {=(TREND($E30:$K30,$E$16:$K$16,O$16) - TREND($E30:$K30,$E$16:$K$16,$N$16))/4 + $N30} -> 297.88042 | P30: {=(TREND($E30:$K30,$E$16:$K$16,P$16) - TREND($E30:$K30,$E$16:$K$16,$N$16))/4 + $N30} -> 270.82239 | Q30: {=(TREND($E30:$K30,$E$16:$K$16,Q$16) - TREND($E30:$K30,$E$16:$K$16,$N$16))/4 + $N30} -> 243.76435
A31: Italy | B31: 15143.832 | C31: 18342.052 | D31: 17877.681 | E31: 19141.137 | F31: 22024.172 | G31: 21609.1 | H31: 19670.68 | I31: 48597.187 | J31: 52269.82 | K31: 51662.157 | N31: {=TREND($B31:$K31,$B$16:$K$16,N$16)} -> 48295.52 | O31: =AVERAGE($I31:$K31) -> 50843.055 | P31: =AVERAGE($I31:$K31) -> 50843.055 | Q31: =AVERAGE($I31:$K31) -> 50843.055
A32: Cyprus | B32: 78.233 | C32: 86.727 | D32: 97.96 | E32: 107.961 | F32: 122.161 | G32: 138.033 | H32: 149.871 | I32: 225.367 | J32: 291.957 | K32: 417.664 | N32: {=TREND($B32:$K32,$B$16:$K$16,N$16)} -> 315.32411 | O32: {=(TREND($E32:$K32,$E$16:$K$16,O$16) - TREND($E32:$K32,$E$16:$K$16,$N$16))/4 + $N32} -> 339.53902 | P32: {=(TREND($E32:$K32,$E$16:$K$16,P$16) - TREND($E32:$K32,$E$16:$K$16,$N$16))/4 + $N32} -> 400.0763 | Q32: {=(TREND($E32:$K32,$E$16:$K$16,Q$16) - TREND($E32:$K32,$E$16:$K$16,$N$16))/4 + $N32} -> 460.61357
A33: Latvia | B33: 244 | C33: 241 | D33: 192.82 | E33: 185.669 | F33: 177.712 | G33: 174.877 | H33: 169.497 | I33: 156.993 | J33: 199.382 | K33: 316.082 | M33: LV00 | N33: {=TREND($B33:$K33,$B$16:$K$16,N$16)} -> 209.26482 | O33: {=(TREND($E33:$K33,$E$16:$K$16,O$16) - TREND($E33:$K33,$E$16:$K$16,$N$16))/4 + $N33} -> 216.7058 | P33: {=(TREND($E33:$K33,$E$16:$K$16,P$16) - TREND($E33:$K33,$E$16:$K$16,$N$16))/4 + $N33} -> 235.30826 | Q33: {=(TREND($E33:$K33,$E$16:$K$16,Q$16) - TREND($E33:$K33,$E$16:$K$16,$N$16))/4 + $N33} -> 253.91071
A34: Lithuania | B34: 690 | C34: 875 | D34: 837 | E34: 781.6 | F34: 601.6 | G34: 769 | H34: 753.1 | I34: 642.6 | J34: 667.7 | K34: 487 | M34: LT00 | N34: {=TREND($B34:$K34,$B$16:$K$16,N$16)} -> 596.78182 | O34: {=(TREND($E34:$K34,$E$16:$K$16,O$16) - TREND($E34:$K34,$E$16:$K$16,$N$16))/4 + $N34} -> 581.10325 | P34: {=(TREND($E34:$K34,$E$16:$K$16,P$16) - TREND($E34:$K34,$E$16:$K$16,$N$16))/4 + $N34} -> 541.90682 | Q34: {=(TREND($E34:$K34,$E$16:$K$16,Q$16) - TREND($E34:$K34,$E$16:$K$16,$N$16))/4 + $N34} -> 502.71039
A35: Luxembourg | B35: 269.364 | C35: 274.201 | D35: 285.123 | E35: 278.269 | F35: 282.107 | G35: 284.981 | H35: 308.518 | I35: 312.351 | J35: 387.077 | K35: 388.809 | N35: {=TREND($B35:$K35,$B$16:$K$16,N$16)} -> 364.21358 | O35: {=(TREND($E35:$K35,$E$16:$K$16,O$16) - TREND($E35:$K35,$E$16:$K$16,$N$16))/4 + $N35} -> 374.37305 | P35: {=(TREND($E35:$K35,$E$16:$K$16,P$16) - TREND($E35:$K35,$E$16:$K$16,$N$16))/4 + $N35} -> 399.77171 | Q35: {=(TREND($E35:$K35,$E$16:$K$16,Q$16) - TREND($E35:$K35,$E$16:$K$16,$N$16))/4 + $N35} -> 425.17037
A36: Hungary | B36: 592 | C36: 740 | D36: 929 | E36: 1215 | F36: 1479 | G36: 1880 | H36: 2262 | I36: 2763 | J36: 3112 | K36: 3974 | N36: {=TREND($B36:$K36,$B$16:$K$16,N$16)} -> 3524.2545 | O36: {=(TREND($E36:$K36,$E$16:$K$16,O$16) - TREND($E36:$K36,$E$16:$K$16,$N$16))/4 + $N36} -> 3746.1474 | P36: {=(TREND($E36:$K36,$E$16:$K$16,P$16) - TREND($E36:$K36,$E$16:$K$16,$N$16))/4 + $N36} -> 4300.8795 | Q36: {=(TREND($E36:$K36,$E$16:$K$16,Q$16) - TREND($E36:$K36,$E$16:$K$16,$N$16))/4 + $N36} -> 4855.6117
