Workbook
Name Bottom: OFFSET(#REF!,1,0,COUNT(#REF!),1)
Name fd: OFFSET(#REF!,1,0,COUNT(#REF!),1)
Name Labels: OFFSET(Bottom,0,-1)
Name SecondQ: OFFSET(#REF!,1,0,COUNT(#REF!),1)
Name ThirdQ: OFFSET(#REF!,1,0,COUNT(#REF!),1)

Sheet vomcost mult
A1: Data extracted on 10/03/2026 09:16:55 from [ESTAT]
A2: Dataset: | B2: Real GDP per capita [sdg_08_10]
A3: Last updated: | B3: 09/03/2026 23:00
A5: Time frequency | C5: Annual
A6: Unit of measure | C6: Chain linked volumes (2020), euro per capita
A7: National accounts indicator (ESA 2010) | C7: Gross domestic product at market prices
A9: TIME | B9: 2020 | C9: 2021 | D9: 2022 | E9: 2023 | F9: 2024
A10: GEO (Labels) | J10: model country | O10: GDP pc of country | P10: vomCosts country multiplier | Q10: region multiplier | R10: final
A11: European Union - 27 countries (from 2020) | B11: 30510 | C11: 32470 | D11: 33420 | E11: 33400 | F11: 33650 | N11: AT00 | O11: =SUMIFS($F:$F,$J:$J,LEFT($N11,2)) -> 45140 | P11: =LOG(O11/O$34) -> 0.12757649 | Q11: 1 | R11: =ROUND(P11*Q11, 3) -> 0.128
A12: Euro area – 21 countries (from 2026) | B12: 33160 | C12: 35280 | D12: 36400 | E12: 36340 | F12: 36530 | N12: BE00 | O12: =SUMIFS($F:$F,$J:$J,LEFT($N12,2)) -> 44440 | P12: =LOG(O12/O$34) -> 0.12078898 | Q12: 1 | R12: =ROUND(P12*Q12, 3) -> 0.121
A13: Euro area – 20 countries (2023-2025) | B13: 33610 | C13: 35750 | D13: 36880 | E13: 36810 | F13: 36990 | N13: CH00 | O13: =SUMIFS($F:$F,$J:$J,LEFT($N13,2)) -> 96081 | P13: =LOG(O13/O$34) -> 0.45565245 | Q13: 1 | R13: =ROUND(P13*Q13, 3) -> 0.456
A14: Belgium | B14: 40190 | C14: 42530 | D14: 43860 | E14: 44230 | F14: 44440 | J14: BE | N14: DE00 | O14: =SUMIFS($F:$F,$J:$J,LEFT($N14,2)) -> 43110 | P14: =LOG(O14/O$34) -> 0.10759295 | Q14: 1 | R14: =ROUND(P14*Q14, 3) -> 0.108
A15: Bulgaria | B15: 9440 | C15: 10250 | D15: 10740 | E15: 10950 | F15: 11330 | N15: DKE1 | O15: =SUMIFS($F:$F,$J:$J,LEFT($N15,2)) -> 58160 | P15: =LOG(O15/O$34) -> 0.23763933 | Q15: 1.05 | R15: =ROUND(P15*Q15, 3) -> 0.25
A16: Czechia | B16: 20980 | C16: 21830 | D16: 21910 | E16: 21680 | F16: 21920 | N16: DKW1 | O16: =SUMIFS($F:$F,$J:$J,LEFT($N16,2)) -> 58160 | P16: =LOG(O16/O$34) -> 0.23763933 | Q16: 1 | R16: =ROUND(P16*Q16, 3) -> 0.238
A17: Denmark | B17: 53540 | C17: 56780 | D17: 56530 | E17: 56470 | F17: 58160 | J17: DK | N17: EE00 | O17: =SUMIFS($F:$F,$J:$J,LEFT($N17,2)) -> 21060 | P17: =LOG(O17/O$34) -> -0.2035267 | Q17: 1 | R17: =ROUND(P17*Q17, 3) -> -0.204
A18: Germany | B18: 42020 | C18: 43730 | D18: 44230 | E18: 43450 | F18: 43110 | J18: DE | N18: ES00 | O18: =SUMIFS($F:$F,$J:$J,LEFT($N18,2)) -> 27800 | P18: =LOG(O18/O$34) -> -0.082940273 | Q18: 1 | R18: =ROUND(P18*Q18, 3) -> -0.083
A19: Estonia | B19: 20960 | C19: 22670 | D19: 22370 | E19: 21210 | F19: 21060 | J19: EE | N19: FI00 | O19: =SUMIFS($F:$F,$J:$J,LEFT($N19,2)) -> 43110 | P19: =LOG(O19/O$34) -> 0.10759295 | Q19: 1 | R19: =ROUND(P19*Q19, 3) -> 0.108
A20: Ireland | B20: 75820 | C20: 87160 | D20: 91760 | E20: 87810 | F20: 88600 | N20: FR00 | O20: =SUMIFS($F:$F,$J:$J,LEFT($N20,2)) -> 38110 | P20: =LOG(O20/O$34) -> 0.05405388 | Q20: 1 | R20: =ROUND(P20*Q20, 3) -> 0.054
A21: Greece | B21: 15660 | C21: 17110 | D21: 18160 | E21: 18600 | F21: 19020 | N21: LT00 | O21: =SUMIFS($F:$F,$J:$J,LEFT($N21,2)) -> 19690 | P21: =LOG(O21/O$34) -> -0.23273935 | Q21: 1 | R21: =ROUND(P21*Q21, 3) -> -0.233
A22: Spain | B22: 23850 | C22: 25440 | D22: 26820 | E22: 27150 | F22: 27800 | J22: ES | N22: LV00 | O22: =SUMIFS($F:$F,$J:$J,LEFT($N22,2)) -> 16910 | P22: =LOG(O22/O$34) -> -0.29884146 | Q22: 1 | R22: =ROUND(P22*Q22, 3) -> -0.299
A23: France | B23: 34280 | C23: 36470 | D23: 37320 | E23: 37760 | F23: 38110 | J23: FR | N23: NL00 | O23: =SUMIFS($F:$F,$J:$J,LEFT($N23,2)) -> 50880 | P23: =LOG(O23/O$34) -> 0.17956203 | Q23: 1 | R23: =ROUND(P23*Q23, 3) -> 0.18
A24: Croatia | B24: 12980 | C24: 14750 | D24: 15900 | E24: 16490 | F24: 17060 | N24: NOM1 | O24: =SUMIFS($F:$F,$J:$J,LEFT($N24,2)) -> 66460 | P24: =LOG(O24/O$34) -> 0.29557527 | Q24: 1.05 | R24: =ROUND(P24*Q24, 3) -> 0.31
A25: Italy | B25: 28100 | C25: 30760 | D25: 32310 | E25: 32630 | F25: 32900 | N25: NON1 | O25: =SUMIFS($F:$F,$J:$J,LEFT($N25,2)) -> 66460 | P25: =LOG(O25/O$34) -> 0.29557527 | Q25: 1.1 | R25: =ROUND(P25*Q25, 3) -> 0.325
A26: Cyprus | B26: 24630 | C26: 27030 | D26: 28730 | E26: 29200 | F26: 29820 | N26: NOS0 | O26: =SUMIFS($F:$F,$J:$J,LEFT($N26,2)) -> 66460 | P26: =LOG(O26/O$34) -> 0.29557527 | Q26: 1 | R26: =ROUND(P26*Q26, 3) -> 0.296
A27: Latvia | B27: 15370 | C27: 16580 | D27: 16890 | E27: 16770 | F27: 16910 | J27: LV | N27: PL00 | O27: =SUMIFS($F:$F,$J:$J,LEFT($N27,2)) -> 16470 | P27: =LOG(O27/O$34) -> -0.31029147 | Q27: 1 | R27: =ROUND(P27*Q27, 3) -> -0.31
A28: Lithuania | B28: 17890 | C28: 19040 | D28: 19350 | E28: 19220 | F28: 19690 | J28: LT | N28: SE01 | O28: =SUMIFS($F:$F,$J:$J,LEFT($N28,2)) -> 48310 | P28: =LOG(O28/O$34) -> 0.15705197 | Q28: 1.15 | R28: =ROUND(P28*Q28, 3) -> 0.181
A29: Luxembourg | B29: 102190 | C29: 107570 | D29: 104100 | E29: 102250 | F29: 101000 | J29: - | N29: SE02 | O29: =SUMIFS($F:$F,$J:$J,LEFT($N29,2)) -> 48310 | P29: =LOG(O29/O$34) -> 0.15705197 | Q29: 1.1 | R29: =ROUND(P29*Q29, 3) -> 0.173
A30: Hungary | B30: 14370 | C30: 15470 | D30: 16160 | E30: 16050 | F30: 16190 | N30: SE03 | O30: =SUMIFS($F:$F,$J:$J,LEFT($N30,2)) -> 48310 | P30: =LOG(O30/O$34) -> 0.15705197 | Q30: 1.05 | R30: =ROUND(P30*Q30, 3) -> 0.165
A31: Malta | B31: 27870 | C31: 31420 | D31: 31390 | E31: 33380 | F31: 34480 | N31: SE04 | O31: =SUMIFS($F:$F,$J:$J,LEFT($N31,2)) -> 48310 | P31: =LOG(O31/O$34) -> 0.15705197 | Q31: 1 | R31: =ROUND(P31*Q31, 3) -> 0.157
A32: Netherlands | B32: 46810 | C32: 49490 | D32: 51480 | E32: 50660 | F32: 50880 | J32: NL | N32: UK00 | O32: =SUMIFS($F:$F,$J:$J,LEFT($N32,2)) -> 49193 | P32: =LOG(O32/O$34) -> 0.16491824 | Q32: 1 | R32: =ROUND(P32*Q32, 3) -> 0.165
A33: Austria | B33: 42650 | C33: 44580 | D33: 46430 | E33: 45670 | F33: 45140 | J33: AT
A34: Poland | B34: 14310 | C34: 15380 | D34: 15840 | E34: 15950 | F34: 16470 | J34: PL | N34: EU | O34: =F11 -> 33650
A35: Portugal | B35: 19360 | C35: 20390 | D35: 21690 | E35: 22130 | F35: 22370
A36: Romania | B36: 11390 | C36: 12130 | D36: 12690 | E36: 12970 | F36: 13090
A37: Slovenia | B37: 22230 | C37: 24040 | D37: 24660 | E37: 25120 | F37: 25480
A38: Slovakia | B38: 17270 | C38: 18320 | D38: 18360 | E38: 18750 | F38: 19110
A39: Finland | B39: 42740 | C39: 43800 | D39: 44010 | E39: 43280 | F39: 43110 | J39: FI
A40: Sweden | B40: 46180 | C40: 48300 | D40: 48390 | E40: 47960 | F40: 48310 | J40: SE
A41: Iceland | B41: 54190 | C41: 56150 | D41: 59720 | E41: 61170 | F41: 59270
A42: Norway | B42: 62400 | C42: 64640 | D42: 66670 | E42: 66140 | F42: 66460 | J42: NO
...

Sheet VRE-NT2030
A1: country | B1: region | C1: techname | D1: scenario | E1: capacity
A2: =LEFT(B2,2) -> AT | B2: AT00 | C2: PV | D2: NT2030 | E2: 3019.7
A3: =LEFT(B3,2) -> AT | B3: AT00 | C3: wind_onshore | D3: NT2030 | E3: 8295.4
A4: =LEFT(B4,2) -> BE | B4: BE00 | C4: PV | D4: NT2030 | E4: 12429.3
A5: =LEFT(B5,2) -> BE | B5: BE00 | C5: wind_offshore | D5: NT2030 | E5: 2261.8 | J5: AT00
A6: =LEFT(B6,2) -> BE | B6: BE00 | C6: wind_onshore | D6: NT2030 | E6: 6109.9 | J6: BE00
A7: =LEFT(B7,2) -> CH | B7: CH00 | C7: PV | D7: NT2030 | E7: 6242.8 | J7: CH00
A8: =LEFT(B8,2) -> CH | B8: CH00 | C8: wind_onshore | D8: NT2030 | E8: 202.8 | J8: DE00
A9: =LEFT(B9,2) -> DE | B9: DE00 | C9: PV | D9: NT2030 | E9: 58458.9 | J9: DKE1
A10: =LEFT(B10,2) -> DE | B10: DE00 | C10: wind_offshore | D10: NT2030 | E10: 21165 | J10: DKW1
A11: =LEFT(B11,2) -> DE | B11: DE00 | C11: wind_onshore | D11: NT2030 | E11: 129413.7 | J11: EE00
A12: =LEFT(B12,2) -> DK | B12: DKE1 | C12: PV | D12: NT2030 | E12: 634.6 | J12: ES00
A13: =LEFT(B13,2) -> DK | B13: DKE1 | C13: wind_offshore | D13: NT2030 | E13: 1545 | J13: FI00
A14: =LEFT(B14,2) -> DK | B14: DKE1 | C14: wind_onshore | D14: NT2030 | E14: 1561.4 | J14: FR00
A15: =LEFT(B15,2) -> DK | B15: DKW1 | C15: PV | D15: NT2030 | E15: 1670.6 | J15: LT00
A16: =LEFT(B16,2) -> DK | B16: DKW1 | C16: wind_offshore | D16: NT2030 | E16: 760.8 | J16: LV00
... A26: =LEFT(B26,2) -> FR | B26: FR00 | C26: PV | D26: NT2030 | E26: 72002.1 | J26: UK00
A27: =LEFT(B27,2) -> FR | B27: FR00 | C27: wind_offshore | D27: NT2030 | E27: 2
A28: =LEFT(B28,2) -> FR | B28: FR00 | C28: wind_onshore | D28: NT2030 | E28: 64363
A29: =LEFT(B29,2) -> LT | B29: LT00 | C29: PV | D29: NT2030 | E29: 164
A30: =LEFT(B30,2) -> LT | B30: LT00 | C30: wind_onshore | D30: NT2030 | E30: 671
A31: =LEFT(B31,2) -> LV | B31: LV00 | C31: PV | D31: NT2030 | E31: 7
A32: =LEFT(B32,2) -> LV | B32: LV00 | C32: wind_onshore | D32: NT2030 | E32: 2754
A33: =LEFT(B33,2) -> NL | B33: NL00 | C33: PV | D33: NT2030 | E33: 15101.9
A34: =LEFT(B34,2) -> NL | B34: NL00 | C34: wind_offshore | D34: NT2030 | E34: 2459.9
A35: =LEFT(B35,2) -> NL | B35: NL00 | C35: wind_onshore | D35: NT2030 | E35: 13479.2
A36: =LEFT(B36,2) -> NO | B36: NOM1 | C36: PV | D36: NT2030 | E36: 38
A37: =LEFT(B37,2) -> NO | B37: NOM1 | C37: wind_onshore | D37: NT2030 | E37: 1950.2
A38: =LEFT(B38,2) -> NO | B38: NON1 | C38: wind_onshore | D38: NT2030 | E38: 891.3
... A55: =LEFT(B55,2) -> UK | B55: UK00 | C55: wind_onshore | D55: NT2030 | E55: 34229.1

Sheet wind
A1: Installed wind power capacity
A3: Europe wind power Capacity (MW)[58][59][60][61][62][63][64][65]
A4: # | B4: Country | D4: 2024[66] | E4: 2023[67] | F4: 2022[68] | G4: 2021[69] | H4: 2020[70] | I4: 2019[71] | J4: 2018[72] | K4: 2017[73] | L4: 2016 | M4: 2015 | N4: 2014 | O4: 2013 | P4: 2012 | Q4: 2011 | R4: 2010 | S4: 2009 | T4: 2008 | U4: 2007 | V4: 2006 | W4: 2005 | X4: 2004 | Y4: 2003 | Z4: 2002 | AA4: 2001 | AB4: 2000 | AC4: 1999 | AD4: 1998
A5: Installed wind power capacity in Europe
D6: =LEFT(D4,4)+0 -> 2024 | E6: =LEFT(E4,4)+0 -> 2023 | F6: =LEFT(F4,4)+0 -> 2022 | G6: =LEFT(G4,4)+0 -> 2021 | H6: =LEFT(H4,4)+0 -> 2020 | I6: =LEFT(I4,4)+0 -> 2019 | J6: =LEFT(J4,4)+0 -> 2018 | K6: =LEFT(K4,4)+0 -> 2017 | ... AD6: =LEFT(AD4,4)+0 -> 1998
A7: 1 | B7: Germany | C7: DE | D7: 72672 | E7: 69675 | F7: 66322 | G7: 64040 | H7: 62580 | I7: 60720 | J7: 58850 | K7: 55580 | L7: 49430 | M7: 44580 | N7: 38610 | O7: 33480 | P7: 30830 | Q7: 28770 | R7: 27180 | S7: 25777 | T7: 23897 | U7: 22247 | V7: 20622 | W7: 18415 | X7: 16629 | Y7: 14609 | Z7: 11994 | AA7: 8754 | AB7: 6113 | AC7: 4442 | AD7: 2875
A8: 2 | B8: UK | C8: GB | D8: 31636 | E8: 29622 | F8: 28493 | G8: 26812 | H8: 24167 | I8: 23515 | J8: 20970 | K8: 18872 | L8: 15030 | M8: 14291 | N8: 12440 | O8: 10531 | P8: 8445 | Q8: 6540 | R8: 5204 | S8: 4051 | T8: 2974 | U8: 2406 | V8: 1962 | W8: 1332 | X8: 904 | Y8: 667 | Z8: 552 | AA8: 474 | AB8: 406 | AC8: 362 | AD8: 333
A9: 3 | B9: Spain | C9: ES | D9: 31180 | E9: 30569 | F9: 29798 | G9: 28196 | H9: 27264 | I9: 25808 | J9: 23494 | K9: 23170 | L9: 23026 | M9: 22987 | N9: 22986 | O9: 22959 | P9: 22796 | Q9: 21674 | R9: 20676 | S9: 19149 | T9: 16689 | U9: 15131 | V9: 11623 | W9: 10028 | X9: 8264 | Y9: 6203 | Z9: 4825 | AA9: 3337 | AB9: 2235 | AC9: 1812 | AD9: 834
A10: 4 | B10: France | C10: FR | D10: 24383 | E10: 22792 | F10: 21135 | G10: 19081 | H10: 17949 | I10: 16646 | J10: 15309 | K10: 13759 | L10: 11670 | M10: 10324 | N10: 9285 | O10: 8254 | P10: 7196 | Q10: 6800 | R10: 5660 | S10: 4492 | T10: 3404 | U10: 2454 | V10: 1567 | W10: 757 | X10: 390 | Y10: 257 | Z10: 148 | AA10: 93 | AB10: 66 | AC10: 25 | AD10: 19
A11: 5 | B11: Sweden | C11: SE | D11: 17200 | E11: 16441 | F11: 14585 | G11: 12097 | H11: 9992 | I11: 8985 | J11: 7407 | K11: 6691 | L11: 6519 | M11: 6029 | N11: 5425 | O11: 4470 | P11: 3745 | Q11: 2907 | R11: 2163 | S11: 1560 | T11: 1048 | U11: 788 | V11: 571 | W11: 509 | X11: 442 | Y11: 399 | Z11: 345 | AA11: 293 | AB11: 231 | AC11: 220 | AD11: 174
A12: 6 | B12: Turkey | C12: TR | D12: 13793 | E12: 12342 | F12: 11969 | G12: 10750 | H12: 9305 | I12: 8056 | J12: 7369 | K12: 6857 | L12: 6101 | M12: 4718 | N12: 3763 | O12: 2956 | P12: 2312 | Q12: 1691 | R12: 1329 | S12: 801 | T12: 458
A13: 7 | B13: Italy | C13: IT | D13: 12945 | E13: 12336 | F13: 11848 | G13: 11108 | H13: 10852 | I13: 10512 | J13: 9958 | K13: 9479 | L13: 9255 | M13: 8973 | N13: 8663 | O13: 8551 | P13: 8144 | Q13: 6747 | R13: 5797 | S13: 4850 | T13: 3736 | U13: 2726 | V13: 2123 | W13: 1718 | X13: 1266 | Y13: 905 | Z13: 788 | AA13: 682 | AB13: 427 | AC13: 277 | AD13: 180
A14: 8 | B14: Netherlands | C14: NL | D14: 11706 | E14: 11493 | F14: 9052 | G14: 8165 | H14: 6784 | I14: 4600 | J14: 4471 | K14: 4341 | L14: 4180 | M14: 3391 | N14: 2805 | O14: 2693 | P14: 2391 | Q14: 2328 | R14: 2245 | S14: 2229 | T14: 2225 | U14: 1747 | V14: 1558 | W14: 1219 | X14: 1079 | Y14: 910 | Z14: 693 | AA14: 486 | AB14: 446 | AC14: 433 | AD14: 361
A15: 9 | B15: Poland | C15: PL | D15: 10233 | E15: 9383 | F15: 7864 | G15: 7116 | H15: 6614 | I15: 5917 | J15: 5864 | K15: 6397 | L15: 5782 | M15: 5100 | N15: 3834 | O15: 3390 | P15: 2497 | Q15: 1616 | R15: 1107 | S15: 725 | T15: 544 | U15: 276 | V15: 153 | W15: 83 | X15: 63 | Y15: 63 | Z15: 27 | AA15: 0 | AB15: 0 | AC15: 0 | AD15: 0
A16: 10 | B16: Finland | C16: FI | D16: 8357 | E16: 6943 | F16: 5678 | G16: 3328 | H16: 2586 | I16: 2284 | J16: 2041 | K16: 2113 | L16: 1533 | M16: 1005 | N16: 627 | O16: 448 | P16: 288 | Q16: 197 | R16: 197 | S16: 146 | T16: 143 | U16: 110 | V16: 86 | W16: 82 | X16: 82 | Y16: 52 | Z16: 43 | AA16: 39 | AB16: 39 | AC16: 39 | AD16: 17
A17: 11 | B17: Denmark | C17: DK | D17: 7612 | E17: 7562 | F17: 7282 | G17: 7178 | H17: 6180 | I17: 6128 | J17: 5758 | K17: 5476 | L17: 5242 | M17: 5075 | N17: 4845 | O17: 4772 | P17: 4162 | Q17: 3871 | R17: 3752 | S17: 3465 | T17: 3163 | U17: 3125 | V17: 3136 | W17: 3128 | X17: 3118 | Y17: 3116 | Z17: 2889 | AA17: 2489 | AB17: 2417 | AC17: 1771 | AD17: 1443
A18: 12 | B18: Portugal | C18: PT | D18: 5963 | E18: 5834 | F18: 5696 | G18: 5612 | H18: 5486 | I18: 5437 | J18: 5380 | K18: 5316 | L18: 5269 | M18: 5034 | N18: 4914 | O18: 4724 | P18: 4525 | Q18: 4083 | R18: 3898 | S18: 3535 | T18: 2862 | U18: 2150 | V18: 1716 | W18: 1022 | X18: 522 | Y18: 296 | Z18: 195 | AA18: 131 | AB18: 100 | AC18: 61 | AD18: 60
A19: 13 | B19: Belgium | C19: BE | D19: 5648 | E19: 5492 | F19: 5306 | G19: 5002 | H19: 4719 | I19: 3879 | J19: 3360 | K19: 2843 | L19: 2400 | M19: 2169 | N19: 1959 | O19: 1651 | P19: 1375 | Q19: 1078 | R19: 911 | S19: 563 | T19: 415 | U19: 287 | V19: 194 | W19: 167 | X19: 96 | Y19: 68 | Z19: 35 | AA19: 32 | AB19: 13 | AC19: 6 | AD19: 6
A20: 14 | B20: Greece | C20: GR | D20: 5354 | E20: 5226 | F20: 4682 | G20: 4452 | H20: 4113 | I20: 3576 | J20: 2844 | K20: 2651 | L20: 2374 | M20: 2136 | N20: 1980 | O20: 1865 | P20: 1749 | Q20: 1629 | R20: 1208 | S20: 1087 | T20: 985 | U20: 871 | V20: 746 | W20: 573 | X20: 473 | Y20: 383 | Z20: 297 | AA20: 272 | AB20: 189 | AC20: 112 | AD20: 39
A21: 15 | B21: Norway | C21: NO | D21: 5188 | E21: 5184 | F21: 5149 | G21: 4655 | H21: 3980 | I21: 2444 | J21: 1675 | K21: 1162 | L21: 838 | M21: 822 | N21: 819 | O21: 768 | P21: 703 | Q21: 520 | R21: 441 | S21: 431 | T21: 429 | U21: 333 | V21: 314 | W21: 267 | X21: 160 | Y21: 101
A22: 16 | B22: Ireland | C22: IE | D22: 4861 | E22: 4802 | F22: 4637 | G22: 4405 | H22: 4351 | I22: 4155 | J22: 3564 | K22: 3127 | L22: 2765 | M22: 2440 | N22: 2272 | O22: 2037 | P22: 1738 | Q22: 1631 | R22: 1428 | S22: 1260 | T22: 1027 | U22: 795 | V22: 746 | W22: 496 | X22: 339 | Y22: 190 | Z22: 137 | AA22: 124 | AB22: 118 | AC22: 74 | AD22: 73
A23: 17 | B23: Austria | C23: AT | D23: 4028 | E23: 3885 | F23: 3586 | G23: 3300 | H23: 3120 | I23: 3159 | J23: 3045 | K23: 2828 | L23: 2632 | M23: 2404 | N23: 2095 | O23: 1684 | P23: 1378 | Q23: 1084 | R23: 1011 | S23: 995 | T23: 995 | U23: 982 | V23: 965 | W23: 819 | X23: 606 | Y23: 415 | Z23: 140 | AA23: 94 | AB23: 77 | AC23: 34 | AD23: 30
A24: 18 | B24: Romania | C24: RO | D24: 3150 | E24: 3100 | F24: 3029 | G24: 3029 | H24: 3029 | I24: 3029 | J24: 3029 | K24: 3029 | L24: 3028 | M24: 2976 | N24: 2954 | O24: 2599 | P24: 1905 | Q24: 982 | R24: 462 | S24: 14 | T24: 11 | U24: 8 | V24: 3 | W24: 2 | X24: 1 | Y24: 1 | Z24: 0 | AA24: 0 | AB24: 0 | AC24: 0 | AD24: 0
A25: 19 | B25: Russia | C25: RU | E25: 2043 | F25: 2043 | G25: 2043 | H25: 905 | I25: 191 | J25: 139 | K25: 104 | L25: 15 | M25: 15 | N25: 15 | O25: 15 | P25: 15 | Q25: 15 | R25: 9 | S25: 9 | T25: 0 | U25: 0 | V25: 0 | W25: 0 | X25: 0 | Y25: 0 | Z25: 0 | AA25: 0 | AB25: 0 | AC25: 0 | AD25: 0
A26: 20 | B26: Ukraine | C26: UA | D26: 1947 | E26: 1902 | F26: 1673 | G26: 1673 | H26: 1314 | I26: 1170 | J26: 533 | K26: 593 | L26: 526 | M26: 514 | N26: 498 | O26: 371 | P26: 278 | Q26: 151 | R26: 87 | S26: 94 | T26: 90 | U26: 89 | V26: 86 | W26: 77 | X26: 0 | Y26: 0 | Z26: 0 | AA26: 0 | AB26: 0 | AC26: 0 | AD26: 0
A27: 21 | B27: Lithuania | C27: LT | D27: 1750 | E27: 1208 | F27: 740 | G27: 668 | H27: 548 | I27: 548 | J27: 439 | K27: 421 | L27: 421 | M27: 421 | N27: 279 | O27: 279 | P27: 225 | Q27: 179 | R27: 163 | S27: 91 | T27: 54 | U27: 54 | V27: 51 | W27: 48 | X27: 6 | Y27: 6 | Z27: 0 | AA27: 0 | AB27: 0 | AC27: 0 | AD27: 0
A28: 22 | B28: Croatia | C28: HR | D28: 1303 | E28: 1256 | F28: 1100 | G28: 990 | H28: 803 | I28: 652 | J28: 583 | K28: 583 | L28: 466 | M28: 462 | N28: 347 | O28: 339[74] | P28: 180 | Q28: 131 | R28: 89 | S28: 28 | T28: 0 | U28: 0 | V28: 0 | W28: 0 | X28: 0 | Y28: 0 | Z28: 0 | AA28: 0 | AB28: 0 | AC28: 0 | AD28: 0
A29: 23 | B29: Estonia | C29: EE | D29: 711 | E29: 376 | F29: 320 | G29: 320 | H29: 320 | I29: 320 | J29: 310 | K29: 310 | L29: 310 | M29: 302 | N29: 302 | O29: 280 | P29: 269 | Q29: 184 | R29: 149 | S29: 142 | T29: 78 | U29: 59 | V29: 32 | W29: 32 | X29: 6 | Y29: 2 | Z29: 2 | AA29: 0 | AB29: 0 | AC29: 0 | AD29: 0
A30: 24 | B30: Bulgaria | C30: BG | D30: 706 | E30: 706 | F30: 707 | G30: 707 | H30: 691 | I30: 691 | J30: 691 | K30: 691 | L30: 691 | M30: 691 | N30: 691 | O30: 681 | P30: 674 | Q30: 612 | R30: 375 | S30: 177 | T30: 120 | U30: 57 | V30: 36 | W30: 10 | X30: 10 | Y30: 0 | Z30: 0 | AA30: 0 | AB30: 0 | AC30: 0 | AD30: 0
A31: 25 | B31: Serbia | C31: RS | D31: 623 | E31: 512 | F31: 374 | G31: 374 | H31: 374 | I31: 374 | J31: 374 | K31: 18 | L31: 10 | M31: 0 | N31: 0 | O31: 0 | P31: 0 | Q31: 0 | R31: 0 | S31: 0 | T31: 0 | U31: 0 | V31: 0 | W31: 0 | X31: 0 | Y31: 0 | Z31: 0 | AA31: 0 | AB31: 0 | AC31: 0 | AD31: 0
A32: 26 | B32: Czech Republic | C32: CZ | D32: 371 | E32: 337 | F32: 337 | G32: 337 | H32: 337 | I32: 337 | J32: 317 | K32: 308 | L32: 281 | M32: 281 | N32: 281 | O32: 269 | P32: 260 | Q32: 217 | R32: 215 | S32: 192 | T32: 150 | U32: 116 | V32: 54 | W32: 28 | X32: 17 | Y32: 9 | Z32: 3 | AA32: 0 | AB32: 0 | AC32: 0 | AD32: 0
A33: 27 | B33: Hungary | C33: HU | D33: 329 | E33: 329 | F33: 329 | G33: 329 | H33: 329 | I33: 329 | J33: 329 | K33: 329 | L33: 329 | M33: 329 | N33: 329 | O33: 329 | P33: 329 | Q33: 329 | R33: 295 | S33: 201 | T33: 127 | U33: 65 | V33: 61 | W33: 17 | X33: 3 | Y33: 3 | Z33: 3 | AA33: 0 | AB33: 0 | AC33: 0 | AD33: 0
A34: 28 | B34: Bosnia and Herzegovina | C34: BA | D34: 244 | E34: 135 | F34: 135 | G34: 135 | H34: 135 | I34: 87 | J34: 51
A35: 29 | B35: Luxembourg | C35: LU | D35: 214 | E35: 208 | F35: 166 | G35: 168 | H35: 166 | I35: 136 | J35: 120 | K35: 120 | L35: 100 | M35: 58 | N35: 58 | O35: 58 | P35: 58 | Q35: 44 | R35: 44 | S35: 35 | T35: 35 | U35: 35 | V35: 35 | W35: 35 | X35: 35 | Y35: 22 | Z35: 17 | AA35: 15 | AB35: 10 | AC35: 10 | AD35: 9
A36: 30 | B36: Cyprus | C36: CY | D36: 158 | E36: 158 | F36: 158 | G36: 158 | H36: 158 | I36: 158 | J36: 158 | K36: 158 | L36: 158 | M36: 158 | N36: 147 | O36: 147 | P36: 147 | Q36: 134 | R36: 82 | S36: 0 | T36: 0 | U36: 0 | V36: 0 | W36: 0 | X36: 0 | Y36: 0 | Z36: 0 | AA36: 0 | AB36: 0 | AC36: 0 | AD36: 0
A37: 31 | B37: Kosovo | C37: XK | D37: 137 | E37: 137 | F37: 137 | G37: 137 | H37: 32 | I37: 32 | J37: 32
A38: 32 | B38: Latvia | C38: LV | D38: 137 | E38: 137 | F38: 137 | G38: 66 | H38: 66 | I38: 66 | J38: 66 | K38: 66 | L38: 70 | M38: 69 | N38: 62 | O38: 62 | P38: 60 | Q38: 31 | R38: 30 | S38: 28 | T38: 27 | U38: 27 | V38: 27 | W38: 27 | X38: 27 | Y38: 27 | Z38: 24 | AA38: 0 | AB38: 0 | AC38: 0 | AD38: 0
A39: 33 | B39: Montenegro | C39: ME | D39: 118 | E39: 118 | F39: 118 | G39: 118 | H39: 118 | I39: 118 | J39: 118
A40: 34 | B40: Switzerland | C40: CH | D40: 100 | E40: 101 | F40: 87 | G40: 87 | H40: 87 | I40: 75 | J40: 75 | K40: 75 | L40: 75 | M40: 60 | N40: 60 | O40: 60 | P40: 50 | Q40: 46 | R40: 42 | S40: 18 | T40: 14 | U40: 12 | V40: 12 | W40: 12 | X40: 0 | Y40: 0 | Z40: 0 | AA40: 0 | AB40: 0 | AC40: 0 | AD40: 0
A41: 35 | B41: North Macedonia | C41: MK | D41: 73 | E41: 73 | F41: 37 | G41: 37 | H41: 37 | I41: 37 | J41: 37 | K41: 37 | L41: 37 | M41: 37 | N41: 37 | O41: 0 | P41: 0 | Q41: 0 | R41: 0 | S41: 0 | T41: 0 | U41: 0 | V41: 0 | W41: 0 | X41: 0 | Y41: 0 | Z41: 0 | AA41: 0 | AB41: 0 | AC41: 0 | AD41: 0
...

Sheet onshore
B4: region | C4: tot | D4: offshore | E4: country | F4: 1998 | G4: 1999 | H4: 2000 | I4: 2001 | J4: 2002 | K4: 2003 | L4: 2004 | M4: 2005 | N4: 2006 | O4: 2007 | P4: 2008 | Q4: 2009 | R4: 2010 | S4: 2011 | T4: 2012 | U4: 2013 | V4: 2014 | W4: 2015 | X4: 2016 | Y4: 2017 | Z4: 2018 | AA4: 2019 | AB4: 2020 | AC4: 2021 | AD4: 2022 | AE4: 2023 | AF4: 2024 | AG4: 2025 | AH4: 2030 | AJ4: 2025 factor | AK4: 2030 factor
B5: DE00 | C5: =MATCH($E5, wind!$C:$C, 0) -> 7 | D5: =IFERROR(MATCH($E5, offshore!$D:$D, 0), 1) -> 6 | E5: DE | F5: =SUMIFS( INDIRECT(CONCATENATE("'wind'!", $C5, ":", $C5)), wind!$6:$6, F$4) - SUMIFS( INDIRECT(CONCATENATE("offshore!",$D5,":", $D5)), offshore!$4:$4, F$4) -> 2875 | G5: =SUMIFS( INDIRECT(CONCATENATE("'wind'!", $C5, ":", $C5)), wind!$6:$6, G$4) - SUMIFS( INDIRECT(CONCATENATE("offshore!",$D5,":", $D5)), offshore!$4:$4, G$4) -> 4442 | H5: =SUMIFS( INDIRECT(CONCATENATE("'wind'!", $C5, ":", $C5)), wind!$6:$6, H$4) - SUMIFS( INDIRECT(CONCATENATE("offshore!",$D5,":", $D5)), offshore!$4:$4, H$4) -> 6113 | I5: =SUMIFS( INDIRECT(CONCATENATE("'wind'!", $C5, ":", $C5)), wind!$6:$6, I$4) - SUMIFS( INDIRECT(CONCATENATE("offshore!",$D5,":", $D5)), offshore!$4:$4, I$4) -> 8754 | J5: =SUMIFS( INDIRECT(CONCATENATE("'wind'!", $C5, ":", $C5)), wind!$6:$6, J$4) - SUMIFS( INDIRECT(CONCATENATE("offshore!",$D5,":", $D5)), offshore!$4:$4, J$4) -> 11994 | K5: =SUMIFS( INDIRECT(CONCATENATE("'wind'!", $C5, ":", $C5)), wind!$6:$6, K$4) - SUMIFS( INDIRECT(CONCATENATE("offshore!",$D5,":", $D5)), offshore!$4:$4, K$4) -> 14609 | L5: =SUMIFS( INDIRECT(CONCATENATE("'wind'!", $C5, ":", $C5)), wind!$6:$6, L$4) - SUMIFS( INDIRECT(CONCATENATE("offshore!",$D5,":", $D5)), offshore!$4:$4, L$4) -> 16629 | M5: =SUMIFS( INDIRECT(CONCATENATE("'wind'!", $C5, ":", $C5)), wind!$6:$6, M$4) - SUMIFS( INDIRECT(CONCATENATE("offshore!",$D5,":", $D5)), offshore!$4:$4, M$4) -> 18415 | ... AF5: =SUMIFS( INDIRECT(CONCATENATE("'wind'!", $C5, ":", $C5)), wind!$6:$6, AF$4) - SUMIFS( INDIRECT(CONCATENATE("offshore!",$D5,":", $D5)), offshore!$4:$4, AF$4) -> 63457 | AG5: =MAX(AVERAGE(TREND($W5:$AF5,$W$4:$AF$4,AG$4), TREND($AB5:$AF5,$AB$4:$AF$4,AG$4)) * AJ5, AF5* 1.03) -> 65612.19 | AH5: =AVERAGE(TREND($W5:$AG5,$W$4:$AG$4,AH$4), TREND($AB5:$AG5,$AB$4:$AG$4,AH$4)) * AK5 -> 84415.019 | AJ5: 1 | AK5: 1.1
B6: UK00 | C6: =MATCH($E6, wind!$C:$C, 0) -> 8 | D6: =IFERROR(MATCH($E6, offshore!$D:$D, 0), 1) -> 5 | E6: GB | F6: =SUMIFS( INDIRECT(CONCATENATE("'wind'!", $C6, ":", $C6)), wind!$6:$6, F$4) - SUMIFS( INDIRECT(CONCATENATE("offshore!",$D6,":", $D6)), offshore!$4:$4, F$4) -> 333 | G6: =SUMIFS( INDIRECT(CONCATENATE("'wind'!", $C6, ":", $C6)), wind!$6:$6, G$4) - SUMIFS( INDIRECT(CONCATENATE("offshore!",$D6,":", $D6)), offshore!$4:$4, G$4) -> 362 | H6: =SUMIFS( INDIRECT(CONCATENATE("'wind'!", $C6, ":", $C6)), wind!$6:$6, H$4) - SUMIFS( INDIRECT(CONCATENATE("offshore!",$D6,":", $D6)), offshore!$4:$4, H$4) -> 406 | I6: =SUMIFS( INDIRECT(CONCATENATE("'wind'!", $C6, ":", $C6)), wind!$6:$6, I$4) - SUMIFS( INDIRECT(CONCATENATE("offshore!",$D6,":", $D6)), offshore!$4:$4, I$4) -> 474 | J6: =SUMIFS( INDIRECT(CONCATENATE("'wind'!", $C6, ":", $C6)), wind!$6:$6, J$4) - SUMIFS( INDIRECT(CONCATENATE("offshore!",$D6,":", $D6)), offshore!$4:$4, J$4) -> 552 | K6: =SUMIFS( INDIRECT(CONCATENATE("'wind'!", $C6, ":", $C6)), wind!$6:$6, K$4) - SUMIFS( INDIRECT(CONCATENATE("offshore!",$D6,":", $D6)), offshore!$4:$4, K$4) -> 667 | L6: =SUMIFS( INDIRECT(CONCATENATE("'wind'!", $C6, ":", $C6)), wind!$6:$6, L$4) - SUMIFS( INDIRECT(CONCATENATE("offshore!",$D6,":", $D6)), offshore!$4:$4, L$4) -> 904 | M6: =SUMIFS( INDIRECT(CONCATENATE("'wind'!", $C6, ":", $C6)), wind!$6:$6, M$4) - SUMIFS( INDIRECT(CONCATENATE("offshore!",$D6,":", $D6)), offshore!$4:$4, M$4) -> 1332 | ... AF6: =SUMIFS( INDIRECT(CONCATENATE("'wind'!", $C6, ":", $C6)), wind!$6:$6, AF$4) - SUMIFS( INDIRECT(CONCATENATE("offshore!",$D6,":", $D6)), offshore!$4:$4, AF$4) -> 15736 | AG6: =MAX(AVERAGE(TREND($W6:$AF6,$W$4:$AF$4,AG$4), TREND($AB6:$AF6,$AB$4:$AF$4,AG$4)) * AJ6, AF6* 1.03) -> 16862.95 | AH6: =AVERAGE(TREND($W6:$AG6,$W$4:$AG$4,AH$4), TREND($AB6:$AG6,$AB$4:$AG$4,AH$4)) * AK6 -> 19388.422 | AJ6: 1 | AK6: 1
B7: ES00 | C7: =MATCH($E7, wind!$C:$C, 0) -> 9 | D7: =IFERROR(MATCH($E7, offshore!$D:$D, 0), 1) -> 13 | E7: ES | F7: =SUMIFS( INDIRECT(CONCATENATE("'wind'!", $C7, ":", $C7)), wind!$6:$6, F$4) - SUMIFS( INDIRECT(CONCATENATE("offshore!",$D7,":", $D7)), offshore!$4:$4, F$4) -> 834 | G7: =SUMIFS( INDIRECT(CONCATENATE("'wind'!", $C7, ":", $C7)), wind!$6:$6, G$4) - SUMIFS( INDIRECT(CONCATENATE("offshore!",$D7,":", $D7)), offshore!$4:$4, G$4) -> 1812 | H7: =SUMIFS( INDIRECT(CONCATENATE("'wind'!", $C7, ":", $C7)), wind!$6:$6, H$4) - SUMIFS( INDIRECT(CONCATENATE("offshore!",$D7,":", $D7)), offshore!$4:$4, H$4) -> 2235 | I7: =SUMIFS( INDIRECT(CONCATENATE("'wind'!", $C7, ":", $C7)), wind!$6:$6, I$4) - SUMIFS( INDIRECT(CONCATENATE("offshore!",$D7,":", $D7)), offshore!$4:$4, I$4) -> 3337 | J7: =SUMIFS( INDIRECT(CONCATENATE("'wind'!", $C7, ":", $C7)), wind!$6:$6, J$4) - SUMIFS( INDIRECT(CONCATENATE("offshore!",$D7,":", $D7)), offshore!$4:$4, J$4) -> 4825 | K7: =SUMIFS( INDIRECT(CONCATENATE("'wind'!", $C7, ":", $C7)), wind!$6:$6, K$4) - SUMIFS( INDIRECT(CONCATENATE("offshore!",$D7,":", $D7)), offshore!$4:$4, K$4) -> 6203 | L7: =SUMIFS( INDIRECT(CONCATENATE("'wind'!", $C7, ":", $C7)), wind!$6:$6, L$4) - SUMIFS( INDIRECT(CONCATENATE("offshore!",$D7,":", $D7)), offshore!$4:$4, L$4) -> 8264 | M7: =SUMIFS( INDIRECT(CONCATENATE("'wind'!", $C7, ":", $C7)), wind!$6:$6, M$4) - SUMIFS( INDIRECT(CONCATENATE("offshore!",$D7,":", $D7)), offshore!$4:$4, M$4) -> 10028 | ... AF7: =SUMIFS( INDIRECT(CONCATENATE("'wind'!", $C7, ":", $C7)), wind!$6:$6, AF$4) - SUMIFS( INDIRECT(CONCATENATE("offshore!",$D7,":", $D7)), offshore!$4:$4, AF$4) -> 31175 | AG7: =MAX(AVERAGE(TREND($W7:$AF7,$W$4:$AF$4,AG$4), TREND($AB7:$AF7,$AB$4:$AF$4,AG$4)) * AJ7, AF7* 1.03) -> 32422.467 | AH7: =AVERAGE(TREND($W7:$AG7,$W$4:$AG$4,AH$4), TREND($AB7:$AG7,$AB$4:$AG$4,AH$4)) * AK7 -> 37614.048 | AJ7: 1 | AK7: 1
B8: =E8&"00" -> FR00 | C8: =MATCH($E8, wind!$C:$C, 0) -> 10 | D8: =IFERROR(MATCH($E8, offshore!$D:$D, 0), 1) -> 15 | E8: FR | F8: =SUMIFS( INDIRECT(CONCATENATE("'wind'!", $C8, ":", $C8)), wind!$6:$6, F$4) - SUMIFS( INDIRECT(CONCATENATE("offshore!",$D8,":", $D8)), offshore!$4:$4, F$4) -> 19 | G8: =SUMIFS( INDIRECT(CONCATENATE("'wind'!", $C8, ":", $C8)), wind!$6:$6, G$4) - SUMIFS( INDIRECT(CONCATENATE("offshore!",$D8,":", $D8)), offshore!$4:$4, G$4) -> 25 | H8: =SUMIFS( INDIRECT(CONCATENATE("'wind'!", $C8, ":", $C8)), wind!$6:$6, H$4) - SUMIFS( INDIRECT(CONCATENATE("offshore!",$D8,":", $D8)), offshore!$4:$4, H$4) -> 66 | I8: =SUMIFS( INDIRECT(CONCATENATE("'wind'!", $C8, ":", $C8)), wind!$6:$6, I$4) - SUMIFS( INDIRECT(CONCATENATE("offshore!",$D8,":", $D8)), offshore!$4:$4, I$4) -> 93 | J8: =SUMIFS( INDIRECT(CONCATENATE("'wind'!", $C8, ":", $C8)), wind!$6:$6, J$4) - SUMIFS( INDIRECT(CONCATENATE("offshore!",$D8,":", $D8)), offshore!$4:$4, J$4) -> 148 | K8: =SUMIFS( INDIRECT(CONCATENATE("'wind'!", $C8, ":", $C8)), wind!$6:$6, K$4) - SUMIFS( INDIRECT(CONCATENATE("offshore!",$D8,":", $D8)), offshore!$4:$4, K$4) -> 257 | L8: =SUMIFS( INDIRECT(CONCATENATE("'wind'!", $C8, ":", $C8)), wind!$6:$6, L$4) - SUMIFS( INDIRECT(CONCATENATE("offshore!",$D8,":", $D8)), offshore!$4:$4, L$4) -> 390 | M8: =SUMIFS( INDIRECT(CONCATENATE("'wind'!", $C8, ":", $C8)), wind!$6:$6, M$4) - SUMIFS( INDIRECT(CONCATENATE("offshore!",$D8,":", $D8)), offshore!$4:$4, M$4) -> 757 | ... AF8: =SUMIFS( INDIRECT(CONCATENATE("'wind'!", $C8, ":", $C8)), wind!$6:$6, AF$4) - SUMIFS( INDIRECT(CONCATENATE("offshore!",$D8,":", $D8)), offshore!$4:$4, AF$4) -> 22875 | AG8: =MAX(AVERAGE(TREND($W8:$AF8,$W$4:$AF$4,AG$4), TREND($AB8:$AF8,$AB$4:$AF$4,AG$4)) * AJ8, AF8* 1.03) -> 24269.933 | AH8: =AVERAGE(TREND($W8:$AG8,$W$4:$AG$4,AH$4), TREND($AB8:$AG8,$AB$4:$AG$4,AH$4)) * AK8 -> 30831.618 | AJ8: 1 | AK8: 1
C9: =MATCH($E9, wind!$C:$C, 0) -> 11 | D9: =IFERROR(MATCH($E9, offshore!$D:$D, 0), 1) -> 10 | E9: SE | F9: =SUMIFS( INDIRECT(CONCATENATE("'wind'!", $C9, ":", $C9)), wind!$6:$6, F$4) - SUMIFS( INDIRECT(CONCATENATE("offshore!",$D9,":", $D9)), offshore!$4:$4, F$4) -> 174 | G9: =SUMIFS( INDIRECT(CONCATENATE("'wind'!", $C9, ":", $C9)), wind!$6:$6, G$4) - SUMIFS( INDIRECT(CONCATENATE("offshore!",$D9,":", $D9)), offshore!$4:$4, G$4) -> 220 | H9: =SUMIFS( INDIRECT(CONCATENATE("'wind'!", $C9, ":", $C9)), wind!$6:$6, H$4) - SUMIFS( INDIRECT(CONCATENATE("offshore!",$D9,":", $D9)), offshore!$4:$4, H$4) -> 231 | I9: =SUMIFS( INDIRECT(CONCATENATE("'wind'!", $C9, ":", $C9)), wind!$6:$6, I$4) - SUMIFS( INDIRECT(CONCATENATE("offshore!",$D9,":", $D9)), offshore!$4:$4, I$4) -> 293 | J9: =SUMIFS( INDIRECT(CONCATENATE("'wind'!", $C9, ":", $C9)), wind!$6:$6, J$4) - SUMIFS( INDIRECT(CONCATENATE("offshore!",$D9,":", $D9)), offshore!$4:$4, J$4) -> 345 | K9: =SUMIFS( INDIRECT(CONCATENATE("'wind'!", $C9, ":", $C9)), wind!$6:$6, K$4) - SUMIFS( INDIRECT(CONCATENATE("offshore!",$D9,":", $D9)), offshore!$4:$4, K$4) -> 399 | L9: =SUMIFS( INDIRECT(CONCATENATE("'wind'!", $C9, ":", $C9)), wind!$6:$6, L$4) - SUMIFS( INDIRECT(CONCATENATE("offshore!",$D9,":", $D9)), offshore!$4:$4, L$4) -> 442 | M9: =SUMIFS( INDIRECT(CONCATENATE("'wind'!", $C9, ":", $C9)), wind!$6:$6, M$4) - SUMIFS( INDIRECT(CONCATENATE("offshore!",$D9,":", $D9)), offshore!$4:$4, M$4) -> 509 | ... AF9: =SUMIFS( INDIRECT(CONCATENATE("'wind'!", $C9, ":", $C9)), wind!$6:$6, AF$4) - SUMIFS( INDIRECT(CONCATENATE("offshore!",$D9,":", $D9)), offshore!$4:$4, AF$4) -> 17007 | AG9: =MAX(AVERAGE(TREND($W9:$AF9,$W$4:$AF$4,AG$4), TREND($AB9:$AF9,$AB$4:$AF$4,AG$4)) * AJ9, AF9* 1.03) -> 18694.723 | AH9: =AVERAGE(TREND($W9:$AG9,$W$4:$AG$4,AH$4), TREND($AB9:$AG9,$AB$4:$AG$4,AH$4)) * AK9 -> 26517.031 | AJ9: 1 | AK9: 1
C10: =MATCH($E10, wind!$C:$C, 0) -> 12 | D10: =IFERROR(MATCH($E10, offshore!$D:$D, 0), 1) -> 1 | E10: TR | F10: =SUMIFS( INDIRECT(CONCATENATE("'wind'!", $C10, ":", $C10)), wind!$6:$6, F$4) - SUMIFS( INDIRECT(CONCATENATE("offshore!",$D10,":", $D10)), offshore!$4:$4, F$4) -> 0 | G10: =SUMIFS( INDIRECT(CONCATENATE("'wind'!", $C10, ":", $C10)), wind!$6:$6, G$4) - SUMIFS( INDIRECT(CONCATENATE("offshore!",$D10,":", $D10)), offshore!$4:$4, G$4) -> 0 | H10: =SUMIFS( INDIRECT(CONCATENATE("'wind'!", $C10, ":", $C10)), wind!$6:$6, H$4) - SUMIFS( INDIRECT(CONCATENATE("offshore!",$D10,":", $D10)), offshore!$4:$4, H$4) -> 0 | I10: =SUMIFS( INDIRECT(CONCATENATE("'wind'!", $C10, ":", $C10)), wind!$6:$6, I$4) - SUMIFS( INDIRECT(CONCATENATE("offshore!",$D10,":", $D10)), offshore!$4:$4, I$4) -> 0 | J10: =SUMIFS( INDIRECT(CONCATENATE("'wind'!", $C10, ":", $C10)), wind!$6:$6, J$4) - SUMIFS( INDIRECT(CONCATENATE("offshore!",$D10,":", $D10)), offshore!$4:$4, J$4) -> 0 | K10: =SUMIFS( INDIRECT(CONCATENATE("'wind'!", $C10, ":", $C10)), wind!$6:$6, K$4) - SUMIFS( INDIRECT(CONCATENATE("offshore!",$D10,":", $D10)), offshore!$4:$4, K$4) -> 0 | L10: =SUMIFS( INDIRECT(CONCATENATE("'wind'!", $C10, ":", $C10)), wind!$6:$6, L$4) - SUMIFS( INDIRECT(CONCATENATE("offshore!",$D10,":", $D10)), offshore!$4:$4, L$4) -> 0 | M10: =SUMIFS( INDIRECT(CONCATENATE("'wind'!", $C10, ":", $C10)), wind!$6:$6, M$4) - SUMIFS( INDIRECT(CONCATENATE("offshore!",$D10,":", $D10)), offshore!$4:$4, M$4) -> 0 | ... AF10: =SUMIFS( INDIRECT(CONCATENATE("'wind'!", $C10, ":", $C10)), wind!$6:$6, AF$4) - SUMIFS( INDIRECT(CONCATENATE("offshore!",$D10,":", $D10)), offshore!$4:$4, AF$4) -> 13793 | AG10: =MAX(AVERAGE(TREND($W10:$AF10,$W$4:$AF$4,AG$4), TREND($AB10:$AF10,$AB$4:$AF$4,AG$4)) * AJ10, AF10* 1.03) -> 14669.333 | AH10: =AVERAGE(TREND($W10:$AG10,$W$4:$AG$4,AH$4), TREND($AB10:$AG10,$AB$4:$AG$4,AH$4)) * AK10 -> 19724.622 | AJ10: 1 | AK10: 1
C11: =MATCH($E11, wind!$C:$C, 0) -> 13 | D11: =IFERROR(MATCH($E11, offshore!$D:$D, 0), 1) -> 16 | E11: IT | F11: =SUMIFS( INDIRECT(CONCATENATE("'wind'!", $C11, ":", $C11)), wind!$6:$6, F$4) - SUMIFS( INDIRECT(CONCATENATE("offshore!",$D11,":", $D11)), offshore!$4:$4, F$4) -> 180 | G11: =SUMIFS( INDIRECT(CONCATENATE("'wind'!", $C11, ":", $C11)), wind!$6:$6, G$4) - SUMIFS( INDIRECT(CONCATENATE("offshore!",$D11,":", $D11)), offshore!$4:$4, G$4) -> 277 | H11: =SUMIFS( INDIRECT(CONCATENATE("'wind'!", $C11, ":", $C11)), wind!$6:$6, H$4) - SUMIFS( INDIRECT(CONCATENATE("offshore!",$D11,":", $D11)), offshore!$4:$4, H$4) -> 427 | I11: =SUMIFS( INDIRECT(CONCATENATE("'wind'!", $C11, ":", $C11)), wind!$6:$6, I$4) - SUMIFS( INDIRECT(CONCATENATE("offshore!",$D11,":", $D11)), offshore!$4:$4, I$4) -> 682 | J11: =SUMIFS( INDIRECT(CONCATENATE("'wind'!", $C11, ":", $C11)), wind!$6:$6, J$4) - SUMIFS( INDIRECT(CONCATENATE("offshore!",$D11,":", $D11)), offshore!$4:$4, J$4) -> 788 | K11: =SUMIFS( INDIRECT(CONCATENATE("'wind'!", $C11, ":", $C11)), wind!$6:$6, K$4) - SUMIFS( INDIRECT(CONCATENATE("offshore!",$D11,":", $D11)), offshore!$4:$4, K$4) -> 905 | L11: =SUMIFS( INDIRECT(CONCATENATE("'wind'!", $C11, ":", $C11)), wind!$6:$6, L$4) - SUMIFS( INDIRECT(CONCATENATE("offshore!",$D11,":", $D11)), offshore!$4:$4, L$4) -> 1266 | M11: =SUMIFS( INDIRECT(CONCATENATE("'wind'!", $C11, ":", $C11)), wind!$6:$6, M$4) - SUMIFS( INDIRECT(CONCATENATE("offshore!",$D11,":", $D11)), offshore!$4:$4, M$4) -> 1718 | ... AF11: =SUMIFS( INDIRECT(CONCATENATE("'wind'!", $C11, ":", $C11)), wind!$6:$6, AF$4) - SUMIFS( INDIRECT(CONCATENATE("offshore!",$D11,":", $D11)), offshore!$4:$4, AF$4) -> 12914 | AG11: =MAX(AVERAGE(TREND($W11:$AF11,$W$4:$AF$4,AG$4), TREND($AB11:$AF11,$AB$4:$AF$4,AG$4)) * AJ11, AF11* 1.03) -> 13301.42 | AH11: =AVERAGE(TREND($W11:$AG11,$W$4:$AG$4,AH$4), TREND($AB11:$AG11,$AB$4:$AG$4,AH$4)) * AK11 -> 15676.442 | AJ11: 1 | AK11: 1
B12: =E12&"00" -> NL00 | C12: =MATCH($E12, wind!$C:$C, 0) -> 14 | D12: =IFERROR(MATCH($E12, offshore!$D:$D, 0), 1) -> 8 | E12: NL | F12: =SUMIFS( INDIRECT(CONCATENATE("'wind'!", $C12, ":", $C12)), wind!$6:$6, F$4) - SUMIFS( INDIRECT(CONCATENATE("offshore!",$D12,":", $D12)), offshore!$4:$4, F$4) -> 361 | G12: =SUMIFS( INDIRECT(CONCATENATE("'wind'!", $C12, ":", $C12)), wind!$6:$6, G$4) - SUMIFS( INDIRECT(CONCATENATE("offshore!",$D12,":", $D12)), offshore!$4:$4, G$4) -> 433 | H12: =SUMIFS( INDIRECT(CONCATENATE("'wind'!", $C12, ":", $C12)), wind!$6:$6, H$4) - SUMIFS( INDIRECT(CONCATENATE("offshore!",$D12,":", $D12)), offshore!$4:$4, H$4) -> 446 | I12: =SUMIFS( INDIRECT(CONCATENATE("'wind'!", $C12, ":", $C12)), wind!$6:$6, I$4) - SUMIFS( INDIRECT(CONCATENATE("offshore!",$D12,":", $D12)), offshore!$4:$4, I$4) -> 486 | J12: =SUMIFS( INDIRECT(CONCATENATE("'wind'!", $C12, ":", $C12)), wind!$6:$6, J$4) - SUMIFS( INDIRECT(CONCATENATE("offshore!",$D12,":", $D12)), offshore!$4:$4, J$4) -> 693 | K12: =SUMIFS( INDIRECT(CONCATENATE("'wind'!", $C12, ":", $C12)), wind!$6:$6, K$4) - SUMIFS( INDIRECT(CONCATENATE("offshore!",$D12,":", $D12)), offshore!$4:$4, K$4) -> 910 | L12: =SUMIFS( INDIRECT(CONCATENATE("'wind'!", $C12, ":", $C12)), wind!$6:$6, L$4) - SUMIFS( INDIRECT(CONCATENATE("offshore!",$D12,":", $D12)), offshore!$4:$4, L$4) -> 1079 | M12: =SUMIFS( INDIRECT(CONCATENATE("'wind'!", $C12, ":", $C12)), wind!$6:$6, M$4) - SUMIFS( INDIRECT(CONCATENATE("offshore!",$D12,":", $D12)), offshore!$4:$4, M$4) -> 1219 | ... AF12: =SUMIFS( INDIRECT(CONCATENATE("'wind'!", $C12, ":", $C12)), wind!$6:$6, AF$4) - SUMIFS( INDIRECT(CONCATENATE("offshore!",$D12,":", $D12)), offshore!$4:$4, AF$4) -> 6958 | AG12: =MAX(AVERAGE(TREND($W12:$AF12,$W$4:$AF$4,AG$4), TREND($AB12:$AF12,$AB$4:$AF$4,AG$4)) * AJ12, AF12* 1.03) -> 8017.5333 | AH12: =AVERAGE(TREND($W12:$AG12,$W$4:$AG$4,AH$4), TREND($AB12:$AG12,$AB$4:$AG$4,AH$4)) * AK12 -> 11016.95 | AJ12: 1 | AK12: 1
B13: =E13&"00" -> PL00 | C13: =MATCH($E13, wind!$C:$C, 0) -> 15 | D13: =IFERROR(MATCH($E13, offshore!$D:$D, 0), 1) -> 1 | E13: PL | F13: =SUMIFS( INDIRECT(CONCATENATE("'wind'!", $C13, ":", $C13)), wind!$6:$6, F$4) - SUMIFS( INDIRECT(CONCATENATE("offshore!",$D13,":", $D13)), offshore!$4:$4, F$4) -> 0 | G13: =SUMIFS( INDIRECT(CONCATENATE("'wind'!", $C13, ":", $C13)), wind!$6:$6, G$4) - SUMIFS( INDIRECT(CONCATENATE("offshore!",$D13,":", $D13)), offshore!$4:$4, G$4) -> 0 | H13: =SUMIFS( INDIRECT(CONCATENATE("'wind'!", $C13, ":", $C13)), wind!$6:$6, H$4) - SUMIFS( INDIRECT(CONCATENATE("offshore!",$D13,":", $D13)), offshore!$4:$4, H$4) -> 0 | I13: =SUMIFS( INDIRECT(CONCATENATE("'wind'!", $C13, ":", $C13)), wind!$6:$6, I$4) - SUMIFS( INDIRECT(CONCATENATE("offshore!",$D13,":", $D13)), offshore!$4:$4, I$4) -> 0 | J13: =SUMIFS( INDIRECT(CONCATENATE("'wind'!", $C13, ":", $C13)), wind!$6:$6, J$4) - SUMIFS( INDIRECT(CONCATENATE("offshore!",$D13,":", $D13)), offshore!$4:$4, J$4) -> 27 | K13: =SUMIFS( INDIRECT(CONCATENATE("'wind'!", $C13, ":", $C13)), wind!$6:$6, K$4) - SUMIFS( INDIRECT(CONCATENATE("offshore!",$D13,":", $D13)), offshore!$4:$4, K$4) -> 63 | L13: =SUMIFS( INDIRECT(CONCATENATE("'wind'!", $C13, ":", $C13)), wind!$6:$6, L$4) - SUMIFS( INDIRECT(CONCATENATE("offshore!",$D13,":", $D13)), offshore!$4:$4, L$4) -> 63 | M13: =SUMIFS( INDIRECT(CONCATENATE("'wind'!", $C13, ":", $C13)), wind!$6:$6, M$4) - SUMIFS( INDIRECT(CONCATENATE("offshore!",$D13,":", $D13)), offshore!$4:$4, M$4) -> 83 | ... AF13: =SUMIFS( INDIRECT(CONCATENATE("'wind'!", $C13, ":", $C13)), wind!$6:$6, AF$4) - SUMIFS( INDIRECT(CONCATENATE("offshore!",$D13,":", $D13)), offshore!$4:$4, AF$4) -> 10233 | AG13: =MAX(AVERAGE(TREND($W13:$AF13,$W$4:$AF$4,AG$4), TREND($AB13:$AF13,$AB$4:$AF$4,AG$4)) * AJ13, AF13* 1.03) -> 10539.99 | AH13: =AVERAGE(TREND($W13:$AG13,$W$4:$AG$4,AH$4), TREND($AB13:$AG13,$AB$4:$AG$4,AH$4)) * AK13 -> 13942.666 | AJ13: 1 | AK13: 1
B14: =E14&"00" -> FI00 | C14: =MATCH($E14, wind!$C:$C, 0) -> 16 | D14: =IFERROR(MATCH($E14, offshore!$D:$D, 0), 1) -> 11 | E14: FI | F14: =SUMIFS( INDIRECT(CONCATENATE("'wind'!", $C14, ":", $C14)), wind!$6:$6, F$4) - SUMIFS( INDIRECT(CONCATENATE("offshore!",$D14,":", $D14)), offshore!$4:$4, F$4) -> 17 | G14: =SUMIFS( INDIRECT(CONCATENATE("'wind'!", $C14, ":", $C14)), wind!$6:$6, G$4) - SUMIFS( INDIRECT(CONCATENATE("offshore!",$D14,":", $D14)), offshore!$4:$4, G$4) -> 39 | H14: =SUMIFS( INDIRECT(CONCATENATE("'wind'!", $C14, ":", $C14)), wind!$6:$6, H$4) - SUMIFS( INDIRECT(CONCATENATE("offshore!",$D14,":", $D14)), offshore!$4:$4, H$4) -> 39 | I14: =SUMIFS( INDIRECT(CONCATENATE("'wind'!", $C14, ":", $C14)), wind!$6:$6, I$4) - SUMIFS( INDIRECT(CONCATENATE("offshore!",$D14,":", $D14)), offshore!$4:$4, I$4) -> 39 | J14: =SUMIFS( INDIRECT(CONCATENATE("'wind'!", $C14, ":", $C14)), wind!$6:$6, J$4) - SUMIFS( INDIRECT(CONCATENATE("offshore!",$D14,":", $D14)), offshore!$4:$4, J$4) -> 43 | K14: =SUMIFS( INDIRECT(CONCATENATE("'wind'!", $C14, ":", $C14)), wind!$6:$6, K$4) - SUMIFS( INDIRECT(CONCATENATE("offshore!",$D14,":", $D14)), offshore!$4:$4, K$4) -> 52 | L14: =SUMIFS( INDIRECT(CONCATENATE("'wind'!", $C14, ":", $C14)), wind!$6:$6, L$4) - SUMIFS( INDIRECT(CONCATENATE("offshore!",$D14,":", $D14)), offshore!$4:$4, L$4) -> 82 | M14: =SUMIFS( INDIRECT(CONCATENATE("'wind'!", $C14, ":", $C14)), wind!$6:$6, M$4) - SUMIFS( INDIRECT(CONCATENATE("offshore!",$D14,":", $D14)), offshore!$4:$4, M$4) -> 82 | ... AF14: =SUMIFS( INDIRECT(CONCATENATE("'wind'!", $C14, ":", $C14)), wind!$6:$6, AF$4) - SUMIFS( INDIRECT(CONCATENATE("offshore!",$D14,":", $D14)), offshore!$4:$4, AF$4) -> 8284 | AG14: =MAX(AVERAGE(TREND($W14:$AF14,$W$4:$AF$4,AG$4), TREND($AB14:$AF14,$AB$4:$AF$4,AG$4)) * AJ14, AF14* 1.03) -> 8776.35 | AH14: =AVERAGE(TREND($W14:$AG14,$W$4:$AG$4,AH$4), TREND($AB14:$AG14,$AB$4:$AG$4,AH$4)) * AK14 -> 14091.866 | AJ14: 1 | AK14: 1
C15: =MATCH($E15, wind!$C:$C, 0) -> 17 | D15: =IFERROR(MATCH($E15, offshore!$D:$D, 0), 1) -> 7 | E15: DK | F15: =SUMIFS( INDIRECT(CONCATENATE("'wind'!", $C15, ":", $C15)), wind!$6:$6, F$4) - SUMIFS( INDIRECT(CONCATENATE("offshore!",$D15,":", $D15)), offshore!$4:$4, F$4) -> 1443 | G15: =SUMIFS( INDIRECT(CONCATENATE("'wind'!", $C15, ":", $C15)), wind!$6:$6, G$4) - SUMIFS( INDIRECT(CONCATENATE("offshore!",$D15,":", $D15)), offshore!$4:$4, G$4) -> 1771 | H15: =SUMIFS( INDIRECT(CONCATENATE("'wind'!", $C15, ":", $C15)), wind!$6:$6, H$4) - SUMIFS( INDIRECT(CONCATENATE("offshore!",$D15,":", $D15)), offshore!$4:$4, H$4) -> 2417 | I15: =SUMIFS( INDIRECT(CONCATENATE("'wind'!", $C15, ":", $C15)), wind!$6:$6, I$4) - SUMIFS( INDIRECT(CONCATENATE("offshore!",$D15,":", $D15)), offshore!$4:$4, I$4) -> 2489 | J15: =SUMIFS( INDIRECT(CONCATENATE("'wind'!", $C15, ":", $C15)), wind!$6:$6, J$4) - SUMIFS( INDIRECT(CONCATENATE("offshore!",$D15,":", $D15)), offshore!$4:$4, J$4) -> 2889 | K15: =SUMIFS( INDIRECT(CONCATENATE("'wind'!", $C15, ":", $C15)), wind!$6:$6, K$4) - SUMIFS( INDIRECT(CONCATENATE("offshore!",$D15,":", $D15)), offshore!$4:$4, K$4) -> 3116 | L15: =SUMIFS( INDIRECT(CONCATENATE("'wind'!", $C15, ":", $C15)), wind!$6:$6, L$4) - SUMIFS( INDIRECT(CONCATENATE("offshore!",$D15,":", $D15)), offshore!$4:$4, L$4) -> 3118 | M15: =SUMIFS( INDIRECT(CONCATENATE("'wind'!", $C15, ":", $C15)), wind!$6:$6, M$4) - SUMIFS( INDIRECT(CONCATENATE("offshore!",$D15,":", $D15)), offshore!$4:$4, M$4) -> 3128 | ... AF15: =SUMIFS( INDIRECT(CONCATENATE("'wind'!", $C15, ":", $C15)), wind!$6:$6, AF$4) - SUMIFS( INDIRECT(CONCATENATE("offshore!",$D15,":", $D15)), offshore!$4:$4, AF$4) -> 4970.5 | AG15: =MAX(AVERAGE(TREND($W15:$AF15,$W$4:$AF$4,AG$4), TREND($AB15:$AF15,$AB$4:$AF$4,AG$4)) * AJ15, AF15* 1.03) -> 5275.7117 | AH15: =AVERAGE(TREND($W15:$AG15,$W$4:$AG$4,AH$4), TREND($AB15:$AG15,$AB$4:$AG$4,AH$4)) * AK15 -> 5965.4331 | AJ15: 1 | AK15: 1
B16: =E16&"00" -> PT00 | C16: =MATCH($E16, wind!$C:$C, 0) -> 18 | D16: =IFERROR(MATCH($E16, offshore!$D:$D, 0), 1) -> 14 | E16: PT | F16: =SUMIFS( INDIRECT(CONCATENATE("'wind'!", $C16, ":", $C16)), wind!$6:$6, F$4) - SUMIFS( INDIRECT(CONCATENATE("offshore!",$D16,":", $D16)), offshore!$4:$4, F$4) -> 60 | G16: =SUMIFS( INDIRECT(CONCATENATE("'wind'!", $C16, ":", $C16)), wind!$6:$6, G$4) - SUMIFS( INDIRECT(CONCATENATE("offshore!",$D16,":", $D16)), offshore!$4:$4, G$4) -> 61 | H16: =SUMIFS( INDIRECT(CONCATENATE("'wind'!", $C16, ":", $C16)), wind!$6:$6, H$4) - SUMIFS( INDIRECT(CONCATENATE("offshore!",$D16,":", $D16)), offshore!$4:$4, H$4) -> 100 | I16: =SUMIFS( INDIRECT(CONCATENATE("'wind'!", $C16, ":", $C16)), wind!$6:$6, I$4) - SUMIFS( INDIRECT(CONCATENATE("offshore!",$D16,":", $D16)), offshore!$4:$4, I$4) -> 131 | J16: =SUMIFS( INDIRECT(CONCATENATE("'wind'!", $C16, ":", $C16)), wind!$6:$6, J$4) - SUMIFS( INDIRECT(CONCATENATE("offshore!",$D16,":", $D16)), offshore!$4:$4, J$4) -> 195 | K16: =SUMIFS( INDIRECT(CONCATENATE("'wind'!", $C16, ":", $C16)), wind!$6:$6, K$4) - SUMIFS( INDIRECT(CONCATENATE("offshore!",$D16,":", $D16)), offshore!$4:$4, K$4) -> 296 | L16: =SUMIFS( INDIRECT(CONCATENATE("'wind'!", $C16, ":", $C16)), wind!$6:$6, L$4) - SUMIFS( INDIRECT(CONCATENATE("offshore!",$D16,":", $D16)), offshore!$4:$4, L$4) -> 522 | M16: =SUMIFS( INDIRECT(CONCATENATE("'wind'!", $C16, ":", $C16)), wind!$6:$6, M$4) - SUMIFS( INDIRECT(CONCATENATE("offshore!",$D16,":", $D16)), offshore!$4:$4, M$4) -> 1022 | ... AF16: =SUMIFS( INDIRECT(CONCATENATE("'wind'!", $C16, ":", $C16)), wind!$6:$6, AF$4) - SUMIFS( INDIRECT(CONCATENATE("offshore!",$D16,":", $D16)), offshore!$4:$4, AF$4) -> 5938 | AG16: =MAX(AVERAGE(TREND($W16:$AF16,$W$4:$AF$4,AG$4), TREND($AB16:$AF16,$AB$4:$AF$4,AG$4)) * AJ16, AF16* 1.03) -> 6116.14 | AH16: =AVERAGE(TREND($W16:$AG16,$W$4:$AG$4,AH$4), TREND($AB16:$AG16,$AB$4:$AG$4,AH$4)) * AK16 -> 6603.8309 | AJ16: 1 | AK16: 1
B17: =E17&"00" -> BE00 | C17: =MATCH($E17, wind!$C:$C, 0) -> 19 | D17: =IFERROR(MATCH($E17, offshore!$D:$D, 0), 1) -> 9 | E17: BE | F17: =SUMIFS( INDIRECT(CONCATENATE("'wind'!", $C17, ":", $C17)), wind!$6:$6, F$4) - SUMIFS( INDIRECT(CONCATENATE("offshore!",$D17,":", $D17)), offshore!$4:$4, F$4) -> 6 | G17: =SUMIFS( INDIRECT(CONCATENATE("'wind'!", $C17, ":", $C17)), wind!$6:$6, G$4) - SUMIFS( INDIRECT(CONCATENATE("offshore!",$D17,":", $D17)), offshore!$4:$4, G$4) -> 6 | H17: =SUMIFS( INDIRECT(CONCATENATE("'wind'!", $C17, ":", $C17)), wind!$6:$6, H$4) - SUMIFS( INDIRECT(CONCATENATE("offshore!",$D17,":", $D17)), offshore!$4:$4, H$4) -> 13 | I17: =SUMIFS( INDIRECT(CONCATENATE("'wind'!", $C17, ":", $C17)), wind!$6:$6, I$4) - SUMIFS( INDIRECT(CONCATENATE("offshore!",$D17,":", $D17)), offshore!$4:$4, I$4) -> 32 | J17: =SUMIFS( INDIRECT(CONCATENATE("'wind'!", $C17, ":", $C17)), wind!$6:$6, J$4) - SUMIFS( INDIRECT(CONCATENATE("offshore!",$D17,":", $D17)), offshore!$4:$4, J$4) -> 35 | K17: =SUMIFS( INDIRECT(CONCATENATE("'wind'!", $C17, ":", $C17)), wind!$6:$6, K$4) - SUMIFS( INDIRECT(CONCATENATE("offshore!",$D17,":", $D17)), offshore!$4:$4, K$4) -> 68 | L17: =SUMIFS( INDIRECT(CONCATENATE("'wind'!", $C17, ":", $C17)), wind!$6:$6, L$4) - SUMIFS( INDIRECT(CONCATENATE("offshore!",$D17,":", $D17)), offshore!$4:$4, L$4) -> 96 | M17: =SUMIFS( INDIRECT(CONCATENATE("'wind'!", $C17, ":", $C17)), wind!$6:$6, M$4) - SUMIFS( INDIRECT(CONCATENATE("offshore!",$D17,":", $D17)), offshore!$4:$4, M$4) -> 167 | ... AF17: =SUMIFS( INDIRECT(CONCATENATE("'wind'!", $C17, ":", $C17)), wind!$6:$6, AF$4) - SUMIFS( INDIRECT(CONCATENATE("offshore!",$D17,":", $D17)), offshore!$4:$4, AF$4) -> 3386.2 | AG17: =MAX(AVERAGE(TREND($W17:$AF17,$W$4:$AF$4,AG$4), TREND($AB17:$AF17,$AB$4:$AF$4,AG$4)) * AJ17, AF17* 1.03) -> 3651.3 | AH17: =AVERAGE(TREND($W17:$AG17,$W$4:$AG$4,AH$4), TREND($AB17:$AG17,$AB$4:$AG$4,AH$4)) * AK17 -> 4765.7595 | AJ17: 1 | AK17: 1
C18: =MATCH($E18, wind!$C:$C, 0) -> 20 | D18: =IFERROR(MATCH($E18, offshore!$D:$D, 0), 1) -> 1 | E18: GR | F18: =SUMIFS( INDIRECT(CONCATENATE("'wind'!", $C18, ":", $C18)), wind!$6:$6, F$4) - SUMIFS( INDIRECT(CONCATENATE("offshore!",$D18,":", $D18)), offshore!$4:$4, F$4) -> 39 | G18: =SUMIFS( INDIRECT(CONCATENATE("'wind'!", $C18, ":", $C18)), wind!$6:$6, G$4) - SUMIFS( INDIRECT(CONCATENATE("offshore!",$D18,":", $D18)), offshore!$4:$4, G$4) -> 112 | H18: =SUMIFS( INDIRECT(CONCATENATE("'wind'!", $C18, ":", $C18)), wind!$6:$6, H$4) - SUMIFS( INDIRECT(CONCATENATE("offshore!",$D18,":", $D18)), offshore!$4:$4, H$4) -> 189 | I18: =SUMIFS( INDIRECT(CONCATENATE("'wind'!", $C18, ":", $C18)), wind!$6:$6, I$4) - SUMIFS( INDIRECT(CONCATENATE("offshore!",$D18,":", $D18)), offshore!$4:$4, I$4) -> 272 | J18: =SUMIFS( INDIRECT(CONCATENATE("'wind'!", $C18, ":", $C18)), wind!$6:$6, J$4) - SUMIFS( INDIRECT(CONCATENATE("offshore!",$D18,":", $D18)), offshore!$4:$4, J$4) -> 297 | K18: =SUMIFS( INDIRECT(CONCATENATE("'wind'!", $C18, ":", $C18)), wind!$6:$6, K$4) - SUMIFS( INDIRECT(CONCATENATE("offshore!",$D18,":", $D18)), offshore!$4:$4, K$4) -> 383 | L18: =SUMIFS( INDIRECT(CONCATENATE("'wind'!", $C18, ":", $C18)), wind!$6:$6, L$4) - SUMIFS( INDIRECT(CONCATENATE("offshore!",$D18,":", $D18)), offshore!$4:$4, L$4) -> 473 | M18: =SUMIFS( INDIRECT(CONCATENATE("'wind'!", $C18, ":", $C18)), wind!$6:$6, M$4) - SUMIFS( INDIRECT(CONCATENATE("offshore!",$D18,":", $D18)), offshore!$4:$4, M$4) -> 573 | ... AF18: =SUMIFS( INDIRECT(CONCATENATE("'wind'!", $C18, ":", $C18)), wind!$6:$6, AF$4) - SUMIFS( INDIRECT(CONCATENATE("offshore!",$D18,":", $D18)), offshore!$4:$4, AF$4) -> 5354 | AG18: =MAX(AVERAGE(TREND($W18:$AF18,$W$4:$AF$4,AG$4), TREND($AB18:$AF18,$AB$4:$AF$4,AG$4)) * AJ18, AF18* 1.03) -> 5815.5333 | AH18: =AVERAGE(TREND($W18:$AG18,$W$4:$AG$4,AH$4), TREND($AB18:$AG18,$AB$4:$AG$4,AH$4)) * AK18 -> 7631.3241 | AJ18: 1 | AK18: 1
C19: =MATCH($E19, wind!$C:$C, 0) -> 21 | D19: =IFERROR(MATCH($E19, offshore!$D:$D, 0), 1) -> 20 | E19: NO | F19: =SUMIFS( INDIRECT(CONCATENATE("'wind'!", $C19, ":", $C19)), wind!$6:$6, F$4) - SUMIFS( INDIRECT(CONCATENATE("offshore!",$D19,":", $D19)), offshore!$4:$4, F$4) -> 0 | G19: =SUMIFS( INDIRECT(CONCATENATE("'wind'!", $C19, ":", $C19)), wind!$6:$6, G$4) - SUMIFS( INDIRECT(CONCATENATE("offshore!",$D19,":", $D19)), offshore!$4:$4, G$4) -> 0 | H19: =SUMIFS( INDIRECT(CONCATENATE("'wind'!", $C19, ":", $C19)), wind!$6:$6, H$4) - SUMIFS( INDIRECT(CONCATENATE("offshore!",$D19,":", $D19)), offshore!$4:$4, H$4) -> 0 | I19: =SUMIFS( INDIRECT(CONCATENATE("'wind'!", $C19, ":", $C19)), wind!$6:$6, I$4) - SUMIFS( INDIRECT(CONCATENATE("offshore!",$D19,":", $D19)), offshore!$4:$4, I$4) -> 0 | J19: =SUMIFS( INDIRECT(CONCATENATE("'wind'!", $C19, ":", $C19)), wind!$6:$6, J$4) - SUMIFS( INDIRECT(CONCATENATE("offshore!",$D19,":", $D19)), offshore!$4:$4, J$4) -> 0 | K19: =SUMIFS( INDIRECT(CONCATENATE("'wind'!", $C19, ":", $C19)), wind!$6:$6, K$4) - SUMIFS( INDIRECT(CONCATENATE("offshore!",$D19,":", $D19)), offshore!$4:$4, K$4) -> 101 | L19: =SUMIFS( INDIRECT(CONCATENATE("'wind'!", $C19, ":", $C19)), wind!$6:$6, L$4) - SUMIFS( INDIRECT(CONCATENATE("offshore!",$D19,":", $D19)), offshore!$4:$4, L$4) -> 160 | M19: =SUMIFS( INDIRECT(CONCATENATE("'wind'!", $C19, ":", $C19)), wind!$6:$6, M$4) - SUMIFS( INDIRECT(CONCATENATE("offshore!",$D19,":", $D19)), offshore!$4:$4, M$4) -> 267 | ... AF19: =SUMIFS( INDIRECT(CONCATENATE("'wind'!", $C19, ":", $C19)), wind!$6:$6, AF$4) - SUMIFS( INDIRECT(CONCATENATE("offshore!",$D19,":", $D19)), offshore!$4:$4, AF$4) -> 5093.4 | AG19: =MAX(AVERAGE(TREND($W19:$AF19,$W$4:$AF$4,AG$4), TREND($AB19:$AF19,$AB$4:$AF$4,AG$4)) * AJ19, AF19* 1.03) -> 5984.9067 | AH19: =AVERAGE(TREND($W19:$AG19,$W$4:$AG$4,AH$4), TREND($AB19:$AG19,$AB$4:$AG$4,AH$4)) * AK19 -> 8285.8488 | AJ19: 1 | AK19: 1
C20: =MATCH($E20, wind!$C:$C, 0) -> 22 | D20: =IFERROR(MATCH($E20, offshore!$D:$D, 0), 1) -> 12 | E20: IE | F20: =SUMIFS( INDIRECT(CONCATENATE("'wind'!", $C20, ":", $C20)), wind!$6:$6, F$4) - SUMIFS( INDIRECT(CONCATENATE("offshore!",$D20,":", $D20)), offshore!$4:$4, F$4) -> 73 | G20: =SUMIFS( INDIRECT(CONCATENATE("'wind'!", $C20, ":", $C20)), wind!$6:$6, G$4) - SUMIFS( INDIRECT(CONCATENATE("offshore!",$D20,":", $D20)), offshore!$4:$4, G$4) -> 74 | H20: =SUMIFS( INDIRECT(CONCATENATE("'wind'!", $C20, ":", $C20)), wind!$6:$6, H$4) - SUMIFS( INDIRECT(CONCATENATE("offshore!",$D20,":", $D20)), offshore!$4:$4, H$4) -> 118 | I20: =SUMIFS( INDIRECT(CONCATENATE("'wind'!", $C20, ":", $C20)), wind!$6:$6, I$4) - SUMIFS( INDIRECT(CONCATENATE("offshore!",$D20,":", $D20)), offshore!$4:$4, I$4) -> 124 | J20: =SUMIFS( INDIRECT(CONCATENATE("'wind'!", $C20, ":", $C20)), wind!$6:$6, J$4) - SUMIFS( INDIRECT(CONCATENATE("offshore!",$D20,":", $D20)), offshore!$4:$4, J$4) -> 137 | K20: =SUMIFS( INDIRECT(CONCATENATE("'wind'!", $C20, ":", $C20)), wind!$6:$6, K$4) - SUMIFS( INDIRECT(CONCATENATE("offshore!",$D20,":", $D20)), offshore!$4:$4, K$4) -> 190 | L20: =SUMIFS( INDIRECT(CONCATENATE("'wind'!", $C20, ":", $C20)), wind!$6:$6, L$4) - SUMIFS( INDIRECT(CONCATENATE("offshore!",$D20,":", $D20)), offshore!$4:$4, L$4) -> 339 | M20: =SUMIFS( INDIRECT(CONCATENATE("'wind'!", $C20, ":", $C20)), wind!$6:$6, M$4) - SUMIFS( INDIRECT(CONCATENATE("offshore!",$D20,":", $D20)), offshore!$4:$4, M$4) -> 496 | ... AF20: =SUMIFS( INDIRECT(CONCATENATE("'wind'!", $C20, ":", $C20)), wind!$6:$6, AF$4) - SUMIFS( INDIRECT(CONCATENATE("offshore!",$D20,":", $D20)), offshore!$4:$4, AF$4) -> 4836 | AG20: =MAX(AVERAGE(TREND($W20:$AF20,$W$4:$AF$4,AG$4), TREND($AB20:$AF20,$AB$4:$AF$4,AG$4)) * AJ20, AF20* 1.03) -> 5221.2933 | AH20: =AVERAGE(TREND($W20:$AG20,$W$4:$AG$4,AH$4), TREND($AB20:$AG20,$AB$4:$AG$4,AH$4)) * AK20 -> 6350.2421 | AJ20: 1 | AK20: 1
B21: =E21&"00" -> AT00 | C21: =MATCH($E21, wind!$C:$C, 0) -> 23 | D21: =IFERROR(MATCH($E21, offshore!$D:$D, 0), 1) -> 1 | E21: AT | F21: =SUMIFS( INDIRECT(CONCATENATE("'wind'!", $C21, ":", $C21)), wind!$6:$6, F$4) - SUMIFS( INDIRECT(CONCATENATE("offshore!",$D21,":", $D21)), offshore!$4:$4, F$4) -> 30 | G21: =SUMIFS( INDIRECT(CONCATENATE("'wind'!", $C21, ":", $C21)), wind!$6:$6, G$4) - SUMIFS( INDIRECT(CONCATENATE("offshore!",$D21,":", $D21)), offshore!$4:$4, G$4) -> 34 | H21: =SUMIFS( INDIRECT(CONCATENATE("'wind'!", $C21, ":", $C21)), wind!$6:$6, H$4) - SUMIFS( INDIRECT(CONCATENATE("offshore!",$D21,":", $D21)), offshore!$4:$4, H$4) -> 77 | I21: =SUMIFS( INDIRECT(CONCATENATE("'wind'!", $C21, ":", $C21)), wind!$6:$6, I$4) - SUMIFS( INDIRECT(CONCATENATE("offshore!",$D21,":", $D21)), offshore!$4:$4, I$4) -> 94 | J21: =SUMIFS( INDIRECT(CONCATENATE("'wind'!", $C21, ":", $C21)), wind!$6:$6, J$4) - SUMIFS( INDIRECT(CONCATENATE("offshore!",$D21,":", $D21)), offshore!$4:$4, J$4) -> 140 | K21: =SUMIFS( INDIRECT(CONCATENATE("'wind'!", $C21, ":", $C21)), wind!$6:$6, K$4) - SUMIFS( INDIRECT(CONCATENATE("offshore!",$D21,":", $D21)), offshore!$4:$4, K$4) -> 415 | L21: =SUMIFS( INDIRECT(CONCATENATE("'wind'!", $C21, ":", $C21)), wind!$6:$6, L$4) - SUMIFS( INDIRECT(CONCATENATE("offshore!",$D21,":", $D21)), offshore!$4:$4, L$4) -> 606 | M21: =SUMIFS( INDIRECT(CONCATENATE("'wind'!", $C21, ":", $C21)), wind!$6:$6, M$4) - SUMIFS( INDIRECT(CONCATENATE("offshore!",$D21,":", $D21)), offshore!$4:$4, M$4) -> 819 | ... AF21: =SUMIFS( INDIRECT(CONCATENATE("'wind'!", $C21, ":", $C21)), wind!$6:$6, AF$4) - SUMIFS( INDIRECT(CONCATENATE("offshore!",$D21,":", $D21)), offshore!$4:$4, AF$4) -> 4028 | AG21: =MAX(AVERAGE(TREND($W21:$AF21,$W$4:$AF$4,AG$4), TREND($AB21:$AF21,$AB$4:$AF$4,AG$4)) * AJ21, AF21* 1.03) -> 4216.45 | AH21: =AVERAGE(TREND($W21:$AG21,$W$4:$AG$4,AH$4), TREND($AB21:$AG21,$AB$4:$AG$4,AH$4)) * AK21 -> 5209.1177 | AJ21: 1 | AK21: 1
C22: =MATCH($E22, wind!$C:$C, 0) -> 24 | D22: =IFERROR(MATCH($E22, offshore!$D:$D, 0), 1) -> 1 | E22: RO | F22: =SUMIFS( INDIRECT(CONCATENATE("'wind'!", $C22, ":", $C22)), wind!$6:$6, F$4) - SUMIFS( INDIRECT(CONCATENATE("offshore!",$D22,":", $D22)), offshore!$4:$4, F$4) -> 0 | G22: =SUMIFS( INDIRECT(CONCATENATE("'wind'!", $C22, ":", $C22)), wind!$6:$6, G$4) - SUMIFS( INDIRECT(CONCATENATE("offshore!",$D22,":", $D22)), offshore!$4:$4, G$4) -> 0 | H22: =SUMIFS( INDIRECT(CONCATENATE("'wind'!", $C22, ":", $C22)), wind!$6:$6, H$4) - SUMIFS( INDIRECT(CONCATENATE("offshore!",$D22,":", $D22)), offshore!$4:$4, H$4) -> 0 | I22: =SUMIFS( INDIRECT(CONCATENATE("'wind'!", $C22, ":", $C22)), wind!$6:$6, I$4) - SUMIFS( INDIRECT(CONCATENATE("offshore!",$D22,":", $D22)), offshore!$4:$4, I$4) -> 0 | J22: =SUMIFS( INDIRECT(CONCATENATE("'wind'!", $C22, ":", $C22)), wind!$6:$6, J$4) - SUMIFS( INDIRECT(CONCATENATE("offshore!",$D22,":", $D22)), offshore!$4:$4, J$4) -> 0 | K22: =SUMIFS( INDIRECT(CONCATENATE("'wind'!", $C22, ":", $C22)), wind!$6:$6, K$4) - SUMIFS( INDIRECT(CONCATENATE("offshore!",$D22,":", $D22)), offshore!$4:$4, K$4) -> 1 | L22: =SUMIFS( INDIRECT(CONCATENATE("'wind'!", $C22, ":", $C22)), wind!$6:$6, L$4) - SUMIFS( INDIRECT(CONCATENATE("offshore!",$D22,":", $D22)), offshore!$4:$4, L$4) -> 1 | M22: =SUMIFS( INDIRECT(CONCATENATE("'wind'!", $C22, ":", $C22)), wind!$6:$6, M$4) - SUMIFS( INDIRECT(CONCATENATE("offshore!",$D22,":", $D22)), offshore!$4:$4, M$4) -> 2 | ... AF22: =SUMIFS( INDIRECT(CONCATENATE("'wind'!", $C22, ":", $C22)), wind!$6:$6, AF$4) - SUMIFS( INDIRECT(CONCATENATE("offshore!",$D22,":", $D22)), offshore!$4:$4, AF$4) -> 3150 | AG22: =MAX(AVERAGE(TREND($W22:$AF22,$W$4:$AF$4,AG$4), TREND($AB22:$AF22,$AB$4:$AF$4,AG$4)) * AJ22, AF22* 1.03) -> 3244.5 | AH22: =AVERAGE(TREND($W22:$AG22,$W$4:$AG$4,AH$4), TREND($AB22:$AG22,$AB$4:$AG$4,AH$4)) * AK22 -> 3333.8593 | AJ22: 1 | AK22: 1
C23: =MATCH($E23, wind!$C:$C, 0) -> 25 | D23: =IFERROR(MATCH($E23, offshore!$D:$D, 0), 1) -> 1 | E23: RU | F23: =SUMIFS( INDIRECT(CONCATENATE("'wind'!", $C23, ":", $C23)), wind!$6:$6, F$4) - SUMIFS( INDIRECT(CONCATENATE("offshore!",$D23,":", $D23)), offshore!$4:$4, F$4) -> 0 | G23: =SUMIFS( INDIRECT(CONCATENATE("'wind'!", $C23, ":", $C23)), wind!$6:$6, G$4) - SUMIFS( INDIRECT(CONCATENATE("offshore!",$D23,":", $D23)), offshore!$4:$4, G$4) -> 0 | H23: =SUMIFS( INDIRECT(CONCATENATE("'wind'!", $C23, ":", $C23)), wind!$6:$6, H$4) - SUMIFS( INDIRECT(CONCATENATE("offshore!",$D23,":", $D23)), offshore!$4:$4, H$4) -> 0 | I23: =SUMIFS( INDIRECT(CONCATENATE("'wind'!", $C23, ":", $C23)), wind!$6:$6, I$4) - SUMIFS( INDIRECT(CONCATENATE("offshore!",$D23,":", $D23)), offshore!$4:$4, I$4) -> 0 | J23: =SUMIFS( INDIRECT(CONCATENATE("'wind'!", $C23, ":", $C23)), wind!$6:$6, J$4) - SUMIFS( INDIRECT(CONCATENATE("offshore!",$D23,":", $D23)), offshore!$4:$4, J$4) -> 0 | K23: =SUMIFS( INDIRECT(CONCATENATE("'wind'!", $C23, ":", $C23)), wind!$6:$6, K$4) - SUMIFS( INDIRECT(CONCATENATE("offshore!",$D23,":", $D23)), offshore!$4:$4, K$4) -> 0 | L23: =SUMIFS( INDIRECT(CONCATENATE("'wind'!", $C23, ":", $C23)), wind!$6:$6, L$4) - SUMIFS( INDIRECT(CONCATENATE("offshore!",$D23,":", $D23)), offshore!$4:$4, L$4) -> 0 | M23: =SUMIFS( INDIRECT(CONCATENATE("'wind'!", $C23, ":", $C23)), wind!$6:$6, M$4) - SUMIFS( INDIRECT(CONCATENATE("offshore!",$D23,":", $D23)), offshore!$4:$4, M$4) -> 0 | ... AE23: =SUMIFS( INDIRECT(CONCATENATE("'wind'!", $C23, ":", $C23)), wind!$6:$6, AE$4) - SUMIFS( INDIRECT(CONCATENATE("offshore!",$D23,":", $D23)), offshore!$4:$4, AE$4) -> 2043 | AF23: =AE23 -> 2043 | AG23: =MAX(AVERAGE(TREND($W23:$AF23,$W$4:$AF$4,AG$4), TREND($AB23:$AF23,$AB$4:$AF$4,AG$4)) * AJ23, AF23* 1.03) -> 2535.6333 | AH23: =AVERAGE(TREND($W23:$AG23,$W$4:$AG$4,AH$4), TREND($AB23:$AG23,$AB$4:$AG$4,AH$4)) * AK23 -> 3853.4912 | AJ23: 1 | AK23: 1
C24: =MATCH($E24, wind!$C:$C, 0) -> 26 | D24: =IFERROR(MATCH($E24, offshore!$D:$D, 0), 1) -> 1 | E24: UA | F24: =SUMIFS( INDIRECT(CONCATENATE("'wind'!", $C24, ":", $C24)), wind!$6:$6, F$4) - SUMIFS( INDIRECT(CONCATENATE("offshore!",$D24,":", $D24)), offshore!$4:$4, F$4) -> 0 | G24: =SUMIFS( INDIRECT(CONCATENATE("'wind'!", $C24, ":", $C24)), wind!$6:$6, G$4) - SUMIFS( INDIRECT(CONCATENATE("offshore!",$D24,":", $D24)), offshore!$4:$4, G$4) -> 0 | H24: =SUMIFS( INDIRECT(CONCATENATE("'wind'!", $C24, ":", $C24)), wind!$6:$6, H$4) - SUMIFS( INDIRECT(CONCATENATE("offshore!",$D24,":", $D24)), offshore!$4:$4, H$4) -> 0 | I24: =SUMIFS( INDIRECT(CONCATENATE("'wind'!", $C24, ":", $C24)), wind!$6:$6, I$4) - SUMIFS( INDIRECT(CONCATENATE("offshore!",$D24,":", $D24)), offshore!$4:$4, I$4) -> 0 | J24: =SUMIFS( INDIRECT(CONCATENATE("'wind'!", $C24, ":", $C24)), wind!$6:$6, J$4) - SUMIFS( INDIRECT(CONCATENATE("offshore!",$D24,":", $D24)), offshore!$4:$4, J$4) -> 0 | K24: =SUMIFS( INDIRECT(CONCATENATE("'wind'!", $C24, ":", $C24)), wind!$6:$6, K$4) - SUMIFS( INDIRECT(CONCATENATE("offshore!",$D24,":", $D24)), offshore!$4:$4, K$4) -> 0 | L24: =SUMIFS( INDIRECT(CONCATENATE("'wind'!", $C24, ":", $C24)), wind!$6:$6, L$4) - SUMIFS( INDIRECT(CONCATENATE("offshore!",$D24,":", $D24)), offshore!$4:$4, L$4) -> 0 | M24: =SUMIFS( INDIRECT(CONCATENATE("'wind'!", $C24, ":", $C24)), wind!$6:$6, M$4) - SUMIFS( INDIRECT(CONCATENATE("offshore!",$D24,":", $D24)), offshore!$4:$4, M$4) -> 77 | ... AF24: =SUMIFS( INDIRECT(CONCATENATE("'wind'!", $C24, ":", $C24)), wind!$6:$6, AF$4) - SUMIFS( INDIRECT(CONCATENATE("offshore!",$D24,":", $D24)), offshore!$4:$4, AF$4) -> 1947 | AG24: =MAX(AVERAGE(TREND($W24:$AF24,$W$4:$AF$4,AG$4), TREND($AB24:$AF24,$AB$4:$AF$4,AG$4)) * AJ24, AF24* 1.03) -> 2192.2833 | AH24: =AVERAGE(TREND($W24:$AG24,$W$4:$AG$4,AH$4), TREND($AB24:$AG24,$AB$4:$AG$4,AH$4)) * AK24 -> 3057.7397 | AJ24: 1 | AK24: 1
